Workbook
Name __FDS_UNIQUE_RANGE_ID_GENERATOR_COUNTER: 1
Name is: #REF!
Name MARKET_DATA: 'SCB Ticker Sheet'!$P$2:$R$13
Name NewToCopy: 'SCB Ticker Sheet'!$B$160:$N$161
Name sh: #REF!

Sheet BERNSTEIN Cover
K5: =TODAY() -> 46226
C10: For the exclusive use of ANDREW CHUNG at BERNSTEIN on 23-Jul-2026
C15: T-Mobile (TMUS)
C16: U.S. Media & Telecom
C18: Laurent Yoon | H18: laurent.yoon@bernsteinsg.com
C19: Martin Boruchowicz | H19: martin.boruchowicz@bernsteinsg.com
C20: Andrew Chung | H20: andrew.chung@bernsteinsg.com
C32: This model is directed to and intended only for our clients who are “eligible counterparties”, “professional clients”, “institutional investors” and/or “professional investors” as defined by applicable local regulations and must not be redistributed to retail clients. This model is being provided to you with the understanding that you are an investment professional familiar with its limitations and that it may not be reproduced, re-distributed, transmitted or otherwise made available to, or shared with, any third party. Clients may not create derivative works, resell, or commercially exploit any part of the information contained herein with any third party for any purpose without Bernstein’s express prior written consent. This restriction includes extracting data, using this content to develop indexes or products, or inputting any portion of the information contained herein into machine learning or artificial intelligence systems. The analysis contained herein is based on numerous assumptions. Different assumptions could result in materially different results. We believe that the data in this model obtained from public sources is reliable; however, we make no representation that such data is accurate or complete. Estimates of future performance in this model are based on assumptions that may not be realized due to unforeseen factors like market volatility/fluctuation. This model is not a research report, nor is it a substitute for our published research; on its own, this model should not be relied upon to make an investment decision. For our latest research reports, which contain information that may be used to support investment decisions and important disclosures, please see our website at https://www.bernsteinresearch.com.

Sheet Summary
A2: T-Mobile Finanical Summary | AH2: Check sum
A3: in $ millions | B3: 1Q21 | C3: 2Q21 | D3: 3Q21 | E3: 4Q21 | F3: 2021 | G3: 1Q22 | H3: 2Q22 | I3: 3Q22 | J3: 4Q22 | K3: 2022 | L3: 1Q23 | M3: 2Q23 | N3: 3Q23 | O3: 4Q23 | P3: 2023 | Q3: 1Q24 | R3: 2Q24 | S3: 3Q24 | T3: 4Q24 | U3: 2024 | V3: 1Q25 | W3: 2Q25 | X3: 3Q25 | Y3: 4Q25 | Z3: 2025E | AA3: 1Q26 | AB3: 2Q26 | AC3: 3Q26 | AD3: 4Q26 | AE3: 2026E | AH3: 2021 | AI3: =+AH3+1 -> 2022 | AJ3: =+AI3+1 -> 2023 | AK3: =+AJ3+1 -> 2024 | AL3: =+AK3+1 -> 2025 | AM3: =+AL3+1 -> 2026
A4: Income Statement
A5: Postpaid revenues | B5: ='FC - 3FS'!L6 -> 10303 | C5: ='FC - 3FS'!M6 -> 10492 | D5: ='FC - 3FS'!N6 -> 10804 | E5: ='FC - 3FS'!O6 -> 10963 | F5: ='FC - 3FS'!AM6 -> 42562 | G5: ='FC - 3FS'!P6 -> 11201 | H5: ='FC - 3FS'!Q6 -> 11445 | I5: ='FC - 3FS'!R6 -> 11548 | J5: ='FC - 3FS'!S6 -> 11725 | K5: ='FC - 3FS'!AN6 -> 45919 | L5: ='FC - 3FS'!T6 -> 11862 | M5: ='FC - 3FS'!U6 -> 12070 | N5: ='FC - 3FS'!V6 -> 12288 | O5: ='FC - 3FS'!W6 -> 12472 | P5: ='FC - 3FS'!AO6 -> 48692 | Q5: ='FC - 3FS'!X6 -> 12631 | R5: ='FC - 3FS'!Y6 -> 12899 | S5: ='FC - 3FS'!Z6 -> 13308 | T5: ='FC - 3FS'!AA6 -> 13502 | U5: ='FC - 3FS'!AP6 -> 52340 | V5: ='FC - 3FS'!AB6 -> 13594 | W5: ='FC - 3FS'!AC6 -> 14078 | X5: ='FC - 3FS'!AD6 -> 14882 | Y5: ='FC - 3FS'!AE6 -> 15201.075 | Z5: ='FC - 3FS'!AQ6 -> 57755.075 | AA5: ='FC - 3FS'!AF6 -> 15280.936 | AB5: ='FC - 3FS'!AG6 -> 15801.255 | AC5: ='FC - 3FS'!AH6 -> 16201.782 | AD5: ='FC - 3FS'!AI6 -> 16299.262 | AE5: ='FC - 3FS'!AR6 -> 63583.234 | AH5: =+SUM(B5:E5)=F5 -> TRUE | AI5: =+SUM(G5:J5)=K5 -> TRUE | AJ5: =+SUM(L5:O5)=P5 -> TRUE | AK5: =+SUM(Q5:T5)=U5 -> TRUE | AL5: =+SUM(V5:Y5)=Z5 -> TRUE | AM5: =+SUM(AA5:AD5)=AE5 -> TRUE
A6: Prepaid revenues | B6: ='FC - 3FS'!L7 -> 2351 | C6: ='FC - 3FS'!M7 -> 2427 | D6: ='FC - 3FS'!N7 -> 2481 | E6: ='FC - 3FS'!O7 -> 2474 | F6: ='FC - 3FS'!AM7 -> 9733 | G6: ='FC - 3FS'!P7 -> 2455 | H6: ='FC - 3FS'!Q7 -> 2469 | I6: ='FC - 3FS'!R7 -> 2484 | J6: ='FC - 3FS'!S7 -> 2449 | K6: ='FC - 3FS'!AN7 -> 9857 | L6: ='FC - 3FS'!T7 -> 2417 | M6: ='FC - 3FS'!U7 -> 2444 | N6: ='FC - 3FS'!V7 -> 2473 | O6: ='FC - 3FS'!W7 -> 2433 | P6: ='FC - 3FS'!AO7 -> 9767 | Q6: ='FC - 3FS'!X7 -> 2403 | R6: ='FC - 3FS'!Y7 -> 2592 | S6: ='FC - 3FS'!Z7 -> 2716 | T6: ='FC - 3FS'!AA7 -> 2688 | U6: ='FC - 3FS'!AP7 -> 10399 | V6: ='FC - 3FS'!AB7 -> 2643 | W6: ='FC - 3FS'!AC7 -> 2643 | X6: ='FC - 3FS'!AD7 -> 2625 | Y6: ='FC - 3FS'!AE7 -> 2603.7494 | Z6: ='FC - 3FS'!AQ7 -> 10514.749 | AA6: ='FC - 3FS'!AF7 -> 2557.3003 | AB6: ='FC - 3FS'!AG7 -> 2565.5624 | AC6: ='FC - 3FS'!AH7 -> 2549.753 | AD6: ='FC - 3FS'!AI7 -> 2556.1863 | AE6: ='FC - 3FS'!AR7 -> 10228.802 | AH6: =+SUM(B6:E6)=F6 -> TRUE | AI6: =+SUM(G6:J6)=K6 -> TRUE | AJ6: =+SUM(L6:O6)=P6 -> TRUE | AK6: =+SUM(Q6:T6)=U6 -> TRUE | AL6: =+SUM(V6:Y6)=Z6 -> TRUE | AM6: =+SUM(AA6:AD6)=AE6 -> TRUE
A7: Wholesale and other service revenues | B7: ='FC - 3FS'!L8 -> 1538 | C7: ='FC - 3FS'!M8 -> 1573 | D7: ='FC - 3FS'!N8 -> 1437 | E7: ='FC - 3FS'!O8 -> 1526 | F7: ='FC - 3FS'!AM8 -> 6074 | G7: ='FC - 3FS'!P8 -> 1472 | H7: ='FC - 3FS'!Q8 -> 1402 | I7: ='FC - 3FS'!R8 -> 1329 | J7: ='FC - 3FS'!S8 -> 1344 | K7: ='FC - 3FS'!AN8 -> 5547 | L7: ='FC - 3FS'!T8 -> 1267 | M7: ='FC - 3FS'!U8 -> 1224 | N7: ='FC - 3FS'!V8 -> 1153 | O7: ='FC - 3FS'!W8 -> 1138 | P7: ='FC - 3FS'!AO8 -> 4782 | Q7: ='FC - 3FS'!X8 -> 1062 | R7: ='FC - 3FS'!Y8 -> 938 | S7: ='FC - 3FS'!Z8 -> 701 | T7: ='FC - 3FS'!AA8 -> 738 | U7: ='FC - 3FS'!AP8 -> 3439 | V7: ='FC - 3FS'!AB8 -> 688 | W7: ='FC - 3FS'!AC8 -> 717 | X7: ='FC - 3FS'!AD8 -> 734 | Y7: ='FC - 3FS'!AE8 -> 752.76 | Z7: ='FC - 3FS'!AQ8 -> 2891.76 | AA7: ='FC - 3FS'!AF8 -> 694.88 | AB7: ='FC - 3FS'!AG8 -> 731.34 | AC7: ='FC - 3FS'!AH8 -> 756.02 | AD7: ='FC - 3FS'!AI8 -> 782.8704 | AE7: ='FC - 3FS'!AR8 -> 2965.1104 | AH7: =+SUM(B7:E7)=F7 -> TRUE | AI7: =+SUM(G7:J7)=K7 -> TRUE | AJ7: =+SUM(L7:O7)=P7 -> TRUE | AK7: =+SUM(Q7:T7)=U7 -> TRUE | AL7: =+SUM(V7:Y7)=Z7 -> TRUE | AM7: =+SUM(AA7:AD7)=AE7 -> TRUE
A8: Total service revenues | B8: =+SUM(B5:B7) -> 14192 | C8: =+SUM(C5:C7) -> 14492 | D8: =+SUM(D5:D7) -> 14722 | E8: =+SUM(E5:E7) -> 14963 | F8: =+SUM(F5:F7) -> 58369 | G8: =+SUM(G5:G7) -> 15128 | H8: =+SUM(H5:H7) -> 15316 | I8: =+SUM(I5:I7) -> 15361 | ... AE8: =+SUM(AE5:AE7) -> 76777.146 | AH8: =+SUM(B8:E8)=F8 -> TRUE | AI8: =+SUM(G8:J8)=K8 -> TRUE | AJ8: =+SUM(L8:O8)=P8 -> TRUE | AK8: =+SUM(Q8:T8)=U8 -> TRUE | AL8: =+ROUND(SUM(V8:Y8),0)=ROUND(Z8,0) -> TRUE | AM8: =+SUM(AA8:AD8)=AE8 -> TRUE
A9: Equipment revenues | B9: =+'FC - 3FS'!L12 -> 5346 | C9: =+'FC - 3FS'!M12 -> 5215 | D9: =+'FC - 3FS'!N12 -> 4660 | E9: =+'FC - 3FS'!O12 -> 5506 | F9: =+'FC - 3FS'!AM12 -> 20727 | G9: =+'FC - 3FS'!P12 -> 4694 | H9: =+'FC - 3FS'!Q12 -> 4130 | I9: =+'FC - 3FS'!R12 -> 3855 | J9: =+'FC - 3FS'!S12 -> 4451 | K9: =+'FC - 3FS'!AN12 -> 17130 | L9: =+'FC - 3FS'!T12 -> 3719 | M9: =+'FC - 3FS'!U12 -> 3169 | N9: =+'FC - 3FS'!V12 -> 3076 | O9: =+'FC - 3FS'!W12 -> 4174 | P9: =+'FC - 3FS'!AO12 -> 14138 | Q9: =+'FC - 3FS'!X12 -> 3251 | R9: =+'FC - 3FS'!Y12 -> 3106 | S9: =+'FC - 3FS'!Z12 -> 3207 | T9: =+'FC - 3FS'!AA12 -> 4699 | U9: =+'FC - 3FS'!AP12 -> 14263 | V9: =+'FC - 3FS'!AB12 -> 3704 | W9: =+'FC - 3FS'!AC12 -> 3439 | X9: =+'FC - 3FS'!AD12 -> 3465 | Y9: =+'FC - 3FS'!AE12 -> 5051.1421 | Z9: =+'FC - 3FS'!AQ12 -> 15659.142 | AA9: =+'FC - 3FS'!AF12 -> 3756.7179 | AB9: =+'FC - 3FS'!AG12 -> 3782.0806 | AC9: =+'FC - 3FS'!AH12 -> 3696.9684 | AD9: =+'FC - 3FS'!AI12 -> 5317.7985 | AE9: =+'FC - 3FS'!AR12 -> 16553.565 | AH9: =+SUM(B9:E9)=F9 -> TRUE | AI9: =+SUM(G9:J9)=K9 -> TRUE | AJ9: =+SUM(L9:O9)=P9 -> TRUE | AK9: =+SUM(Q9:T9)=U9 -> TRUE | AL9: =+SUM(V9:Y9)=Z9 -> TRUE | AM9: =+SUM(AA9:AD9)=AE9 -> TRUE
A10: Other revenues | B10: =+'FC - 3FS'!L13 -> 221 | C10: =+'FC - 3FS'!M13 -> 243 | D10: =+'FC - 3FS'!N13 -> 242 | E10: =+'FC - 3FS'!O13 -> 316 | F10: =+'FC - 3FS'!AM13 -> 1022 | G10: =+'FC - 3FS'!P13 -> 298 | H10: =+'FC - 3FS'!Q13 -> 255 | I10: =+'FC - 3FS'!R13 -> 261 | J10: =+'FC - 3FS'!S13 -> 304 | K10: =+'FC - 3FS'!AN13 -> 1118 | L10: =+'FC - 3FS'!T13 -> 367 | M10: =+'FC - 3FS'!U13 -> 289 | N10: =+'FC - 3FS'!V13 -> 262 | O10: =+'FC - 3FS'!W13 -> 261 | P10: =+'FC - 3FS'!AO13 -> 1179 | Q10: =+'FC - 3FS'!X13 -> 247 | R10: =+'FC - 3FS'!Y13 -> 237 | S10: =+'FC - 3FS'!Z13 -> 230 | T10: =+'FC - 3FS'!AA13 -> 245 | U10: =+'FC - 3FS'!AP13 -> 959 | V10: =+'FC - 3FS'!AB13 -> 257 | W10: =+'FC - 3FS'!AC13 -> 255 | X10: =+'FC - 3FS'!AD13 -> 251 | Y10: =+'FC - 3FS'!AE13 -> 263.76916 | Z10: =+'FC - 3FS'!AQ13 -> 1026.7692 | AA10: =+'FC - 3FS'!AF13 -> 260.45058 | AB10: =+'FC - 3FS'!AG13 -> 280.63226 | AC10: =+'FC - 3FS'!AH13 -> 267.82291 | AD10: =+'FC - 3FS'!AI13 -> 277.70492 | AE10: =+'FC - 3FS'!AR13 -> 1086.6107 | AH10: =+SUM(B10:E10)=F10 -> TRUE | AI10: =+SUM(G10:J10)=K10 -> TRUE | AJ10: =+SUM(L10:O10)=P10 -> TRUE | AK10: =+SUM(Q10:T10)=U10 -> TRUE | AL10: =+SUM(V10:Y10)=Z10 -> TRUE | AM10: =+SUM(AA10:AD10)=AE10 -> TRUE
A11: Total revenues | B11: =+SUM(B8:B10) -> 19759 | C11: =+SUM(C8:C10) -> 19950 | D11: =+SUM(D8:D10) -> 19624 | E11: =+SUM(E8:E10) -> 20785 | F11: =+SUM(F8:F10) -> 80118 | G11: =+SUM(G8:G10) -> 20120 | H11: =+SUM(H8:H10) -> 19701 | I11: =+SUM(I8:I10) -> 19477 | ... AE11: =+SUM(AE8:AE10) -> 94417.322 | AH11: =+SUM(B11:E11)=F11 -> TRUE | AI11: =+SUM(G11:J11)=K11 -> TRUE | AJ11: =+SUM(L11:O11)=P11 -> TRUE | AK11: =+SUM(Q11:T11)=U11 -> TRUE | AL11: =+ROUND(SUM(V11:Y11),1)=ROUND(Z11,1) -> TRUE | AM11: =+SUM(AA11:AD11)=AE11 -> TRUE
A12: Operating expenses
A13: Cost of services, exclusive of D&A | B13: =+'FC - 3FS'!L16 -> 3384 | C13: =+'FC - 3FS'!M16 -> 3491 | D13: =+'FC - 3FS'!N16 -> 3538 | E13: =+'FC - 3FS'!O16 -> 3521 | F13: =+'FC - 3FS'!AM16 -> 13934 | G13: =+'FC - 3FS'!P16 -> 3727 | H13: =+'FC - 3FS'!Q16 -> 4060 | I13: =+'FC - 3FS'!R16 -> 3712 | J13: =+'FC - 3FS'!S16 -> 3167 | K13: =+'FC - 3FS'!AN16 -> 14666 | L13: =+'FC - 3FS'!T16 -> 3061 | M13: =+'FC - 3FS'!U16 -> 2916 | N13: =+'FC - 3FS'!V16 -> 2886 | O13: =+'FC - 3FS'!W16 -> 2792 | P13: =+'FC - 3FS'!AO16 -> 11655 | Q13: =+'FC - 3FS'!X16 -> 2688 | R13: =+'FC - 3FS'!Y16 -> 2664 | S13: =+'FC - 3FS'!Z16 -> 2722 | T13: =+'FC - 3FS'!AA16 -> 2697 | U13: =+'FC - 3FS'!AP16 -> 10771 | V13: =+'FC - 3FS'!AB16 -> 2602 | W13: =+'FC - 3FS'!AC16 -> 2717 | X13: =+'FC - 3FS'!AD16 -> 2873 | Y13: =+'FC - 3FS'!AE16 -> 2938.0707 | Z13: =+'FC - 3FS'!AQ16 -> 11130.071 | AA13: =+'FC - 3FS'!AF16 -> 2830.694 | AB13: =+'FC - 3FS'!AG16 -> 2956.5695 | AC13: =+'FC - 3FS'!AH16 -> 3052.9778 | AD13: =+'FC - 3FS'!AI16 -> 3089.5363 | AE13: =+'FC - 3FS'!AR16 -> 11929.777 | AH13: =+SUM(B13:E13)=F13 -> TRUE | AI13: =+SUM(G13:J13)=K13 -> TRUE | AJ13: =+SUM(L13:O13)=P13 -> TRUE | AK13: =+SUM(Q13:T13)=U13 -> TRUE | AL13: =+SUM(V13:Y13)=Z13 -> TRUE | AM13: =+SUM(AA13:AD13)=AE13 -> TRUE
A14: Cost of equipment sales, exclusive of D&A | B14: =+'FC - 3FS'!L17 -> 5142 | C14: =+'FC - 3FS'!M17 -> 5453 | D14: =+'FC - 3FS'!N17 -> 5145 | E14: =+'FC - 3FS'!O17 -> 6931 | F14: =+'FC - 3FS'!AM17 -> 22671 | G14: =+'FC - 3FS'!P17 -> 5946 | H14: =+'FC - 3FS'!Q17 -> 5108 | I14: =+'FC - 3FS'!R17 -> 4982 | J14: =+'FC - 3FS'!S17 -> 5504 | K14: =+'FC - 3FS'!AN17 -> 21540 | L14: =+'FC - 3FS'!T17 -> 4588 | M14: =+'FC - 3FS'!U17 -> 4088 | N14: =+'FC - 3FS'!V17 -> 4249 | O14: =+'FC - 3FS'!W17 -> 5608 | P14: =+'FC - 3FS'!AO17 -> 18533 | Q14: =+'FC - 3FS'!X17 -> 4399 | R14: =+'FC - 3FS'!Y17 -> 4088 | S14: =+'FC - 3FS'!Z17 -> 4307 | T14: =+'FC - 3FS'!AA17 -> 6088 | U14: =+'FC - 3FS'!AP17 -> 18882 | V14: =+'FC - 3FS'!AB17 -> 4798 | W14: =+'FC - 3FS'!AC17 -> 4659 | X14: =+'FC - 3FS'!AD17 -> 4853 | Y14: =+'FC - 3FS'!AE17 -> 6907.6944 | Z14: =+'FC - 3FS'!AQ17 -> 21217.694 | AA14: =+'FC - 3FS'!AF17 -> 4862.4198 | AB14: =+'FC - 3FS'!AG17 -> 5127.3165 | AC14: =+'FC - 3FS'!AH17 -> 5178.2652 | AD14: =+'FC - 3FS'!AI17 -> 7272.6497 | AE14: =+'FC - 3FS'!AR17 -> 22440.651 | AH14: =+SUM(B14:E14)=F14 -> TRUE | AI14: =+SUM(G14:J14)=K14 -> TRUE | AJ14: =+SUM(L14:O14)=P14 -> TRUE | AK14: =+SUM(Q14:T14)=U14 -> TRUE | AL14: =+SUM(V14:Y14)=Z14 -> TRUE | AM14: =+SUM(AA14:AD14)=AE14 -> TRUE
A15: Selling, general and administrative | B15: =+'FC - 3FS'!L18 -> 4805 | C15: =+'FC - 3FS'!M18 -> 4823 | D15: =+'FC - 3FS'!N18 -> 5212 | E15: =+'FC - 3FS'!O18 -> 5398 | F15: =+'FC - 3FS'!AM18 -> 20238 | G15: =+'FC - 3FS'!P18 -> 5056 | H15: =+'FC - 3FS'!Q18 -> 5856 | I15: =+'FC - 3FS'!R18 -> 5118 | J15: =+'FC - 3FS'!S18 -> 5577 | K15: =+'FC - 3FS'!AN18 -> 21607 | L15: =+'FC - 3FS'!T18 -> 5425 | M15: =+'FC - 3FS'!U18 -> 5272 | N15: =+'FC - 3FS'!V18 -> 5334 | O15: =+'FC - 3FS'!W18 -> 5280 | P15: =+'FC - 3FS'!AO18 -> 21311 | Q15: =+'FC - 3FS'!X18 -> 5138 | R15: =+'FC - 3FS'!Y18 -> 5142 | S15: =+'FC - 3FS'!Z18 -> 5186 | T15: =+'FC - 3FS'!AA18 -> 5352 | U15: =+'FC - 3FS'!AP18 -> 20818 | V15: =+'FC - 3FS'!AB18 -> 5488 | W15: =+'FC - 3FS'!AC18 -> 5397 | X15: =+'FC - 3FS'!AD18 -> 6015 | Y15: =+'FC - 3FS'!AE18 -> 6320.3537 | Z15: =+'FC - 3FS'!AQ18 -> 23220.354 | AA15: =+'FC - 3FS'!AF18 -> 6186.0398 | AB15: =+'FC - 3FS'!AG18 -> 6055.6418 | AC15: =+'FC - 3FS'!AH18 -> 6542.3422 | AD15: =+'FC - 3FS'!AI18 -> 6325.5909 | AE15: =+'FC - 3FS'!AR18 -> 25109.615 | AH15: =+SUM(B15:E15)=F15 -> TRUE | AI15: =+SUM(G15:J15)=K15 -> TRUE | AJ15: =+SUM(L15:O15)=P15 -> TRUE | AK15: =+SUM(Q15:T15)=U15 -> TRUE | AL15: =+SUM(V15:Y15)=Z15 -> TRUE | AM15: =+SUM(AA15:AD15)=AE15 -> TRUE
A16: Depreciation and amortization | B16: =+'FC - 3FS'!L21 -> 4289 | C16: =+'FC - 3FS'!M21 -> 4077 | D16: =+'FC - 3FS'!N21 -> 4145 | E16: =+'FC - 3FS'!O21 -> 3872 | F16: =+'FC - 3FS'!AM21 -> 16383 | G16: =+'FC - 3FS'!P21 -> 3585 | H16: =+'FC - 3FS'!Q21 -> 3491 | I16: =+'FC - 3FS'!R21 -> 3313 | J16: =+'FC - 3FS'!S21 -> 3262 | K16: =+'FC - 3FS'!AN21 -> 13651 | L16: =+'FC - 3FS'!T21 -> 3203 | M16: =+'FC - 3FS'!U21 -> 3110 | N16: =+'FC - 3FS'!V21 -> 3187 | O16: =+'FC - 3FS'!W21 -> 3318 | P16: =+'FC - 3FS'!AO21 -> 12818 | Q16: =+'FC - 3FS'!X21 -> 3371 | R16: =+'FC - 3FS'!Y21 -> 3248 | S16: =+'FC - 3FS'!Z21 -> 3151 | T16: =+'FC - 3FS'!AA21 -> 3149 | U16: =+'FC - 3FS'!AP21 -> 12919 | V16: =+'FC - 3FS'!AB21 -> 3198 | W16: =+'FC - 3FS'!AC21 -> 3146 | X16: =+'FC - 3FS'!AD21 -> 3408 | Y16: =+'FC - 3FS'!AE21 -> 3670.0321 | Z16: =+'FC - 3FS'!AQ21 -> 13422.032 | AA16: =+'FC - 3FS'!AF21 -> 3720.8608 | AB16: =+'FC - 3FS'!AG21 -> 3615.6245 | AC16: =+'FC - 3FS'!AH21 -> 3525.2306 | AD16: =+'FC - 3FS'!AI21 -> 3446.8785 | AE16: =+'FC - 3FS'!AR21 -> 14308.594 | AH16: =+SUM(B16:E16)=F16 -> TRUE | AI16: =+SUM(G16:J16)=K16 -> TRUE | AJ16: =+SUM(L16:O16)=P16 -> TRUE | AK16: =+SUM(Q16:T16)=U16 -> TRUE | AL16: =+SUM(V16:Y16)=Z16 -> TRUE | AM16: =+SUM(AA16:AD16)=AE16 -> TRUE
A17: Other OpEx | B17: =SUM('FC - 3FS'!L19:L20) -> 0 | C17: =SUM('FC - 3FS'!M19:M20) -> 0 | D17: =SUM('FC - 3FS'!N19:N20) -> 0 | E17: =SUM('FC - 3FS'!O19:O20) -> 0 | F17: =SUM('FC - 3FS'!AM19:AM20) -> 0 | G17: =SUM('FC - 3FS'!P19:P20) -> 0 | H17: =SUM('FC - 3FS'!Q19:Q20) -> 477 | I17: =SUM('FC - 3FS'!R19:R20) -> 1071 | J17: =SUM('FC - 3FS'!S19:S20) -> 16 | K17: =SUM('FC - 3FS'!AN19:AN20) -> 1564 | L17: =SUM('FC - 3FS'!T19:T20) -> -42 | M17: =SUM('FC - 3FS'!U19:U20) -> 17 | N17: =SUM('FC - 3FS'!V19:V20) -> 0 | O17: =SUM('FC - 3FS'!W19:W20) -> 0 | P17: =SUM('FC - 3FS'!AO19:AO20) -> -25 | Q17: =SUM('FC - 3FS'!X19:X20) -> 0 | R17: =SUM('FC - 3FS'!Y19:Y20) -> 0 | S17: =SUM('FC - 3FS'!Z19:Z20) -> 0 | T17: =SUM('FC - 3FS'!AA19:AA20) -> 0 | U17: =SUM('FC - 3FS'!AP19:AP20) -> 0 | V17: =SUM('FC - 3FS'!AB19:AB20) -> 0 | W17: =SUM('FC - 3FS'!AC19:AC20) -> 0 | X17: =SUM('FC - 3FS'!AD19:AD20) -> 278 | Y17: =SUM('FC - 3FS'!AE19:AE20) -> 0 | Z17: =SUM('FC - 3FS'!AQ19:AQ20) -> 278 | AA17: =SUM('FC - 3FS'!AF19:AF20) -> 0 | AB17: =SUM('FC - 3FS'!AG19:AG20) -> 0 | AC17: =SUM('FC - 3FS'!AH19:AH20) -> 0 | AD17: =SUM('FC - 3FS'!AI19:AI20) -> 0 | AE17: =SUM('FC - 3FS'!AR19:AR20) -> 0 | AH17: =+SUM(B17:E17)=F17 -> TRUE | AI17: =+SUM(G17:J17)=K17 -> TRUE | AJ17: =+SUM(L17:O17)=P17 -> TRUE | AK17: =+SUM(Q17:T17)=U17 -> TRUE | AL17: =+SUM(V17:Y17)=Z17 -> TRUE | AM17: =+SUM(AA17:AD17)=AE17 -> TRUE
A18: Operating income | B18: =B11-SUM(B13:B17) -> 2139 | C18: =C11-SUM(C13:C17) -> 2106 | D18: =D11-SUM(D13:D17) -> 1584 | E18: =E11-SUM(E13:E17) -> 1063 | F18: =F11-SUM(F13:F17) -> 6892 | G18: =G11-SUM(G13:G17) -> 1806 | H18: =H11-SUM(H13:H17) -> 709 | I18: =I11-SUM(I13:I17) -> 1281 | ... AE18: =AE11-SUM(AE13:AE17) -> 20628.685 | AH18: =+SUM(B18:E18)=F18 -> TRUE | AI18: =+SUM(G18:J18)=K18 -> TRUE | AJ18: =+SUM(L18:O18)=P18 -> TRUE | AK18: =+SUM(Q18:T18)=U18 -> TRUE | AL18: =+SUM(V18:Y18)=Z18 -> TRUE | AM18: =+SUM(AA18:AD18)=AE18 -> TRUE
A19: Other expense, net | B19: =+'FC - 3FS'!L27 -> -960 | C19: =+'FC - 3FS'!M27 -> -851 | D19: =+'FC - 3FS'!N27 -> -896 | E19: =+'FC - 3FS'!O27 -> -834 | F19: =+'FC - 3FS'!AM27 -> -3541 | G19: =+'FC - 3FS'!P27 -> -875 | H19: =+'FC - 3FS'!Q27 -> -872 | I19: =+'FC - 3FS'!R27 -> -830 | J19: =+'FC - 3FS'!S27 -> -820 | K19: =+'FC - 3FS'!AN27 -> -3397 | L19: =+'FC - 3FS'!T27 -> -826 | M19: =+'FC - 3FS'!U27 -> -855 | N19: =+'FC - 3FS'!V27 -> -749 | O19: =+'FC - 3FS'!W27 -> -837 | P19: =+'FC - 3FS'!AO27 -> -3267 | Q19: =+'FC - 3FS'!X27 -> -860 | R19: =+'FC - 3FS'!Y27 -> -862 | S19: =+'FC - 3FS'!Z27 -> -829 | T19: =+'FC - 3FS'!AA27 -> -747 | U19: =+'FC - 3FS'!AP27 -> -3298 | V19: =+'FC - 3FS'!AB27 -> -962 | W19: =+'FC - 3FS'!AC27 -> -933 | X19: =+'FC - 3FS'!AD27 -> -1002 | Y19: =+'FC - 3FS'!AE27 -> -1092.6249 | Z19: =+'FC - 3FS'!AQ27 -> -3989.6249 | AA19: =+'FC - 3FS'!AF27 -> -1011.0225 | AB19: =+'FC - 3FS'!AG27 -> -1022.2125 | AC19: =+'FC - 3FS'!AH27 -> -1051.9728 | AD19: =+'FC - 3FS'!AI27 -> -1077.5697 | AE19: =+'FC - 3FS'!AR27 -> -4162.7775 | AH19: =+SUM(B19:E19)=F19 -> TRUE | AI19: =+SUM(G19:J19)=K19 -> TRUE | AJ19: =+SUM(L19:O19)=P19 -> TRUE | AK19: =+SUM(Q19:T19)=U19 -> TRUE | AL19: =+SUM(V19:Y19)=Z19 -> TRUE | AM19: =+SUM(AA19:AD19)=AE19 -> TRUE
A20: Income (loss) before income taxes | B20: =+B18+B19 -> 1179 | C20: =+C18+C19 -> 1255 | D20: =+D18+D19 -> 688 | E20: =+E18+E19 -> 229 | F20: =+F18+F19 -> 3351 | G20: =+G18+G19 -> 931 | H20: =+H18+H19 -> -163 | I20: =+I18+I19 -> 451 | ... AE20: =+AE18+AE19 -> 16465.907 | AH20: =+SUM(B20:E20)=F20 -> TRUE | AI20: =+SUM(G20:J20)=K20 -> TRUE | AJ20: =+SUM(L20:O20)=P20 -> TRUE | AK20: =+SUM(Q20:T20)=U20 -> TRUE | AL20: =ROUND(SUM(V20:Y20),1)=ROUND(Z20,1) -> TRUE | AM20: =+SUM(AA20:AD20)=AE20 -> TRUE
A21: Income tax (expense) benefit | B21: =+'FC - 3FS'!L29 -> -246 | C21: =+'FC - 3FS'!M29 -> -277 | D21: =+'FC - 3FS'!N29 -> 3 | E21: =+'FC - 3FS'!O29 -> 193 | F21: =+'FC - 3FS'!AM29 -> -327 | G21: =+'FC - 3FS'!P29 -> -218 | H21: =+'FC - 3FS'!Q29 -> 55 | I21: =+'FC - 3FS'!R29 -> 57 | J21: =+'FC - 3FS'!S29 -> -450 | K21: =+'FC - 3FS'!AN29 -> -556 | L21: =+'FC - 3FS'!T29 -> -631 | M21: =+'FC - 3FS'!U29 -> -717 | N21: =+'FC - 3FS'!V29 -> -705 | O21: =+'FC - 3FS'!W29 -> -629 | P21: =+'FC - 3FS'!AO29 -> -2682 | Q21: =+'FC - 3FS'!X29 -> -764 | R21: =+'FC - 3FS'!Y29 -> -843 | S21: =+'FC - 3FS'!Z29 -> -908 | T21: =+'FC - 3FS'!AA29 -> -858 | U21: =+'FC - 3FS'!AP29 -> -3373 | V21: =+'FC - 3FS'!AB29 -> -885 | W21: =+'FC - 3FS'!AC29 -> -1058 | X21: =+'FC - 3FS'!AD29 -> -814 | Y21: =+'FC - 3FS'!AE29 -> -679.19148 | Z21: =+'FC - 3FS'!AQ29 -> -3436.1915 | AA21: =+'FC - 3FS'!AF29 -> -908.88543 | AB21: =+'FC - 3FS'!AG29 -> -1011.3869 | AC21: =+'FC - 3FS'!AH29 -> -950.94892 | AD21: =+'FC - 3FS'!AI29 -> -927.88543 | AE21: =+'FC - 3FS'!AR29 -> -3799.1067 | AH21: =+SUM(B21:E21)=F21 -> TRUE | AI21: =+SUM(G21:J21)=K21 -> TRUE | AJ21: =+SUM(L21:O21)=P21 -> TRUE | AK21: =+SUM(Q21:T21)=U21 -> TRUE | AL21: =+SUM(V21:Y21)=Z21 -> TRUE | AM21: =+SUM(AA21:AD21)=AE21 -> TRUE
A22: Net income (loss) | B22: =+B21+B20 -> 933 | C22: =+C21+C20 -> 978 | D22: =+D21+D20 -> 691 | E22: =+E21+E20 -> 422 | F22: =+F21+F20 -> 3024 | G22: =+G21+G20 -> 713 | H22: =+H21+H20 -> -108 | I22: =+I21+I20 -> 508 | ... AE22: =+AE21+AE20 -> 12666.801 | AH22: =+SUM(B22:E22)=F22 -> TRUE | AI22: =+SUM(G22:J22)=K22 -> TRUE | AJ22: =+SUM(L22:O22)=P22 -> TRUE | AK22: =+ROUND(SUM(Q22:T22),1)=ROUND(U22,1) -> TRUE | AL22: =+SUM(V22:Y22)=Z22 -> TRUE | AM22: =+SUM(AA22:AD22)=AE22 -> TRUE
A24: Basic EPS | B24: =+'FC - 3FS'!L35 -> 0.75028949 | C24: =+'FC - 3FS'!M35 -> 0.78392814 | D24: =+'FC - 3FS'!N35 -> 0.55360174 | E24: =+'FC - 3FS'!O35 -> 0.33779665 | F24: =+'FC - 3FS'!AM35 -> 2.4247187 | G24: =+'FC - 3FS'!P35 -> 0.5701692 | H24: =+'FC - 3FS'!Q35 -> -0.086129005 | I24: =+'FC - 3FS'!R35 -> 0.40514456 | J24: =+'FC - 3FS'!S35 -> 1.1903345 | K24: =+'FC - 3FS'!AN35 -> 2.0723914 | L24: =+'FC - 3FS'!T35 -> 1.5906746 | M24: =+'FC - 3FS'!U35 -> 1.8615701 | N24: =+'FC - 3FS'!V35 -> 1.8286805 | O24: =+'FC - 3FS'!W35 -> 1.7402374 | P24: =+'FC - 3FS'!AO35 -> 7.0178455 | Q24: =+'FC - 3FS'!X35 -> 2.002871 | R24: =+'FC - 3FS'!Y35 -> 2.4999447 | S24: =+'FC - 3FS'!Z35 -> 2.621337 | T24: =+'FC - 3FS'!AA35 -> 2.5816689 | U24: =+'FC - 3FS'!AP35 -> 9.6981225 | V24: =+'FC - 3FS'!AB35 -> 2.5891291 | W24: =+'FC - 3FS'!AC35 -> 2.8443789 | X24: =+'FC - 3FS'!AD35 -> 2.4151191 | Y24: =+'FC - 3FS'!AE35 -> 2.0011985 | Z24: =+'FC - 3FS'!AQ35 -> 9.8498256 | AA24: =+'FC - 3FS'!AF35 -> 2.7111826 | AB24: =+'FC - 3FS'!AG35 -> 3.0376562 | AC24: =+'FC - 3FS'!AH35 -> 2.8790239 | AD24: =+'FC - 3FS'!AI35 -> 2.7897559 | AE24: =+'FC - 3FS'!AR35 -> 11.417619 | AH24: =+ROUND(SUM(B24:E24),2)=ROUND(F24,2) -> FALSE | AI24: =+ROUND(SUM(G24:J24),2)=ROUND(K24,2) -> FALSE | AJ24: =ROUND(SUM(L24:O24),2)=ROUND(P24,2) -> TRUE | AK24: =ROUND(SUM(Q24:T24),2)=ROUND(U24,2) -> FALSE | AL24: =+SUM(V24:Y24)=Z24 -> TRUE | AM24: =+SUM(AA24:AD24)=AE24 -> TRUE
A25: Diluted EPS | B25: =+'FC - 3FS'!L36 -> 0.74474157 | C25: =+'FC - 3FS'!M36 -> 0.78007965 | D25: =+'FC - 3FS'!N36 -> 0.55118558 | E25: =+'FC - 3FS'!O36 -> 0.33644554 | F25: =+'FC - 3FS'!AM36 -> 2.4100036 | G25: =+'FC - 3FS'!P36 -> 0.56796068 | H25: =+'FC - 3FS'!Q36 -> -0.086129005 | I25: =+'FC - 3FS'!R36 -> 0.40342746 | J25: =+'FC - 3FS'!S36 -> 1.1845565 | K25: =+'FC - 3FS'!AN36 -> 2.0631256 | L25: =+'FC - 3FS'!T36 -> 1.5841847 | M25: =+'FC - 3FS'!U36 -> 1.857748 | N25: =+'FC - 3FS'!V36 -> 1.8239249 | O25: =+'FC - 3FS'!W36 -> 1.6713497 | P25: =+'FC - 3FS'!AO36 -> 6.9291804 | Q25: =+'FC - 3FS'!X36 -> 1.9964813 | R25: =+'FC - 3FS'!Y36 -> 2.4947815 | S25: =+'FC - 3FS'!Z36 -> 2.6130792 | T25: =+'FC - 3FS'!AA36 -> 2.5718325 | U25: =+'FC - 3FS'!AP36 -> 9.6649043 | V25: =+'FC - 3FS'!AB36 -> 2.579816 | W25: =+'FC - 3FS'!AC36 -> 2.8391493 | X25: =+'FC - 3FS'!AD36 -> 2.408959 | Y25: =+'FC - 3FS'!AE36 -> 1.9960941 | Z25: =+'FC - 3FS'!AQ36 -> 9.8240185 | AA25: =+'FC - 3FS'!AF36 -> 2.7042674 | AB25: =+'FC - 3FS'!AG36 -> 3.0299083 | AC25: =+'FC - 3FS'!AH36 -> 2.8716805 | AD25: =+'FC - 3FS'!AI36 -> 2.7826403 | AE25: =+'FC - 3FS'!AR36 -> 11.388496 | AH25: =+ROUND(SUM(B25:E25),2)=ROUND(F25,2) -> TRUE | AI25: =+ROUND(SUM(G25:J25),2)=ROUND(K25,2) -> FALSE | AJ25: =ROUND(SUM(L25:O25),2)=ROUND(P25,2) -> FALSE | AK25: =+SUM(Q25:T25)=U25 -> FALSE | AL25: =+SUM(V25:Y25)=Z25 -> TRUE | AM25: =+SUM(AA25:AD25)=AE25 -> TRUE
A26: Basic Shares Outstanding | B26: =+'FC - 3FS'!L38 -> 1243.52 | C26: =+'FC - 3FS'!M38 -> 1247.5633 | D26: =+'FC - 3FS'!N38 -> 1248.1897 | E26: =+'FC - 3FS'!O38 -> 1249.2723 | F26: =+'FC - 3FS'!AM38 -> 1247.155 | G26: =+'FC - 3FS'!P38 -> 1250.506 | H26: =+'FC - 3FS'!Q38 -> 1253.933 | I26: =+'FC - 3FS'!R38 -> 1253.8734 | J26: =+'FC - 3FS'!S38 -> 1240.8277 | K26: =+'FC - 3FS'!AN38 -> 1249.7639 | L26: =+'FC - 3FS'!T38 -> 1219.6084 | M26: =+'FC - 3FS'!U38 -> 1193.0789 | N26: =+'FC - 3FS'!V38 -> 1171.3364 | O26: =+'FC - 3FS'!W38 -> 1157.3134 | P26: =+'FC - 3FS'!AO38 -> 1185.1216 | Q26: =+'FC - 3FS'!X38 -> 1185.2985 | R26: =+'FC - 3FS'!Y38 -> 1170.0259 | S26: =+'FC - 3FS'!Z38 -> 1166.9618 | T26: =+'FC - 3FS'!AA38 -> 1154.6794 | U26: =+'FC - 3FS'!AP38 -> 1169.1954 | V26: =+'FC - 3FS'!AB38 -> 1140.5379 | W26: =+'FC - 3FS'!AC38 -> 1132.7605 | X26: =+'FC - 3FS'!AD38 -> 1123.7541 | Y26: =+'FC - 3FS'!AE38 -> 1131.5859 | Z26: =+'FC - 3FS'!AQ38 -> 1132.3579 | AA26: =+'FC - 3FS'!AF38 -> 1117.7272 | AB26: =+'FC - 3FS'!AG38 -> 1110.1053 | AC26: =+'FC - 3FS'!AH38 -> 1101.279 | AD26: =+'FC - 3FS'!AI38 -> 1108.9541 | AE26: =+'FC - 3FS'!AR38 -> 1109.4083
A27: Diluted Shares Outstanding | B27: =+'FC - 3FS'!L39 -> 1252.7836 | C27: =+'FC - 3FS'!M39 -> 1253.7181 | D27: =+'FC - 3FS'!N39 -> 1253.6612 | E27: =+'FC - 3FS'!O39 -> 1254.2892 | F27: =+'FC - 3FS'!AM39 -> 1254.7699 | G27: =+'FC - 3FS'!P39 -> 1255.3686 | H27: =+'FC - 3FS'!Q39 -> 1253.933 | I27: =+'FC - 3FS'!R39 -> 1259.2103 | J27: =+'FC - 3FS'!S39 -> 1246.8801 | K27: =+'FC - 3FS'!AN39 -> 1255.3768 | L27: =+'FC - 3FS'!T39 -> 1224.6047 | M27: =+'FC - 3FS'!U39 -> 1195.5335 | N27: =+'FC - 3FS'!V39 -> 1174.3905 | O27: =+'FC - 3FS'!W39 -> 1205.0141 | P27: =+'FC - 3FS'!AO39 -> 1200.2863 | Q27: =+'FC - 3FS'!X39 -> 1189.092 | R27: =+'FC - 3FS'!Y39 -> 1172.4474 | S27: =+'FC - 3FS'!Z39 -> 1170.6496 | T27: =+'FC - 3FS'!AA39 -> 1159.0957 | U27: =+'FC - 3FS'!AP39 -> 1173.2139 | V27: =+'FC - 3FS'!AB39 -> 1144.6553 | W27: =+'FC - 3FS'!AC39 -> 1134.847 | X27: =+'FC - 3FS'!AD39 -> 1126.6277 | Y27: =+'FC - 3FS'!AE39 -> 1134.4795 | Z27: =+'FC - 3FS'!AQ39 -> 1135.3325 | AA27: =+'FC - 3FS'!AF39 -> 1120.5854 | AB27: =+'FC - 3FS'!AG39 -> 1112.944 | AC27: =+'FC - 3FS'!AH39 -> 1104.0952 | AD27: =+'FC - 3FS'!AI39 -> 1111.7899 | AE27: =+'FC - 3FS'!AR39 -> 1112.2452
A29: Adj. EBITDA | B29: =+'FC - 3FS'!L56 -> 6905 | C29: =+'FC - 3FS'!M56 -> 6906 | D29: =+'FC - 3FS'!N56 -> 6811 | E29: =+'FC - 3FS'!O56 -> 6302 | F29: =+'FC - 3FS'!AM56 -> 26924 | G29: =+'FC - 3FS'!P56 -> 6950 | H29: =+'FC - 3FS'!Q56 -> 7004 | I29: =+'FC - 3FS'!R56 -> 7039 | J29: =+'FC - 3FS'!S56 -> 6828 | K29: =+'FC - 3FS'!AN56 -> 27821 | L29: =+'FC - 3FS'!T56 -> 7199 | M29: =+'FC - 3FS'!U56 -> 7405 | N29: =+'FC - 3FS'!V56 -> 7600 | O29: =+'FC - 3FS'!W56 -> 7224 | P29: =+'FC - 3FS'!AO56 -> 29428 | Q29: =+'FC - 3FS'!X56 -> 7652 | R29: =+'FC - 3FS'!Y56 -> 8053 | S29: =+'FC - 3FS'!Z56 -> 8243 | T29: =+'FC - 3FS'!AA56 -> 7916 | U29: =+'FC - 3FS'!AP56 -> 31864 | V29: =+'FC - 3FS'!AB56 -> 8259 | W29: =+'FC - 3FS'!AC56 -> 8547 | X29: =+'FC - 3FS'!AD56 -> 8684 | Y29: =+'FC - 3FS'!AE56 -> 8394.3925 | Z29: =+'FC - 3FS'!AQ56 -> 33884.392 | AA29: =+'FC - 3FS'!AF56 -> 9279.3016 | AB29: =+'FC - 3FS'!AG56 -> 9624.8083 | AC29: =+'FC - 3FS'!AH56 -> 9319.7855 | AD29: =+'FC - 3FS'!AI56 -> 9159.25 | AE29: =+'FC - 3FS'!AR56 -> 37383.145 | AH29: =+SUM(B29:E29)=F29 -> TRUE | AI29: =+SUM(G29:J29)=K29 -> TRUE | AJ29: =+SUM(L29:O29)=P29 -> TRUE | AK29: =+SUM(Q29:T29)=U29 -> TRUE | AL29: =+ROUND(SUM(V29:Y29),0)=ROUND(Z29,0) -> TRUE | AM29: =+SUM(AA29:AD29)=AE29 -> FALSE
A30: Adj. Core EBITDA | B30: =+'FC - 3FS'!L58 -> 5864 | C30: =+'FC - 3FS'!M58 -> 5992 | D30: =+'FC - 3FS'!N58 -> 6041 | E30: =+'FC - 3FS'!O58 -> 5679 | F30: =+'FC - 3FS'!AM58 -> 23576 | G30: =+'FC - 3FS'!P58 -> 6463 | H30: =+'FC - 3FS'!Q58 -> 6618 | I30: =+'FC - 3FS'!R58 -> 6728 | J30: =+'FC - 3FS'!S58 -> 6582 | K30: =+'FC - 3FS'!AN58 -> 26391 | L30: =+'FC - 3FS'!T58 -> 7052 | M30: =+'FC - 3FS'!U58 -> 7336 | N30: =+'FC - 3FS'!V58 -> 7547 | O30: =+'FC - 3FS'!W58 -> 7181 | P30: =+'FC - 3FS'!AO58 -> 29116 | Q30: =+'FC - 3FS'!X58 -> 7617 | R30: =+'FC - 3FS'!Y58 -> 8027 | S30: =+'FC - 3FS'!Z58 -> 8222 | T30: =+'FC - 3FS'!AA58 -> 7905 | U30: =+'FC - 3FS'!AP58 -> 31771 | V30: =+'FC - 3FS'!AB58 -> 8258 | W30: =+'FC - 3FS'!AC58 -> 8541 | X30: =+'FC - 3FS'!AD58 -> 8680 | Y30: =+'FC - 3FS'!AE58 -> 8390.3925 | Z30: =+'FC - 3FS'!AQ58 -> 33869.392 | AA30: =+'FC - 3FS'!AF58 -> 9275.3016 | AB30: =+'FC - 3FS'!AG58 -> 9620.8083 | AC30: =+'FC - 3FS'!AH58 -> 9315.7855 | AD30: =+'FC - 3FS'!AI58 -> 9155.25 | AE30: =+'FC - 3FS'!AR58 -> 37367.145 | AH30: =+SUM(B30:E30)=F30 -> TRUE | AI30: =+SUM(G30:J30)=K30 -> TRUE | AJ30: =+SUM(L30:O30)=P30 -> TRUE | AK30: =+SUM(Q30:T30)=U30 -> TRUE | AL30: =+ROUND(SUM(V30:Y30),0)=ROUND(Z30,0) -> TRUE | AM30: =+SUM(AA30:AD30)=AE30 -> FALSE
A32: Balance Sheet
A33: Total current assets | B33: =+'FC - 3FS'!L75 -> 18779 | C33: =+'FC - 3FS'!M75 -> 20570 | D33: =+'FC - 3FS'!N75 -> 16772 | E33: =+'FC - 3FS'!O75 -> 20891 | F33: =+'FC - 3FS'!AM75 -> 20891 | G33: =+'FC - 3FS'!P75 -> 17455 | H33: =+'FC - 3FS'!Q75 -> 17476 | I33: =+'FC - 3FS'!R75 -> 21427 | J33: =+'FC - 3FS'!S75 -> 19067 | K33: =+'FC - 3FS'!AN75 -> 19067 | L33: =+'FC - 3FS'!T75 -> 18876 | M33: =+'FC - 3FS'!U75 -> 20237 | N33: =+'FC - 3FS'!V75 -> 18669 | O33: =+'FC - 3FS'!W75 -> 19015 | P33: =+'FC - 3FS'!AO75 -> 19015 | Q33: =+'FC - 3FS'!X75 -> 19295 | R33: =+'FC - 3FS'!Y75 -> 19297 | S33: =+'FC - 3FS'!Z75 -> 22531 | T33: =+'FC - 3FS'!AA75 -> 18404 | U33: =+'FC - 3FS'!AP75 -> 18404 | V33: =+'FC - 3FS'!AB75 -> 27441 | W33: =+'FC - 3FS'!AC75 -> 26772 | X33: =+'FC - 3FS'!AD75 -> 21703 | Y33: =+'FC - 3FS'!AE75 -> 20285.235 | Z33: =+'FC - 3FS'!AQ75 -> 20285.235 | AA33: =+'FC - 3FS'!AF75 -> 20828.285 | AB33: =+'FC - 3FS'!AG75 -> 22703.216 | AC33: =+'FC - 3FS'!AH75 -> 25623.945 | AD33: =+'FC - 3FS'!AI75 -> 26887.641 | AE33: =+'FC - 3FS'!AR75 -> 26887.641 | AH33: =E33=F33 -> TRUE | AI33: =J33=K33 -> TRUE | AJ33: =O33=P33 -> TRUE | AK33: =T33=U33 -> TRUE | AL33: =Y33=Z33 -> TRUE | AM33: =AD33=AE33 -> TRUE
A34: Property and equipment, net | B34: =+'FC - 3FS'!L76 -> 40549 | C34: =+'FC - 3FS'!M76 -> 39752 | D34: =+'FC - 3FS'!N76 -> 39355 | E34: =+'FC - 3FS'!O76 -> 39803 | F34: =+'FC - 3FS'!AM76 -> 39803 | G34: =+'FC - 3FS'!P76 -> 40006 | H34: =+'FC - 3FS'!Q76 -> 40245 | I34: =+'FC - 3FS'!R76 -> 41034 | J34: =+'FC - 3FS'!S76 -> 42086 | K34: =+'FC - 3FS'!AN76 -> 42086 | L34: =+'FC - 3FS'!T76 -> 42053 | M34: =+'FC - 3FS'!U76 -> 41804 | N34: =+'FC - 3FS'!V76 -> 41080 | O34: =+'FC - 3FS'!W76 -> 40432 | P34: =+'FC - 3FS'!AO76 -> 40432 | Q34: =+'FC - 3FS'!X76 -> 39286 | R34: =+'FC - 3FS'!Y76 -> 38222 | S34: =+'FC - 3FS'!Z76 -> 37603 | T34: =+'FC - 3FS'!AA76 -> 38533 | U34: =+'FC - 3FS'!AP76 -> 38533 | V34: =+'FC - 3FS'!AB76 -> 37897 | W34: =+'FC - 3FS'!AC76 -> 37481 | X34: =+'FC - 3FS'!AD76 -> 38718 | Y34: =+'FC - 3FS'!AE76 -> 37585.235 | Z34: =+'FC - 3FS'!AQ76 -> 37585.235 | AA34: =+'FC - 3FS'!AF76 -> 36439.382 | AB34: =+'FC - 3FS'!AG76 -> 35450.659 | AC34: =+'FC - 3FS'!AH76 -> 34589.33 | AD34: =+'FC - 3FS'!AI76 -> 33838.887 | AE34: =+'FC - 3FS'!AR76 -> 33838.887 | AH34: =E34=F34 -> TRUE | AI34: =J34=K34 -> TRUE | AJ34: =O34=P34 -> TRUE | AK34: =T34=U34 -> TRUE | AL34: =Y34=Z34 -> TRUE | AM34: =AD34=AE34 -> TRUE
A35: Operating lease right-of-use assets | B35: =+'FC - 3FS'!L77 -> 27793 | C35: =+'FC - 3FS'!M77 -> 27511 | D35: =+'FC - 3FS'!N77 -> 27446 | E35: =+'FC - 3FS'!O77 -> 26959 | F35: =+'FC - 3FS'!AM77 -> 26959 | G35: =+'FC - 3FS'!P77 -> 31449 | H35: =+'FC - 3FS'!Q77 -> 30110 | I35: =+'FC - 3FS'!R77 -> 29264 | J35: =+'FC - 3FS'!S77 -> 28715 | K35: =+'FC - 3FS'!AN77 -> 28715 | L35: =+'FC - 3FS'!T77 -> 28146 | M35: =+'FC - 3FS'!U77 -> 27891 | N35: =+'FC - 3FS'!V77 -> 27568 | O35: =+'FC - 3FS'!W77 -> 27135 | P35: =+'FC - 3FS'!AO77 -> 27135 | Q35: =+'FC - 3FS'!X77 -> 26766 | R35: =+'FC - 3FS'!Y77 -> 26240 | S35: =+'FC - 3FS'!Z77 -> 25833 | T35: =+'FC - 3FS'!AA77 -> 25398 | U35: =+'FC - 3FS'!AP77 -> 25398 | V35: =+'FC - 3FS'!AB77 -> 25025 | W35: =+'FC - 3FS'!AC77 -> 24735 | X35: =+'FC - 3FS'!AD77 -> 26070 | Y35: =+'FC - 3FS'!AE77 -> 26969.97 | Z35: =+'FC - 3FS'!AQ77 -> 26969.97 | AA35: =+'FC - 3FS'!AF77 -> 25801.608 | AB35: =+'FC - 3FS'!AG77 -> 24589.387 | AC35: =+'FC - 3FS'!AH77 -> 26020.107 | AD35: =+'FC - 3FS'!AI77 -> 26996.866 | AE35: =+'FC - 3FS'!AR77 -> 26996.866 | AH35: =E35=F35 -> TRUE | AI35: =J35=K35 -> TRUE | AJ35: =O35=P35 -> TRUE | AK35: =T35=U35 -> TRUE | AL35: =Y35=Z35 -> TRUE | AM35: =AD35=AE35 -> TRUE
A36: Financing lease right-of-use assets | B36: =+'FC - 3FS'!L78 -> 2899 | C36: =+'FC - 3FS'!M78 -> 3072 | D36: =+'FC - 3FS'!N78 -> 3396 | E36: =+'FC - 3FS'!O78 -> 3322 | F36: =+'FC - 3FS'!AM78 -> 3322 | G36: =+'FC - 3FS'!P78 -> 3287 | H36: =+'FC - 3FS'!Q78 -> 3588 | I36: =+'FC - 3FS'!R78 -> 3619 | J36: =+'FC - 3FS'!S78 -> 3257 | K36: =+'FC - 3FS'!AN78 -> 3257 | L36: =+'FC - 3FS'!T78 -> 3282 | M36: =+'FC - 3FS'!U78 -> 3365 | N36: =+'FC - 3FS'!V78 -> 3390 | O36: =+'FC - 3FS'!W78 -> 3270 | P36: =+'FC - 3FS'!AO78 -> 3270 | Q36: =+'FC - 3FS'!X78 -> 3180 | R36: =+'FC - 3FS'!Y78 -> 3271 | S36: =+'FC - 3FS'!Z78 -> 3352 | T36: =+'FC - 3FS'!AA78 -> 3091 | U36: =+'FC - 3FS'!AP78 -> 3091 | V36: =+'FC - 3FS'!AB78 -> 2977 | W36: =+'FC - 3FS'!AC78 -> 3105 | X36: =+'FC - 3FS'!AD78 -> 2955 | Y36: =+'FC - 3FS'!AE78 -> 2962.1068 | Z36: =+'FC - 3FS'!AQ78 -> 2962.1068 | AA36: =+'FC - 3FS'!AF78 -> 2975.9763 | AB36: =+'FC - 3FS'!AG78 -> 2997.3839 | AC36: =+'FC - 3FS'!AH78 -> 3022.9234 | AD36: =+'FC - 3FS'!AI78 -> 3051.3194 | AE36: =+'FC - 3FS'!AR78 -> 3051.3194 | AH36: =E36=F36 -> TRUE | AI36: =J36=K36 -> TRUE | AJ36: =O36=P36 -> TRUE | AK36: =T36=U36 -> TRUE | AL36: =Y36=Z36 -> TRUE | AM36: =AD36=AE36 -> TRUE
A37: Goodwill | B37: =+'FC - 3FS'!L79 -> 11158 | C37: =+'FC - 3FS'!M79 -> 11152 | D37: =+'FC - 3FS'!N79 -> 12188 | E37: =+'FC - 3FS'!O79 -> 12188 | F37: =+'FC - 3FS'!AM79 -> 12188 | G37: =+'FC - 3FS'!P79 -> 12234 | H37: =+'FC - 3FS'!Q79 -> 12234 | I37: =+'FC - 3FS'!R79 -> 12234 | J37: =+'FC - 3FS'!S79 -> 12234 | K37: =+'FC - 3FS'!AN79 -> 12234 | L37: =+'FC - 3FS'!T79 -> 12234 | M37: =+'FC - 3FS'!U79 -> 12234 | N37: =+'FC - 3FS'!V79 -> 12234 | O37: =+'FC - 3FS'!W79 -> 12234 | P37: =+'FC - 3FS'!AO79 -> 12234 | Q37: =+'FC - 3FS'!X79 -> 12234 | R37: =+'FC - 3FS'!Y79 -> 13015 | S37: =+'FC - 3FS'!Z79 -> 13015 | T37: =+'FC - 3FS'!AA79 -> 13005 | U37: =+'FC - 3FS'!AP79 -> 13005 | V37: =+'FC - 3FS'!AB79 -> 13467 | W37: =+'FC - 3FS'!AC79 -> 13460 | X37: =+'FC - 3FS'!AD79 -> 13690 | Y37: =+'FC - 3FS'!AE79 -> 13690 | Z37: =+'FC - 3FS'!AQ79 -> 13690 | AA37: =+'FC - 3FS'!AF79 -> 13690 | AB37: =+'FC - 3FS'!AG79 -> 13690 | AC37: =+'FC - 3FS'!AH79 -> 13690 | AD37: =+'FC - 3FS'!AI79 -> 13690 | AE37: =+'FC - 3FS'!AR79 -> 13690 | AH37: =E37=F37 -> TRUE | AI37: =J37=K37 -> TRUE | AJ37: =O37=P37 -> TRUE | AK37: =T37=U37 -> TRUE | AL37: =Y37=Z37 -> TRUE | AM37: =AD37=AE37 -> TRUE
A38: Spectrum licenses | B38: =+'FC - 3FS'!L80 -> 82901 | C38: =+'FC - 3FS'!M80 -> 82917 | D38: =+'FC - 3FS'!N80 -> 92589 | E38: =+'FC - 3FS'!O80 -> 92606 | F38: =+'FC - 3FS'!AM80 -> 92606 | G38: =+'FC - 3FS'!P80 -> 92661 | H38: =+'FC - 3FS'!Q80 -> 95632 | I38: =+'FC - 3FS'!R80 -> 95767 | J38: =+'FC - 3FS'!S80 -> 95798 | K38: =+'FC - 3FS'!AN80 -> 95798 | L38: =+'FC - 3FS'!T80 -> 95878 | M38: =+'FC - 3FS'!U80 -> 95889 | N38: =+'FC - 3FS'!V80 -> 96689 | O38: =+'FC - 3FS'!W80 -> 96707 | P38: =+'FC - 3FS'!AO80 -> 96707 | Q38: =+'FC - 3FS'!X80 -> 97154 | R38: =+'FC - 3FS'!Y80 -> 98661 | S38: =+'FC - 3FS'!Z80 -> 98736 | T38: =+'FC - 3FS'!AA80 -> 100558 | U38: =+'FC - 3FS'!AP80 -> 100558 | V38: =+'FC - 3FS'!AB80 -> 98733 | W38: =+'FC - 3FS'!AC80 -> 95928 | X38: =+'FC - 3FS'!AD80 -> 97749 | Y38: =+'FC - 3FS'!AE80 -> 99303.702 | Z38: =+'FC - 3FS'!AQ80 -> 99303.702 | AA38: =+'FC - 3FS'!AF80 -> 100883.13 | AB38: =+'FC - 3FS'!AG80 -> 102487.68 | AC38: =+'FC - 3FS'!AH80 -> 104117.75 | AD38: =+'FC - 3FS'!AI80 -> 105773.75 | AE38: =+'FC - 3FS'!AR80 -> 105773.75 | AH38: =E38=F38 -> TRUE | AI38: =J38=K38 -> TRUE | AJ38: =O38=P38 -> TRUE | AK38: =T38=U38 -> TRUE | AL38: =Y38=Z38 -> TRUE | AM38: =AD38=AE38 -> TRUE
A39: Other long-term assets | B39: =SUM('FC - 3FS'!L81:L83) -> 19253 | C39: =SUM('FC - 3FS'!M81:M83) -> 19150 | D39: =SUM('FC - 3FS'!N81:N83) -> 10379 | E39: =SUM('FC - 3FS'!O81:O83) -> 10794 | F39: =SUM('FC - 3FS'!AM81:AM83) -> 10794 | G39: =SUM('FC - 3FS'!P81:P83) -> 13561 | H39: =SUM('FC - 3FS'!Q81:Q83) -> 10178 | I39: =SUM('FC - 3FS'!R81:R83) -> 10154 | J39: =SUM('FC - 3FS'!S81:S83) -> 10181 | K39: =SUM('FC - 3FS'!AN81:AN83) -> 10181 | L39: =SUM('FC - 3FS'!T81:T83) -> 9704 | M39: =SUM('FC - 3FS'!U81:U83) -> 9182 | N39: =SUM('FC - 3FS'!V81:V83) -> 8949 | O39: =SUM('FC - 3FS'!W81:W83) -> 8889 | P39: =SUM('FC - 3FS'!AO81:AO83) -> 8889 | Q39: =SUM('FC - 3FS'!X81:X83) -> 8353 | R39: =SUM('FC - 3FS'!Y81:Y83) -> 9851 | S39: =SUM('FC - 3FS'!Z81:Z83) -> 9672 | T39: =SUM('FC - 3FS'!AA81:AA83) -> 9046 | U39: =SUM('FC - 3FS'!AP81:AP83) -> 9046 | V39: =SUM('FC - 3FS'!AB81:AB83) -> 9093 | W39: =SUM('FC - 3FS'!AC81:AC83) -> 11162 | X39: =SUM('FC - 3FS'!AD81:AD83) -> 16295 | Y39: =SUM('FC - 3FS'!AE81:AE83) -> 16298.637 | Z39: =SUM('FC - 3FS'!AQ81:AQ83) -> 16298.637 | AA39: =SUM('FC - 3FS'!AF81:AF83) -> 16372.323 | AB39: =SUM('FC - 3FS'!AG81:AG83) -> 16489.626 | AC39: =SUM('FC - 3FS'!AH81:AH83) -> 16591.706 | AD39: =SUM('FC - 3FS'!AI81:AI83) -> 16699.875 | AE39: =SUM('FC - 3FS'!AR81:AR83) -> 16699.875 | AH39: =E39=F39 -> TRUE | AI39: =J39=K39 -> TRUE | AJ39: =O39=P39 -> TRUE | AK39: =T39=U39 -> TRUE | AL39: =Y39=Z39 -> TRUE | AM39: =AD39=AE39 -> TRUE
A40: Total assets | B40: =+SUM(B33:B39) -> 203332 | C40: =+SUM(C33:C39) -> 204124 | D40: =+SUM(D33:D39) -> 202125 | E40: =+SUM(E33:E39) -> 206563 | F40: =+SUM(F33:F39) -> 206563 | G40: =+SUM(G33:G39) -> 210653 | H40: =+SUM(H33:H39) -> 209463 | I40: =+SUM(I33:I39) -> 213499 | ... AE40: =+SUM(AE33:AE39) -> 226938.34 | AH40: =E40=F40 -> TRUE | AI40: =J40=K40 -> TRUE | AJ40: =O40=P40 -> TRUE | AK40: =T40=U40 -> TRUE | AL40: =Y40=Z40 -> TRUE | AM40: =AD40=AE40 -> TRUE
A41: short-term debt total | B41: =+'FC - 3FS'!L88+'FC - 3FS'!L89 -> 4423 | C41: =+'FC - 3FS'!M88+'FC - 3FS'!M89 -> 6883 | D41: =+'FC - 3FS'!N88+'FC - 3FS'!N89 -> 4336 | E41: =+'FC - 3FS'!O88+'FC - 3FS'!O89 -> 5623 | F41: =+'FC - 3FS'!AM88+'FC - 3FS'!AM89 -> 5623 | G41: =+'FC - 3FS'!P88+'FC - 3FS'!P89 -> 4115 | H41: =+'FC - 3FS'!Q88+'FC - 3FS'!Q89 -> 2942 | I41: =+'FC - 3FS'!R88+'FC - 3FS'!R89 -> 7398 | J41: =+'FC - 3FS'!S88+'FC - 3FS'!S89 -> 5164 | K41: =+'FC - 3FS'!AN88+'FC - 3FS'!AN89 -> 5164 | L41: =+'FC - 3FS'!T88+'FC - 3FS'!T89 -> 5215 | M41: =+'FC - 3FS'!U88+'FC - 3FS'!U89 -> 7731 | N41: =+'FC - 3FS'!V88+'FC - 3FS'!V89 -> 3437 | O41: =+'FC - 3FS'!W88+'FC - 3FS'!W89 -> 3619 | P41: =+'FC - 3FS'!AO88+'FC - 3FS'!AO89 -> 3619 | Q41: =+'FC - 3FS'!X88+'FC - 3FS'!X89 -> 5356 | R41: =+'FC - 3FS'!Y88+'FC - 3FS'!Y89 -> 5867 | S41: =+'FC - 3FS'!Z88+'FC - 3FS'!Z89 -> 5851 | T41: =+'FC - 3FS'!AA88+'FC - 3FS'!AA89 -> 4068 | U41: =+'FC - 3FS'!AP88+'FC - 3FS'!AP89 -> 4068 | V41: =+'FC - 3FS'!AB88+'FC - 3FS'!AB89 -> 8214 | W41: =+'FC - 3FS'!AC88+'FC - 3FS'!AC89 -> 6408 | X41: =+'FC - 3FS'!AD88+'FC - 3FS'!AD89 -> 6333 | Y41: =+'FC - 3FS'!AE88+'FC - 3FS'!AE89 -> 6333 | Z41: =+'FC - 3FS'!AQ88+'FC - 3FS'!AQ89 -> 6333 | AA41: =+'FC - 3FS'!AF88+'FC - 3FS'!AF89 -> 6333 | AB41: =+'FC - 3FS'!AG88+'FC - 3FS'!AG89 -> 6333 | AC41: =+'FC - 3FS'!AH88+'FC - 3FS'!AH89 -> 6333 | AD41: =+'FC - 3FS'!AI88+'FC - 3FS'!AI89 -> 6333 | AE41: =+'FC - 3FS'!AR88+'FC - 3FS'!AR89 -> 6333 | AH41: =E41=F41 -> TRUE | AI41: =J41=K41 -> TRUE | AJ41: =O41=P41 -> TRUE | AK41: =T41=U41 -> TRUE | AL41: =Y41=Z41 -> TRUE | AM41: =AD41=AE41 -> TRUE
A42: Short-term financing lease liabilities | B42: =+'FC - 3FS'!L92 -> 1013 | C42: =+'FC - 3FS'!M92 -> 1045 | D42: =+'FC - 3FS'!N92 -> 1154 | E42: =+'FC - 3FS'!O92 -> 1120 | F42: =+'FC - 3FS'!AM92 -> 1120 | G42: =+'FC - 3FS'!P92 -> 1121 | H42: =+'FC - 3FS'!Q92 -> 1220 | I42: =+'FC - 3FS'!R92 -> 1239 | J42: =+'FC - 3FS'!S92 -> 1161 | K42: =+'FC - 3FS'!AN92 -> 1161 | L42: =+'FC - 3FS'!T92 -> 1180 | M42: =+'FC - 3FS'!U92 -> 1220 | N42: =+'FC - 3FS'!V92 -> 1286 | O42: =+'FC - 3FS'!W92 -> 1260 | P42: =+'FC - 3FS'!AO92 -> 1260 | Q42: =+'FC - 3FS'!X92 -> 1265 | R42: =+'FC - 3FS'!Y92 -> 1252 | S42: =+'FC - 3FS'!Z92 -> 1252 | T42: =+'FC - 3FS'!AA92 -> 1175 | U42: =+'FC - 3FS'!AP92 -> 1175 | V42: =+'FC - 3FS'!AB92 -> 1136 | W42: =+'FC - 3FS'!AC92 -> 1157 | X42: =+'FC - 3FS'!AD92 -> 1157 | Y42: =+'FC - 3FS'!AE92 -> 1159.7826 | Z42: =+'FC - 3FS'!AQ92 -> 1159.7826 | AA42: =+'FC - 3FS'!AF92 -> 1165.2131 | AB42: =+'FC - 3FS'!AG92 -> 1173.595 | AC42: =+'FC - 3FS'!AH92 -> 1183.5947 | AD42: =+'FC - 3FS'!AI92 -> 1194.7129 | AE42: =+'FC - 3FS'!AR92 -> 1194.7129 | AH42: =E42=F42 -> TRUE | AI42: =J42=K42 -> TRUE | AJ42: =O42=P42 -> TRUE | AK42: =T42=U42 -> TRUE | AL42: =Y42=Z42 -> TRUE | AM42: =AD42=AE42 -> TRUE
A43: Other current liabilities | B43: =+SUM('FC - 3FS'!L87,'FC - 3FS'!L90,'FC - 3FS'!L91,'FC - 3FS'!L93) -> 14059 | C43: =+SUM('FC - 3FS'!M87,'FC - 3FS'!M90,'FC - 3FS'!M91,'FC - 3FS'!M93) -> 13909 | D43: =+SUM('FC - 3FS'!N87,'FC - 3FS'!N90,'FC - 3FS'!N91,'FC - 3FS'!N93) -> 13757 | E43: =+SUM('FC - 3FS'!O87,'FC - 3FS'!O90,'FC - 3FS'!O91,'FC - 3FS'!O93) -> 16756 | F43: =+SUM('FC - 3FS'!AM87,'FC - 3FS'!AM90,'FC - 3FS'!AM91,'FC - 3FS'!AM93) -> 16756 | G43: =+SUM('FC - 3FS'!P87,'FC - 3FS'!P90,'FC - 3FS'!P91,'FC - 3FS'!P93) -> 16187 | H43: =+SUM('FC - 3FS'!Q87,'FC - 3FS'!Q90,'FC - 3FS'!Q91,'FC - 3FS'!Q93) -> 16460 | I43: =+SUM('FC - 3FS'!R87,'FC - 3FS'!R90,'FC - 3FS'!R91,'FC - 3FS'!R93) -> 17725 | J43: =+SUM('FC - 3FS'!S87,'FC - 3FS'!S90,'FC - 3FS'!S91,'FC - 3FS'!S93) -> 18417 | K43: =+SUM('FC - 3FS'!AN87,'FC - 3FS'!AN90,'FC - 3FS'!AN91,'FC - 3FS'!AN93) -> 18417 | L43: =+SUM('FC - 3FS'!T87,'FC - 3FS'!T90,'FC - 3FS'!T91,'FC - 3FS'!T93) -> 17451 | M43: =+SUM('FC - 3FS'!U87,'FC - 3FS'!U90,'FC - 3FS'!U91,'FC - 3FS'!U93) -> 15618 | N43: =+SUM('FC - 3FS'!V87,'FC - 3FS'!V90,'FC - 3FS'!V91,'FC - 3FS'!V93) -> 16988 | O43: =+SUM('FC - 3FS'!W87,'FC - 3FS'!W90,'FC - 3FS'!W91,'FC - 3FS'!W93) -> 16049 | P43: =+SUM('FC - 3FS'!AO87,'FC - 3FS'!AO90,'FC - 3FS'!AO91,'FC - 3FS'!AO93) -> 16049 | Q43: =+SUM('FC - 3FS'!X87,'FC - 3FS'!X90,'FC - 3FS'!X91,'FC - 3FS'!X93) -> 13942 | R43: =+SUM('FC - 3FS'!Y87,'FC - 3FS'!Y90,'FC - 3FS'!Y91,'FC - 3FS'!Y93) -> 15919 | S43: =+SUM('FC - 3FS'!Z87,'FC - 3FS'!Z90,'FC - 3FS'!Z91,'FC - 3FS'!Z93) -> 13852 | T43: =+SUM('FC - 3FS'!AA87,'FC - 3FS'!AA90,'FC - 3FS'!AA91,'FC - 3FS'!AA93) -> 14931 | U43: =+SUM('FC - 3FS'!AP87,'FC - 3FS'!AP90,'FC - 3FS'!AP91,'FC - 3FS'!AP93) -> 14931 | V43: =+SUM('FC - 3FS'!AB87,'FC - 3FS'!AB90,'FC - 3FS'!AB91,'FC - 3FS'!AB93) -> 14279 | W43: =+SUM('FC - 3FS'!AC87,'FC - 3FS'!AC90,'FC - 3FS'!AC91,'FC - 3FS'!AC93) -> 14537 | X43: =+SUM('FC - 3FS'!AD87,'FC - 3FS'!AD90,'FC - 3FS'!AD91,'FC - 3FS'!AD93) -> 16811 | Y43: =+SUM('FC - 3FS'!AE87,'FC - 3FS'!AE90,'FC - 3FS'!AE91,'FC - 3FS'!AE93) -> 16204.003 | Z43: =+SUM('FC - 3FS'!AQ87,'FC - 3FS'!AQ90,'FC - 3FS'!AQ91,'FC - 3FS'!AQ93) -> 16204.003 | AA43: =+SUM('FC - 3FS'!AF87,'FC - 3FS'!AF90,'FC - 3FS'!AF91,'FC - 3FS'!AF93) -> 15235.393 | AB43: =+SUM('FC - 3FS'!AG87,'FC - 3FS'!AG90,'FC - 3FS'!AG91,'FC - 3FS'!AG93) -> 15284.423 | AC43: =+SUM('FC - 3FS'!AH87,'FC - 3FS'!AH90,'FC - 3FS'!AH91,'FC - 3FS'!AH93) -> 16936.214 | AD43: =+SUM('FC - 3FS'!AI87,'FC - 3FS'!AI90,'FC - 3FS'!AI91,'FC - 3FS'!AI93) -> 16950.536 | AE43: =+SUM('FC - 3FS'!AR87,'FC - 3FS'!AR90,'FC - 3FS'!AR91,'FC - 3FS'!AR93) -> 16950.536 | AH43: =E43=F43 -> TRUE | AI43: =J43=K43 -> TRUE | AJ43: =O43=P43 -> TRUE | AK43: =T43=U43 -> TRUE | AL43: =Y43=Z43 -> TRUE | AM43: =AD43=AE43 -> TRUE
A44: Total current liabilities | B44: =+SUM(B41:B43) -> 19495 | C44: =+SUM(C41:C43) -> 21837 | D44: =+SUM(D41:D43) -> 19247 | E44: =+SUM(E41:E43) -> 23499 | F44: =+SUM(F41:F43) -> 23499 | G44: =+SUM(G41:G43) -> 21423 | H44: =+SUM(H41:H43) -> 20622 | I44: =+SUM(I41:I43) -> 26362 | ... AE44: =+SUM(AE41:AE43) -> 24478.248 | AH44: =E44=F44 -> TRUE | AI44: =J44=K44 -> TRUE | AJ44: =O44=P44 -> TRUE | AK44: =T44=U44 -> TRUE | AL44: =Y44=Z44 -> TRUE | AM44: =AD44=AE44 -> TRUE
...

Sheet Valuation
A1: hide
B2: VALUATION METHOD 1: DCF | T2: Start Date | U2: =TODAY()-365*10 -> 42576
T3: Field | U3: BEST_CUR_EV_TO_EBITDA | V3: EV/EBITDA | W3: 10-year average
B4: Current Quarter | C4: =N6&"Q"&RIGHT(O6,2) -> 1Q25 | H4: Assumptions | N4: Last Reported Fiscal | T4: TMUS | U4: 42380 | W4: =AVERAGE($V$4:$V$2517) -> #DIV/0!
B5: +1 Year Quarter | C5: =N8&"Q"&RIGHT(O8,2) -> 1Q26 | H5: WACC | I5: 0.08 | K5: b | L5: 0.8 | N5: Quarter | O5: Year | W5: =AVERAGE($V$4:$V$2517) -> #DIV/0!
B6: Current Share Price | C6: =L10 -> 259.64 | H6: D | I6: =INDEX('BS Drivers'!97:97,MATCH(Valuation!C4,'BS Drivers'!4:4,0)) -> 87997 | K6: Rf | L6: 0.03 | N6: 1 | O6: 2025 | W6: =AVERAGE($V$4:$V$2517) -> #DIV/0!
B7: Target Price | C7: =C48 -> -28 | H7: E | I7: =L9*L10 -> 297198.3 | K7: Risk Prem. | L7: 0.08 | N7: +1 Year | W7: =AVERAGE($V$4:$V$2517) -> #DIV/0!
B8: Upside (Downside) from Current Price | C8: =C7/C6-1 -> -1.1078416 | H8: D/(D+E) | I8: =I6/(I6+I7) -> 0.22844775 | K8: Tax Rate | L8: 0.23 | N8: =N6 -> 1 | O8: =O6+1 -> 2026 | W8: =AVERAGE($V$4:$V$2517) -> #DIV/0!
H9: Kd | I9: 0.04 | K9: Shares | L9: =INDEX('FC - 3FS'!39:39, MATCH(Valuation!C4,'FC - 3FS'!4:4, 0)) -> 1144.6553 | N9: Bloomberg price | W9: =AVERAGE($V$4:$V$2517) -> #DIV/0!
B10: Median Cons. TP | C10: 270 | H10: Ke | I10: =L6+L5*L7 -> 0.094 | K10: Stock Price | L10: 259.64 | N10: 198.6 | W10: =AVERAGE($V$4:$V$2517) -> #DIV/0!
H11: WACC (Calculated) | I11: =I9*(1-L8)*I8+I10*(1-I8) -> 0.079562102 | K11: Terminal Growth | L11: 0.02 | W11: =AVERAGE($V$4:$V$2517) -> #DIV/0!
W12: =AVERAGE($V$4:$V$2517) -> #DIV/0!
B13: ($ MM) | C13: 2020 | D13: 2021 | E13: 2022 | F13: =E13+1 -> 2023 | G13: =F13+1 -> 2024 | H13: =G13+1 -> 2025 | I13: =H13+1 -> 2026 | J13: =I13+1 -> 2027 | K13: =J13+1 -> 2028 | L13: =K13+1 -> 2029 | M13: =L13+1 -> 2030 | W13: =AVERAGE($V$4:$V$2517) -> #DIV/0!
W14: =AVERAGE($V$4:$V$2517) -> #DIV/0!
B15: Revenue | C15: ='FC - 3FS'!AL14 -> 68397 | D15: ='FC - 3FS'!AM14 -> 80118 | E15: ='FC - 3FS'!AN14 -> 79571 | F15: ='FC - 3FS'!AO14 -> 78558 | G15: ='FC - 3FS'!AP14 -> 81400 | H15: ='FC - 3FS'!AQ14 -> 87847.495 | I15: ='FC - 3FS'!AR14 -> 94417.322 | J15: ='FC - 3FS'!AS14 -> 99251.787 | ... M15: ='FC - 3FS'!AV14 -> 0 | W15: =AVERAGE($V$4:$V$2517) -> #DIV/0!
B16: yoy growth | D16: =D15/C15-1 -> 0.17136717 | E16: =E15/D15-1 -> -0.0068274295 | F16: =F15/E15-1 -> -0.012730769 | G16: =G15/F15-1 -> 0.036177092 | H16: =H15/G15-1 -> 0.079207559 | I16: =I15/H15-1 -> 0.074786732 | J16: =J15/I15-1 -> 0.051203153 | K16: =K15/J15-1 -> -1 | ... M16: =M15/L15-1 -> #DIV/0! | W16: =AVERAGE($V$4:$V$2517) -> #DIV/0!
W17: =AVERAGE($V$4:$V$2517) -> #DIV/0!
B18: EBIT | C18: =+'FC - 3FS'!AL23 -> 6636 | D18: =+'FC - 3FS'!AM23 -> 6892 | E18: =+'FC - 3FS'!AN23 -> 6543 | F18: =+'FC - 3FS'!AO23 -> 14266 | G18: =+'FC - 3FS'!AP23 -> 18010 | H18: =+'FC - 3FS'!AQ23 -> 18579.344 | I18: =+'FC - 3FS'!AR23 -> 20628.685 | J18: =+'FC - 3FS'!AS23 -> 23736.335 | ... M18: =+'FC - 3FS'!AV23 -> 0 | W18: =AVERAGE($V$4:$V$2517) -> #DIV/0!
B19: Cost to Achieve | H19: ='IS Drivers'!AQ218 -> 460 | I19: ='IS Drivers'!AR218 -> 1540 | J19: ='IS Drivers'!AS218 -> 660 | K19: ='IS Drivers'!AT218 -> 0 | L19: ='IS Drivers'!AU218 -> 0 | M19: ='IS Drivers'!AV218 -> 0 | W19: =AVERAGE($V$4:$V$2517) -> #DIV/0!
B20: Adj. EBIT | H20: =SUM(H18:H19) -> 19039.344 | I20: =SUM(I18:I19) -> 22168.685 | J20: =SUM(J18:J19) -> 24396.335 | K20: =SUM(K18:K19) -> 0 | L20: =SUM(L18:L19) -> 0 | M20: =SUM(M18:M19) -> 0 | W20: =AVERAGE($V$4:$V$2517) -> #DIV/0!
B21: Operating Margin % | C21: =C18/C15 -> 0.097021799 | D21: =D18/D15 -> 0.086023116 | E21: =E18/E15 -> 0.08222845 | F21: =F18/F15 -> 0.18159831 | G21: =G18/G15 -> 0.22125307 | H21: =H20/H15 -> 0.21673178 | I21: =I20/I15 -> 0.23479468 | J21: =J20/J15 -> 0.24580248 | K21: =K20/K15 -> #DIV/0! | L21: =L20/L15 -> #DIV/0! | M21: =M20/M15 -> #DIV/0! | W21: =AVERAGE($V$4:$V$2517) -> #DIV/0!
W22: =AVERAGE($V$4:$V$2517) -> #DIV/0!
B23: Tax Rate % | C23: =-'BS Drivers'!AL124 -> 0.22266289 | D23: =-'BS Drivers'!AM124 -> 0.097582811 | E23: =-'BS Drivers'!AN124 -> 0.17673236 | F23: =-'BS Drivers'!AO124 -> 0.24384035 | G23: =-'BS Drivers'!AP124 -> 0.22926862 | H23: =-'BS Drivers'!AQ124 -> 0.23552142 | I23: =-'BS Drivers'!AR124 -> 0.23072562 | J23: =-'BS Drivers'!AS124 -> 0.23072562 | ... M23: =-'BS Drivers'!AV124 -> 0 | W23: =AVERAGE($V$4:$V$2517) -> #DIV/0!
B24: NOPAT | C24: =+(1-C23)*C18 -> 5158.4091 | D24: =+(1-D23)*D18 -> 6219.4593 | E24: =+(1-E23)*E18 -> 5386.6402 | F24: =+(1-F23)*F18 -> 10787.374 | G24: =+(1-G23)*G18 -> 13880.872 | H24: =+(1-H23)*H20 -> 14555.171 | I24: =+(1-I23)*I20 -> 17053.801 | J24: =+(1-J23)*J20 -> 18767.475 | K24: =+(1-K23)*K20 -> 0 | L24: =+(1-L23)*L20 -> 0 | M24: =+(1-M23)*M20 -> 0 | W24: =AVERAGE($V$4:$V$2517) -> #DIV/0!
B25: change in working capital | C25: =SUM('FC - 3FS'!AL131:AL138)+'FC - 3FS'!AL145 -> -8751 | D25: =SUM('FC - 3FS'!AM131:AM138)+'FC - 3FS'!AM145 -> -2983 | E25: =SUM('FC - 3FS'!AN131:AN138)+'FC - 3FS'!AN145 -> 1781 | F25: =SUM('FC - 3FS'!AO131:AO138)+'FC - 3FS'!AO145 -> -2242 | G25: =SUM('FC - 3FS'!AP131:AP138)+'FC - 3FS'!AP145 -> -3430 | H25: =SUM('FC - 3FS'!AQ131:AQ138) -> -2766.9768 | I25: =SUM('FC - 3FS'!AR131:AR138) -> -2340.0684 | J25: =SUM('FC - 3FS'!AS131:AS138) -> -1865.3836 | K25: =SUM('FC - 3FS'!AT131:AT138) -> 0 | L25: =SUM('FC - 3FS'!AU131:AU138) -> 0 | M25: =SUM('FC - 3FS'!AV131:AV138) -> 0 | W25: =AVERAGE($V$4:$V$2517) -> #DIV/0!
B26: D&A | C26: ='FC - 3FS'!AL122 -> 14151 | D26: ='FC - 3FS'!AM122 -> 16383 | E26: ='FC - 3FS'!AN122 -> 13651 | F26: ='FC - 3FS'!AO122 -> 12818 | G26: ='FC - 3FS'!AP122 -> 12919 | H26: ='FC - 3FS'!AQ122 -> 13422.032 | I26: ='FC - 3FS'!AR122 -> 14308.594 | J26: ='FC - 3FS'!AS122 -> 14771.983 | ... M26: ='FC - 3FS'!AV122 -> 0 | W26: =AVERAGE($V$4:$V$2517) -> #DIV/0!
B27: CapEx | C27: =+'FC - 3FS'!AL142 -> -11034 | D27: =+'FC - 3FS'!AM142 -> -12326 | E27: =+'FC - 3FS'!AN142 -> -13970 | F27: =+'FC - 3FS'!AO142 -> -9801 | G27: =+'FC - 3FS'!AP142 -> -8840 | H27: =+'FC - 3FS'!AQ142 -> -10023.267 | I27: =+'FC - 3FS'!AR142 -> -10562.247 | J27: =+'FC - 3FS'!AS142 -> -10941.004 | ... M27: =+'FC - 3FS'!AV142 -> 0
B28: as % of revenue | C28: =C27/C15 -> -0.16132287 | D28: =D27/D15 -> -0.15384807 | E28: =E27/E15 -> -0.17556648 | F28: =F27/F15 -> -0.12476132 | G28: =G27/G15 -> -0.10859951 | H28: =H27/H15 -> -0.1140985 | I28: =I27/I15 -> -0.11186768 | J28: =J27/J15 -> -0.11023483 | ... M28: =M27/M15 -> #DIV/0! | W28: =AVERAGE($V$4:$V$2517) -> #DIV/0!
B29: yoy growth | D29: =D27/C27-1 -> 0.11709262 | E29: =E27/D27-1 -> 0.1333766 | F29: =F27/E27-1 -> -0.2984252 | G29: =G27/F27-1 -> -0.098051219 | H29: =H27/G27-1 -> 0.13385374 | I29: =I27/H27-1 -> 0.053772849 | J29: =J27/I27-1 -> 0.035859496 | K29: =K27/J27-1 -> -1 | ... M29: =M27/L27-1 -> #DIV/0! | W29: =AVERAGE($V$4:$V$2517) -> #DIV/0!
W30: =AVERAGE($V$4:$V$2517) -> #DIV/0!
B31: Unlevered FCF | C31: =SUM(C24:C27) -> -475.59093 | D31: =SUM(D24:D27) -> 7293.4593 | E31: =SUM(E24:E27) -> 6848.6402 | F31: =SUM(F24:F27) -> 11562.374 | G31: =SUM(G24:G27) -> 14529.872 | H31: =SUM(H24:H27) -> 15186.959 | I31: =SUM(I24:I27) -> 18460.08 | J31: =SUM(J24:J27) -> 20733.071 | ... M31: =SUM(M24:M27) -> 0 | W31: =AVERAGE($V$4:$V$2517) -> #DIV/0!
B32: yoy growth | E32: =E31/D31-1 -> -0.060988767 | F32: =F31/E31-1 -> 0.68827289 | G32: =G31/F31-1 -> 0.25665132 | H32: =H31/G31-1 -> 0.045223177 | I32: =I31/H31-1 -> 0.21552184 | J32: =J31/I31-1 -> 0.12313006 | K32: =K31/J31-1 -> -1 | L32: =L31/K31-1 -> #DIV/0! | M32: =M31/L31-1 -> #DIV/0! | W32: =AVERAGE($V$4:$V$2517) -> #DIV/0!
B33: FCF Margin | C33: =C31/C15 -> -0.0069533888 | D33: =D31/D15 -> 0.091033966 | E33: =E31/E15 -> 0.08606955 | F33: =F31/F15 -> 0.14718264 | G33: =G31/G15 -> 0.17849966 | H33: =H31/H15 -> 0.17287868 | I33: =I31/I15 -> 0.19551582 | J33: =J31/J15 -> 0.20889368 | ... M33: =M31/M15 -> #DIV/0! | W33: =AVERAGE($V$4:$V$2517) -> #DIV/0!
W34: =AVERAGE($V$4:$V$2517) -> #DIV/0!
B35: Years to Discount | G35: =((G13-$O$6)+(4-$N$6)/4) -> -0.25 | H35: =((H13-$O$6)+(4-$N$6)/4) -> 0.75 | I35: =((I13-$O$6)+(4-$N$6)/4) -> 1.75 | J35: =((J13-$O$6)+(4-$N$6)/4) -> 2.75 | K35: =((K13-$O$6)+(4-$N$6)/4) -> 3.75 | L35: =((L13-$O$6)+(4-$N$6)/4) -> 4.75 | M35: =((M13-$O$6)+(4-$N$6)/4) -> 5.75 | W35: =AVERAGE($V$4:$V$2517) -> #DIV/0!
B36: Discount Factor | G36: =IF(G35>0,1/(1+$I$5)^G35,0) -> 0 | H36: =IF(H35>0,1/(1+$I$5)^H35,0) -> 0.94391347 | I36: =IF(I35>0,1/(1+$I$5)^I35,0) -> 0.87399395 | J36: =IF(J35>0,1/(1+$I$5)^J35,0) -> 0.80925366 | K36: =IF(K35>0,1/(1+$I$5)^K35,0) -> 0.74930894 | L36: =IF(L35>0,1/(1+$I$5)^L35,0) -> 0.69380458 | M36: =IF(M35>0,1/(1+$I$5)^M35,0) -> 0.64241165 | W36: =AVERAGE($V$4:$V$2517) -> #DIV/0!
B37: FCFF Present Value | G37: =G31*G36 -> 0 | H37: =H31*H36 -> 14335.175 | I37: =I31*I36 -> 16133.999 | J37: =J31*J36 -> 16778.314 | K37: =K31*K36 -> 0 | L37: =L31*L36 -> 0 | M37: =M31*M36 -> 0 | W37: =AVERAGE($V$4:$V$2517) -> #DIV/0!
W38: =AVERAGE($V$4:$V$2517) -> #DIV/0!
B39: Terminal Value | C39: =M31*(1+L11)/(I5-L11) -> 0 | D39: Terminal as % of total | W39: =AVERAGE($V$4:$V$2517) -> #DIV/0!
B40: PV of Terminal Value | C40: =C39*M36 -> 0 | D40: =+C40/C41 -> 0 | W40: =AVERAGE($V$4:$V$2517) -> #DIV/0!
...

Sheet Valuation (Don't Use)
A1: hide
B2: VALUATION METHOD 1: DCF | T2: Start Date | U2: =TODAY()-365*10 -> 42576
T3: Field | U3: BEST_CUR_EV_TO_EBITDA | V3: EV/EBITDA | W3: 10-year average
B4: Current Quarter | C4: =N6&"Q"&RIGHT(O6,2) -> 3Q24 | H4: Assumptions | N4: Last Reported Fiscal | T4: TMUS | U4: 42380 | W4: =AVERAGE($V$4:$V$2517) -> #DIV/0!
B5: +1 Year Quarter | C5: =N8&"Q"&RIGHT(O8,2) -> 3Q25 | H5: WACC | I5: =I9*(1-L8)*I8+I10*(1-I8) -> 0.076299929 | K5: b | L5: 0.8 | N5: Quarter | O5: Year | W5: =AVERAGE($V$4:$V$2517) -> #DIV/0!
B6: Current Share Price | C6: =L10 -> 246.94 | H6: D | I6: =INDEX('BS Drivers'!97:97,MATCH('Valuation (Don''t Use)'!C4,'BS Drivers'!4:4,0))+INDEX('BS Drivers'!112:112,MATCH('Valuation (Don''t Use)'!C4,'BS Drivers'!4:4,0)) -> 112456 | K6: Rf | L6: 0.03 | N6: 3 | O6: 2024 | W6: =AVERAGE($V$4:$V$2517) -> #DIV/0!
B7: Target Price | C7: =C46 -> -27 | H7: E | I7: =L9*L10 -> 289080.2 | K7: Risk Prem. | L7: 0.08 | N7: +1 Year | W7: =AVERAGE($V$4:$V$2517) -> #DIV/0!
B8: Upside (Downside) from Current Price | C8: =C7/C6-1 -> -1.1093383 | H8: D/(D+E) | I8: =I6/(I6+I7) -> 0.28006441 | K8: Tax Rate | L8: 0.23 | N8: =N6 -> 3 | O8: =O6+1 -> 2025 | W8: =AVERAGE($V$4:$V$2517) -> #DIV/0!
H9: Kd | I9: 0.04 | K9: Shares | L9: =INDEX('FC - 3FS'!39:39, MATCH('Valuation (Don''t Use)'!C4,'FC - 3FS'!4:4, 0)) -> 1170.6496 | N9: Bloomberg price | W9: =AVERAGE($V$4:$V$2517) -> #DIV/0!
B10: Median Cons. TP | C10: 270 | H10: Ke | I10: =L6+L5*L7 -> 0.094 | K10: Stock Price | L10: 246.94 | N10: 198.6 | W10: =AVERAGE($V$4:$V$2517) -> #DIV/0!
K11: Terminal Growth | L11: 0.02 | W11: =AVERAGE($V$4:$V$2517) -> #DIV/0!
W12: =AVERAGE($V$4:$V$2517) -> #DIV/0!
B13: ($ MM) | C13: 2020 | D13: 2021 | E13: 2022 | F13: =E13+1 -> 2023 | G13: =F13+1 -> 2024 | H13: =G13+1 -> 2025 | I13: =H13+1 -> 2026 | J13: =I13+1 -> 2027 | K13: =J13+1 -> 2028 | L13: =K13+1 -> 2029 | M13: =L13+1 -> 2030 | W13: =AVERAGE($V$4:$V$2517) -> #DIV/0!
W14: =AVERAGE($V$4:$V$2517) -> #DIV/0!
B15: Revenue | C15: ='FC - 3FS'!AL14 -> 68397 | D15: ='FC - 3FS'!AM14 -> 80118 | E15: ='FC - 3FS'!AN14 -> 79571 | F15: ='FC - 3FS'!AO14 -> 78558 | G15: ='FC - 3FS'!AP14 -> 81400 | H15: ='FC - 3FS'!AQ14 -> 87847.495 | I15: ='FC - 3FS'!AR14 -> 94417.322 | J15: ='FC - 3FS'!AS14 -> 99251.787 | ... M15: ='FC - 3FS'!AV14 -> 0 | W15: =AVERAGE($V$4:$V$2517) -> #DIV/0!
B16: yoy growth | D16: =D15/C15-1 -> 0.17136717 | E16: =E15/D15-1 -> -0.0068274295 | F16: =F15/E15-1 -> -0.012730769 | G16: =G15/F15-1 -> 0.036177092 | H16: =H15/G15-1 -> 0.079207559 | I16: =I15/H15-1 -> 0.074786732 | J16: =J15/I15-1 -> 0.051203153 | K16: =K15/J15-1 -> -1 | ... M16: =M15/L15-1 -> #DIV/0! | W16: =AVERAGE($V$4:$V$2517) -> #DIV/0!
W17: =AVERAGE($V$4:$V$2517) -> #DIV/0!
B18: EBIT | C18: =+'FC - 3FS'!AL23 -> 6636 | D18: =+'FC - 3FS'!AM23 -> 6892 | E18: =+'FC - 3FS'!AN23 -> 6543 | F18: =+'FC - 3FS'!AO23 -> 14266 | G18: =+'FC - 3FS'!AP23 -> 18010 | H18: =+'FC - 3FS'!AQ23 -> 18579.344 | I18: =+'FC - 3FS'!AR23 -> 20628.685 | J18: =+'FC - 3FS'!AS23 -> 23736.335 | ... M18: =+'FC - 3FS'!AV23 -> 0 | W18: =AVERAGE($V$4:$V$2517) -> #DIV/0!
B19: Operating Margin % | C19: =C18/C15 -> 0.097021799 | D19: =D18/D15 -> 0.086023116 | E19: =E18/E15 -> 0.08222845 | F19: =F18/F15 -> 0.18159831 | G19: =G18/G15 -> 0.22125307 | H19: =H18/H15 -> 0.21149544 | I19: =I18/I15 -> 0.21848411 | J19: =J18/J15 -> 0.23915272 | ... M19: =M18/M15 -> #DIV/0! | W19: =AVERAGE($V$4:$V$2517) -> #DIV/0!
W20: =AVERAGE($V$4:$V$2517) -> #DIV/0!
B21: Tax Rate % | C21: =-'BS Drivers'!AL124 -> 0.22266289 | D21: =-'BS Drivers'!AM124 -> 0.097582811 | E21: =-'BS Drivers'!AN124 -> 0.17673236 | F21: =-'BS Drivers'!AO124 -> 0.24384035 | G21: =-'BS Drivers'!AP124 -> 0.22926862 | H21: =-'BS Drivers'!AQ124 -> 0.23552142 | I21: =-'BS Drivers'!AR124 -> 0.23072562 | J21: =-'BS Drivers'!AS124 -> 0.23072562 | ... M21: =-'BS Drivers'!AV124 -> 0 | W21: =AVERAGE($V$4:$V$2517) -> #DIV/0!
B22: NOPAT | C22: =+(1-C21)*C18 -> 5158.4091 | D22: =+(1-D21)*D18 -> 6219.4593 | E22: =+(1-E21)*E18 -> 5386.6402 | F22: =+(1-F21)*F18 -> 10787.374 | G22: =+(1-G21)*G18 -> 13880.872 | H22: =+(1-H21)*H18 -> 14203.511 | I22: =+(1-I21)*I18 -> 15869.119 | J22: =+(1-J21)*J18 -> 18259.754 | ... M22: =+(1-M21)*M18 -> 0 | W22: =AVERAGE($V$4:$V$2517) -> #DIV/0!
B23: change in working capital | C23: =SUM('FC - 3FS'!AL131:AL138) -> -11885 | D23: =SUM('FC - 3FS'!AM131:AM138) -> -7114 | E23: =SUM('FC - 3FS'!AN131:AN138) -> -3055 | F23: =SUM('FC - 3FS'!AO131:AO138) -> -7058 | G23: =SUM('FC - 3FS'!AP131:AP138) -> -7009 | H23: =SUM('FC - 3FS'!AQ131:AQ138) -> -2766.9768 | I23: =SUM('FC - 3FS'!AR131:AR138) -> -2340.0684 | J23: =SUM('FC - 3FS'!AS131:AS138) -> -1865.3836 | ... M23: =SUM('FC - 3FS'!AV131:AV138) -> 0 | W23: =AVERAGE($V$4:$V$2517) -> #DIV/0!
B24: other non-cash adjustments | C24: =SUM('FC - 3FS'!AL122:AL129,'FC - 3FS'!AL139) -> 17461 | D24: =SUM('FC - 3FS'!AM122:AM129,'FC - 3FS'!AM139) -> 18007 | E24: =SUM('FC - 3FS'!AN122:AN129,'FC - 3FS'!AN139) -> 17246 | F24: =SUM('FC - 3FS'!AO122:AO129,'FC - 3FS'!AO139) -> 17300 | G24: =SUM('FC - 3FS'!AP122:AP129,'FC - 3FS'!AP139) -> 17963 | H24: =SUM('FC - 3FS'!AQ122:AQ129,'FC - 3FS'!AQ139) -> 19460.315 | I24: =SUM('FC - 3FS'!AR122:AR129,'FC - 3FS'!AR139) -> 21186.464 | J24: =SUM('FC - 3FS'!AS122:AS129,'FC - 3FS'!AS139) -> 19478.43 | ... M24: =SUM('FC - 3FS'!AV122:AV129,'FC - 3FS'!AV139) -> 0 | W24: =AVERAGE($V$4:$V$2517) -> #DIV/0!
B25: CapEx | C25: =+'FC - 3FS'!AL142 -> -11034 | D25: =+'FC - 3FS'!AM142 -> -12326 | E25: =+'FC - 3FS'!AN142 -> -13970 | F25: =+'FC - 3FS'!AO142 -> -9801 | G25: =+'FC - 3FS'!AP142 -> -8840 | H25: =+'FC - 3FS'!AQ142 -> -10023.267 | I25: =+'FC - 3FS'!AR142 -> -10562.247 | J25: =+'FC - 3FS'!AS142 -> -10941.004 | ... M25: =+'FC - 3FS'!AV142 -> 0 | W25: =AVERAGE($V$4:$V$2517) -> #DIV/0!
B26: as % of revenue | C26: =C25/C15 -> -0.16132287 | D26: =D25/D15 -> -0.15384807 | E26: =E25/E15 -> -0.17556648 | F26: =F25/F15 -> -0.12476132 | G26: =G25/G15 -> -0.10859951 | H26: =H25/H15 -> -0.1140985 | I26: =I25/I15 -> -0.11186768 | J26: =J25/J15 -> -0.11023483 | ... M26: =M25/M15 -> #DIV/0! | W26: =AVERAGE($V$4:$V$2517) -> #DIV/0!
W28: =AVERAGE($V$4:$V$2517) -> #DIV/0!
B29: Unlevered FCF | C29: =SUM(C22:C25) -> -299.59093 | D29: =SUM(D22:D25) -> 4786.4593 | E29: =SUM(E22:E25) -> 5607.6402 | F29: =SUM(F22:F25) -> 11228.374 | G29: =SUM(G22:G25) -> 15994.872 | H29: =SUM(H22:H25) -> 20873.582 | I29: =SUM(I22:I25) -> 24153.267 | J29: =SUM(J22:J25) -> 24931.797 | ... M29: =SUM(M22:M25) -> 0 | W29: =AVERAGE($V$4:$V$2517) -> #DIV/0!
B30: yoy growth | E30: =E29/D29-1 -> 0.17156333 | F30: =F29/E29-1 -> 1.0023349 | G30: =G29/F29-1 -> 0.4245048 | H30: =H29/G29-1 -> 0.30501713 | I30: =I29/H29-1 -> 0.15712135 | J30: =J29/I29-1 -> 0.032232914 | K30: =K29/J29-1 -> -1 | L30: =L29/K29-1 -> #DIV/0! | M30: =M29/L29-1 -> #DIV/0! | W30: =AVERAGE($V$4:$V$2517) -> #DIV/0!
B31: FCF Margin | C31: =C29/C15 -> -0.0043801765 | D31: =D29/D15 -> 0.05974262 | E31: =E29/E15 -> 0.070473416 | F31: =F29/F15 -> 0.142931 | G31: =G29/G15 -> 0.1964972 | H31: =H29/H15 -> 0.23761158 | I31: =I29/I15 -> 0.25581394 | J31: =J29/J15 -> 0.25119747 | ... M31: =M29/M15 -> #DIV/0! | W31: =AVERAGE($V$4:$V$2517) -> #DIV/0!
W32: =AVERAGE($V$4:$V$2517) -> #DIV/0!
