Workbook

Sheet Domestic 2025
A1: Rank | B1: Movie | C1: Release Date | D1: Distributor | E1: Genre | F1: 2025 Gross ($M) | G1: Tickets Sold | H1: Title (base) | I1: Row Labels | J1: Sum of 2025 Gross ($M) | K1: NormTitle | L1: Studio | M1: 2025 Box Office Gross ($M) | N1: StudioClean
A2: 1 | B2: A Minecraft Movie | C2: 45751 | D2: Warner Bros. | E2: Adventure | F2: 424087780 | G2: 35458844 | H2: =IFERROR(TRIM(LEFT(B2,FIND("(",B2)-1)),TRIM(B2)) -> A Minecraft Movie | I2: Walt Disney | J2: 1965890585 | K2: =SUBSTITUTE(SUBSTITUTE(SUBSTITUTE(SUBSTITUTE(SUBSTITUTE(SUBSTITUTE(SUBSTITUTE(SUBSTITUTE(SUBSTITUTE(SUBSTITUTE(SUBSTITUTE(SUBSTITUTE(LOWER(LEFT(SUBSTITUTE(H2,"…",""),25)),":",""),",",""),".",""),"'",""),"’",""),"!",""),"*",""),"—",""),"–",""),"-",""),"&","")," ","") -> aminecraftmovie | L2: =I2 -> Walt Disney | M2: =J2 -> 1965890585 | N2: =IF(D2="","Other",D2) -> Warner Bros.
A3: 2 | B3: Lilo & Stitch | C3: 45800 | D3: Walt Disney | E3: Adventure | F3: 423778855 | G3: 35433015 | H3: =IFERROR(TRIM(LEFT(B3,FIND("(",B3)-1)),TRIM(B3)) -> Lilo & Stitch | I3: Warner Bros. | J3: 1891341005 | K3: =SUBSTITUTE(SUBSTITUTE(SUBSTITUTE(SUBSTITUTE(SUBSTITUTE(SUBSTITUTE(SUBSTITUTE(SUBSTITUTE(SUBSTITUTE(SUBSTITUTE(SUBSTITUTE(SUBSTITUTE(LOWER(LEFT(SUBSTITUTE(H3,"…",""),25)),":",""),",",""),".",""),"'",""),"’",""),"!",""),"*",""),"—",""),"–",""),"-",""),"&","")," ","") -> lilostitch | L3: =I3 -> Warner Bros. | M3: =J3 -> 1891341005 | N3: =IF(D3="","Other",D3) -> Walt Disney
A4: 3 | B4: Superman | C4: 45849 | D4: Warner Bros. | E4: Action | F4: 354223803 | G4: 29617375 | H4: =IFERROR(TRIM(LEFT(B4,FIND("(",B4)-1)),TRIM(B4)) -> Superman | I4: Universal | J4: 1571343617 | K4: =SUBSTITUTE(SUBSTITUTE(SUBSTITUTE(SUBSTITUTE(SUBSTITUTE(SUBSTITUTE(SUBSTITUTE(SUBSTITUTE(SUBSTITUTE(SUBSTITUTE(SUBSTITUTE(SUBSTITUTE(LOWER(LEFT(SUBSTITUTE(H4,"…",""),25)),":",""),",",""),".",""),"'",""),"’",""),"!",""),"*",""),"—",""),"–",""),"-",""),"&","")," ","") -> superman | L4: =I4 -> Universal | M4: =J4 -> 1571343617 | N4: =IF(D4="","Other",D4) -> Warner Bros.
A5: 4 | B5: Jurassic World Rebirth | C5: 45840 | D5: Universal | E5: Action | F5: 339640400 | G5: 28398027 | H5: =IFERROR(TRIM(LEFT(B5,FIND("(",B5)-1)),TRIM(B5)) -> Jurassic World Rebirth | I5: Paramount Pictures | J5: 563517149 | K5: =SUBSTITUTE(SUBSTITUTE(SUBSTITUTE(SUBSTITUTE(SUBSTITUTE(SUBSTITUTE(SUBSTITUTE(SUBSTITUTE(SUBSTITUTE(SUBSTITUTE(SUBSTITUTE(SUBSTITUTE(LOWER(LEFT(SUBSTITUTE(H5,"…",""),25)),":",""),",",""),".",""),"'",""),"’",""),"!",""),"*",""),"—",""),"–",""),"-",""),"&","")," ","") -> jurassicworldrebirth | L5: =I5 -> Paramount Pictures | M5: =J5 -> 563517149 | N5: =IF(D5="","Other",D5) -> Universal
A6: 5 | B6: Zootopia 2 | C6: 45987 | D6: Walt Disney | E6: Adventure | F6: 337903155 | G6: 28252772 | H6: =IFERROR(TRIM(LEFT(B6,FIND("(",B6)-1)),TRIM(B6)) -> Zootopia 2 | I6: Sony Pictures | J6: 556796407 | K6: =SUBSTITUTE(SUBSTITUTE(SUBSTITUTE(SUBSTITUTE(SUBSTITUTE(SUBSTITUTE(SUBSTITUTE(SUBSTITUTE(SUBSTITUTE(SUBSTITUTE(SUBSTITUTE(SUBSTITUTE(LOWER(LEFT(SUBSTITUTE(H6,"…",""),25)),":",""),",",""),".",""),"'",""),"’",""),"!",""),"*",""),"—",""),"–",""),"-",""),"&","")," ","") -> zootopia2 | L6: =I6 -> Sony Pictures | M6: =J6 -> 556796407 | N6: =IF(D6="","Other",D6) -> Walt Disney
A7: 6 | B7: Wicked: For Good | C7: 45982 | D7: Universal | E7: Musical | F7: 335438675 | G7: 28046712 | H7: =IFERROR(TRIM(LEFT(B7,FIND("(",B7)-1)),TRIM(B7)) -> Wicked: For Good | I7: 20th Century Stud… | J7: 452223943 | K7: =SUBSTITUTE(SUBSTITUTE(SUBSTITUTE(SUBSTITUTE(SUBSTITUTE(SUBSTITUTE(SUBSTITUTE(SUBSTITUTE(SUBSTITUTE(SUBSTITUTE(SUBSTITUTE(SUBSTITUTE(LOWER(LEFT(SUBSTITUTE(H7,"…",""),25)),":",""),",",""),".",""),"'",""),"’",""),"!",""),"*",""),"—",""),"–",""),"-",""),"&","")," ","") -> wickedforgood | L7: =I7 -> 20th Century Stud… | M7: =J7 -> 452223943 | N7: =IF(D7="","Other",D7) -> Universal
A8: 7 | B8: Sinners | C8: 45765 | D8: Warner Bros. | E8: Horror | F8: 279989632 | G8: 23410504 | H8: =IFERROR(TRIM(LEFT(B8,FIND("(",B8)-1)),TRIM(B8)) -> Sinners | I8: Lionsgate | J8: 331288139 | K8: =SUBSTITUTE(SUBSTITUTE(SUBSTITUTE(SUBSTITUTE(SUBSTITUTE(SUBSTITUTE(SUBSTITUTE(SUBSTITUTE(SUBSTITUTE(SUBSTITUTE(SUBSTITUTE(SUBSTITUTE(LOWER(LEFT(SUBSTITUTE(H8,"…",""),25)),":",""),",",""),".",""),"'",""),"’",""),"!",""),"*",""),"—",""),"–",""),"-",""),"&","")," ","") -> sinners | L8: =I8 -> Lionsgate | M8: =J8 -> 331288139 | N8: =IF(D8="","Other",D8) -> Warner Bros.
A9: 8 | B9: The Fantastic Four: First Ste… | C9: 45863 | D9: Walt Disney | E9: Action | F9: 274286610 | G9: 22933663 | H9: =IFERROR(TRIM(LEFT(B9,FIND("(",B9)-1)),TRIM(B9)) -> The Fantastic Four: First Ste… | I9: A24 | J9: 231026707 | K9: =SUBSTITUTE(SUBSTITUTE(SUBSTITUTE(SUBSTITUTE(SUBSTITUTE(SUBSTITUTE(SUBSTITUTE(SUBSTITUTE(SUBSTITUTE(SUBSTITUTE(SUBSTITUTE(SUBSTITUTE(LOWER(LEFT(SUBSTITUTE(H9,"…",""),25)),":",""),",",""),".",""),"'",""),"’",""),"!",""),"*",""),"—",""),"–",""),"-",""),"&","")," ","") -> thefantasticfourfirst | L9: =I9 -> A24 | M9: =J9 -> 231026707 | N9: =IF(D9="","Other",D9) -> Walt Disney
A10: 9 | B10: How to Train Your Dragon | C10: 45821 | D10: Universal | E10: Adventure | F10: 262958100 | G10: 21986463 | H10: =IFERROR(TRIM(LEFT(B10,FIND("(",B10)-1)),TRIM(B10)) -> How to Train Your Dragon | I10: Focus Features | J10: 217958718 | K10: =SUBSTITUTE(SUBSTITUTE(SUBSTITUTE(SUBSTITUTE(SUBSTITUTE(SUBSTITUTE(SUBSTITUTE(SUBSTITUTE(SUBSTITUTE(SUBSTITUTE(SUBSTITUTE(SUBSTITUTE(LOWER(LEFT(SUBSTITUTE(H10,"…",""),25)),":",""),",",""),".",""),"'",""),"’",""),"!",""),"*",""),"—",""),"–",""),"-",""),"&","")," ","") -> howtotrainyourdragon | L10: Other | M10: =J132-SUM(M2:M9) -> 1152634501 | N10: =IF(D10="","Other",D10) -> Universal
A11: 10 | B11: Avatar: Fire and Ash | C11: 46010 | D11: 20th Century Stud… | E11: Action | F11: 250353869 | G11: 20932598 | H11: =IFERROR(TRIM(LEFT(B11,FIND("(",B11)-1)),TRIM(B11)) -> Avatar: Fire and Ash | I11: Angel Studios | J11: 167944327 | K11: =SUBSTITUTE(SUBSTITUTE(SUBSTITUTE(SUBSTITUTE(SUBSTITUTE(SUBSTITUTE(SUBSTITUTE(SUBSTITUTE(SUBSTITUTE(SUBSTITUTE(SUBSTITUTE(SUBSTITUTE(LOWER(LEFT(SUBSTITUTE(H11,"…",""),25)),":",""),",",""),".",""),"'",""),"’",""),"!",""),"*",""),"—",""),"–",""),"-",""),"&","")," ","") -> avatarfireandash | L11: Grand Total | M11: =SUM(M2:M10) -> 8716062053 | N11: =IF(D11="","Other",D11) -> 20th Century Stud…
A12: 11 | B12: Captain America: Brave New Wo… | C12: 45702 | D12: Walt Disney | E12: Action | F12: 200500001 | G12: 16764214 | H12: =IFERROR(TRIM(LEFT(B12,FIND("(",B12)-1)),TRIM(B12)) -> Captain America: Brave New Wo… | I12: Amazon MGM Studios | J12: 123549330 | K12: =SUBSTITUTE(SUBSTITUTE(SUBSTITUTE(SUBSTITUTE(SUBSTITUTE(SUBSTITUTE(SUBSTITUTE(SUBSTITUTE(SUBSTITUTE(SUBSTITUTE(SUBSTITUTE(SUBSTITUTE(LOWER(LEFT(SUBSTITUTE(H12,"…",""),25)),":",""),",",""),".",""),"'",""),"’",""),"!",""),"*",""),"—",""),"–",""),"-",""),"&","")," ","") -> captainamericabravene | N12: =IF(D12="","Other",D12) -> Walt Disney
A13: 12 | B13: Mission: Impossible—The Final… | C13: 45800 | D13: Paramount Pictures | E13: Action | F13: 197413515 | G13: 16506147 | H13: =IFERROR(TRIM(LEFT(B13,FIND("(",B13)-1)),TRIM(B13)) -> Mission: Impossible—The Final… | I13: Neon | J13: 104352652 | K13: =SUBSTITUTE(SUBSTITUTE(SUBSTITUTE(SUBSTITUTE(SUBSTITUTE(SUBSTITUTE(SUBSTITUTE(SUBSTITUTE(SUBSTITUTE(SUBSTITUTE(SUBSTITUTE(SUBSTITUTE(LOWER(LEFT(SUBSTITUTE(H13,"…",""),25)),":",""),",",""),".",""),"'",""),"’",""),"!",""),"*",""),"—",""),"–",""),"-",""),"&","")," ","") -> missionimpossiblethef | N13: =IF(D13="","Other",D13) -> Paramount Pictures
A14: 13 | B14: Thunderbolts* | C14: 45779 | D14: Walt Disney | E14: Action | F14: 190274328 | G14: 15909225 | H14: =IFERROR(TRIM(LEFT(B14,FIND("(",B14)-1)),TRIM(B14)) -> Thunderbolts* | I14: Searchlight Pictu… | J14: 73377390 | K14: =SUBSTITUTE(SUBSTITUTE(SUBSTITUTE(SUBSTITUTE(SUBSTITUTE(SUBSTITUTE(SUBSTITUTE(SUBSTITUTE(SUBSTITUTE(SUBSTITUTE(SUBSTITUTE(SUBSTITUTE(LOWER(LEFT(SUBSTITUTE(H14,"…",""),25)),":",""),",",""),".",""),"'",""),"’",""),"!",""),"*",""),"—",""),"–",""),"-",""),"&","")," ","") -> thunderbolts | N14: =IF(D14="","Other",D14) -> Walt Disney
A15: 14 | B15: F1: The Movie | C15: 45835 | D15: Warner Bros. | E15: Action | F15: 189642436 | G15: 15856391 | H15: =IFERROR(TRIM(LEFT(B15,FIND("(",B15)-1)),TRIM(B15)) -> F1: The Movie | I15: Fathom Entertainm… | J15: 52321724 | K15: =SUBSTITUTE(SUBSTITUTE(SUBSTITUTE(SUBSTITUTE(SUBSTITUTE(SUBSTITUTE(SUBSTITUTE(SUBSTITUTE(SUBSTITUTE(SUBSTITUTE(SUBSTITUTE(SUBSTITUTE(LOWER(LEFT(SUBSTITUTE(H15,"…",""),25)),":",""),",",""),".",""),"'",""),"’",""),"!",""),"*",""),"—",""),"–",""),"-",""),"&","")," ","") -> f1themovie | N15: =IF(D15="","Other",D15) -> Warner Bros.
A16: 15 | B16: The Conjuring: Last Rites | C16: 45905 | D16: Warner Bros. | E16: Horror | F16: 177756445 | G16: 14862579 | H16: =IFERROR(TRIM(LEFT(B16,FIND("(",B16)-1)),TRIM(B16)) -> The Conjuring: Last Rites | I16: Sony Pictures Cla… | J16: 49945605 | K16: =SUBSTITUTE(SUBSTITUTE(SUBSTITUTE(SUBSTITUTE(SUBSTITUTE(SUBSTITUTE(SUBSTITUTE(SUBSTITUTE(SUBSTITUTE(SUBSTITUTE(SUBSTITUTE(SUBSTITUTE(LOWER(LEFT(SUBSTITUTE(H16,"…",""),25)),":",""),",",""),".",""),"'",""),"’",""),"!",""),"*",""),"—",""),"–",""),"-",""),"&","")," ","") -> theconjuringlastrites | N16: =IF(D16="","Other",D16) -> Warner Bros.
A17: 16 | B17: Weapons | C17: 45877 | D17: Warner Bros. | E17: Horror | F17: 151572492 | G17: 12673285 | H17: =IFERROR(TRIM(LEFT(B17,FIND("(",B17)-1)),TRIM(B17)) -> Weapons | I17: GKIDS | J17: 45341684 | K17: =SUBSTITUTE(SUBSTITUTE(SUBSTITUTE(SUBSTITUTE(SUBSTITUTE(SUBSTITUTE(SUBSTITUTE(SUBSTITUTE(SUBSTITUTE(SUBSTITUTE(SUBSTITUTE(SUBSTITUTE(LOWER(LEFT(SUBSTITUTE(H17,"…",""),25)),":",""),",",""),".",""),"'",""),"’",""),"!",""),"*",""),"—",""),"–",""),"-",""),"&","")," ","") -> weapons | N17: =IF(D17="","Other",D17) -> Warner Bros.
A18: 17 | B18: Final Destination: Bloodlines | C18: 45793 | D18: Warner Bros. | E18: Horror | F18: 138254739 | G18: 11559761 | H18: =IFERROR(TRIM(LEFT(B18,FIND("(",B18)-1)),TRIM(B18)) -> Final Destination: Bloodlines | I18: AMC Theatres Dist… | J18: 34062774 | K18: =SUBSTITUTE(SUBSTITUTE(SUBSTITUTE(SUBSTITUTE(SUBSTITUTE(SUBSTITUTE(SUBSTITUTE(SUBSTITUTE(SUBSTITUTE(SUBSTITUTE(SUBSTITUTE(SUBSTITUTE(LOWER(LEFT(SUBSTITUTE(H18,"…",""),25)),":",""),",",""),".",""),"'",""),"’",""),"!",""),"*",""),"—",""),"–",""),"-",""),"&","")," ","") -> finaldestinationbloodl | N18: =IF(D18="","Other",D18) -> Warner Bros.
A19: 18 | B19: Demon Slayer -Kimetsu no Yaib… | C19: 45912 | D19: Sony Pictures | E19: Action | F19: 134487320 | G19: 11244759 | H19: =IFERROR(TRIM(LEFT(B19,FIND("(",B19)-1)),TRIM(B19)) -> Demon Slayer -Kimetsu no Yaib… | I19: Netflix | J19: 26800000 | K19: =SUBSTITUTE(SUBSTITUTE(SUBSTITUTE(SUBSTITUTE(SUBSTITUTE(SUBSTITUTE(SUBSTITUTE(SUBSTITUTE(SUBSTITUTE(SUBSTITUTE(SUBSTITUTE(SUBSTITUTE(LOWER(LEFT(SUBSTITUTE(H19,"…",""),25)),":",""),",",""),".",""),"'",""),"’",""),"!",""),"*",""),"—",""),"–",""),"-",""),"&","")," ","") -> demonslayerkimetsuno | N19: =IF(D19="","Other",D19) -> Sony Pictures
A20: 19 | B20: Mufasa: The Lion King | C20: 45646 | D20: Walt Disney | E20: Musical | F20: 126423748 | G20: 10570547 | H20: =IFERROR(TRIM(LEFT(B20,FIND("(",B20)-1)),TRIM(B20)) -> Mufasa: The Lion King | I20: (blank) | J20: 25925670 | K20: =SUBSTITUTE(SUBSTITUTE(SUBSTITUTE(SUBSTITUTE(SUBSTITUTE(SUBSTITUTE(SUBSTITUTE(SUBSTITUTE(SUBSTITUTE(SUBSTITUTE(SUBSTITUTE(SUBSTITUTE(LOWER(LEFT(SUBSTITUTE(H20,"…",""),25)),":",""),",",""),".",""),"'",""),"’",""),"!",""),"*",""),"—",""),"–",""),"-",""),"&","")," ","") -> mufasathelionking | N20: =IF(D20="","Other",D20) -> Walt Disney
A21: 20 | B21: Five Nights at Freddy’s 2 | C21: 45996 | D21: Universal | E21: Horror | F21: 121680315 | G21: 10173939 | H21: =IFERROR(TRIM(LEFT(B21,FIND("(",B21)-1)),TRIM(B21)) -> Five Nights at Freddy’s 2 | I21: Yash Raj Films | J21: 25359370 | K21: =SUBSTITUTE(SUBSTITUTE(SUBSTITUTE(SUBSTITUTE(SUBSTITUTE(SUBSTITUTE(SUBSTITUTE(SUBSTITUTE(SUBSTITUTE(SUBSTITUTE(SUBSTITUTE(SUBSTITUTE(LOWER(LEFT(SUBSTITUTE(H21,"…",""),25)),":",""),",",""),".",""),"'",""),"’",""),"!",""),"*",""),"—",""),"–",""),"-",""),"&","")," ","") -> fivenightsatfreddys2 | N21: =IF(D21="","Other",D21) -> Universal
A22: 21 | B22: Dog Man | C22: 45688 | D22: Universal | E22: Adventure | F22: 97970355 | G22: 8191501 | H22: =IFERROR(TRIM(LEFT(B22,FIND("(",B22)-1)),TRIM(B22)) -> Dog Man | I22: Roadside Attracti… | J22: 15690190 | K22: =SUBSTITUTE(SUBSTITUTE(SUBSTITUTE(SUBSTITUTE(SUBSTITUTE(SUBSTITUTE(SUBSTITUTE(SUBSTITUTE(SUBSTITUTE(SUBSTITUTE(SUBSTITUTE(SUBSTITUTE(LOWER(LEFT(SUBSTITUTE(H22,"…",""),25)),":",""),",",""),".",""),"'",""),"’",""),"!",""),"*",""),"—",""),"–",""),"-",""),"&","")," ","") -> dogman | N22: =IF(D22="","Other",D22) -> Universal
A23: 22 | B23: Freakier Friday | C23: 45877 | D23: Walt Disney | E23: Comedy | F23: 94186236 | G23: 7875103 | H23: =IFERROR(TRIM(LEFT(B23,FIND("(",B23)-1)),TRIM(B23)) -> Freakier Friday | I23: Bleecker Street | J23: 15424862 | K23: =SUBSTITUTE(SUBSTITUTE(SUBSTITUTE(SUBSTITUTE(SUBSTITUTE(SUBSTITUTE(SUBSTITUTE(SUBSTITUTE(SUBSTITUTE(SUBSTITUTE(SUBSTITUTE(SUBSTITUTE(LOWER(LEFT(SUBSTITUTE(H23,"…",""),25)),":",""),",",""),".",""),"'",""),"’",""),"!",""),"*",""),"—",""),"–",""),"-",""),"&","")," ","") -> freakierfriday | N23: =IF(D23="","Other",D23) -> Walt Disney
... A71: 70 | B71: M3GAN 2.0 | C71: 45835 | D71: Universal | E71: Horror | F71: 24101280 | G71: 2015157 | H71: =IFERROR(TRIM(LEFT(B71,FIND("(",B71)-1)),TRIM(B71)) -> M3GAN 2.0 | I71: Samuel Goldwyn Fi… | J71: 508403 | K71: =SUBSTITUTE(SUBSTITUTE(SUBSTITUTE(SUBSTITUTE(SUBSTITUTE(SUBSTITUTE(SUBSTITUTE(SUBSTITUTE(SUBSTITUTE(SUBSTITUTE(SUBSTITUTE(SUBSTITUTE(LOWER(LEFT(SUBSTITUTE(H71,"…",""),25)),":",""),",",""),".",""),"'",""),"’",""),"!",""),"*",""),"—",""),"–",""),"-",""),"&","")," ","") -> m3gan20 | N71: =IF(D71="","Other",D71) -> Universal
A72: 71 | B72: Ne Zha 2 (哪吒之魔童闹海) | C72: 45702 | E72: Action | F72: 23251218 | G72: 1944082 | H72: =IFERROR(TRIM(LEFT(B72,FIND("(",B72)-1)),TRIM(B72)) -> Ne Zha 2 | I72: Indican Pictures | J72: 444656 | K72: =SUBSTITUTE(SUBSTITUTE(SUBSTITUTE(SUBSTITUTE(SUBSTITUTE(SUBSTITUTE(SUBSTITUTE(SUBSTITUTE(SUBSTITUTE(SUBSTITUTE(SUBSTITUTE(SUBSTITUTE(LOWER(LEFT(SUBSTITUTE(H72,"…",""),25)),":",""),",",""),".",""),"'",""),"’",""),"!",""),"*",""),"—",""),"–",""),"-",""),"&","")," ","") -> nezha2 | N72: =IF(D72="","Other",D72) -> Other
A73: 72 | B73: Roofman | C73: 45940 | D73: Paramount Pictures | E73: Black Comedy | F73: 22739882 | G73: 1901328 | H73: =IFERROR(TRIM(LEFT(B73,FIND("(",B73)-1)),TRIM(B73)) -> Roofman | I73: 8 Above | J73: 388141 | K73: =SUBSTITUTE(SUBSTITUTE(SUBSTITUTE(SUBSTITUTE(SUBSTITUTE(SUBSTITUTE(SUBSTITUTE(SUBSTITUTE(SUBSTITUTE(SUBSTITUTE(SUBSTITUTE(SUBSTITUTE(LOWER(LEFT(SUBSTITUTE(H73,"…",""),25)),":",""),",",""),".",""),"'",""),"’",""),"!",""),"*",""),"—",""),"–",""),"-",""),"&","")," ","") -> roofman | N73: =IF(D73="","Other",D73) -> Paramount Pictures
A74: 73 | B74: Springsteen: Deliver Me From … | C74: 45954 | D74: 20th Century Stud… | E74: Drama | F74: 22638297 | G74: 1892834 | H74: =IFERROR(TRIM(LEFT(B74,FIND("(",B74)-1)),TRIM(B74)) -> Springsteen: Deliver Me From … | I74: FUNimation | J74: 383542 | K74: =SUBSTITUTE(SUBSTITUTE(SUBSTITUTE(SUBSTITUTE(SUBSTITUTE(SUBSTITUTE(SUBSTITUTE(SUBSTITUTE(SUBSTITUTE(SUBSTITUTE(SUBSTITUTE(SUBSTITUTE(LOWER(LEFT(SUBSTITUTE(H74,"…",""),25)),":",""),",",""),".",""),"'",""),"’",""),"!",""),"*",""),"—",""),"–",""),"-",""),"&","")," ","") -> springsteendelivermef | N74: =IF(D74="","Other",D74) -> 20th Century Stud…
A75: 74 | B75: The Woman in the Yard | C75: 45744 | D75: Universal | E75: Horror | F75: 22405985 | G75: 1873410 | H75: =IFERROR(TRIM(LEFT(B75,FIND("(",B75)-1)),TRIM(B75)) -> The Woman in the Yard | I75: Republic Pictures | J75: 368186 | K75: =SUBSTITUTE(SUBSTITUTE(SUBSTITUTE(SUBSTITUTE(SUBSTITUTE(SUBSTITUTE(SUBSTITUTE(SUBSTITUTE(SUBSTITUTE(SUBSTITUTE(SUBSTITUTE(SUBSTITUTE(LOWER(LEFT(SUBSTITUTE(H75,"…",""),25)),":",""),",",""),".",""),"'",""),"’",""),"!",""),"*",""),"—",""),"–",""),"-",""),"&","")," ","") -> thewomanintheyard | N75: =IF(D75="","Other",D75) -> Universal
A76: 75 | B76: Nobody 2 | C76: 45884 | D76: Universal | E76: Thriller/Suspense | F76: 21604985 | G76: 1806437 | H76: =IFERROR(TRIM(LEFT(B76,FIND("(",B76)-1)),TRIM(B76)) -> Nobody 2 | I76: Shudder | J76: 308555 | K76: =SUBSTITUTE(SUBSTITUTE(SUBSTITUTE(SUBSTITUTE(SUBSTITUTE(SUBSTITUTE(SUBSTITUTE(SUBSTITUTE(SUBSTITUTE(SUBSTITUTE(SUBSTITUTE(SUBSTITUTE(LOWER(LEFT(SUBSTITUTE(H76,"…",""),25)),":",""),",",""),".",""),"'",""),"’",""),"!",""),"*",""),"—",""),"–",""),"-",""),"&","")," ","") -> nobody2 | N76: =IF(D76="","Other",D76) -> Universal
A77: 76 | B77: Black Bag | C77: 45730 | D77: Focus Features | E77: Thriller/Suspense | F77: 21474035 | G77: 1795488 | H77: =IFERROR(TRIM(LEFT(B77,FIND("(",B77)-1)),TRIM(B77)) -> Black Bag | I77: Miramax | J77: 272559 | K77: =SUBSTITUTE(SUBSTITUTE(SUBSTITUTE(SUBSTITUTE(SUBSTITUTE(SUBSTITUTE(SUBSTITUTE(SUBSTITUTE(SUBSTITUTE(SUBSTITUTE(SUBSTITUTE(SUBSTITUTE(LOWER(LEFT(SUBSTITUTE(H77,"…",""),25)),":",""),",",""),".",""),"'",""),"’",""),"!",""),"*",""),"—",""),"–",""),"-",""),"&","")," ","") -> blackbag | N77: =IF(D77="","Other",D77) -> Focus Features
A78: 77 | B78: Together | C78: 45868 | D78: Neon | E78: Horror | F78: 21273161 | G78: 1778692 | H78: =IFERROR(TRIM(LEFT(B78,FIND("(",B78)-1)),TRIM(B78)) -> Together | I78: SRH | J78: 243844 | K78: =SUBSTITUTE(SUBSTITUTE(SUBSTITUTE(SUBSTITUTE(SUBSTITUTE(SUBSTITUTE(SUBSTITUTE(SUBSTITUTE(SUBSTITUTE(SUBSTITUTE(SUBSTITUTE(SUBSTITUTE(LOWER(LEFT(SUBSTITUTE(H78,"…",""),25)),":",""),",",""),".",""),"'",""),"’",""),"!",""),"*",""),"—",""),"–",""),"-",""),"&","")," ","") -> together | N78: =IF(D78="","Other",D78) -> Neon
A79: 78 | B79: Last Breath | C79: 45716 | D79: Focus Features | E79: Thriller/Suspense | F79: 21051180 | G79: 1760132 | H79: =IFERROR(TRIM(LEFT(B79,FIND("(",B79)-1)),TRIM(B79)) -> Last Breath | I79: 1-2 Special | J79: 231031 | K79: =SUBSTITUTE(SUBSTITUTE(SUBSTITUTE(SUBSTITUTE(SUBSTITUTE(SUBSTITUTE(SUBSTITUTE(SUBSTITUTE(SUBSTITUTE(SUBSTITUTE(SUBSTITUTE(SUBSTITUTE(LOWER(LEFT(SUBSTITUTE(H79,"…",""),25)),":",""),",",""),".",""),"'",""),"’",""),"!",""),"*",""),"—",""),"–",""),"-",""),"&","")," ","") -> lastbreath | N79: =IF(D79="","Other",D79) -> Focus Features
A80: 79 | B80: Companion | C80: 45688 | D80: Warner Bros. | E80: Black Comedy | F80: 20869122 | G80: 1744910 | H80: =IFERROR(TRIM(LEFT(B80,FIND("(",B80)-1)),TRIM(B80)) -> Companion | I80: Cartuna | J80: 205882 | K80: =SUBSTITUTE(SUBSTITUTE(SUBSTITUTE(SUBSTITUTE(SUBSTITUTE(SUBSTITUTE(SUBSTITUTE(SUBSTITUTE(SUBSTITUTE(SUBSTITUTE(SUBSTITUTE(SUBSTITUTE(LOWER(LEFT(SUBSTITUTE(H80,"…",""),25)),":",""),",",""),".",""),"'",""),"’",""),"!",""),"*",""),"—",""),"–",""),"-",""),"&","")," ","") -> companion | N80: =IF(D80="","Other",D80) -> Warner Bros.
A81: 80 | B81: Wolf Man | C81: 45674 | D81: Universal | E81: Horror | F81: 20707280 | G81: 1731378 | H81: =IFERROR(TRIM(LEFT(B81,FIND("(",B81)-1)),TRIM(B81)) -> Wolf Man | I81: Atlas Distribution | J81: 197000 | K81: =SUBSTITUTE(SUBSTITUTE(SUBSTITUTE(SUBSTITUTE(SUBSTITUTE(SUBSTITUTE(SUBSTITUTE(SUBSTITUTE(SUBSTITUTE(SUBSTITUTE(SUBSTITUTE(SUBSTITUTE(LOWER(LEFT(SUBSTITUTE(H81,"…",""),25)),":",""),",",""),".",""),"'",""),"’",""),"!",""),"*",""),"—",""),"–",""),"-",""),"&","")," ","") -> wolfman | N81: =IF(D81="","Other",D81) -> Universal
A82: 81 | B82: The Chosen: Last Supper — Par… | C82: 45743 | D82: Fathom Entertainm… | E82: Drama | F82: 20257290 | G82: 1693753 | H82: =IFERROR(TRIM(LEFT(B82,FIND("(",B82)-1)),TRIM(B82)) -> The Chosen: Last Supper — Par… | I82: SDG Releasing | J82: 174932 | K82: =SUBSTITUTE(SUBSTITUTE(SUBSTITUTE(SUBSTITUTE(SUBSTITUTE(SUBSTITUTE(SUBSTITUTE(SUBSTITUTE(SUBSTITUTE(SUBSTITUTE(SUBSTITUTE(SUBSTITUTE(LOWER(LEFT(SUBSTITUTE(H82,"…",""),25)),":",""),",",""),".",""),"'",""),"’",""),"!",""),"*",""),"—",""),"–",""),"-",""),"&","")," ","") -> thechosenlastsupper | N82: =IF(D82="","Other",D82) -> Fathom Entertainm…
A83: 82 | B83: Until Dawn | C83: 45772 | D83: Sony Pictures | E83: Horror | F83: 20172192 | G83: 1686638 | H83: =IFERROR(TRIM(LEFT(B83,FIND("(",B83)-1)),TRIM(B83)) -> Until Dawn | I83: Seismic Releasing | J83: 172187 | K83: =SUBSTITUTE(SUBSTITUTE(SUBSTITUTE(SUBSTITUTE(SUBSTITUTE(SUBSTITUTE(SUBSTITUTE(SUBSTITUTE(SUBSTITUTE(SUBSTITUTE(SUBSTITUTE(SUBSTITUTE(LOWER(LEFT(SUBSTITUTE(H83,"…",""),25)),":",""),",",""),".",""),"'",""),"’",""),"!",""),"*",""),"—",""),"–",""),"-",""),"&","")," ","") -> untildawn | N83: =IF(D83="","Other",D83) -> Sony Pictures
A84: 83 | B84: Novocaine | C84: 45730 | D84: Paramount Pictures | E84: Action | F84: 19861854 | G84: 1660690 | H84: =IFERROR(TRIM(LEFT(B84,FIND("(",B84)-1)),TRIM(B84)) -> Novocaine | I84: Abramorama Films | J84: 163200 | K84: =SUBSTITUTE(SUBSTITUTE(SUBSTITUTE(SUBSTITUTE(SUBSTITUTE(SUBSTITUTE(SUBSTITUTE(SUBSTITUTE(SUBSTITUTE(SUBSTITUTE(SUBSTITUTE(SUBSTITUTE(LOWER(LEFT(SUBSTITUTE(H84,"…",""),25)),":",""),",",""),".",""),"'",""),"’",""),"!",""),"*",""),"—",""),"–",""),"-",""),"&","")," ","") -> novocaine | N84: =IF(D84="","Other",D84) -> Paramount Pictures
... A101: 100 | B101: The Strangers: Chapter 2 | C101: 45926 | D101: Lionsgate | E101: Horror | F101: 15153346 | G101: 1267002 | H101: =IFERROR(TRIM(LEFT(B101,FIND("(",B101)-1)),TRIM(B101)) -> The Strangers: Chapter 2 | I101: Lost and Found Fi… | J101: 67407 | K101: =SUBSTITUTE(SUBSTITUTE(SUBSTITUTE(SUBSTITUTE(SUBSTITUTE(SUBSTITUTE(SUBSTITUTE(SUBSTITUTE(SUBSTITUTE(SUBSTITUTE(SUBSTITUTE(SUBSTITUTE(LOWER(LEFT(SUBSTITUTE(H101,"…",""),25)),":",""),",",""),".",""),"'",""),"’",""),"!",""),"*",""),"—",""),"–",""),"-",""),"&","")," ","") -> thestrangerschapter2 | N101: =IF(D101="","Other",D101) -> Lionsgate
A102: 101 | B102: Warner Bros. Other Catalog | C102: 46022 | D102: Warner Bros. | F102: 14889055 | G102: 1244904 | H102: =IFERROR(TRIM(LEFT(B102,FIND("(",B102)-1)),TRIM(B102)) -> Warner Bros. Other Catalog | I102: Falling Forward F… | J102: 65182 | K102: =SUBSTITUTE(SUBSTITUTE(SUBSTITUTE(SUBSTITUTE(SUBSTITUTE(SUBSTITUTE(SUBSTITUTE(SUBSTITUTE(SUBSTITUTE(SUBSTITUTE(SUBSTITUTE(SUBSTITUTE(LOWER(LEFT(SUBSTITUTE(H102,"…",""),25)),":",""),",",""),".",""),"'",""),"’",""),"!",""),"*",""),"—",""),"–",""),"-",""),"&","")," ","") -> warnerbrosothercatalo | N102: =IF(D102="","Other",D102) -> Warner Bros.
A103: 102 | B103: Nuremberg | C103: 45968 | D103: Sony Pictures Cla… | E103: Drama | F103: 14296489 | G103: 1195359 | H103: =IFERROR(TRIM(LEFT(B103,FIND("(",B103)-1)),TRIM(B103)) -> Nuremberg | I103: MTV Documentary F… | J103: 60970 | K103: =SUBSTITUTE(SUBSTITUTE(SUBSTITUTE(SUBSTITUTE(SUBSTITUTE(SUBSTITUTE(SUBSTITUTE(SUBSTITUTE(SUBSTITUTE(SUBSTITUTE(SUBSTITUTE(SUBSTITUTE(LOWER(LEFT(SUBSTITUTE(H103,"…",""),25)),":",""),",",""),".",""),"'",""),"’",""),"!",""),"*",""),"—",""),"–",""),"-",""),"&","")," ","") -> nuremberg | N103: =IF(D103="","Other",D103) -> Sony Pictures Cla…
...

Sheet Global 2025
A1: Rank | B1: Release Group | C1: Worldwide | D1: Domestic | E1: % | F1: Foreign | G1: % | H1: Title (base) | I1: NormTitle | J1: Studio
A2: 1 | B2: Ne Zha 2 | C2: 2267446370 | D2: 23308176 | E2: 0.01 | F2: 2244138194 | G2: 0.99 | H2: =IFERROR(TRIM(LEFT(B2,FIND("(",B2)-1)),TRIM(B2)) -> Ne Zha 2 | I2: =SUBSTITUTE(SUBSTITUTE(SUBSTITUTE(SUBSTITUTE(SUBSTITUTE(SUBSTITUTE(SUBSTITUTE(SUBSTITUTE(SUBSTITUTE(SUBSTITUTE(SUBSTITUTE(SUBSTITUTE(LOWER(LEFT(SUBSTITUTE(H2,"…",""),25)),":",""),",",""),".",""),"'",""),"’",""),"!",""),"*",""),"—",""),"–",""),"-",""),"&","")," ","") -> nezha2 | J2: =IFERROR(INDEX('Domestic 2025'!$N:$N,MATCH($I2,'Domestic 2025'!$K:$K,0)),IFERROR(INDEX('Domestic 2025'!$N:$N,MATCH($D2,'Domestic 2025'!$F:$F,0)),"Other")) -> Other
A3: 2 | B3: Zootopia 2 | C3: 1866647950 | D3: 428130160 | E3: 0.229 | F3: 1438517790 | G3: 0.771 | H3: =IFERROR(TRIM(LEFT(B3,FIND("(",B3)-1)),TRIM(B3)) -> Zootopia 2 | I3: =SUBSTITUTE(SUBSTITUTE(SUBSTITUTE(SUBSTITUTE(SUBSTITUTE(SUBSTITUTE(SUBSTITUTE(SUBSTITUTE(SUBSTITUTE(SUBSTITUTE(SUBSTITUTE(SUBSTITUTE(LOWER(LEFT(SUBSTITUTE(H3,"…",""),25)),":",""),",",""),".",""),"'",""),"’",""),"!",""),"*",""),"—",""),"–",""),"-",""),"&","")," ","") -> zootopia2 | J3: =IFERROR(INDEX('Domestic 2025'!$N:$N,MATCH($I3,'Domestic 2025'!$K:$K,0)),IFERROR(INDEX('Domestic 2025'!$N:$N,MATCH($D3,'Domestic 2025'!$F:$F,0)),"Other")) -> Walt Disney
A4: 3 | B4: Avatar: Fire and Ash | C4: 1485999890 | D4: 404340010 | E4: 0.272 | F4: 1081659880 | G4: 0.728 | H4: =IFERROR(TRIM(LEFT(B4,FIND("(",B4)-1)),TRIM(B4)) -> Avatar: Fire and Ash | I4: =SUBSTITUTE(SUBSTITUTE(SUBSTITUTE(SUBSTITUTE(SUBSTITUTE(SUBSTITUTE(SUBSTITUTE(SUBSTITUTE(SUBSTITUTE(SUBSTITUTE(SUBSTITUTE(SUBSTITUTE(LOWER(LEFT(SUBSTITUTE(H4,"…",""),25)),":",""),",",""),".",""),"'",""),"’",""),"!",""),"*",""),"—",""),"–",""),"-",""),"&","")," ","") -> avatarfireandash | J4: =IFERROR(INDEX('Domestic 2025'!$N:$N,MATCH($I4,'Domestic 2025'!$K:$K,0)),IFERROR(INDEX('Domestic 2025'!$N:$N,MATCH($D4,'Domestic 2025'!$F:$F,0)),"Other")) -> 20th Century Stud…
A5: 4 | B5: Lilo & Stitch | C5: 1038027526 | D5: 423778855 | E5: 0.408 | F5: 614248671 | G5: 0.592 | H5: =IFERROR(TRIM(LEFT(B5,FIND("(",B5)-1)),TRIM(B5)) -> Lilo & Stitch | I5: =SUBSTITUTE(SUBSTITUTE(SUBSTITUTE(SUBSTITUTE(SUBSTITUTE(SUBSTITUTE(SUBSTITUTE(SUBSTITUTE(SUBSTITUTE(SUBSTITUTE(SUBSTITUTE(SUBSTITUTE(LOWER(LEFT(SUBSTITUTE(H5,"…",""),25)),":",""),",",""),".",""),"'",""),"’",""),"!",""),"*",""),"—",""),"–",""),"-",""),"&","")," ","") -> lilostitch | J5: =IFERROR(INDEX('Domestic 2025'!$N:$N,MATCH($I5,'Domestic 2025'!$K:$K,0)),IFERROR(INDEX('Domestic 2025'!$N:$N,MATCH($D5,'Domestic 2025'!$F:$F,0)),"Other")) -> Walt Disney
A6: 5 | B6: A Minecraft Movie | C6: 960387780 | D6: 424087780 | E6: 0.442 | F6: 536300000 | G6: 0.558 | H6: =IFERROR(TRIM(LEFT(B6,FIND("(",B6)-1)),TRIM(B6)) -> A Minecraft Movie | I6: =SUBSTITUTE(SUBSTITUTE(SUBSTITUTE(SUBSTITUTE(SUBSTITUTE(SUBSTITUTE(SUBSTITUTE(SUBSTITUTE(SUBSTITUTE(SUBSTITUTE(SUBSTITUTE(SUBSTITUTE(LOWER(LEFT(SUBSTITUTE(H6,"…",""),25)),":",""),",",""),".",""),"'",""),"’",""),"!",""),"*",""),"—",""),"–",""),"-",""),"&","")," ","") -> aminecraftmovie | J6: =IFERROR(INDEX('Domestic 2025'!$N:$N,MATCH($I6,'Domestic 2025'!$K:$K,0)),IFERROR(INDEX('Domestic 2025'!$N:$N,MATCH($D6,'Domestic 2025'!$F:$F,0)),"Other")) -> Warner Bros.
A7: 6 | B7: Jurassic World: Rebirth | C7: 869146189 | D7: 339640400 | E7: 0.391 | F7: 529505789 | G7: 0.609 | H7: =IFERROR(TRIM(LEFT(B7,FIND("(",B7)-1)),TRIM(B7)) -> Jurassic World: Rebirth | I7: =SUBSTITUTE(SUBSTITUTE(SUBSTITUTE(SUBSTITUTE(SUBSTITUTE(SUBSTITUTE(SUBSTITUTE(SUBSTITUTE(SUBSTITUTE(SUBSTITUTE(SUBSTITUTE(SUBSTITUTE(LOWER(LEFT(SUBSTITUTE(H7,"…",""),25)),":",""),",",""),".",""),"'",""),"’",""),"!",""),"*",""),"—",""),"–",""),"-",""),"&","")," ","") -> jurassicworldrebirth | J7: =IFERROR(INDEX('Domestic 2025'!$N:$N,MATCH($I7,'Domestic 2025'!$K:$K,0)),IFERROR(INDEX('Domestic 2025'!$N:$N,MATCH($D7,'Domestic 2025'!$F:$F,0)),"Other")) -> Universal
A8: 7 | B8: Demon Slayer: Kimetsu No Yaiba Infinity Castle | C8: 793498985 | D8: 136950340 | E8: 0.173 | F8: 656548645 | G8: 0.827 | H8: =IFERROR(TRIM(LEFT(B8,FIND("(",B8)-1)),TRIM(B8)) -> Demon Slayer: Kimetsu No Yaiba Infinity Castle | I8: =SUBSTITUTE(SUBSTITUTE(SUBSTITUTE(SUBSTITUTE(SUBSTITUTE(SUBSTITUTE(SUBSTITUTE(SUBSTITUTE(SUBSTITUTE(SUBSTITUTE(SUBSTITUTE(SUBSTITUTE(LOWER(LEFT(SUBSTITUTE(H8,"…",""),25)),":",""),",",""),".",""),"'",""),"’",""),"!",""),"*",""),"—",""),"–",""),"-",""),"&","")," ","") -> demonslayerkimetsuno | J8: =IFERROR(INDEX('Domestic 2025'!$N:$N,MATCH($I8,'Domestic 2025'!$K:$K,0)),IFERROR(INDEX('Domestic 2025'!$N:$N,MATCH($D8,'Domestic 2025'!$F:$F,0)),"Other")) -> Sony Pictures
A9: 8 | B9: How to Train Your Dragon | C9: 636596299 | D9: 262958100 | E9: 0.413 | F9: 373638199 | G9: 0.587 | H9: =IFERROR(TRIM(LEFT(B9,FIND("(",B9)-1)),TRIM(B9)) -> How to Train Your Dragon | I9: =SUBSTITUTE(SUBSTITUTE(SUBSTITUTE(SUBSTITUTE(SUBSTITUTE(SUBSTITUTE(SUBSTITUTE(SUBSTITUTE(SUBSTITUTE(SUBSTITUTE(SUBSTITUTE(SUBSTITUTE(LOWER(LEFT(SUBSTITUTE(H9,"…",""),25)),":",""),",",""),".",""),"'",""),"’",""),"!",""),"*",""),"—",""),"–",""),"-",""),"&","")," ","") -> howtotrainyourdragon | J9: =IFERROR(INDEX('Domestic 2025'!$N:$N,MATCH($I9,'Domestic 2025'!$K:$K,0)),IFERROR(INDEX('Domestic 2025'!$N:$N,MATCH($D9,'Domestic 2025'!$F:$F,0)),"Other")) -> Universal
A10: 9 | B10: F1: The Movie | C10: 634142436 | D10: 189642436 | E10: 0.299 | F10: 444500000 | G10: 0.701 | H10: =IFERROR(TRIM(LEFT(B10,FIND("(",B10)-1)),TRIM(B10)) -> F1: The Movie | I10: =SUBSTITUTE(SUBSTITUTE(SUBSTITUTE(SUBSTITUTE(SUBSTITUTE(SUBSTITUTE(SUBSTITUTE(SUBSTITUTE(SUBSTITUTE(SUBSTITUTE(SUBSTITUTE(SUBSTITUTE(LOWER(LEFT(SUBSTITUTE(H10,"…",""),25)),":",""),",",""),".",""),"'",""),"’",""),"!",""),"*",""),"—",""),"–",""),"-",""),"&","")," ","") -> f1themovie | J10: =IFERROR(INDEX('Domestic 2025'!$N:$N,MATCH($I10,'Domestic 2025'!$K:$K,0)),IFERROR(INDEX('Domestic 2025'!$N:$N,MATCH($D10,'Domestic 2025'!$F:$F,0)),"Other")) -> Warner Bros.
A11: 10 | B11: Superman | C11: 618723803 | D11: 354223803 | E11: 0.573 | F11: 264500000 | G11: 0.427 | H11: =IFERROR(TRIM(LEFT(B11,FIND("(",B11)-1)),TRIM(B11)) -> Superman | I11: =SUBSTITUTE(SUBSTITUTE(SUBSTITUTE(SUBSTITUTE(SUBSTITUTE(SUBSTITUTE(SUBSTITUTE(SUBSTITUTE(SUBSTITUTE(SUBSTITUTE(SUBSTITUTE(SUBSTITUTE(LOWER(LEFT(SUBSTITUTE(H11,"…",""),25)),":",""),",",""),".",""),"'",""),"’",""),"!",""),"*",""),"—",""),"–",""),"-",""),"&","")," ","") -> superman | J11: =IFERROR(INDEX('Domestic 2025'!$N:$N,MATCH($I11,'Domestic 2025'!$K:$K,0)),IFERROR(INDEX('Domestic 2025'!$N:$N,MATCH($D11,'Domestic 2025'!$F:$F,0)),"Other")) -> Warner Bros.
A12: 11 | B12: Mission: Impossible - The Final Reckoning | C12: 598767057 | D12: 197413515 | E12: 0.33 | F12: 401353542 | G12: 0.67 | H12: =IFERROR(TRIM(LEFT(B12,FIND("(",B12)-1)),TRIM(B12)) -> Mission: Impossible - The Final Reckoning | I12: =SUBSTITUTE(SUBSTITUTE(SUBSTITUTE(SUBSTITUTE(SUBSTITUTE(SUBSTITUTE(SUBSTITUTE(SUBSTITUTE(SUBSTITUTE(SUBSTITUTE(SUBSTITUTE(SUBSTITUTE(LOWER(LEFT(SUBSTITUTE(H12,"…",""),25)),":",""),",",""),".",""),"'",""),"’",""),"!",""),"*",""),"—",""),"–",""),"-",""),"&","")," ","") -> missionimpossiblethe | J12: =IFERROR(INDEX('Domestic 2025'!$N:$N,MATCH($I12,'Domestic 2025'!$K:$K,0)),IFERROR(INDEX('Domestic 2025'!$N:$N,MATCH($D12,'Domestic 2025'!$F:$F,0)),"Other")) -> Paramount Pictures
A13: 12 | B13: Wicked: For Good | C13: 540807925 | D13: 342915090 | E13: 0.634 | F13: 197892835 | G13: 0.366 | H13: =IFERROR(TRIM(LEFT(B13,FIND("(",B13)-1)),TRIM(B13)) -> Wicked: For Good | I13: =SUBSTITUTE(SUBSTITUTE(SUBSTITUTE(SUBSTITUTE(SUBSTITUTE(SUBSTITUTE(SUBSTITUTE(SUBSTITUTE(SUBSTITUTE(SUBSTITUTE(SUBSTITUTE(SUBSTITUTE(LOWER(LEFT(SUBSTITUTE(H13,"…",""),25)),":",""),",",""),".",""),"'",""),"’",""),"!",""),"*",""),"—",""),"–",""),"-",""),"&","")," ","") -> wickedforgood | J13: =IFERROR(INDEX('Domestic 2025'!$N:$N,MATCH($I13,'Domestic 2025'!$K:$K,0)),IFERROR(INDEX('Domestic 2025'!$N:$N,MATCH($D13,'Domestic 2025'!$F:$F,0)),"Other")) -> Universal
... A16: 15 | B16: The Conjuring: Last Rites | C16: 499256445 | D16: 177756445 | E16: 0.356 | F16: 321500000 | G16: 0.644 | H16: =IFERROR(TRIM(LEFT(B16,FIND("(",B16)-1)),TRIM(B16)) -> The Conjuring: Last Rites | I16: =SUBSTITUTE(SUBSTITUTE(SUBSTITUTE(SUBSTITUTE(SUBSTITUTE(SUBSTITUTE(SUBSTITUTE(SUBSTITUTE(SUBSTITUTE(SUBSTITUTE(SUBSTITUTE(SUBSTITUTE(LOWER(LEFT(SUBSTITUTE(H16,"…",""),25)),":",""),",",""),".",""),"'",""),"’",""),"!",""),"*",""),"—",""),"–",""),"-",""),"&","")," ","") -> theconjuringlastrites | J16: =IFERROR(INDEX('Domestic 2025'!$N:$N,MATCH($I16,'Domestic 2025'!$K:$K,0)),IFERROR(INDEX('Domestic 2025'!$N:$N,MATCH($D16,'Domestic 2025'!$F:$F,0)),"Other")) -> Warner Bros.
A17: 16 | B17: Dead to Rights | C17: 422789550 | D17: - | E17: - | F17: 422789550 | G17: 1 | H17: =IFERROR(TRIM(LEFT(B17,FIND("(",B17)-1)),TRIM(B17)) -> Dead to Rights | I17: =SUBSTITUTE(SUBSTITUTE(SUBSTITUTE(SUBSTITUTE(SUBSTITUTE(SUBSTITUTE(SUBSTITUTE(SUBSTITUTE(SUBSTITUTE(SUBSTITUTE(SUBSTITUTE(SUBSTITUTE(LOWER(LEFT(SUBSTITUTE(H17,"…",""),25)),":",""),",",""),".",""),"'",""),"’",""),"!",""),"*",""),"—",""),"–",""),"-",""),"&","")," ","") -> deadtorights | J17: =IFERROR(INDEX('Domestic 2025'!$N:$N,MATCH($I17,'Domestic 2025'!$K:$K,0)),IFERROR(INDEX('Domestic 2025'!$N:$N,MATCH($D17,'Domestic 2025'!$F:$F,0)),"Other")) -> Other
A18: 17 | B18: Captain America: Brave New World | C18: 415101577 | D18: 200500001 | E18: 0.483 | F18: 214601576 | G18: 0.517 | H18: =IFERROR(TRIM(LEFT(B18,FIND("(",B18)-1)),TRIM(B18)) -> Captain America: Brave New World | I18: =SUBSTITUTE(SUBSTITUTE(SUBSTITUTE(SUBSTITUTE(SUBSTITUTE(SUBSTITUTE(SUBSTITUTE(SUBSTITUTE(SUBSTITUTE(SUBSTITUTE(SUBSTITUTE(SUBSTITUTE(LOWER(LEFT(SUBSTITUTE(H18,"…",""),25)),":",""),",",""),".",""),"'",""),"’",""),"!",""),"*",""),"—",""),"–",""),"-",""),"&","")," ","") -> captainamericabravene | J18: =IFERROR(INDEX('Domestic 2025'!$N:$N,MATCH($I18,'Domestic 2025'!$K:$K,0)),IFERROR(INDEX('Domestic 2025'!$N:$N,MATCH($D18,'Domestic 2025'!$F:$F,0)),"Other")) -> Walt Disney
A19: 18 | B19: The Housemaid | C19: 400530884 | D19: 126432462 | E19: 0.316 | F19: 274098422 | G19: 0.684 | H19: =IFERROR(TRIM(LEFT(B19,FIND("(",B19)-1)),TRIM(B19)) -> The Housemaid | I19: =SUBSTITUTE(SUBSTITUTE(SUBSTITUTE(SUBSTITUTE(SUBSTITUTE(SUBSTITUTE(SUBSTITUTE(SUBSTITUTE(SUBSTITUTE(SUBSTITUTE(SUBSTITUTE(SUBSTITUTE(LOWER(LEFT(SUBSTITUTE(H19,"…",""),25)),":",""),",",""),".",""),"'",""),"’",""),"!",""),"*",""),"—",""),"–",""),"-",""),"&","")," ","") -> thehousemaid | J19: =IFERROR(INDEX('Domestic 2025'!$N:$N,MATCH($I19,'Domestic 2025'!$K:$K,0)),IFERROR(INDEX('Domestic 2025'!$N:$N,MATCH($D19,'Domestic 2025'!$F:$F,0)),"Other")) -> Lionsgate
A20: 19 | B20: Thunderbolts* | C20: 382436917 | D20: 190274328 | E20: 0.498 | F20: 192162589 | G20: 0.502 | H20: =IFERROR(TRIM(LEFT(B20,FIND("(",B20)-1)),TRIM(B20)) -> Thunderbolts* | I20: =SUBSTITUTE(SUBSTITUTE(SUBSTITUTE(SUBSTITUTE(SUBSTITUTE(SUBSTITUTE(SUBSTITUTE(SUBSTITUTE(SUBSTITUTE(SUBSTITUTE(SUBSTITUTE(SUBSTITUTE(LOWER(LEFT(SUBSTITUTE(H20,"…",""),25)),":",""),",",""),".",""),"'",""),"’",""),"!",""),"*",""),"—",""),"–",""),"-",""),"&","")," ","") -> thunderbolts | J20: =IFERROR(INDEX('Domestic 2025'!$N:$N,MATCH($I20,'Domestic 2025'!$K:$K,0)),IFERROR(INDEX('Domestic 2025'!$N:$N,MATCH($D20,'Domestic 2025'!$F:$F,0)),"Other")) -> Walt Disney
A21: 20 | B21: Sinners | C21: 370289632 | D21: 279989632 | E21: 0.756 | F21: 90300000 | G21: 0.244 | H21: =IFERROR(TRIM(LEFT(B21,FIND("(",B21)-1)),TRIM(B21)) -> Sinners | I21: =SUBSTITUTE(SUBSTITUTE(SUBSTITUTE(SUBSTITUTE(SUBSTITUTE(SUBSTITUTE(SUBSTITUTE(SUBSTITUTE(SUBSTITUTE(SUBSTITUTE(SUBSTITUTE(SUBSTITUTE(LOWER(LEFT(SUBSTITUTE(H21,"…",""),25)),":",""),",",""),".",""),"'",""),"’",""),"!",""),"*",""),"—",""),"–",""),"-",""),"&","")," ","") -> sinners | J21: =IFERROR(INDEX('Domestic 2025'!$N:$N,MATCH($I21,'Domestic 2025'!$K:$K,0)),IFERROR(INDEX('Domestic 2025'!$N:$N,MATCH($D21,'Domestic 2025'!$F:$F,0)),"Other")) -> Warner Bros.
A22: 21 | B22: Final Destination: Bloodlines | C22: 317854739 | D22: 138254739 | E22: 0.435 | F22: 179600000 | G22: 0.565 | H22: =IFERROR(TRIM(LEFT(B22,FIND("(",B22)-1)),TRIM(B22)) -> Final Destination: Bloodlines | I22: =SUBSTITUTE(SUBSTITUTE(SUBSTITUTE(SUBSTITUTE(SUBSTITUTE(SUBSTITUTE(SUBSTITUTE(SUBSTITUTE(SUBSTITUTE(SUBSTITUTE(SUBSTITUTE(SUBSTITUTE(LOWER(LEFT(SUBSTITUTE(H22,"…",""),25)),":",""),",",""),".",""),"'",""),"’",""),"!",""),"*",""),"—",""),"–",""),"-",""),"&","")," ","") -> finaldestinationbloodl | J22: =IFERROR(INDEX('Domestic 2025'!$N:$N,MATCH($I22,'Domestic 2025'!$K:$K,0)),IFERROR(INDEX('Domestic 2025'!$N:$N,MATCH($D22,'Domestic 2025'!$F:$F,0)),"Other")) -> Warner Bros.
A23: 22 | B23: 731 | C23: 274090081 | D23: 410904 | E23: 0.001 | F23: 273679177 | G23: 0.999 | H23: =IFERROR(TRIM(LEFT(B23,FIND("(",B23)-1)),TRIM(B23)) -> 731 | I23: =SUBSTITUTE(SUBSTITUTE(SUBSTITUTE(SUBSTITUTE(SUBSTITUTE(SUBSTITUTE(SUBSTITUTE(SUBSTITUTE(SUBSTITUTE(SUBSTITUTE(SUBSTITUTE(SUBSTITUTE(LOWER(LEFT(SUBSTITUTE(H23,"…",""),25)),":",""),",",""),".",""),"'",""),"’",""),"!",""),"*",""),"—",""),"–",""),"-",""),"&","")," ","") -> 731 | J23: =IFERROR(INDEX('Domestic 2025'!$N:$N,MATCH($I23,'Domestic 2025'!$K:$K,0)),IFERROR(INDEX('Domestic 2025'!$N:$N,MATCH($D23,'Domestic 2025'!$F:$F,0)),"Other")) -> Well Go USA
A24: 23 | B24: Weapons | C24: 270072492 | D24: 151572492 | E24: 0.561 | F24: 118500000 | G24: 0.439 | H24: =IFERROR(TRIM(LEFT(B24,FIND("(",B24)-1)),TRIM(B24)) -> Weapons | I24: =SUBSTITUTE(SUBSTITUTE(SUBSTITUTE(SUBSTITUTE(SUBSTITUTE(SUBSTITUTE(SUBSTITUTE(SUBSTITUTE(SUBSTITUTE(SUBSTITUTE(SUBSTITUTE(SUBSTITUTE(LOWER(LEFT(SUBSTITUTE(H24,"…",""),25)),":",""),",",""),".",""),"'",""),"’",""),"!",""),"*",""),"—",""),"–",""),"-",""),"&","")," ","") -> weapons | J24: =IFERROR(INDEX('Domestic 2025'!$N:$N,MATCH($I24,'Domestic 2025'!$K:$K,0)),IFERROR(INDEX('Domestic 2025'!$N:$N,MATCH($D24,'Domestic 2025'!$F:$F,0)),"Other")) -> Warner Bros.
A25: 24 | B25: Now You See Me: Now You Don't | C25: 246602999 | D25: 61882396 | E25: 0.251 | F25: 184720603 | G25: 0.749 | H25: =IFERROR(TRIM(LEFT(B25,FIND("(",B25)-1)),TRIM(B25)) -> Now You See Me: Now You Don't | I25: =SUBSTITUTE(SUBSTITUTE(SUBSTITUTE(SUBSTITUTE(SUBSTITUTE(SUBSTITUTE(SUBSTITUTE(SUBSTITUTE(SUBSTITUTE(SUBSTITUTE(SUBSTITUTE(SUBSTITUTE(LOWER(LEFT(SUBSTITUTE(H25,"…",""),25)),":",""),",",""),".",""),"'",""),"’",""),"!",""),"*",""),"—",""),"–",""),"-",""),"&","")," ","") -> nowyouseemenowyoud | J25: =IFERROR(INDEX('Domestic 2025'!$N:$N,MATCH($I25,'Domestic 2025'!$K:$K,0)),IFERROR(INDEX('Domestic 2025'!$N:$N,MATCH($D25,'Domestic 2025'!$F:$F,0)),"Other")) -> Lionsgate
A26: 25 | B26: The Bad Guys 2 | C26: 239753615 | D26: 82593605 | E26: 0.344 | F26: 157160010 | G26: 0.656 | H26: =IFERROR(TRIM(LEFT(B26,FIND("(",B26)-1)),TRIM(B26)) -> The Bad Guys 2 | I26: =SUBSTITUTE(SUBSTITUTE(SUBSTITUTE(SUBSTITUTE(SUBSTITUTE(SUBSTITUTE(SUBSTITUTE(SUBSTITUTE(SUBSTITUTE(SUBSTITUTE(SUBSTITUTE(SUBSTITUTE(LOWER(LEFT(SUBSTITUTE(H26,"…",""),25)),":",""),",",""),".",""),"'",""),"’",""),"!",""),"*",""),"—",""),"–",""),"-",""),"&","")," ","") -> thebadguys2 | J26: =IFERROR(INDEX('Domestic 2025'!$N:$N,MATCH($I26,'Domestic 2025'!$K:$K,0)),IFERROR(INDEX('Domestic 2025'!$N:$N,MATCH($D26,'Domestic 2025'!$F:$F,0)),"Other")) -> Universal
A27: 26 | B27: Five Nights at Freddy's 2 | C27: 238569800 | D27: 127730290 | E27: 0.535 | F27: 110839510 | G27: 0.465 | H27: =IFERROR(TRIM(LEFT(B27,FIND("(",B27)-1)),TRIM(B27)) -> Five Nights at Freddy's 2 | I27: =SUBSTITUTE(SUBSTITUTE(SUBSTITUTE(SUBSTITUTE(SUBSTITUTE(SUBSTITUTE(SUBSTITUTE(SUBSTITUTE(SUBSTITUTE(SUBSTITUTE(SUBSTITUTE(SUBSTITUTE(LOWER(LEFT(SUBSTITUTE(H27,"…",""),25)),":",""),",",""),".",""),"'",""),"’",""),"!",""),"*",""),"—",""),"–",""),"-",""),"&","")," ","") -> fivenightsatfreddys2 | J27: =IFERROR(INDEX('Domestic 2025'!$N:$N,MATCH($I27,'Domestic 2025'!$K:$K,0)),IFERROR(INDEX('Domestic 2025'!$N:$N,MATCH($D27,'Domestic 2025'!$F:$F,0)),"Other")) -> Universal
A28: 27 | B28: One Battle After Another | C28: 213121406 | D28: 72918884 | E28: 0.342 | F28: 140202522 | G28: 0.658 | H28: =IFERROR(TRIM(LEFT(B28,FIND("(",B28)-1)),TRIM(B28)) -> One Battle After Another | I28: =SUBSTITUTE(SUBSTITUTE(SUBSTITUTE(SUBSTITUTE(SUBSTITUTE(SUBSTITUTE(SUBSTITUTE(SUBSTITUTE(SUBSTITUTE(SUBSTITUTE(SUBSTITUTE(SUBSTITUTE(LOWER(LEFT(SUBSTITUTE(H28,"…",""),25)),":",""),",",""),".",""),"'",""),"’",""),"!",""),"*",""),"—",""),"–",""),"-",""),"&","")," ","") -> onebattleafteranother | J28: =IFERROR(INDEX('Domestic 2025'!$N:$N,MATCH($I28,'Domestic 2025'!$K:$K,0)),IFERROR(INDEX('Domestic 2025'!$N:$N,MATCH($D28,'Domestic 2025'!$F:$F,0)),"Other")) -> Warner Bros.
A29: 28 | B29: Snow White | C29: 205679463 | D29: 87203963 | E29: 0.424 | F29: 118475500 | G29: 0.576 | H29: =IFERROR(TRIM(LEFT(B29,FIND("(",B29)-1)),TRIM(B29)) -> Snow White | I29: =SUBSTITUTE(SUBSTITUTE(SUBSTITUTE(SUBSTITUTE(SUBSTITUTE(SUBSTITUTE(SUBSTITUTE(SUBSTITUTE(SUBSTITUTE(SUBSTITUTE(SUBSTITUTE(SUBSTITUTE(LOWER(LEFT(SUBSTITUTE(H29,"…",""),25)),":",""),",",""),".",""),"'",""),"’",""),"!",""),"*",""),"—",""),"–",""),"-",""),"&","")," ","") -> snowwhite | J29: =IFERROR(INDEX('Domestic 2025'!$N:$N,MATCH($I29,'Domestic 2025'!$K:$K,0)),IFERROR(INDEX('Domestic 2025'!$N:$N,MATCH($D29,'Domestic 2025'!$F:$F,0)),"Other")) -> Walt Disney
A30: 29 | B30: Marty Supreme | C30: 191886340 | D30: 96040064 | E30: 0.501 | F30: 95846276 | G30: 0.499 | H30: =IFERROR(TRIM(LEFT(B30,FIND("(",B30)-1)),TRIM(B30)) -> Marty Supreme | I30: =SUBSTITUTE(SUBSTITUTE(SUBSTITUTE(SUBSTITUTE(SUBSTITUTE(SUBSTITUTE(SUBSTITUTE(SUBSTITUTE(SUBSTITUTE(SUBSTITUTE(SUBSTITUTE(SUBSTITUTE(LOWER(LEFT(SUBSTITUTE(H30,"…",""),25)),":",""),",",""),".",""),"'",""),"’",""),"!",""),"*",""),"—",""),"–",""),"-",""),"&","")," ","") -> martysupreme | J30: =IFERROR(INDEX('Domestic 2025'!$N:$N,MATCH($I30,'Domestic 2025'!$K:$K,0)),IFERROR(INDEX('Domestic 2025'!$N:$N,MATCH($D30,'Domestic 2025'!$F:$F,0)),"Other")) -> A24
A31: 30 | B31: Predator: Badlands | C31: 184561056 | D31: 91083631 | E31: 0.494 | F31: 93477425 | G31: 0.506 | H31: =IFERROR(TRIM(LEFT(B31,FIND("(",B31)-1)),TRIM(B31)) -> Predator: Badlands | I31: =SUBSTITUTE(SUBSTITUTE(SUBSTITUTE(SUBSTITUTE(SUBSTITUTE(SUBSTITUTE(SUBSTITUTE(SUBSTITUTE(SUBSTITUTE(SUBSTITUTE(SUBSTITUTE(SUBSTITUTE(LOWER(LEFT(SUBSTITUTE(H31,"…",""),25)),":",""),",",""),".",""),"'",""),"’",""),"!",""),"*",""),"—",""),"–",""),"-",""),"&","")," ","") -> predatorbadlands | J31: =IFERROR(INDEX('Domestic 2025'!$N:$N,MATCH($I31,'Domestic 2025'!$K:$K,0)),IFERROR(INDEX('Domestic 2025'!$N:$N,MATCH($D31,'Domestic 2025'!$F:$F,0)),"Other")) -> 20th Century Stud…
A32: 31 | B32: The SpongeBob Movie: Search for SquarePants | C32: 169269936 | D32: 71068170 | E32: 0.42 | F32: 98201766 | G32: 0.58 | H32: =IFERROR(TRIM(LEFT(B32,FIND("(",B32)-1)),TRIM(B32)) -> The SpongeBob Movie: Search for SquarePants | I32: =SUBSTITUTE(SUBSTITUTE(SUBSTITUTE(SUBSTITUTE(SUBSTITUTE(SUBSTITUTE(SUBSTITUTE(SUBSTITUTE(SUBSTITUTE(SUBSTITUTE(SUBSTITUTE(SUBSTITUTE(LOWER(LEFT(SUBSTITUTE(H32,"…",""),25)),":",""),",",""),".",""),"'",""),"’",""),"!",""),"*",""),"—",""),"–",""),"-",""),"&","")," ","") -> thespongebobmoviesear | J32: =IFERROR(INDEX('Domestic 2025'!$N:$N,MATCH($I32,'Domestic 2025'!$K:$K,0)),IFERROR(INDEX('Domestic 2025'!$N:$N,MATCH($D32,'Domestic 2025'!$F:$F,0)),"Other")) -> Paramount Pictures
A33: 32 | B33: Detective Conan: One-Eyed Flashback | C33: 166061012 | D33: - | E33: - | F33: 166061012 | G33: 1 | H33: =IFERROR(TRIM(LEFT(B33,FIND("(",B33)-1)),TRIM(B33)) -> Detective Conan: One-Eyed Flashback | I33: =SUBSTITUTE(SUBSTITUTE(SUBSTITUTE(SUBSTITUTE(SUBSTITUTE(SUBSTITUTE(SUBSTITUTE(SUBSTITUTE(SUBSTITUTE(SUBSTITUTE(SUBSTITUTE(SUBSTITUTE(LOWER(LEFT(SUBSTITUTE(H33,"…",""),25)),":",""),",",""),".",""),"'",""),"’",""),"!",""),"*",""),"—",""),"–",""),"-",""),"&","")," ","") -> detectiveconanoneeyed | J33: =IFERROR(INDEX('Domestic 2025'!$N:$N,MATCH($I33,'Domestic 2025'!$K:$K,0)),IFERROR(INDEX('Domestic 2025'!$N:$N,MATCH($D33,'Domestic 2025'!$F:$F,0)),"Other")) -> Other
A34: 33 | B34: Chainsaw Man - The Movie: Reze Arc | C34: 162440471 | D34: 43438461 | E34: 0.267 | F34: 119002010 | G34: 0.733 | H34: =IFERROR(TRIM(LEFT(B34,FIND("(",B34)-1)),TRIM(B34)) -> Chainsaw Man - The Movie: Reze Arc | I34: =SUBSTITUTE(SUBSTITUTE(SUBSTITUTE(SUBSTITUTE(SUBSTITUTE(SUBSTITUTE(SUBSTITUTE(SUBSTITUTE(SUBSTITUTE(SUBSTITUTE(SUBSTITUTE(SUBSTITUTE(LOWER(LEFT(SUBSTITUTE(H34,"…",""),25)),":",""),",",""),".",""),"'",""),"’",""),"!",""),"*",""),"—",""),"–",""),"-",""),"&","")," ","") -> chainsawmanthemovie | J34: =IFERROR(INDEX('Domestic 2025'!$N:$N,MATCH($I34,'Domestic 2025'!$K:$K,0)),IFERROR(INDEX('Domestic 2025'!$N:$N,MATCH($D34,'Domestic 2025'!$F:$F,0)),"Other")) -> Sony Pictures
A35: 34 | B35: Elio | C35: 154291182 | D35: 72987454 | E35: 0.473 | F35: 81303728 | G35: 0.527 | H35: =IFERROR(TRIM(LEFT(B35,FIND("(",B35)-1)),TRIM(B35)) -> Elio | I35: =SUBSTITUTE(SUBSTITUTE(SUBSTITUTE(SUBSTITUTE(SUBSTITUTE(SUBSTITUTE(SUBSTITUTE(SUBSTITUTE(SUBSTITUTE(SUBSTITUTE(SUBSTITUTE(SUBSTITUTE(LOWER(LEFT(SUBSTITUTE(H35,"…",""),25)),":",""),",",""),".",""),"'",""),"’",""),"!",""),"*",""),"—",""),"–",""),"-",""),"&","")," ","") -> elio | J35: =IFERROR(INDEX('Domestic 2025'!$N:$N,MATCH($I35,'Domestic 2025'!$K:$K,0)),IFERROR(INDEX('Domestic 2025'!$N:$N,MATCH($D35,'Domestic 2025'!$F:$F,0)),"Other")) -> Walt Disney
A36: 35 | B36: Freakier Friday | C36: 153176952 | D36: 94186236 | E36: 0.615 | F36: 58990716 | G36: 0.385 | H36: =IFERROR(TRIM(LEFT(B36,FIND("(",B36)-1)),TRIM(B36)) -> Freakier Friday | I36: =SUBSTITUTE(SUBSTITUTE(SUBSTITUTE(SUBSTITUTE(SUBSTITUTE(SUBSTITUTE(SUBSTITUTE(SUBSTITUTE(SUBSTITUTE(SUBSTITUTE(SUBSTITUTE(SUBSTITUTE(LOWER(LEFT(SUBSTITUTE(H36,"…",""),25)),":",""),",",""),".",""),"'",""),"’",""),"!",""),"*",""),"—",""),"–",""),"-",""),"&","")," ","") -> freakierfriday | J36: =IFERROR(INDEX('Domestic 2025'!$N:$N,MATCH($I36,'Domestic 2025'!$K:$K,0)),IFERROR(INDEX('Domestic 2025'!$N:$N,MATCH($D36,'Domestic 2025'!$F:$F,0)),"Other")) -> Walt Disney
A37: 36 | B37: 28 Years Later | C37: 151329249 | D37: 70446897 | E37: 0.466 | F37: 80882352 | G37: 0.534 | H37: =IFERROR(TRIM(LEFT(B37,FIND("(",B37)-1)),TRIM(B37)) -> 28 Years Later | I37: =SUBSTITUTE(SUBSTITUTE(SUBSTITUTE(SUBSTITUTE(SUBSTITUTE(SUBSTITUTE(SUBSTITUTE(SUBSTITUTE(SUBSTITUTE(SUBSTITUTE(SUBSTITUTE(SUBSTITUTE(LOWER(LEFT(SUBSTITUTE(H37,"…",""),25)),":",""),",",""),".",""),"'",""),"’",""),"!",""),"*",""),"—",""),"–",""),"-",""),"&","")," ","") -> 28yearslater | J37: =IFERROR(INDEX('Domestic 2025'!$N:$N,MATCH($I37,'Domestic 2025'!$K:$K,0)),IFERROR(INDEX('Domestic 2025'!$N:$N,MATCH($D37,'Domestic 2025'!$F:$F,0)),"Other")) -> Sony Pictures
A38: 37 | B38: Dog Man | C38: 146076772 | D38: 97970355 | E38: 0.671 | F38: 48106417 | G38: 0.329 | H38: =IFERROR(TRIM(LEFT(B38,FIND("(",B38)-1)),TRIM(B38)) -> Dog Man | I38: =SUBSTITUTE(SUBSTITUTE(SUBSTITUTE(SUBSTITUTE(SUBSTITUTE(SUBSTITUTE(SUBSTITUTE(SUBSTITUTE(SUBSTITUTE(SUBSTITUTE(SUBSTITUTE(SUBSTITUTE(LOWER(LEFT(SUBSTITUTE(H38,"…",""),25)),":",""),",",""),".",""),"'",""),"’",""),"!",""),"*",""),"—",""),"–",""),"-",""),"&","")," ","") -> dogman | J38: =IFERROR(INDEX('Domestic 2025'!$N:$N,MATCH($I38,'Domestic 2025'!$K:$K,0)),IFERROR(INDEX('Domestic 2025'!$N:$N,MATCH($D38,'Domestic 2025'!$F:$F,0)),"Other")) -> Universal
A39: 38 | B39: Tron: Ares | C39: 142249983 | D39: 73161014 | E39: 0.514 | F39: 69088969 | G39: 0.486 | H39: =IFERROR(TRIM(LEFT(B39,FIND("(",B39)-1)),TRIM(B39)) -> Tron: Ares | I39: =SUBSTITUTE(SUBSTITUTE(SUBSTITUTE(SUBSTITUTE(SUBSTITUTE(SUBSTITUTE(SUBSTITUTE(SUBSTITUTE(SUBSTITUTE(SUBSTITUTE(SUBSTITUTE(SUBSTITUTE(LOWER(LEFT(SUBSTITUTE(H39,"…",""),25)),":",""),",",""),".",""),"'",""),"’",""),"!",""),"*",""),"—",""),"–",""),"-",""),"&","")," ","") -> tronares | J39: =IFERROR(INDEX('Domestic 2025'!$N:$N,MATCH($I39,'Domestic 2025'!$K:$K,0)),IFERROR(INDEX('Domestic 2025'!$N:$N,MATCH($D39,'Domestic 2025'!$F:$F,0)),"Other")) -> Walt Disney
A40: 39 | B40: Bridget Jones: Mad About the Boy | C40: 140433351 | D40: - | E40: - | F40: 140433351 | G40: 1 | H40: =IFERROR(TRIM(LEFT(B40,FIND("(",B40)-1)),TRIM(B40)) -> Bridget Jones: Mad About the Boy | I40: =SUBSTITUTE(SUBSTITUTE(SUBSTITUTE(SUBSTITUTE(SUBSTITUTE(SUBSTITUTE(SUBSTITUTE(SUBSTITUTE(SUBSTITUTE(SUBSTITUTE(SUBSTITUTE(SUBSTITUTE(LOWER(LEFT(SUBSTITUTE(H40,"…",""),25)),":",""),",",""),".",""),"'",""),"’",""),"!",""),"*",""),"—",""),"–",""),"-",""),"&","")," ","") -> bridgetjonesmadabout | J40: =IFERROR(INDEX('Domestic 2025'!$N:$N,MATCH($I40,'Domestic 2025'!$K:$K,0)),IFERROR(INDEX('Domestic 2025'!$N:$N,MATCH($D40,'Domestic 2025'!$F:$F,0)),"Other")) -> Other
A41: 40 | B41: Ballerina | C41: 140201236 | D41: 58051327 | E41: 0.414 | F41: 82149909 | G41: 0.586 | H41: =IFERROR(TRIM(LEFT(B41,FIND("(",B41)-1)),TRIM(B41)) -> Ballerina | I41: =SUBSTITUTE(SUBSTITUTE(SUBSTITUTE(SUBSTITUTE(SUBSTITUTE(SUBSTITUTE(SUBSTITUTE(SUBSTITUTE(SUBSTITUTE(SUBSTITUTE(SUBSTITUTE(SUBSTITUTE(LOWER(LEFT(SUBSTITUTE(H41,"…",""),25)),":",""),",",""),".",""),"'",""),"’",""),"!",""),"*",""),"—",""),"–",""),"-",""),"&","")," ","") -> ballerina | J41: =IFERROR(INDEX('Domestic 2025'!$N:$N,MATCH($I41,'Domestic 2025'!$K:$K,0)),IFERROR(INDEX('Domestic 2025'!$N:$N,MATCH($D41,'Domestic 2025'!$F:$F,0)),"Other")) -> Lionsgate
A42: 41 | B42: Dhurandhar | C42: 137246897 | D42: 19702994 | E42: 0.144 | F42: 117543903 | G42: 0.856 | H42: =IFERROR(TRIM(LEFT(B42,FIND("(",B42)-1)),TRIM(B42)) -> Dhurandhar | I42: =SUBSTITUTE(SUBSTITUTE(SUBSTITUTE(SUBSTITUTE(SUBSTITUTE(SUBSTITUTE(SUBSTITUTE(SUBSTITUTE(SUBSTITUTE(SUBSTITUTE(SUBSTITUTE(SUBSTITUTE(LOWER(LEFT(SUBSTITUTE(H42,"…",""),25)),":",""),",",""),".",""),"'",""),"’",""),"!",""),"*",""),"—",""),"–",""),"-",""),"&","")," ","") -> dhurandhar | J42: =IFERROR(INDEX('Domestic 2025'!$N:$N,MATCH($I42,'Domestic 2025'!$K:$K,0)),IFERROR(INDEX('Domestic 2025'!$N:$N,MATCH($D42,'Domestic 2025'!$F:$F,0)),"Other")) -> Yash Raj Films
...

Sheet Domestic 2024
A1: 1 | B1: Inside Out 2 | C1: 45457 | D1: Walt Disney | E1: Adventure | F1: 652980194 | G1: 57734765 | H1: =IFERROR(TRIM(LEFT(B1,FIND("(",B1)-1)),TRIM(B1)) -> Inside Out 2 | I1: =SUBSTITUTE(SUBSTITUTE(SUBSTITUTE(SUBSTITUTE(SUBSTITUTE(SUBSTITUTE(SUBSTITUTE(SUBSTITUTE(SUBSTITUTE(SUBSTITUTE(SUBSTITUTE(SUBSTITUTE(LOWER(LEFT(SUBSTITUTE(H1,"…",""),25)),":",""),",",""),".",""),"'",""),"’",""),"!",""),"*",""),"—",""),"–",""),"-",""),"&","")," ","") -> insideout2 | J1: =IF(D1="","Other",D1) -> Walt Disney
A2: 2 | B2: Deadpool & Wolverine | C2: 45499 | D2: Walt Disney | E2: Action | F2: 636745858 | G2: 56299369 | H2: =IFERROR(TRIM(LEFT(B2,FIND("(",B2)-1)),TRIM(B2)) -> Deadpool & Wolverine | I2: =SUBSTITUTE(SUBSTITUTE(SUBSTITUTE(SUBSTITUTE(SUBSTITUTE(SUBSTITUTE(SUBSTITUTE(SUBSTITUTE(SUBSTITUTE(SUBSTITUTE(SUBSTITUTE(SUBSTITUTE(LOWER(LEFT(SUBSTITUTE(H2,"…",""),25)),":",""),",",""),".",""),"'",""),"’",""),"!",""),"*",""),"—",""),"–",""),"-",""),"&","")," ","") -> deadpoolwolverine | J2: =IF(D2="","Other",D2) -> Walt Disney
A3: 3 | B3: Wicked | C3: 45618 | D3: Universal | E3: Musical | F3: 432943285 | G3: 38279689 | H3: =IFERROR(TRIM(LEFT(B3,FIND("(",B3)-1)),TRIM(B3)) -> Wicked | I3: =SUBSTITUTE(SUBSTITUTE(SUBSTITUTE(SUBSTITUTE(SUBSTITUTE(SUBSTITUTE(SUBSTITUTE(SUBSTITUTE(SUBSTITUTE(SUBSTITUTE(SUBSTITUTE(SUBSTITUTE(LOWER(LEFT(SUBSTITUTE(H3,"…",""),25)),":",""),",",""),".",""),"'",""),"’",""),"!",""),"*",""),"—",""),"–",""),"-",""),"&","")," ","") -> wicked | J3: =IF(D3="","Other",D3) -> Universal
A4: 4 | B4: Moana 2 | C4: 45623 | D4: Walt Disney | E4: Musical | F4: 404017489 | G4: 35722148 | H4: =IFERROR(TRIM(LEFT(B4,FIND("(",B4)-1)),TRIM(B4)) -> Moana 2 | I4: =SUBSTITUTE(SUBSTITUTE(SUBSTITUTE(SUBSTITUTE(SUBSTITUTE(SUBSTITUTE(SUBSTITUTE(SUBSTITUTE(SUBSTITUTE(SUBSTITUTE(SUBSTITUTE(SUBSTITUTE(LOWER(LEFT(SUBSTITUTE(H4,"…",""),25)),":",""),",",""),".",""),"'",""),"’",""),"!",""),"*",""),"—",""),"–",""),"-",""),"&","")," ","") -> moana2 | J4: =IF(D4="","Other",D4) -> Walt Disney
A5: 5 | B5: Despicable Me 4 | C5: 45476 | D5: Universal | E5: Adventure | F5: 361004205 | G5: 31919028 | H5: =IFERROR(TRIM(LEFT(B5,FIND("(",B5)-1)),TRIM(B5)) -> Despicable Me 4 | I5: =SUBSTITUTE(SUBSTITUTE(SUBSTITUTE(SUBSTITUTE(SUBSTITUTE(SUBSTITUTE(SUBSTITUTE(SUBSTITUTE(SUBSTITUTE(SUBSTITUTE(SUBSTITUTE(SUBSTITUTE(LOWER(LEFT(SUBSTITUTE(H5,"…",""),25)),":",""),",",""),".",""),"'",""),"’",""),"!",""),"*",""),"—",""),"–",""),"-",""),"&","")," ","") -> despicableme4 | J5: =IF(D5="","Other",D5) -> Universal
A6: 6 | B6: Beetlejuice Beetlejuice | C6: 45541 | D6: Warner Bros. | E6: Comedy | F6: 294100435 | G6: 26003575 | H6: =IFERROR(TRIM(LEFT(B6,FIND("(",B6)-1)),TRIM(B6)) -> Beetlejuice Beetlejuice | I6: =SUBSTITUTE(SUBSTITUTE(SUBSTITUTE(SUBSTITUTE(SUBSTITUTE(SUBSTITUTE(SUBSTITUTE(SUBSTITUTE(SUBSTITUTE(SUBSTITUTE(SUBSTITUTE(SUBSTITUTE(LOWER(LEFT(SUBSTITUTE(H6,"…",""),25)),":",""),",",""),".",""),"'",""),"’",""),"!",""),"*",""),"—",""),"–",""),"-",""),"&","")," ","") -> beetlejuicebeetlejuice | J6: =IF(D6="","Other",D6) -> Warner Bros.
A7: 7 | B7: Dune: Part Two | C7: 45352 | D7: Warner Bros. | E7: Action | F7: 282709065 | G7: 24996381 | H7: =IFERROR(TRIM(LEFT(B7,FIND("(",B7)-1)),TRIM(B7)) -> Dune: Part Two | I7: =SUBSTITUTE(SUBSTITUTE(SUBSTITUTE(SUBSTITUTE(SUBSTITUTE(SUBSTITUTE(SUBSTITUTE(SUBSTITUTE(SUBSTITUTE(SUBSTITUTE(SUBSTITUTE(SUBSTITUTE(LOWER(LEFT(SUBSTITUTE(H7,"…",""),25)),":",""),",",""),".",""),"'",""),"’",""),"!",""),"*",""),"—",""),"–",""),"-",""),"&","")," ","") -> duneparttwo | J7: =IF(D7="","Other",D7) -> Warner Bros.
A8: 8 | B8: Twisters | C8: 45492 | D8: Universal | E8: Thriller/Suspense | F8: 267762265 | G8: 23674824 | H8: =IFERROR(TRIM(LEFT(B8,FIND("(",B8)-1)),TRIM(B8)) -> Twisters | I8: =SUBSTITUTE(SUBSTITUTE(SUBSTITUTE(SUBSTITUTE(SUBSTITUTE(SUBSTITUTE(SUBSTITUTE(SUBSTITUTE(SUBSTITUTE(SUBSTITUTE(SUBSTITUTE(SUBSTITUTE(LOWER(LEFT(SUBSTITUTE(H8,"…",""),25)),":",""),",",""),".",""),"'",""),"’",""),"!",""),"*",""),"—",""),"–",""),"-",""),"&","")," ","") -> twisters | J8: =IF(D8="","Other",D8) -> Universal
A9: 9 | B9: Godzilla x Kong: The New Empi… | C9: 45380 | D9: Warner Bros. | E9: Action | F9: 196805338 | G9: 17401002 | H9: =IFERROR(TRIM(LEFT(B9,FIND("(",B9)-1)),TRIM(B9)) -> Godzilla x Kong: The New Empi… | I9: =SUBSTITUTE(SUBSTITUTE(SUBSTITUTE(SUBSTITUTE(SUBSTITUTE(SUBSTITUTE(SUBSTITUTE(SUBSTITUTE(SUBSTITUTE(SUBSTITUTE(SUBSTITUTE(SUBSTITUTE(LOWER(LEFT(SUBSTITUTE(H9,"…",""),25)),":",""),",",""),".",""),"'",""),"’",""),"!",""),"*",""),"—",""),"–",""),"-",""),"&","")," ","") -> godzillaxkongthenew | J9: =IF(D9="","Other",D9) -> Warner Bros.
A10: 10 | B10: Kung Fu Panda 4 | C10: 45359 | D10: Universal | E10: Comedy | F10: 193590620 | G10: 17116766 | H10: =IFERROR(TRIM(LEFT(B10,FIND("(",B10)-1)),TRIM(B10)) -> Kung Fu Panda 4 | I10: =SUBSTITUTE(SUBSTITUTE(SUBSTITUTE(SUBSTITUTE(SUBSTITUTE(SUBSTITUTE(SUBSTITUTE(SUBSTITUTE(SUBSTITUTE(SUBSTITUTE(SUBSTITUTE(SUBSTITUTE(LOWER(LEFT(SUBSTITUTE(H10,"…",""),25)),":",""),",",""),".",""),"'",""),"’",""),"!",""),"*",""),"—",""),"–",""),"-",""),"&","")," ","") -> kungfupanda4 | J10: =IF(D10="","Other",D10) -> Universal
A11: 11 | B11: Bad Boys: Ride or Die | C11: 45450 | D11: Sony Pictures | E11: Action | F11: 193573217 | G11: 17115227 | H11: =IFERROR(TRIM(LEFT(B11,FIND("(",B11)-1)),TRIM(B11)) -> Bad Boys: Ride or Die | I11: =SUBSTITUTE(SUBSTITUTE(SUBSTITUTE(SUBSTITUTE(SUBSTITUTE(SUBSTITUTE(SUBSTITUTE(SUBSTITUTE(SUBSTITUTE(SUBSTITUTE(SUBSTITUTE(SUBSTITUTE(LOWER(LEFT(SUBSTITUTE(H11,"…",""),25)),":",""),",",""),".",""),"'",""),"’",""),"!",""),"*",""),"—",""),"–",""),"-",""),"&","")," ","") -> badboysrideordie | J11: =IF(D11="","Other",D11) -> Sony Pictures
A12: 12 | B12: Kingdom of the Planet of the … | C12: 45422 | D12: 20th Century Stud… | E12: Action | F12: 171130165 | G12: 15130872 | H12: =IFERROR(TRIM(LEFT(B12,FIND("(",B12)-1)),TRIM(B12)) -> Kingdom of the Planet of the … | I12: =SUBSTITUTE(SUBSTITUTE(SUBSTITUTE(SUBSTITUTE(SUBSTITUTE(SUBSTITUTE(SUBSTITUTE(SUBSTITUTE(SUBSTITUTE(SUBSTITUTE(SUBSTITUTE(SUBSTITUTE(LOWER(LEFT(SUBSTITUTE(H12,"…",""),25)),":",""),",",""),".",""),"'",""),"’",""),"!",""),"*",""),"—",""),"–",""),"-",""),"&","")," ","") -> kingdomoftheplanetof | J12: =IF(D12="","Other",D12) -> 20th Century Stud…
... A158: 158 | B158: Jesus Thirsts: The Miracle of… | C158: 45447 | D158: Fathom Events | E158: Documentary | F158: 2927121 | G158: 258808 | H158: =IFERROR(TRIM(LEFT(B158,FIND("(",B158)-1)),TRIM(B158)) -> Jesus Thirsts: The Miracle of… | I158: =SUBSTITUTE(SUBSTITUTE(SUBSTITUTE(SUBSTITUTE(SUBSTITUTE(SUBSTITUTE(SUBSTITUTE(SUBSTITUTE(SUBSTITUTE(SUBSTITUTE(SUBSTITUTE(SUBSTITUTE(LOWER(LEFT(SUBSTITUTE(H158,"…",""),25)),":",""),",",""),".",""),"'",""),"’",""),"!",""),"*",""),"—",""),"–",""),"-",""),"&","")," ","") -> jesusthirststhemiracl | J158: =IF(D158="","Other",D158) -> Fathom Events
A159: 159 | B159: 1992 | C159: 45534 | D159: Lionsgate | E159: Thriller/Suspense | F159: 2906073 | G159: 256947 | H159: =IFERROR(TRIM(LEFT(B159,FIND("(",B159)-1)),TRIM(B159)) -> 1992 | I159: =SUBSTITUTE(SUBSTITUTE(SUBSTITUTE(SUBSTITUTE(SUBSTITUTE(SUBSTITUTE(SUBSTITUTE(SUBSTITUTE(SUBSTITUTE(SUBSTITUTE(SUBSTITUTE(SUBSTITUTE(LOWER(LEFT(SUBSTITUTE(H159,"…",""),25)),":",""),",",""),".",""),"'",""),"’",""),"!",""),"*",""),"—",""),"–",""),"-",""),"&","")," ","") -> 1992 | J159: =IF(D159="","Other",D159) -> Lionsgate
A160: 160 | B160: The Fabulous Four | C160: 45499 | D160: Bleecker Street | E160: Comedy | F160: 2854289 | G160: 252369 | H160: =IFERROR(TRIM(LEFT(B160,FIND("(",B160)-1)),TRIM(B160)) -> The Fabulous Four | I160: =SUBSTITUTE(SUBSTITUTE(SUBSTITUTE(SUBSTITUTE(SUBSTITUTE(SUBSTITUTE(SUBSTITUTE(SUBSTITUTE(SUBSTITUTE(SUBSTITUTE(SUBSTITUTE(SUBSTITUTE(LOWER(LEFT(SUBSTITUTE(H160,"…",""),25)),":",""),",",""),".",""),"'",""),"’",""),"!",""),"*",""),"—",""),"–",""),"-",""),"&","")," ","") -> thefabulousfour | J160: =IF(D160="","Other",D160) -> Bleecker Street
A161: 161 | B161: Queer | C161: 45623 | D161: A24 | E161: Drama | F161: 2837173 | G161: 250855 | H161: =IFERROR(TRIM(LEFT(B161,FIND("(",B161)-1)),TRIM(B161)) -> Queer | I161: =SUBSTITUTE(SUBSTITUTE(SUBSTITUTE(SUBSTITUTE(SUBSTITUTE(SUBSTITUTE(SUBSTITUTE(SUBSTITUTE(SUBSTITUTE(SUBSTITUTE(SUBSTITUTE(SUBSTITUTE(LOWER(LEFT(SUBSTITUTE(H161,"…",""),25)),":",""),",",""),".",""),"'",""),"’",""),"!",""),"*",""),"—",""),"–",""),"-",""),"&","")," ","") -> queer | J161: =IF(D161="","Other",D161) -> A24
A162: 162 | B162: For King + Country: A Drummer… | C162: 45631 | D162: Fathom Events | E162: Concert/Performance | F162: 2827417 | G162: 249993 | H162: =IFERROR(TRIM(LEFT(B162,FIND("(",B162)-1)),TRIM(B162)) -> For King + Country: A Drummer… | I162: =SUBSTITUTE(SUBSTITUTE(SUBSTITUTE(SUBSTITUTE(SUBSTITUTE(SUBSTITUTE(SUBSTITUTE(SUBSTITUTE(SUBSTITUTE(SUBSTITUTE(SUBSTITUTE(SUBSTITUTE(LOWER(LEFT(SUBSTITUTE(H162,"…",""),25)),":",""),",",""),".",""),"'",""),"’",""),"!",""),"*",""),"—",""),"–",""),"-",""),"&","")," ","") -> forking+countryadru | J162: =IF(D162="","Other",D162) -> Fathom Events
A163: 163 | B163: White Christmas | C163: 19841 | D163: Fathom Events | E163: Musical | F163: 2800094 | G163: 247577 | H163: =IFERROR(TRIM(LEFT(B163,FIND("(",B163)-1)),TRIM(B163)) -> White Christmas | I163: =SUBSTITUTE(SUBSTITUTE(SUBSTITUTE(SUBSTITUTE(SUBSTITUTE(SUBSTITUTE(SUBSTITUTE(SUBSTITUTE(SUBSTITUTE(SUBSTITUTE(SUBSTITUTE(SUBSTITUTE(LOWER(LEFT(SUBSTITUTE(H163,"…",""),25)),":",""),",",""),".",""),"'",""),"’",""),"!",""),"*",""),"—",""),"–",""),"-",""),"&","")," ","") -> whitechristmas | J163: =IF(D163="","Other",D163) -> Fathom Events
A164: 164 | B164: Sing Sing | C164: 45485 | D164: A24 | E164: Drama | F164: 2778745 | G164: 245689 | H164: =IFERROR(TRIM(LEFT(B164,FIND("(",B164)-1)),TRIM(B164)) -> Sing Sing | I164: =SUBSTITUTE(SUBSTITUTE(SUBSTITUTE(SUBSTITUTE(SUBSTITUTE(SUBSTITUTE(SUBSTITUTE(SUBSTITUTE(SUBSTITUTE(SUBSTITUTE(SUBSTITUTE(SUBSTITUTE(LOWER(LEFT(SUBSTITUTE(H164,"…",""),25)),":",""),",",""),".",""),"'",""),"’",""),"!",""),"*",""),"—",""),"–",""),"-",""),"&","")," ","") -> singsing | J164: =IF(D164="","Other",D164) -> A24
A165: 165 | B165: My Penguin Friend | C165: 45520 | D165: Roadside Attracti… | E165: Drama | F165: 2769460 | G165: 244868 | H165: =IFERROR(TRIM(LEFT(B165,FIND("(",B165)-1)),TRIM(B165)) -> My Penguin Friend | I165: =SUBSTITUTE(SUBSTITUTE(SUBSTITUTE(SUBSTITUTE(SUBSTITUTE(SUBSTITUTE(SUBSTITUTE(SUBSTITUTE(SUBSTITUTE(SUBSTITUTE(SUBSTITUTE(SUBSTITUTE(LOWER(LEFT(SUBSTITUTE(H165,"…",""),25)),":",""),",",""),".",""),"'",""),"’",""),"!",""),"*",""),"—",""),"–",""),"-",""),"&","")," ","") -> mypenguinfriend | J165: =IF(D165="","Other",D165) -> Roadside Attracti…
A166: 166 | B166: Absolution | C166: 45597 | D166: Samuel Goldwyn Fi… | E166: Drama | F166: 2715727 | G166: 240117 | H166: =IFERROR(TRIM(LEFT(B166,FIND("(",B166)-1)),TRIM(B166)) -> Absolution | I166: =SUBSTITUTE(SUBSTITUTE(SUBSTITUTE(SUBSTITUTE(SUBSTITUTE(SUBSTITUTE(SUBSTITUTE(SUBSTITUTE(SUBSTITUTE(SUBSTITUTE(SUBSTITUTE(SUBSTITUTE(LOWER(LEFT(SUBSTITUTE(H166,"…",""),25)),":",""),",",""),".",""),"'",""),"’",""),"!",""),"*",""),"—",""),"–",""),"-",""),"&","")," ","") -> absolution | J166: =IF(D166="","Other",D166) -> Samuel Goldwyn Fi…
