Workbook

Sheet README
A1: Hotchkis & Wiley — Quant RA Excel Practice
A2: Built for Andrew · Live screen-share prep · Data is synthetic
A4: HOW TO USE
A5: 1. | B5: Work tab by tab. Each tab has numbered tasks at the top and the data below.
A6: 2. | B6: Type a formula (not a hardcoded number!) in the yellow 'Your Answer' cell. The 'Check' column grades it instantly (±0.1%).
A7: 3. | B7: Build helper columns in the green 'workspace' area next to the data — that's how you'd do it live.
A8: 4. | B8: Stuck? Use the Hint column first. Model solutions are on the hidden 'Answer Key' tab (right-click any tab → Unhide).
A9: 5. | B9: Practice NARRATING out loud as if Janvi and Sky are watching: what you're doing, why, and how you'll sanity-check it.
A10: LEGEND
A11: Yellow fill | B11: Your answer cells / inputs
A12: Blue text | B12: Hardcoded data
A13: Green fill | B13: Workspace for your helper columns
A14: SUGGESTED TIME BUDGET
A15: If you have ~60 min | B15: 3_Returns (R1–R11) → 4_Screening (S1–S9) → 2_Aggregation (A1–A8)
A16: If you have ~2 hrs | B16: All of the above, then 1_Lookups, 5_Regression (G1–G7), 6_Valuation (V1–V9)
A17: Timed run | B17: Aim for ~2–3 min per task. Most live tasks are shorter than these.
A19: TABS & SCORE | C19: Score
A20: 1_Lookups | B20: Cleaning, INDEX/MATCH, two-way & approximate lookups | C20: =COUNTIF(1_Lookups!I:I,"✓ Correct")&" / 13" -> 0 / 13
A21: 2_Aggregation | B21: SUMIFS/COUNTIFS/AVERAGEIFS/MAXIFS, weighted avgs, aggregate P/E, pivot | C21: =COUNTIF(2_Aggregation!I:I,"✓ Correct")&" / 14" -> 0 / 14
A22: 3_Returns | B22: Cumulative/CAGR, vol, Sharpe, Sortino, drawdown, beta, TE/IR, calendar returns | C22: =COUNTIF(3_Returns!I:I,"✓ Correct")&" / 19" -> 0 / 19
A23: 4_Screening | B23: Multiples, RANK/PERCENTRANK, z-scores, composite value score, quintiles, winsorizing | C23: =COUNTIF(4_Screening!I:I,"✓ Correct")&" / 13" -> 0 / 13
A24: 5_Regression | B24: CORREL, SLOPE, INTERCEPT, RSQ, covariance, 3-factor LINEST, t-stats | C24: =COUNTIF(5_Regression!I:I,"✓ Correct")&" / 13" -> 0 / 13
A25: 6_Valuation | B25: Mkt cap, EV bridge, margins, CAGR, FCF yield, leverage, implied price, mini-DCF | C25: =COUNTIF(6_Valuation!I:I,"✓ Correct")&" / 16" -> 0 / 16
A26: TOTAL | C26: =COUNTIF(1_Lookups!I:I,"✓ Correct")+COUNTIF(2_Aggregation!I:I,"✓ Correct")+COUNTIF(3_Returns!I:I,"✓ Correct")+COUNTIF(4_Screening!I:I,"✓ Correct")+COUNTIF(5_Regression!I:I,"✓ Correct")+COUNTIF(6_Valuation!I:I,"✓ Correct")&" / 88" -> 0 / 88

Sheet 1_Lookups
A1: 1 · Lookups & Data Cleaning
A2: Messy trade blotter + clean reference table + month-end price grid. Clean, match, and look up.
A4: # | B4: Task | H4: Your Answer | I4: Check | J4: Hint (functions to use)
A5: L1 | B5: What sector is FENX in? (Use the reference table.) | I5: =IF(H5="","",IFERROR(IF(ISNUMBER('Answer Key'!$D$5),IF(ABS(H5-'Answer Key'!$D$5)<=MAX(0.0001,ABS('Answer Key'!$D$5)*0.001),"✓ Correct","✗ Try again"),IF(TRIM(H5)=TRIM('Answer Key'!$D$5),"✓ Correct","✗ Try again")),"✗ Try again")) | J5: INDEX/MATCH or XLOOKUP
A6: L2 | B6: Reverse lookup: what is the ticker for 'Harbor Logistics'? (Ticker column is to the LEFT of company name.) | I6: =IF(H6="","",IFERROR(IF(ISNUMBER('Answer Key'!$D$6),IF(ABS(H6-'Answer Key'!$D$6)<=MAX(0.0001,ABS('Answer Key'!$D$6)*0.001),"✓ Correct","✗ Try again"),IF(TRIM(H6)=TRIM('Answer Key'!$D$6),"✓ Correct","✗ Try again")),"✗ Try again")) | J6: INDEX/MATCH (VLOOKUP can't look left)
A7: L3 | B7: How many rows in the raw blotter have a 'dirty' ticker (leading/trailing spaces or lowercase)? | I7: =IF(H7="","",IFERROR(IF(ISNUMBER('Answer Key'!$D$7),IF(ABS(H7-'Answer Key'!$D$7)<=MAX(0.0001,ABS('Answer Key'!$D$7)*0.001),"✓ Correct","✗ Try again"),IF(TRIM(H7)=TRIM('Answer Key'!$D$7),"✓ Correct","✗ Try again")),"✗ Try again")) | J7: EXACT, TRIM, UPPER, SUMPRODUCT
A8: L4 | B8: How many prices in the raw blotter are stored as TEXT rather than numbers? | I8: =IF(H8="","",IFERROR(IF(ISNUMBER('Answer Key'!$D$8),IF(ABS(H8-'Answer Key'!$D$8)<=MAX(0.0001,ABS('Answer Key'!$D$8)*0.001),"✓ Correct","✗ Try again"),IF(TRIM(H8)=TRIM('Answer Key'!$D$8),"✓ Correct","✗ Try again")),"✗ Try again")) | J8: ISTEXT, SUMPRODUCT
A9: L5 | B9: Total market value (price × shares) across ALL blotter rows, after converting text prices to numbers. Include duplicates and unknown tickers. | I9: =IF(H9="","",IFERROR(IF(ISNUMBER('Answer Key'!$D$9),IF(ABS(H9-'Answer Key'!$D$9)<=MAX(0.0001,ABS('Answer Key'!$D$9)*0.001),"✓ Correct","✗ Try again"),IF(TRIM(H9)=TRIM('Answer Key'!$D$9),"✓ Correct","✗ Try again")),"✗ Try again")) | J9: VALUE / TRIM helper column, then SUM
A10: L6 | B10: After cleaning tickers (TRIM + UPPER), how many blotter rows have a ticker NOT in the reference table? | I10: =IF(H10="","",IFERROR(IF(ISNUMBER('Answer Key'!$D$10),IF(ABS(H10-'Answer Key'!$D$10)<=MAX(0.0001,ABS('Answer Key'!$D$10)*0.001),"✓ Correct","✗ Try again"),IF(TRIM(H10)=TRIM('Answer Key'!$D$10),"✓ Correct","✗ Try again")),"✗ Try again")) | J10: ISNA/ISNUMBER + MATCH, or COUNTIF=0
A11: L7 | B11: Total market value of blotter rows in the Energy sector (look up each row's sector first; all rows incl. duplicates). | I11: =IF(H11="","",IFERROR(IF(ISNUMBER('Answer Key'!$D$11),IF(ABS(H11-'Answer Key'!$D$11)<=MAX(0.0001,ABS('Answer Key'!$D$11)*0.001),"✓ Correct","✗ Try again"),IF(TRIM(H11)=TRIM('Answer Key'!$D$11),"✓ Correct","✗ Try again")),"✗ Try again")) | J11: Helper sector column + SUMIFS
A12: L8 | B12: How many rows are duplicate copies (same Trade ID appearing again after its first occurrence)? | I12: =IF(H12="","",IFERROR(IF(ISNUMBER('Answer Key'!$D$12),IF(ABS(H12-'Answer Key'!$D$12)<=MAX(0.0001,ABS('Answer Key'!$D$12)*0.001),"✓ Correct","✗ Try again"),IF(TRIM(H12)=TRIM('Answer Key'!$D$12),"✓ Correct","✗ Try again")),"✗ Try again")) | J12: COUNTIF with an expanding range $F$x:F2
A13: L9 | B13: Two-way lookup: MRDN's closing price on 2026-06-30 from the month-end grid. | I13: =IF(H13="","",IFERROR(IF(ISNUMBER('Answer Key'!$D$13),IF(ABS(H13-'Answer Key'!$D$13)<=MAX(0.0001,ABS('Answer Key'!$D$13)*0.001),"✓ Correct","✗ Try again"),IF(TRIM(H13)=TRIM('Answer Key'!$D$13),"✓ Correct","✗ Try again")),"✗ Try again")) | J13: INDEX(grid, MATCH(row), MATCH(col))
A14: L10 | B14: Extract the plain ticker from the BBG ID of trade T1017 (e.g. 'ABC US Equity' → 'ABC'). | I14: =IF(H14="","",IFERROR(IF(ISNUMBER('Answer Key'!$D$14),IF(ABS(H14-'Answer Key'!$D$14)<=MAX(0.0001,ABS('Answer Key'!$D$14)*0.001),"✓ Correct","✗ Try again"),IF(TRIM(H14)=TRIM('Answer Key'!$D$14),"✓ Correct","✗ Try again")),"✗ Try again")) | J14: LEFT + FIND (or TEXTBEFORE)
A15: L11 | B15: What is the company name for trade T1033? (Its raw ticker is dirty — clean it inside the lookup.) | I15: =IF(H15="","",IFERROR(IF(ISNUMBER('Answer Key'!$D$15),IF(ABS(H15-'Answer Key'!$D$15)<=MAX(0.0001,ABS('Answer Key'!$D$15)*0.001),"✓ Correct","✗ Try again"),IF(TRIM(H15)=TRIM('Answer Key'!$D$15),"✓ Correct","✗ Try again")),"✗ Try again")) | J15: INDEX/MATCH on UPPER(TRIM(x))
A16: L12 | B16: Approximate match: for trade T1025, return its ticker's most recent month-end close ON OR BEFORE the trade date. | I16: =IF(H16="","",IFERROR(IF(ISNUMBER('Answer Key'!$D$16),IF(ABS(H16-'Answer Key'!$D$16)<=MAX(0.0001,ABS('Answer Key'!$D$16)*0.001),"✓ Correct","✗ Try again"),IF(TRIM(H16)=TRIM('Answer Key'!$D$16),"✓ Correct","✗ Try again")),"✗ Try again")) | J16: MATCH(date, header, 1) — header sorted ascending
A17: L13 | B17: Total market value EXCLUDING duplicate rows AND rows with tickers not in the reference table. | I17: =IF(H17="","",IFERROR(IF(ISNUMBER('Answer Key'!$D$17),IF(ABS(H17-'Answer Key'!$D$17)<=MAX(0.0001,ABS('Answer Key'!$D$17)*0.001),"✓ Correct","✗ Try again"),IF(TRIM(H17)=TRIM('Answer Key'!$D$17),"✓ Correct","✗ Try again")),"✗ Try again")) | J17: Combine your helper flags with SUMPRODUCT or SUMIFS
G18: Score: | H18: =COUNTIF(I5:I17,"✓ Correct")&" / 13" -> 0 / 13
A21: DATA
A22: Reference (A:D) · Raw trade blotter (F:K) · Month-end close grid (M:Y). Green columns AA:AH = your workspace for helper columns.
A24: Ticker | B24: Company | C24: Sector | D24: Country | F24: Trade ID | G24: Ticker (raw) | H24: Trade Date | I24: Price (raw) | J24: Shares | K24: BBG ID | M24: Ticker | N24: 45961 | O24: 45991 | P24: 46022 | Q24: 46053 | R24: 46081 | S24: 46112 | T24: 46142 | U24: 46173 | V24: 46203 | W24: 46234 | X24: 46265 | Y24: 46295 | AA24: workspace
A25: ALDR | B25: Alder Resources | C25: Energy | D25: Germany | F25: T1001 | G25: LMRA | H25: 46160 | I25: 244.07 | J25: 2600 | K25: LMRA US Equity | M25: ALDR | N25: 147.3 | O25: 134.92 | P25: 131.94 | Q25: 115.7 | R25: 106.42 | S25: 93.76 | T25: 93.16 | U25: 85.82 | V25: 88.31 | W25: 90.16 | X25: 89.88 | Y25: 74.95
A26: BRKN | B26: Brookline Bancorp | C26: Financials | D26: Japan | F26: T1002 | G26: HRBR | H26: 46265 | I26: 264.22 | J26: 2300 | K26: HRBR US Equity | M26: BRKN | N26: 230.95 | O26: 232.47 | P26: 236.64 | Q26: 213.66 | R26: 208.65 | S26: 196.45 | T26: 187.29 | U26: 203.07 | V26: 193.62 | W26: 195.12 | X26: 209.15 | Y26: 202.7
A27: CVLT | B27: Cobalt Systems | C27: Technology | D27: Japan | F27: T1003 | G27: DMNX | H27: 46213 | I27: 41.96 | J27: 4900 | K27: DMNX US Equity | M27: CVLT | N27: 81.55 | O27: 82.99 | P27: 84.19 | Q27: 77.82 | R27: 79.01 | S27: 87.31 | T27: 78.73 | U27: 84.26 | V27: 85.8 | W27: 82.81 | X27: 95.23 | Y27: 101.26
A28: DMNX | B28: Domino Semiconductor | C28: Health Care | D28: Germany | F28: T1004 | G28: ZNTH | H28: 46237 | I28: 133.18 | J28: 3500 | K28: ZNTH US Equity | M28: DMNX | N28: 33.63 | O28: 34.14 | P28: 35.86 | Q28: 35.74 | R28: 37.81 | S28: 38.01 | T28: 40.17 | U28: 44.61 | V28: 42.95 | W28: 43.99 | X28: 43 | Y28: 43.82
A29: ELMR | B29: Elmore Therapeutics | C29: Industrials | D29: Japan | F29: T1005 | G29: xera | H29: 46188 | I29: 152.39 | J29: 1700 | K29: XERA US Equity | M29: ELMR | N29: 121.27 | O29: 117.57 | P29: 117.13 | Q29: 125.67 | R29: 137 | S29: 125.68 | T29: 119.94 | U29: 126.57 | V29: 110.19 | W29: 107.72 | X29: 108.06 | Y29: 118.65
A30: FENX | B30: Fenwick Oil & Gas | C30: Energy | D30: Germany | F30: T1006 | G30: KSTL | H30: 46070 | I30: 154.72 | J30: 900 | K30: KSTL US Equity | M30: FENX | N30: 237.34 | O30: 234.28 | P30: 230.57 | Q30: 228.84 | R30: 255.53 | S30: 250.43 | T30: 247.61 | U30: 256.2 | V30: 256.6 | W30: 255.62 | X30: 238.24 | Y30: 240.43
A31: GRVL | B31: Gravel Industrial | C31: Energy | D31: Germany | F31: T1007 | G31: ABRV | H31: 46016 | I31: 173.91 | J31: 4200 | K31: ABRV US Equity | M31: GRVL | N31: 114.52 | O31: 125.01 | P31: 131.98 | Q31: 133.08 | R31: 140.63 | S31: 138.69 | T31: 150.29 | U31: 151.74 | V31: 159.45 | W31: 146.64 | X31: 151.66 | Y31: 135.26
A32: HRBR | B32: Harbor Logistics | C32: Financials | D32: US | F32: T1008 | G32: ULMN | H32: 46282 | I32: 34.3 | J32: 1700 | K32: ULMN US Equity | M32: HRBR | N32: 242.44 | O32: 239.7 | P32: 227 | Q32: 231.88 | R32: 270.63 | S32: 257.58 | T32: 248.9 | U32: 254.97 | V32: 266.32 | W32: 265.7 | X32: 264.52 | Y32: 280.18
A33: IRNW | B33: Ironwood Insurance | C33: Technology | D33: US | F33: T1009 | G33: TRVO | H33: 46013 | I33: 59.4 | J33: 1400 | K33: TRVO US Equity | M33: IRNW | N33: 54.74 | O33: 51.33 | P33: 51.56 | Q33: 52.2 | R33: 48.87 | S33: 50.25 | T33: 47.73 | U33: 51.46 | V33: 52.67 | W33: 53.52 | X33: 51.84 | Y33: 51.93
A34: KSTL | B34: Kestrel Software | C34: Health Care | D34: UK | F34: T1010 | G34: CVLT | H34: 46020 | I34: 81.69 | J34: 4800 | K34: CVLT US Equity | M34: KSTL | N34: 186.95 | O34: 174.01 | P34: 180.17 | Q34: 155.13 | R34: 165.87 | S34: 147.25 | T34: 156.53 | U34: 148.83 | V34: 158.43 | W34: 161.47 | X34: 145.71 | Y34: 159.91
A35: LMRA | B35: Lamarra Foods | C35: Industrials | D35: UK | F35: T1011 | G35: ZZZZ | H35: 46227 | I35: 31.4 | J35: 2900 | K35: ZZZZ US Equity | M35: LMRA | N35: 245.49 | O35: 246.81 | P35: 244.55 | Q35: 244.26 | R35: 230.03 | S35: 250.02 | T35: 243.02 | U35: 244.58 | V35: 233.44 | W35: 225.54 | X35: 207.63 | Y35: 227.97
A36: MRDN | B36: Meridian Health | C36: Consumer | D36: Germany | F36: T1012 | G36: ABRV | H36: 46114 | I36: 170.12 | J36: 3500 | K36: ABRV US Equity | M36: MRDN | N36: 139.49 | O36: 150.31 | P36: 151.96 | Q36: 146.09 | R36: 144.21 | S36: 140 | T36: 141.48 | U36: 139.17 | V36: 137.64 | W36: 125.74 | X36: 119.89 | Y36: 134.97
A37: NOVX | B37: Novex Pharma | C37: Energy | D37: Germany | F37: T1013 | G37: BLCK | H37: 46275 | I37: 64.3 | J37: 1200 | K37: BLCK US Equity | M37: NOVX | N37: 230.56 | O37: 215.85 | P37: 223.11 | Q37: 247.31 | R37: 224.62 | S37: 223.58 | T37: 215.93 | U37: 191.47 | V37: 203.23 | W37: 204.93 | X37: 208.01 | Y37: 199.13
A38: OKRA | B38: Okra Brands | C38: Financials | D38: US | F38: T1014 | G38: okra | H38: 45964 | I38: 32.93 | J38: 3400 | K38: OKRA US Equity | M38: OKRA | N38: 34.23 | O38: 33.28 | P38: 33.28 | Q38: 31.03 | R38: 28.7 | S38: 31.67 | T38: 30.86 | U38: 31.8 | V38: 32.04 | W38: 31.37 | X38: 30.57 | Y38: 32.23
A39: PLMT | B39: Palmetto Energy | C39: Technology | D39: UK | F39: T1015 | G39: YRLW | H39: 46072 | I39: 308.54 | J39: 2100 | K39: YRLW US Equity | M39: PLMT | N39: 26.97 | O39: 26.95 | P39: 27.26 | Q39: 29.78 | R39: 31.5 | S39: 32.65 | T39: 31.69 | U39: 28.94 | V39: 31.16 | W39: 33.58 | X39: 33.58 | Y39: 35.19
A40: QRSN | B40: Quorsan Capital | C40: Health Care | D40: Germany | F40: T1016 | G40: GRVL | H40: 45978 | I40: 113.84 | J40: 2800 | K40: GRVL US Equity | M40: QRSN | N40: 235.82 | O40: 251.9 | P40: 270.66 | Q40: 264.74 | R40: 295.46 | S40: 272.63 | T40: 291.8 | U40: 304.81 | V40: 326.5 | W40: 372.71 | X40: 415.16 | Y40: 386.04
A41: RDGE | B41: Ridgeline Machinery | C41: Industrials | D41: US | F41: T1017 | G41: BRKN | H41: 46204 | I41: 192.94 | J41: 3600 | K41: BRKN US Equity | M41: RDGE | N41: 97.89 | O41: 104.47 | P41: 98.09 | Q41: 98.99 | R41: 105.79 | S41: 94.68 | T41: 81.64 | U41: 83.94 | V41: 85.04 | W41: 84.43 | X41: 85.5 | Y41: 81.2
A42: SLTN | B42: Saltonstall Bank | C42: Consumer | D42: Germany | F42: T1018 | G42: VSTR | H42: 46279 | I42: 113.22 | J42: 2400 | K42: VSTR US Equity | M42: SLTN | N42: 151.94 | O42: 151.68 | P42: 142.88 | Q42: 127.87 | R42: 133.68 | S42: 134.44 | T42: 139.61 | U42: 131.34 | V42: 126.6 | W42: 119.02 | X42: 112.82 | Y42: 115.49
A43: TRVO | B43: Trevo Devices | C43: Energy | D43: US | F43: T1019 | G43: OKRA | H43: 45980 | I43: 33.97 | J43: 3600 | K43: OKRA US Equity | M43: TRVO | N43: 57.15 | O43: 59.14 | P43: 61.14 | Q43: 70.42 | R43: 64.26 | S43: 68.9 | T43: 69.15 | U43: 69.78 | V43: 63.39 | W43: 61.98 | X43: 65.83 | Y43: 66.11
A44: ULMN | B44: Ulman Retail | C44: Financials | D44: UK | F44: T1020 | G44: EVRG | H44: 46203 | I44: 37.19 | J44: 4700 | K44: EVRG US Equity | M44: ULMN | N44: 50.76 | O44: 50.23 | P44: 54.79 | Q44: 55.26 | R44: 47.3 | S44: 45.48 | T44: 39.67 | U44: 31.04 | V44: 30.19 | W44: 33.32 | X44: 33.76 | Y44: 31.33
...

Sheet 2_Aggregation
A1: 2 · Conditional Aggregation & Pivots
A2: 60-stock global universe. SUMIFS / COUNTIFS / AVERAGEIFS / MAXIFS / SUMPRODUCT, plus a pivot-table check.
A4: # | B4: Task | H4: Your Answer | I4: Check | J4: Hint (functions to use)
A5: A1 | B5: Total market cap of the Financials sector ($bn). | I5: =IF(H5="","",IFERROR(IF(ISNUMBER('Answer Key'!$D$18),IF(ABS(H5-'Answer Key'!$D$18)<=MAX(0.0001,ABS('Answer Key'!$D$18)*0.001),"✓ Correct","✗ Try again"),IF(TRIM(H5)=TRIM('Answer Key'!$D$18),"✓ Correct","✗ Try again")),"✗ Try again")) | J5: SUMIFS
A6: A2 | B6: How many Technology stocks returned more than 10% over the past year? | I6: =IF(H6="","",IFERROR(IF(ISNUMBER('Answer Key'!$D$19),IF(ABS(H6-'Answer Key'!$D$19)<=MAX(0.0001,ABS('Answer Key'!$D$19)*0.001),"✓ Correct","✗ Try again"),IF(TRIM(H6)=TRIM('Answer Key'!$D$19),"✓ Correct","✗ Try again")),"✗ Try again")) | J6: COUNTIFS with ">0.1"
A7: A3 | B7: Average P/E of US Industrials (ignore NM). | I7: =IF(H7="","",IFERROR(IF(ISNUMBER('Answer Key'!$D$20),IF(ABS(H7-'Answer Key'!$D$20)<=MAX(0.0001,ABS('Answer Key'!$D$20)*0.001),"✓ Correct","✗ Try again"),IF(TRIM(H7)=TRIM('Answer Key'!$D$20),"✓ Correct","✗ Try again")),"✗ Try again")) | J7: AVERAGEIFS (text 'NM' is skipped automatically)
A8: A4 | B8: Market-cap-weighted average 1Y return of Health Care. | I8: =IF(H8="","",IFERROR(IF(ISNUMBER('Answer Key'!$D$21),IF(ABS(H8-'Answer Key'!$D$21)<=MAX(0.0001,ABS('Answer Key'!$D$21)*0.001),"✓ Correct","✗ Try again"),IF(TRIM(H8)=TRIM('Answer Key'!$D$21),"✓ Correct","✗ Try again")),"✗ Try again")) | J8: SUMPRODUCT((cond)*cap*ret)/SUMIFS(cap)
A9: A5 | B9: Highest dividend yield in Energy. | I9: =IF(H9="","",IFERROR(IF(ISNUMBER('Answer Key'!$D$22),IF(ABS(H9-'Answer Key'!$D$22)<=MAX(0.0001,ABS('Answer Key'!$D$22)*0.001),"✓ Correct","✗ Try again"),IF(TRIM(H9)=TRIM('Answer Key'!$D$22),"✓ Correct","✗ Try again")),"✗ Try again")) | J9: MAXIFS
A10: A6 | B10: Lowest P/E among UK stocks (ignore NM). | I10: =IF(H10="","",IFERROR(IF(ISNUMBER('Answer Key'!$D$23),IF(ABS(H10-'Answer Key'!$D$23)<=MAX(0.0001,ABS('Answer Key'!$D$23)*0.001),"✓ Correct","✗ Try again"),IF(TRIM(H10)=TRIM('Answer Key'!$D$23),"✓ Correct","✗ Try again")),"✗ Try again")) | J10: MINIFS
A11: A7 | B11: How many stocks have a market cap between $10bn and $50bn inclusive? | I11: =IF(H11="","",IFERROR(IF(ISNUMBER('Answer Key'!$D$24),IF(ABS(H11-'Answer Key'!$D$24)<=MAX(0.0001,ABS('Answer Key'!$D$24)*0.001),"✓ Correct","✗ Try again"),IF(TRIM(H11)=TRIM('Answer Key'!$D$24),"✓ Correct","✗ Try again")),"✗ Try again")) | J11: COUNTIFS on the same column twice
A12: A8 | B12: Combined market cap of Technology OR Health Care. | I12: =IF(H12="","",IFERROR(IF(ISNUMBER('Answer Key'!$D$25),IF(ABS(H12-'Answer Key'!$D$25)<=MAX(0.0001,ABS('Answer Key'!$D$25)*0.001),"✓ Correct","✗ Try again"),IF(TRIM(H12)=TRIM('Answer Key'!$D$25),"✓ Correct","✗ Try again")),"✗ Try again")) | J12: Two SUMIFS added, or SUM(SUMIFS(...,{"A","B"}))
A13: A9 | B13: Which sector has the largest total market cap? (text) | I13: =IF(H13="","",IFERROR(IF(ISNUMBER('Answer Key'!$D$26),IF(ABS(H13-'Answer Key'!$D$26)<=MAX(0.0001,ABS('Answer Key'!$D$26)*0.001),"✓ Correct","✗ Try again"),IF(TRIM(H13)=TRIM('Answer Key'!$D$26),"✓ Correct","✗ Try again")),"✗ Try again")) | J13: Build a small sector table with SUMIFS, then INDEX/MATCH on MAX
A14: A10 | B14: AGGREGATE P/E of Energy = total cap ÷ total net income (include loss-makers). Why is this better than averaging P/Es? | I14: =IF(H14="","",IFERROR(IF(ISNUMBER('Answer Key'!$D$27),IF(ABS(H14-'Answer Key'!$D$27)<=MAX(0.0001,ABS('Answer Key'!$D$27)*0.001),"✓ Correct","✗ Try again"),IF(TRIM(H14)=TRIM('Answer Key'!$D$27),"✓ Correct","✗ Try again")),"✗ Try again")) | J14: SUMIFS / SUMIFS
A15: A11 | B15: PIVOT: Build a PivotTable of average 1Y Return by Sector (rows) × Country (cols). What is Japan / Technology? | I15: =IF(H15="","",IFERROR(IF(ISNUMBER('Answer Key'!$D$28),IF(ABS(H15-'Answer Key'!$D$28)<=MAX(0.0001,ABS('Answer Key'!$D$28)*0.001),"✓ Correct","✗ Try again"),IF(TRIM(H15)=TRIM('Answer Key'!$D$28),"✓ Correct","✗ Try again")),"✗ Try again")) | J15: Insert → PivotTable; Values = Average. Verify with AVERAGEIFS
A16: A12 | B16: What % of total universe market cap is rated 'Buy'? | I16: =IF(H16="","",IFERROR(IF(ISNUMBER('Answer Key'!$D$29),IF(ABS(H16-'Answer Key'!$D$29)<=MAX(0.0001,ABS('Answer Key'!$D$29)*0.001),"✓ Correct","✗ Try again"),IF(TRIM(H16)=TRIM('Answer Key'!$D$29),"✓ Correct","✗ Try again")),"✗ Try again")) | J16: SUMIFS / SUM
A17: A13 | B17: How many stocks have a P/E of 'NM'? | I17: =IF(H17="","",IFERROR(IF(ISNUMBER('Answer Key'!$D$30),IF(ABS(H17-'Answer Key'!$D$30)<=MAX(0.0001,ABS('Answer Key'!$D$30)*0.001),"✓ Correct","✗ Try again"),IF(TRIM(H17)=TRIM('Answer Key'!$D$30),"✓ Correct","✗ Try again")),"✗ Try again")) | J17: COUNTIF
A18: A14 | B18: Average 1Y return of the 10 largest stocks by market cap. | I18: =IF(H18="","",IFERROR(IF(ISNUMBER('Answer Key'!$D$31),IF(ABS(H18-'Answer Key'!$D$31)<=MAX(0.0001,ABS('Answer Key'!$D$31)*0.001),"✓ Correct","✗ Try again"),IF(TRIM(H18)=TRIM('Answer Key'!$D$31),"✓ Correct","✗ Try again")),"✗ Try again")) | J18: AVERAGEIFS with ">="&LARGE(cap,10)
G19: Score: | H19: =COUNTIF(I5:I18,"✓ Correct")&" / 14" -> 0 / 14
A22: DATA
A23: Mkt Cap & Net Income in $bn. P/E shows 'NM' (not meaningful) when earnings ≤ 0. Then build a PivotTable (Insert → PivotTable) for A11.
A25: Ticker | B25: Sector | C25: Country | D25: Mkt Cap ($bn) | E25: Net Income ($bn) | F25: P/E | G25: Div Yield | H25: 1Y Return | I25: Rating
A26: ALDR | B26: Energy | C26: UK | D26: 16.42 | E26: -0.26 | F26: NM | G26: 0.0096 | H26: 0.0812 | I26: Buy
A27: BRKN | B27: Financials | C27: Germany | D27: 10.28 | E27: 0.89 | F27: 11.6 | G27: 0.042 | H27: 0.2894 | I27: Hold
A28: CVLT | B28: Technology | C28: UK | D28: 3.69 | E28: 0.44 | F28: 8.4 | G28: 0.0246 | H28: 0.5206 | I28: Buy
A29: DMNX | B29: Health Care | C29: US | D29: 16.55 | E29: 1.83 | F29: 9 | G29: 0.0139 | H29: 0.055 | I29: Buy
A30: ELMR | B30: Industrials | C30: Japan | D30: 23.79 | E30: 1.71 | F30: 13.9 | G30: 0.0197 | H30: 0.0794 | I30: Buy
A31: FENX | B31: Consumer | C31: Germany | D31: 22.55 | E31: -0.4 | F31: NM | G31: 0.0217 | H31: 0.1337 | I31: Hold
A32: GRVL | B32: Energy | C32: Germany | D32: 22.34 | E32: 2.39 | F32: 9.3 | G32: 0.0355 | H32: 0.3855 | I32: Buy
A33: HRBR | B33: Financials | C33: UK | D33: 7.99 | E33: 0.42 | F33: 19 | G33: 0.0011 | H33: 0.0833 | I33: Buy
A34: IRNW | B34: Technology | C34: Germany | D34: 22.96 | E34: -1.53 | F34: NM | G34: 0.0094 | H34: 0.4133 | I34: Hold
A35: KSTL | B35: Health Care | C35: Germany | D35: 23.6 | E35: 1.86 | F35: 12.7 | G35: 0.0193 | H35: -0.1227 | I35: Buy
A36: LMRA | B36: Industrials | C36: UK | D36: 89.17 | E36: -1.3 | F36: NM | G36: 0.063 | H36: 0.0491 | I36: Sell
A37: MRDN | B37: Consumer | C37: UK | D37: 158.66 | E37: -0.77 | F37: NM | G37: 0.0393 | H37: 0.0464 | I37: Sell
A38: NOVX | B38: Energy | C38: UK | D38: 21.39 | E38: 0.6 | F38: 35.7 | G38: 0.0233 | H38: 0.263 | I38: Buy
A39: OKRA | B39: Financials | C39: UK | D39: 11.4 | E39: 1.41 | F39: 8.1 | G39: 0.0357 | H39: 0.32 | I39: Hold
A40: PLMT | B40: Technology | C40: Germany | D40: 22.99 | E40: 0.95 | F40: 24.2 | G40: 0.0559 | H40: -0.2421 | I40: Buy
A41: QRSN | B41: Health Care | C41: UK | D41: 13.36 | E41: 0.98 | F41: 13.6 | G41: 0.0215 | H41: -0.1113 | I41: Buy
A42: RDGE | B42: Industrials | C42: UK | D42: 11.68 | E42: 1.72 | F42: 6.8 | G42: 0.0195 | H42: 0.1641 | I42: Buy
A43: SLTN | B43: Consumer | C43: Germany | D43: 23.14 | E43: 3.23 | F43: 7.2 | G43: 0.0432 | H43: -0.0549 | I43: Hold
A44: TRVO | B44: Energy | C44: Japan | D44: 8.64 | E44: 0.47 | F44: 18.4 | G44: 0.0324 | H44: -0.2449 | I44: Sell
...

Sheet Key_Work
A1: Key_Work — helper columns used by the Answer Key (rows mirror each practice tab's data rows)
J4: S2 Sector | K4: Total Cap | AH4: S6 DCF
J5: Energy | K5: =SUMIFS(2_Aggregation!$D$26:$D$85,2_Aggregation!$B$26:$B$85,J5) -> 198.99 | AH5: FCF0 | AJ5: =6_Valuation!$F$34-6_Valuation!$F$35 -> 590
J6: Financials | K6: =SUMIFS(2_Aggregation!$D$26:$D$85,2_Aggregation!$B$26:$B$85,J6) -> 203.62 | AH6: FCF yr1 | AI6: 1 | AJ6: =$AJ$5*(1+6_Valuation!$B$47)^1 -> 619.5
J7: Technology | K7: =SUMIFS(2_Aggregation!$D$26:$D$85,2_Aggregation!$B$26:$B$85,J7) -> 146.14 | AH7: FCF yr2 | AI7: 2 | AJ7: =$AJ$5*(1+6_Valuation!$B$47)^2 -> 650.475
J8: Health Care | K8: =SUMIFS(2_Aggregation!$D$26:$D$85,2_Aggregation!$B$26:$B$85,J8) -> 267.49 | AH8: FCF yr3 | AI8: 3 | AJ8: =$AJ$5*(1+6_Valuation!$B$47)^3 -> 682.99875
J9: Industrials | K9: =SUMIFS(2_Aggregation!$D$26:$D$85,2_Aggregation!$B$26:$B$85,J9) -> 279.14 | AH9: FCF yr4 | AI9: 4 | AJ9: =$AJ$5*(1+6_Valuation!$B$47)^4 -> 717.14869
J10: Consumer | K10: =SUMIFS(2_Aggregation!$D$26:$D$85,2_Aggregation!$B$26:$B$85,J10) -> 352.12 | AH10: FCF yr5 | AI10: 5 | AJ10: =$AJ$5*(1+6_Valuation!$B$47)^5 -> 753.00612
AH11: EV (DCF) | AJ11: =NPV(6_Valuation!$B$46,AJ6:AJ10)+AJ10*(1+6_Valuation!$B$48)/(6_Valuation!$B$46-6_Valuation!$B$48)/(1+6_Valuation!$B$46)^5 -> 10358.187
AH12: Implied px | AJ12: =(AJ11-(6_Valuation!$B$41-6_Valuation!$B$42+6_Valuation!$B$43+6_Valuation!$B$44))/6_Valuation!$F$37 -> 36.371652
A24: S1 Clean Tkr | B24: Price# | C24: Mkt Val | D24: In Ref | E24: Sector | F24: Dup | G24: Dirty Tkr | H24: Text Px | V24: S4 P/B | W24: E/P | X24: EV/EBITDA | Y24: Rk PB | Z24: Rk EP | AA24: Rk EV | AB24: Composite | AC24: Comp Rk | AD24: Quintile | AE24: P/E pos | AF24: ROE wins
A25: =UPPER(TRIM(1_Lookups!G25)) -> LMRA | B25: =VALUE(TRIM(1_Lookups!I25)) -> 244.07 | C25: =B25*1_Lookups!J25 -> 634582 | D25: =IF(ISNUMBER(MATCH(A25,1_Lookups!$A$25:$A$54,0)),1,0) -> 1 | E25: =IFERROR(INDEX(1_Lookups!$C$25:$C$54,MATCH(A25,1_Lookups!$A$25:$A$54,0)),"Not Found") -> Industrials | F25: =IF(COUNTIF(1_Lookups!$F$25:F25,1_Lookups!F25)>1,1,0) -> 0 | G25: =IF(EXACT(1_Lookups!G25,A25),0,1) -> 0 | H25: =IF(ISTEXT(1_Lookups!I25),1,0) -> 0 | V25: =4_Screening!C25/4_Screening!D25 -> 1.5482032 | W25: =4_Screening!E25/4_Screening!C25 -> 0.10074627 | X25: =4_Screening!F25/4_Screening!G25 -> 6.9076923 | Y25: =RANK(V25,$V$25:$V$74,1) -> 20 | Z25: =RANK(W25,$W$25:$W$74,0) -> 6 | AA25: =RANK(X25,$X$25:$X$74,1) -> 9 | AB25: =AVERAGE(Y25:AA25) -> 11.666667 | AC25: =RANK(AB25,$AB$25:$AB$74,1) -> 1 | AD25: =ROUNDUP(5*AC25/COUNT($AB$25:$AB$74),0) -> 1 | AE25: =IF(4_Screening!E25>0,4_Screening!C25/4_Screening!E25,"") -> 9.9259259 | AF25: =MIN(MAX(4_Screening!H25,PERCENTILE(4_Screening!$H$25:$H$74,0.05)),PERCENTILE(4_Screening!$H$25:$H$74,0.95)) -> 0.1456
A26: =UPPER(TRIM(1_Lookups!G26)) -> HRBR | B26: =VALUE(TRIM(1_Lookups!I26)) -> 264.22 | C26: =B26*1_Lookups!J26 -> 607706 | D26: =IF(ISNUMBER(MATCH(A26,1_Lookups!$A$25:$A$54,0)),1,0) -> 1 | E26: =IFERROR(INDEX(1_Lookups!$C$25:$C$54,MATCH(A26,1_Lookups!$A$25:$A$54,0)),"Not Found") -> Financials | F26: =IF(COUNTIF(1_Lookups!$F$25:F26,1_Lookups!F26)>1,1,0) -> 0 | G26: =IF(EXACT(1_Lookups!G26,A26),0,1) -> 0 | H26: =IF(ISTEXT(1_Lookups!I26),1,0) -> 1 | V26: =4_Screening!C26/4_Screening!D26 -> 2.1747621 | W26: =4_Screening!E26/4_Screening!C26 -> 0.12653266 | X26: =4_Screening!F26/4_Screening!G26 -> 11.553191 | Y26: =RANK(V26,$V$25:$V$74,1) -> 33 | Z26: =RANK(W26,$W$25:$W$74,0) -> 3 | AA26: =RANK(X26,$X$25:$X$74,1) -> 33 | AB26: =AVERAGE(Y26:AA26) -> 23 | AC26: =RANK(AB26,$AB$25:$AB$74,1) -> 21 | AD26: =ROUNDUP(5*AC26/COUNT($AB$25:$AB$74),0) -> 3 | AE26: =IF(4_Screening!E26>0,4_Screening!C26/4_Screening!E26,"") -> 7.903098 | AF26: =MIN(MAX(4_Screening!H26,PERCENTILE(4_Screening!$H$25:$H$74,0.05)),PERCENTILE(4_Screening!$H$25:$H$74,0.95)) -> 0.1727
A27: =UPPER(TRIM(1_Lookups!G27)) -> DMNX | B27: =VALUE(TRIM(1_Lookups!I27)) -> 41.96 | C27: =B27*1_Lookups!J27 -> 205604 | D27: =IF(ISNUMBER(MATCH(A27,1_Lookups!$A$25:$A$54,0)),1,0) -> 1 | E27: =IFERROR(INDEX(1_Lookups!$C$25:$C$54,MATCH(A27,1_Lookups!$A$25:$A$54,0)),"Not Found") -> Health Care | F27: =IF(COUNTIF(1_Lookups!$F$25:F27,1_Lookups!F27)>1,1,0) -> 0 | G27: =IF(EXACT(1_Lookups!G27,A27),0,1) -> 1 | H27: =IF(ISTEXT(1_Lookups!I27),1,0) -> 0 | V27: =4_Screening!C27/4_Screening!D27 -> 1.4397487 | W27: =4_Screening!E27/4_Screening!C27 -> 0.1032659 | X27: =4_Screening!F27/4_Screening!G27 -> 8.654321 | Y27: =RANK(V27,$V$25:$V$74,1) -> 18 | Z27: =RANK(W27,$W$25:$W$74,0) -> 4 | AA27: =RANK(X27,$X$25:$X$74,1) -> 23 | AB27: =AVERAGE(Y27:AA27) -> 15 | AC27: =RANK(AB27,$AB$25:$AB$74,1) -> 7 | AD27: =ROUNDUP(5*AC27/COUNT($AB$25:$AB$74),0) -> 1 | AE27: =IF(4_Screening!E27>0,4_Screening!C27/4_Screening!E27,"") -> 9.6837388 | AF27: =MIN(MAX(4_Screening!H27,PERCENTILE(4_Screening!$H$25:$H$74,0.05)),PERCENTILE(4_Screening!$H$25:$H$74,0.95)) -> 0.1747
A28: =UPPER(TRIM(1_Lookups!G28)) -> ZNTH | B28: =VALUE(TRIM(1_Lookups!I28)) -> 133.18 | C28: =B28*1_Lookups!J28 -> 466130 | D28: =IF(ISNUMBER(MATCH(A28,1_Lookups!$A$25:$A$54,0)),1,0) -> 1 | E28: =IFERROR(INDEX(1_Lookups!$C$25:$C$54,MATCH(A28,1_Lookups!$A$25:$A$54,0)),"Not Found") -> Energy | F28: =IF(COUNTIF(1_Lookups!$F$25:F28,1_Lookups!F28)>1,1,0) -> 0 | G28: =IF(EXACT(1_Lookups!G28,A28),0,1) -> 0 | H28: =IF(ISTEXT(1_Lookups!I28),1,0) -> 0 | V28: =4_Screening!C28/4_Screening!D28 -> 0.7474555 | W28: =4_Screening!E28/4_Screening!C28 -> 0.055272337 | X28: =4_Screening!F28/4_Screening!G28 -> 6.7920904 | Y28: =RANK(V28,$V$25:$V$74,1) -> 3 | Z28: =RANK(W28,$W$25:$W$74,0) -> 28 | AA28: =RANK(X28,$X$25:$X$74,1) -> 8 | AB28: =AVERAGE(Y28:AA28) -> 13 | AC28: =RANK(AB28,$AB$25:$AB$74,1) -> 2 | AD28: =ROUNDUP(5*AC28/COUNT($AB$25:$AB$74),0) -> 1 | AE28: =IF(4_Screening!E28>0,4_Screening!C28/4_Screening!E28,"") -> 18.092233 | AF28: =MIN(MAX(4_Screening!H28,PERCENTILE(4_Screening!$H$25:$H$74,0.05)),PERCENTILE(4_Screening!$H$25:$H$74,0.95)) -> 0.29721
A29: =UPPER(TRIM(1_Lookups!G29)) -> XERA | B29: =VALUE(TRIM(1_Lookups!I29)) -> 152.39 | C29: =B29*1_Lookups!J29 -> 259063 | D29: =IF(ISNUMBER(MATCH(A29,1_Lookups!$A$25:$A$54,0)),1,0) -> 1 | E29: =IFERROR(INDEX(1_Lookups!$C$25:$C$54,MATCH(A29,1_Lookups!$A$25:$A$54,0)),"Not Found") -> Industrials | F29: =IF(COUNTIF(1_Lookups!$F$25:F29,1_Lookups!F29)>1,1,0) -> 0 | G29: =IF(EXACT(1_Lookups!G29,A29),0,1) -> 1 | H29: =IF(ISTEXT(1_Lookups!I29),1,0) -> 0 | V29: =4_Screening!C29/4_Screening!D29 -> 3.1378057 | W29: =4_Screening!E29/4_Screening!C29 -> 0.070352817 | X29: =4_Screening!F29/4_Screening!G29 -> 12.47561 | Y29: =RANK(V29,$V$25:$V$74,1) -> 46 | Z29: =RANK(W29,$W$25:$W$74,0) -> 16 | AA29: =RANK(X29,$X$25:$X$74,1) -> 38 | AB29: =AVERAGE(Y29:AA29) -> 33.333333 | AC29: =RANK(AB29,$AB$25:$AB$74,1) -> 41 | AD29: =ROUNDUP(5*AC29/COUNT($AB$25:$AB$74),0) -> 5 | AE29: =IF(4_Screening!E29>0,4_Screening!C29/4_Screening!E29,"") -> 14.214072 | AF29: =MIN(MAX(4_Screening!H29,PERCENTILE(4_Screening!$H$25:$H$74,0.05)),PERCENTILE(4_Screening!$H$25:$H$74,0.95)) -> 0.1075
A30: =UPPER(TRIM(1_Lookups!G30)) -> KSTL | B30: =VALUE(TRIM(1_Lookups!I30)) -> 154.72 | C30: =B30*1_Lookups!J30 -> 139248 | D30: =IF(ISNUMBER(MATCH(A30,1_Lookups!$A$25:$A$54,0)),1,0) -> 1 | E30: =IFERROR(INDEX(1_Lookups!$C$25:$C$54,MATCH(A30,1_Lookups!$A$25:$A$54,0)),"Not Found") -> Health Care | F30: =IF(COUNTIF(1_Lookups!$F$25:F30,1_Lookups!F30)>1,1,0) -> 0 | G30: =IF(EXACT(1_Lookups!G30,A30),0,1) -> 0 | H30: =IF(ISTEXT(1_Lookups!I30),1,0) -> 1 | M30: S3 rA | N30: rB | O30: rM | P30: RunMax A | Q30: DD A | R30: ln rA | S30: rA-rM | T30: A>M | V30: =4_Screening!C30/4_Screening!D30 -> 0.96569228 | W30: =4_Screening!E30/4_Screening!C30 -> 0.067156063 | X30: =4_Screening!F30/4_Screening!G30 -> 11.617021 | Y30: =RANK(V30,$V$25:$V$74,1) -> 7 | Z30: =RANK(W30,$W$25:$W$74,0) -> 18 | AA30: =RANK(X30,$X$25:$X$74,1) -> 34 | AB30: =AVERAGE(Y30:AA30) -> 19.666667 | AC30: =RANK(AB30,$AB$25:$AB$74,1) -> 13 | AD30: =ROUNDUP(5*AC30/COUNT($AB$25:$AB$74),0) -> 2 | AE30: =IF(4_Screening!E30>0,4_Screening!C30/4_Screening!E30,"") -> 14.890688 | AF30: =MIN(MAX(4_Screening!H30,PERCENTILE(4_Screening!$H$25:$H$74,0.05)),PERCENTILE(4_Screening!$H$25:$H$74,0.95)) -> 0.1399
A31: =UPPER(TRIM(1_Lookups!G31)) -> ABRV | B31: =VALUE(TRIM(1_Lookups!I31)) -> 173.91 | C31: =B31*1_Lookups!J31 -> 730422 | D31: =IF(ISNUMBER(MATCH(A31,1_Lookups!$A$25:$A$54,0)),1,0) -> 1 | E31: =IFERROR(INDEX(1_Lookups!$C$25:$C$54,MATCH(A31,1_Lookups!$A$25:$A$54,0)),"Not Found") -> Financials | F31: =IF(COUNTIF(1_Lookups!$F$25:F31,1_Lookups!F31)>1,1,0) -> 0 | G31: =IF(EXACT(1_Lookups!G31,A31),0,1) -> 0 | H31: =IF(ISTEXT(1_Lookups!I31),1,0) -> 0 | P31: =MAX(3_Returns!$B$31:B31) -> 48.2 | Q31: =3_Returns!B31/P31-1 -> 0 | V31: =4_Screening!C31/4_Screening!D31 -> 2.7388265 | W31: =4_Screening!E31/4_Screening!C31 -> -0.06837451 | X31: =4_Screening!F31/4_Screening!G31 -> 7.3333333 | Y31: =RANK(V31,$V$25:$V$74,1) -> 42 | Z31: =RANK(W31,$W$25:$W$74,0) -> 49 | AA31: =RANK(X31,$X$25:$X$74,1) -> 12 | AB31: =AVERAGE(Y31:AA31) -> 34.333333 | AC31: =RANK(AB31,$AB$25:$AB$74,1) -> 45 | AD31: =ROUNDUP(5*AC31/COUNT($AB$25:$AB$74),0) -> 5 | AE31: =IF(4_Screening!E31>0,4_Screening!C31/4_Screening!E31,"") | AF31: =MIN(MAX(4_Screening!H31,PERCENTILE(4_Screening!$H$25:$H$74,0.05)),PERCENTILE(4_Screening!$H$25:$H$74,0.95)) -> 0.186
A32: =UPPER(TRIM(1_Lookups!G32)) -> ULMN | B32: =VALUE(TRIM(1_Lookups!I32)) -> 34.3 | C32: =B32*1_Lookups!J32 -> 58310 | D32: =IF(ISNUMBER(MATCH(A32,1_Lookups!$A$25:$A$54,0)),1,0) -> 1 | E32: =IFERROR(INDEX(1_Lookups!$C$25:$C$54,MATCH(A32,1_Lookups!$A$25:$A$54,0)),"Not Found") -> Financials | F32: =IF(COUNTIF(1_Lookups!$F$25:F32,1_Lookups!F32)>1,1,0) -> 0 | G32: =IF(EXACT(1_Lookups!G32,A32),0,1) -> 1 | H32: =IF(ISTEXT(1_Lookups!I32),1,0) -> 0 | M32: =3_Returns!B32/3_Returns!B31-1 -> 0.010580913 | N32: =3_Returns!C32/3_Returns!C31-1 -> -0.0024681201 | O32: =3_Returns!D32/3_Returns!D31-1 -> 0.0066837056 | P32: =MAX(3_Returns!$B$31:B32) -> 48.71 | Q32: =3_Returns!B32/P32-1 -> 0 | R32: =LN(3_Returns!B32/3_Returns!B31) -> 0.010525327 | S32: =M32-O32 -> 0.0038972072 | T32: =IF(M32>O32,1,0) -> 1 | V32: =4_Screening!C32/4_Screening!D32 -> 2.3447154 | W32: =4_Screening!E32/4_Screening!C32 -> 0.067961165 | X32: =4_Screening!F32/4_Screening!G32 -> 13.558333 | Y32: =RANK(V32,$V$25:$V$74,1) -> 39 | Z32: =RANK(W32,$W$25:$W$74,0) -> 17 | AA32: =RANK(X32,$X$25:$X$74,1) -> 43 | AB32: =AVERAGE(Y32:AA32) -> 33 | AC32: =RANK(AB32,$AB$25:$AB$74,1) -> 40 | AD32: =ROUNDUP(5*AC32/COUNT($AB$25:$AB$74),0) -> 4 | AE32: =IF(4_Screening!E32>0,4_Screening!C32/4_Screening!E32,"") -> 14.714286 | AF32: =MIN(MAX(4_Screening!H32,PERCENTILE(4_Screening!$H$25:$H$74,0.05)),PERCENTILE(4_Screening!$H$25:$H$74,0.95)) -> 0.0849
A33: =UPPER(TRIM(1_Lookups!G33)) -> TRVO | B33: =VALUE(TRIM(1_Lookups!I33)) -> 59.4 | C33: =B33*1_Lookups!J33 -> 83160 | D33: =IF(ISNUMBER(MATCH(A33,1_Lookups!$A$25:$A$54,0)),1,0) -> 1 | E33: =IFERROR(INDEX(1_Lookups!$C$25:$C$54,MATCH(A33,1_Lookups!$A$25:$A$54,0)),"Not Found") -> Energy | F33: =IF(COUNTIF(1_Lookups!$F$25:F33,1_Lookups!F33)>1,1,0) -> 0 | G33: =IF(EXACT(1_Lookups!G33,A33),0,1) -> 0 | H33: =IF(ISTEXT(1_Lookups!I33),1,0) -> 0 | M33: =3_Returns!B33/3_Returns!B32-1 -> 0.011701909 | N33: =3_Returns!C33/3_Returns!C32-1 -> -0.0028041237 | O33: =3_Returns!D33/3_Returns!D32-1 -> 0.00070079888 | P33: =MAX(3_Returns!$B$31:B33) -> 49.28 | Q33: =3_Returns!B33/P33-1 -> 0 | R33: =LN(3_Returns!B33/3_Returns!B32) -> 0.011633971 | S33: =M33-O33 -> 0.01100111 | T33: =IF(M33>O33,1,0) -> 1 | V33: =4_Screening!C33/4_Screening!D33 -> 0.67463432 | W33: =4_Screening!E33/4_Screening!C33 -> 0.028556319 | X33: =4_Screening!F33/4_Screening!G33 -> 8.1295812 | Y33: =RANK(V33,$V$25:$V$74,1) -> 2 | Z33: =RANK(W33,$W$25:$W$74,0) -> 37 | AA33: =RANK(X33,$X$25:$X$74,1) -> 19 | AB33: =AVERAGE(Y33:AA33) -> 19.333333 | AC33: =RANK(AB33,$AB$25:$AB$74,1) -> 11 | AD33: =ROUNDUP(5*AC33/COUNT($AB$25:$AB$74),0) -> 2 | AE33: =IF(4_Screening!E33>0,4_Screening!C33/4_Screening!E33,"") -> 35.018519 | AF33: =MIN(MAX(4_Screening!H33,PERCENTILE(4_Screening!$H$25:$H$74,0.05)),PERCENTILE(4_Screening!$H$25:$H$74,0.95)) -> 0.0486
A34: =UPPER(TRIM(1_Lookups!G34)) -> CVLT | B34: =VALUE(TRIM(1_Lookups!I34)) -> 81.69 | C34: =B34*1_Lookups!J34 -> 392112 | D34: =IF(ISNUMBER(MATCH(A34,1_Lookups!$A$25:$A$54,0)),1,0) -> 1 | E34: =IFERROR(INDEX(1_Lookups!$C$25:$C$54,MATCH(A34,1_Lookups!$A$25:$A$54,0)),"Not Found") -> Technology | F34: =IF(COUNTIF(1_Lookups!$F$25:F34,1_Lookups!F34)>1,1,0) -> 0 | G34: =IF(EXACT(1_Lookups!G34,A34),0,1) -> 0 | H34: =IF(ISTEXT(1_Lookups!I34),1,0) -> 1 | M34: =3_Returns!B34/3_Returns!B33-1 -> 0.014813312 | N34: =3_Returns!C34/3_Returns!C33-1 -> 0.026962203 | O34: =3_Returns!D34/3_Returns!D33-1 -> 0.012777582 | P34: =MAX(3_Returns!$B$31:B34) -> 50.01 | Q34: =3_Returns!B34/P34-1 -> 0 | R34: =LN(3_Returns!B34/3_Returns!B33) -> 0.014704666 | S34: =M34-O34 -> 0.0020357299 | T34: =IF(M34>O34,1,0) -> 1 | V34: =4_Screening!C34/4_Screening!D34 -> 1.0337497 | W34: =4_Screening!E34/4_Screening!C34 -> -0.024166376 | X34: =4_Screening!F34/4_Screening!G34 -> 8.0985915 | Y34: =RANK(V34,$V$25:$V$74,1) -> 8 | Z34: =RANK(W34,$W$25:$W$74,0) -> 44 | AA34: =RANK(X34,$X$25:$X$74,1) -> 17 | AB34: =AVERAGE(Y34:AA34) -> 23 | AC34: =RANK(AB34,$AB$25:$AB$74,1) -> 21 | AD34: =ROUNDUP(5*AC34/COUNT($AB$25:$AB$74),0) -> 3 | AE34: =IF(4_Screening!E34>0,4_Screening!C34/4_Screening!E34,"") | AF34: =MIN(MAX(4_Screening!H34,PERCENTILE(4_Screening!$H$25:$H$74,0.05)),PERCENTILE(4_Screening!$H$25:$H$74,0.95)) -> 0.2002
A35: =UPPER(TRIM(1_Lookups!G35)) -> ZZZZ | B35: =VALUE(TRIM(1_Lookups!I35)) -> 31.4 | C35: =B35*1_Lookups!J35 -> 91060 | D35: =IF(ISNUMBER(MATCH(A35,1_Lookups!$A$25:$A$54,0)),1,0) -> 0 | E35: =IFERROR(INDEX(1_Lookups!$C$25:$C$54,MATCH(A35,1_Lookups!$A$25:$A$54,0)),"Not Found") -> Not Found | F35: =IF(COUNTIF(1_Lookups!$F$25:F35,1_Lookups!F35)>1,1,0) -> 0 | G35: =IF(EXACT(1_Lookups!G35,A35),0,1) -> 0 | H35: =IF(ISTEXT(1_Lookups!I35),1,0) -> 0 | M35: =3_Returns!B35/3_Returns!B34-1 -> 0.015396921 | N35: =3_Returns!C35/3_Returns!C34-1 -> 0.0063622453 | O35: =3_Returns!D35/3_Returns!D34-1 -> 0.0046000954 | P35: =MAX(3_Returns!$B$31:B35) -> 50.78 | Q35: =3_Returns!B35/P35-1 -> 0 | R35: =LN(3_Returns!B35/3_Returns!B34) -> 0.015279591 | S35: =M35-O35 -> 0.010796825 | T35: =IF(M35>O35,1,0) -> 1 | V35: =4_Screening!C35/4_Screening!D35 -> 1.338455 | W35: =4_Screening!E35/4_Screening!C35 -> 0.033107122 | X35: =4_Screening!F35/4_Screening!G35 -> 9.4074074 | Y35: =RANK(V35,$V$25:$V$74,1) -> 15 | Z35: =RANK(W35,$W$25:$W$74,0) -> 33 | AA35: =RANK(X35,$X$25:$X$74,1) -> 26 | AB35: =AVERAGE(Y35:AA35) -> 24.666667 | AC35: =RANK(AB35,$AB$25:$AB$74,1) -> 24 | AD35: =ROUNDUP(5*AC35/COUNT($AB$25:$AB$74),0) -> 3 | AE35: =IF(4_Screening!E35>0,4_Screening!C35/4_Screening!E35,"") -> 30.204981 | AF35: =MIN(MAX(4_Screening!H35,PERCENTILE(4_Screening!$H$25:$H$74,0.05)),PERCENTILE(4_Screening!$H$25:$H$74,0.95)) -> 0.2074
A36: =UPPER(TRIM(1_Lookups!G36)) -> ABRV | B36: =VALUE(TRIM(1_Lookups!I36)) -> 170.12 | C36: =B36*1_Lookups!J36 -> 595420 | D36: =IF(ISNUMBER(MATCH(A36,1_Lookups!$A$25:$A$54,0)),1,0) -> 1 | E36: =IFERROR(INDEX(1_Lookups!$C$25:$C$54,MATCH(A36,1_Lookups!$A$25:$A$54,0)),"Not Found") -> Financials | F36: =IF(COUNTIF(1_Lookups!$F$25:F36,1_Lookups!F36)>1,1,0) -> 0 | G36: =IF(EXACT(1_Lookups!G36,A36),0,1) -> 1 | H36: =IF(ISTEXT(1_Lookups!I36),1,0) -> 0 | M36: =3_Returns!B36/3_Returns!B35-1 -> -0.014769594 | N36: =3_Returns!C36/3_Returns!C35-1 -> 0.004081306 | O36: =3_Returns!D36/3_Returns!D35-1 -> 0.0042698913 | P36: =MAX(3_Returns!$B$31:B36) -> 50.78 | Q36: =3_Returns!B36/P36-1 -> -0.014769594 | R36: =LN(3_Returns!B36/3_Returns!B35) -> -0.014879751 | S36: =M36-O36 -> -0.019039486 | T36: =IF(M36>O36,1,0) -> 0 | V36: =4_Screening!C36/4_Screening!D36 -> 1.1135418 | W36: =4_Screening!E36/4_Screening!C36 -> -0.021033526 | X36: =4_Screening!F36/4_Screening!G36 -> 6.9367816 | Y36: =RANK(V36,$V$25:$V$74,1) -> 9 | Z36: =RANK(W36,$W$25:$W$74,0) -> 43 | AA36: =RANK(X36,$X$25:$X$74,1) -> 10 | AB36: =AVERAGE(Y36:AA36) -> 20.666667 | AC36: =RANK(AB36,$AB$25:$AB$74,1) -> 15 | AD36: =ROUNDUP(5*AC36/COUNT($AB$25:$AB$74),0) -> 2 | AE36: =IF(4_Screening!E36>0,4_Screening!C36/4_Screening!E36,"") | AF36: =MIN(MAX(4_Screening!H36,PERCENTILE(4_Screening!$H$25:$H$74,0.05)),PERCENTILE(4_Screening!$H$25:$H$74,0.95)) -> 0.1559
A37: =UPPER(TRIM(1_Lookups!G37)) -> BLCK | B37: =VALUE(TRIM(1_Lookups!I37)) -> 64.3 | C37: =B37*1_Lookups!J37 -> 77160 | D37: =IF(ISNUMBER(MATCH(A37,1_Lookups!$A$25:$A$54,0)),1,0) -> 1 | E37: =IFERROR(INDEX(1_Lookups!$C$25:$C$54,MATCH(A37,1_Lookups!$A$25:$A$54,0)),"Not Found") -> Technology | F37: =IF(COUNTIF(1_Lookups!$F$25:F37,1_Lookups!F37)>1,1,0) -> 0 | G37: =IF(EXACT(1_Lookups!G37,A37),0,1) -> 0 | H37: =IF(ISTEXT(1_Lookups!I37),1,0) -> 0 | M37: =3_Returns!B37/3_Returns!B36-1 -> 0.019588247 | N37: =3_Returns!C37/3_Returns!C36-1 -> 0.0243883 | O37: =3_Returns!D37/3_Returns!D36-1 -> 0.0044490174 | P37: =MAX(3_Returns!$B$31:B37) -> 51.01 | Q37: =3_Returns!B37/P37-1 -> 0 | R37: =LN(3_Returns!B37/3_Returns!B36) -> 0.019398866 | S37: =M37-O37 -> 0.01513923 | T37: =IF(M37>O37,1,0) -> 1 | V37: =4_Screening!C37/4_Screening!D37 -> 0.89650512 | W37: =4_Screening!E37/4_Screening!C37 -> 0.062674995 | X37: =4_Screening!F37/4_Screening!G37 -> 7.736 | Y37: =RANK(V37,$V$25:$V$74,1) -> 5 | Z37: =RANK(W37,$W$25:$W$74,0) -> 21 | AA37: =RANK(X37,$X$25:$X$74,1) -> 13 | AB37: =AVERAGE(Y37:AA37) -> 13 | AC37: =RANK(AB37,$AB$25:$AB$74,1) -> 2 | AD37: =ROUNDUP(5*AC37/COUNT($AB$25:$AB$74),0) -> 1 | AE37: =IF(4_Screening!E37>0,4_Screening!C37/4_Screening!E37,"") -> 15.955326 | AF37: =MIN(MAX(4_Screening!H37,PERCENTILE(4_Screening!$H$25:$H$74,0.05)),PERCENTILE(4_Screening!$H$25:$H$74,0.95)) -> 0.0874
A38: =UPPER(TRIM(1_Lookups!G38)) -> OKRA | B38: =VALUE(TRIM(1_Lookups!I38)) -> 32.93 | C38: =B38*1_Lookups!J38 -> 111962 | D38: =IF(ISNUMBER(MATCH(A38,1_Lookups!$A$25:$A$54,0)),1,0) -> 1 | E38: =IFERROR(INDEX(1_Lookups!$C$25:$C$54,MATCH(A38,1_Lookups!$A$25:$A$54,0)),"Not Found") -> Financials | F38: =IF(COUNTIF(1_Lookups!$F$25:F38,1_Lookups!F38)>1,1,0) -> 0 | G38: =IF(EXACT(1_Lookups!G38,A38),0,1) -> 1 | H38: =IF(ISTEXT(1_Lookups!I38),1,0) -> 0 | M38: =3_Returns!B38/3_Returns!B37-1 -> -0.024701039 | N38: =3_Returns!C38/3_Returns!C37-1 -> -0.0065354392 | O38: =3_Returns!D38/3_Returns!D37-1 -> -0.014364785 | P38: =MAX(3_Returns!$B$31:B38) -> 51.01 | Q38: =3_Returns!B38/P38-1 -> -0.024701039 | R38: =LN(3_Returns!B38/3_Returns!B37) -> -0.025011228 | S38: =M38-O38 -> -0.010336254 | T38: =IF(M38>O38,1,0) -> 0 | V38: =4_Screening!C38/4_Screening!D38 -> 2.8401072 | W38: =4_Screening!E38/4_Screening!C38 -> 0.060229596 | X38: =4_Screening!F38/4_Screening!G38 -> 8.5338983 | Y38: =RANK(V38,$V$25:$V$74,1) -> 44 | Z38: =RANK(W38,$W$25:$W$74,0) -> 24 | AA38: =RANK(X38,$X$25:$X$74,1) -> 22 | AB38: =AVERAGE(Y38:AA38) -> 30 | AC38: =RANK(AB38,$AB$25:$AB$74,1) -> 33 | AD38: =ROUNDUP(5*AC38/COUNT($AB$25:$AB$74),0) -> 4 | AE38: =IF(4_Screening!E38>0,4_Screening!C38/4_Screening!E38,"") -> 16.603133 | AF38: =MIN(MAX(4_Screening!H38,PERCENTILE(4_Screening!$H$25:$H$74,0.05)),PERCENTILE(4_Screening!$H$25:$H$74,0.95)) -> 0.1585
A39: =UPPER(TRIM(1_Lookups!G39)) -> YRLW | B39: =VALUE(TRIM(1_Lookups!I39)) -> 308.54 | C39: =B39*1_Lookups!J39 -> 647934 | D39: =IF(ISNUMBER(MATCH(A39,1_Lookups!$A$25:$A$54,0)),1,0) -> 1 | E39: =IFERROR(INDEX(1_Lookups!$C$25:$C$54,MATCH(A39,1_Lookups!$A$25:$A$54,0)),"Not Found") -> Consumer | F39: =IF(COUNTIF(1_Lookups!$F$25:F39,1_Lookups!F39)>1,1,0) -> 0 | G39: =IF(EXACT(1_Lookups!G39,A39),0,1) -> 0 | H39: =IF(ISTEXT(1_Lookups!I39),1,0) -> 1 | M39: =3_Returns!B39/3_Returns!B38-1 -> 0.0064321608 | N39: =3_Returns!C39/3_Returns!C38-1 -> -0.0085362988 | O39: =3_Returns!D39/3_Returns!D38-1 -> -0.0013416316 | P39: =MAX(3_Returns!$B$31:B39) -> 51.01 | Q39: =3_Returns!B39/P39-1 -> -0.018427759 | R39: =LN(3_Returns!B39/3_Returns!B38) -> 0.0064115627 | S39: =M39-O39 -> 0.0077737924 | T39: =IF(M39>O39,1,0) -> 1 | V39: =4_Screening!C39/4_Screening!D39 -> 1.5782149 | W39: =4_Screening!E39/4_Screening!C39 -> -0.0069965746 | X39: =4_Screening!F39/4_Screening!G39 -> 15.433333 | Y39: =RANK(V39,$V$25:$V$74,1) -> 23 | Z39: =RANK(W39,$W$25:$W$74,0) -> 41 | AA39: =RANK(X39,$X$25:$X$74,1) -> 46 | AB39: =AVERAGE(Y39:AA39) -> 36.666667 | AC39: =RANK(AB39,$AB$25:$AB$74,1) -> 47 | AD39: =ROUNDUP(5*AC39/COUNT($AB$25:$AB$74),0) -> 5 | AE39: =IF(4_Screening!E39>0,4_Screening!C39/4_Screening!E39,"") | AF39: =MIN(MAX(4_Screening!H39,PERCENTILE(4_Screening!$H$25:$H$74,0.05)),PERCENTILE(4_Screening!$H$25:$H$74,0.95)) -> 0.1377
A40: =UPPER(TRIM(1_Lookups!G40)) -> GRVL | B40: =VALUE(TRIM(1_Lookups!I40)) -> 113.84 | C40: =B40*1_Lookups!J40 -> 318752 | D40: =IF(ISNUMBER(MATCH(A40,1_Lookups!$A$25:$A$54,0)),1,0) -> 1 | E40: =IFERROR(INDEX(1_Lookups!$C$25:$C$54,MATCH(A40,1_Lookups!$A$25:$A$54,0)),"Not Found") -> Energy | F40: =IF(COUNTIF(1_Lookups!$F$25:F40,1_Lookups!F40)>1,1,0) -> 0 | G40: =IF(EXACT(1_Lookups!G40,A40),0,1) -> 0 | H40: =IF(ISTEXT(1_Lookups!I40),1,0) -> 0 | M40: =3_Returns!B40/3_Returns!B39-1 -> -0.00019972039 | N40: =3_Returns!C40/3_Returns!C39-1 -> 0.005450237 | O40: =3_Returns!D40/3_Returns!D39-1 -> -0.0022963949 | P40: =MAX(3_Returns!$B$31:B40) -> 51.01 | Q40: =3_Returns!B40/P40-1 -> -0.018623799 | R40: =LN(3_Returns!B40/3_Returns!B39) -> -0.00019974034 | S40: =M40-O40 -> 0.0020966745 | T40: =IF(M40>O40,1,0) -> 1 | V40: =4_Screening!C40/4_Screening!D40 -> 2.2965387 | W40: =4_Screening!E40/4_Screening!C40 -> 0.087532003 | X40: =4_Screening!F40/4_Screening!G40 -> 15.25431 | Y40: =RANK(V40,$V$25:$V$74,1) -> 38 | Z40: =RANK(W40,$W$25:$W$74,0) -> 11 | AA40: =RANK(X40,$X$25:$X$74,1) -> 45 | AB40: =AVERAGE(Y40:AA40) -> 31.333333 | AC40: =RANK(AB40,$AB$25:$AB$74,1) -> 34 | AD40: =ROUNDUP(5*AC40/COUNT($AB$25:$AB$74),0) -> 4 | AE40: =IF(4_Screening!E40>0,4_Screening!C40/4_Screening!E40,"") -> 11.424393 | AF40: =MIN(MAX(4_Screening!H40,PERCENTILE(4_Screening!$H$25:$H$74,0.05)),PERCENTILE(4_Screening!$H$25:$H$74,0.95)) -> 0.1886
A41: =UPPER(TRIM(1_Lookups!G41)) -> BRKN | B41: =VALUE(TRIM(1_Lookups!I41)) -> 192.94 | C41: =B41*1_Lookups!J41 -> 694584 | D41: =IF(ISNUMBER(MATCH(A41,1_Lookups!$A$25:$A$54,0)),1,0) -> 1 | E41: =IFERROR(INDEX(1_Lookups!$C$25:$C$54,MATCH(A41,1_Lookups!$A$25:$A$54,0)),"Not Found") -> Financials | F41: =IF(COUNTIF(1_Lookups!$F$25:F41,1_Lookups!F41)>1,1,0) -> 0 | G41: =IF(EXACT(1_Lookups!G41,A41),0,1) -> 0 | H41: =IF(ISTEXT(1_Lookups!I41),1,0) -> 0 | M41: =3_Returns!B41/3_Returns!B40-1 -> -0.029564523 | N41: =3_Returns!C41/3_Returns!C40-1 -> -0.009427292 | O41: =3_Returns!D41/3_Returns!D40-1 -> 0.002408575 | P41: =MAX(3_Returns!$B$31:B41) -> 51.01 | Q41: =3_Returns!B41/P41-1 -> -0.047637718 | R41: =LN(3_Returns!B41/3_Returns!B40) -> -0.030010362 | S41: =M41-O41 -> -0.031973098 | T41: =IF(M41>O41,1,0) -> 0 | V41: =4_Screening!C41/4_Screening!D41 -> 1.4072814 | W41: =4_Screening!E41/4_Screening!C41 -> 0.094709516 | X41: =4_Screening!F41/4_Screening!G41 -> 8.2432432 | Y41: =RANK(V41,$V$25:$V$74,1) -> 17 | Z41: =RANK(W41,$W$25:$W$74,0) -> 9 | AA41: =RANK(X41,$X$25:$X$74,1) -> 20 | AB41: =AVERAGE(Y41:AA41) -> 15.333333 | AC41: =RANK(AB41,$AB$25:$AB$74,1) -> 8 | AD41: =ROUNDUP(5*AC41/COUNT($AB$25:$AB$74),0) -> 1 | AE41: =IF(4_Screening!E41>0,4_Screening!C41/4_Screening!E41,"") -> 10.558601 | AF41: =MIN(MAX(4_Screening!H41,PERCENTILE(4_Screening!$H$25:$H$74,0.05)),PERCENTILE(4_Screening!$H$25:$H$74,0.95)) -> 0.0426
A42: =UPPER(TRIM(1_Lookups!G42)) -> VSTR | B42: =VALUE(TRIM(1_Lookups!I42)) -> 113.22 | C42: =B42*1_Lookups!J42 -> 271728 | D42: =IF(ISNUMBER(MATCH(A42,1_Lookups!$A$25:$A$54,0)),1,0) -> 1 | E42: =IFERROR(INDEX(1_Lookups!$C$25:$C$54,MATCH(A42,1_Lookups!$A$25:$A$54,0)),"Not Found") -> Technology | F42: =IF(COUNTIF(1_Lookups!$F$25:F42,1_Lookups!F42)>1,1,0) -> 0 | G42: =IF(EXACT(1_Lookups!G42,A42),0,1) -> 0 | H42: =IF(ISTEXT(1_Lookups!I42),1,0) -> 0 | M42: =3_Returns!B42/3_Returns!B41-1 -> -0.025319061 | N42: =3_Returns!C42/3_Returns!C41-1 -> 0.0014275517 | O42: =3_Returns!D42/3_Returns!D41-1 -> -0.013376149 | P42: =MAX(3_Returns!$B$31:B42) -> 51.01 | Q42: =3_Returns!B42/P42-1 -> -0.071750637 | R42: =LN(3_Returns!B42/3_Returns!B41) -> -0.025645104 | S42: =M42-O42 -> -0.011942912 | T42: =IF(M42>O42,1,0) -> 0 | V42: =4_Screening!C42/4_Screening!D42 -> 2.1881574 | W42: =4_Screening!E42/4_Screening!C42 -> 0.063913121 | X42: =4_Screening!F42/4_Screening!G42 -> 15.861111 | Y42: =RANK(V42,$V$25:$V$74,1) -> 34 | Z42: =RANK(W42,$W$25:$W$74,0) -> 20 | AA42: =RANK(X42,$X$25:$X$74,1) -> 47 | AB42: =AVERAGE(Y42:AA42) -> 33.666667 | AC42: =RANK(AB42,$AB$25:$AB$74,1) -> 44 | AD42: =ROUNDUP(5*AC42/COUNT($AB$25:$AB$74),0) -> 5 | AE42: =IF(4_Screening!E42>0,4_Screening!C42/4_Screening!E42,"") -> 15.64624 | AF42: =MIN(MAX(4_Screening!H42,PERCENTILE(4_Screening!$H$25:$H$74,0.05)),PERCENTILE(4_Screening!$H$25:$H$74,0.95)) -> 0.03151
A43: =UPPER(TRIM(1_Lookups!G43)) -> OKRA | B43: =VALUE(TRIM(1_Lookups!I43)) -> 33.97 | C43: =B43*1_Lookups!J43 -> 122292 | D43: =IF(ISNUMBER(MATCH(A43,1_Lookups!$A$25:$A$54,0)),1,0) -> 1 | E43: =IFERROR(INDEX(1_Lookups!$C$25:$C$54,MATCH(A43,1_Lookups!$A$25:$A$54,0)),"Not Found") -> Financials | F43: =IF(COUNTIF(1_Lookups!$F$25:F43,1_Lookups!F43)>1,1,0) -> 0 | G43: =IF(EXACT(1_Lookups!G43,A43),0,1) -> 0 | H43: =IF(ISTEXT(1_Lookups!I43),1,0) -> 1 | M43: =3_Returns!B43/3_Returns!B42-1 -> 0.023020063 | N43: =3_Returns!C43/3_Returns!C42-1 -> 0.02328344 | O43: =3_Returns!D43/3_Returns!D42-1 -> 0.016787796 | P43: =MAX(3_Returns!$B$31:B43) -> 51.01 | Q43: =3_Returns!B43/P43-1 -> -0.050382278 | R43: =LN(3_Returns!B43/3_Returns!B42) -> 0.022759099 | S43: =M43-O43 -> 0.0062322677 | T43: =IF(M43>O43,1,0) -> 1 | V43: =4_Screening!C43/4_Screening!D43 -> 1.1610414 | W43: =4_Screening!E43/4_Screening!C43 -> 0.12672559 | X43: =4_Screening!F43/4_Screening!G43 -> 8.888361 | Y43: =RANK(V43,$V$25:$V$74,1) -> 12 | Z43: =RANK(W43,$W$25:$W$74,0) -> 2 | AA43: =RANK(X43,$X$25:$X$74,1) -> 25 | AB43: =AVERAGE(Y43:AA43) -> 13 | AC43: =RANK(AB43,$AB$25:$AB$74,1) -> 2 | AD43: =ROUNDUP(5*AC43/COUNT($AB$25:$AB$74),0) -> 1 | AE43: =IF(4_Screening!E43>0,4_Screening!C43/4_Screening!E43,"") -> 7.8910663 | AF43: =MIN(MAX(4_Screening!H43,PERCENTILE(4_Screening!$H$25:$H$74,0.05)),PERCENTILE(4_Screening!$H$25:$H$74,0.95)) -> 0.1189
... A67: =UPPER(TRIM(1_Lookups!G67)) -> NOVX | B67: =VALUE(TRIM(1_Lookups!I67)) -> 215.18 | C67: =B67*1_Lookups!J67 -> 602504 | D67: =IF(ISNUMBER(MATCH(A67,1_Lookups!$A$25:$A$54,0)),1,0) -> 1 | E67: =IFERROR(INDEX(1_Lookups!$C$25:$C$54,MATCH(A67,1_Lookups!$A$25:$A$54,0)),"Not Found") -> Energy | F67: =IF(COUNTIF(1_Lookups!$F$25:F67,1_Lookups!F67)>1,1,0) -> 1 | G67: =IF(EXACT(1_Lookups!G67,A67),0,1) -> 0 | H67: =IF(ISTEXT(1_Lookups!I67),1,0) -> 0 | M67: =3_Returns!B67/3_Returns!B66-1 -> -0.041117764 | N67: =3_Returns!C67/3_Returns!C66-1 -> -0.017359641 | O67: =3_Returns!D67/3_Returns!D66-1 -> -0.020853805 | P67: =MAX(3_Returns!$B$31:B67) -> 52.89 | Q67: =3_Returns!B67/P67-1 -> -0.091699754 | R67: =LN(3_Returns!B67/3_Returns!B66) -> -0.041987011 | S67: =M67-O67 -> -0.02026396 | T67: =IF(M67>O67,1,0) -> 0 | V67: =4_Screening!C67/4_Screening!D67 -> 1.765873 | W67: =4_Screening!E67/4_Screening!C67 -> -0.066292135 | X67: =4_Screening!F67/4_Screening!G67 -> 8.4637681 | Y67: =RANK(V67,$V$25:$V$74,1) -> 26 | Z67: =RANK(W67,$W$25:$W$74,0) -> 48 | AA67: =RANK(X67,$X$25:$X$74,1) -> 21 | AB67: =AVERAGE(Y67:AA67) -> 31.666667 | AC67: =RANK(AB67,$AB$25:$AB$74,1) -> 36 | AD67: =ROUNDUP(5*AC67/COUNT($AB$25:$AB$74),0) -> 4 | AE67: =IF(4_Screening!E67>0,4_Screening!C67/4_Screening!E67,"") | AF67: =MIN(MAX(4_Screening!H67,PERCENTILE(4_Screening!$H$25:$H$74,0.05)),PERCENTILE(4_Screening!$H$25:$H$74,0.95)) -> 0.1694
M68: =3_Returns!B68/3_Returns!B67-1 -> -0.01602831 | N68: =3_Returns!C68/3_Returns!C67-1 -> -0.020079283 | O68: =3_Returns!D68/3_Returns!D67-1 -> -0.014250764 | P68: =MAX(3_Returns!$B$31:B68) -> 52.89 | Q68: =3_Returns!B68/P68-1 -> -0.10625827 | R68: =LN(3_Returns!B68/3_Returns!B67) -> -0.016158152 | S68: =M68-O68 -> -0.0017775454 | T68: =IF(M68>O68,1,0) -> 0 | V68: =4_Screening!C68/4_Screening!D68 -> 0.80855783 | W68: =4_Screening!E68/4_Screening!C68 -> -0.051263001 | X68: =4_Screening!F68/4_Screening!G68 -> 6.7777778 | Y68: =RANK(V68,$V$25:$V$74,1) -> 4 | Z68: =RANK(W68,$W$25:$W$74,0) -> 46 | AA68: =RANK(X68,$X$25:$X$74,1) -> 7 | AB68: =AVERAGE(Y68:AA68) -> 19 | AC68: =RANK(AB68,$AB$25:$AB$74,1) -> 10 | AD68: =ROUNDUP(5*AC68/COUNT($AB$25:$AB$74),0) -> 1 | AE68: =IF(4_Screening!E68>0,4_Screening!C68/4_Screening!E68,"") | AF68: =MIN(MAX(4_Screening!H68,PERCENTILE(4_Screening!$H$25:$H$74,0.05)),PERCENTILE(4_Screening!$H$25:$H$74,0.95)) -> 0.2568
M69: =3_Returns!B69/3_Returns!B68-1 -> -0.013327692 | N69: =3_Returns!C69/3_Returns!C68-1 -> 0.007035441 | O69: =3_Returns!D69/3_Returns!D68-1 -> -0.0038455727 | P69: =MAX(3_Returns!$B$31:B69) -> 52.89 | Q69: =3_Returns!B69/P69-1 -> -0.11816979 | R69: =LN(3_Returns!B69/3_Returns!B68) -> -0.013417303 | S69: =M69-O69 -> -0.0094821193 | T69: =IF(M69>O69,1,0) -> 0 | V69: =4_Screening!C69/4_Screening!D69 -> 1.5919198 | W69: =4_Screening!E69/4_Screening!C69 -> 0.088333661 | X69: =4_Screening!F69/4_Screening!G69 -> 10.512821 | Y69: =RANK(V69,$V$25:$V$74,1) -> 24 | Z69: =RANK(W69,$W$25:$W$74,0) -> 10 | AA69: =RANK(X69,$X$25:$X$74,1) -> 32 | AB69: =AVERAGE(Y69:AA69) -> 22 | AC69: =RANK(AB69,$AB$25:$AB$74,1) -> 17 | AD69: =ROUNDUP(5*AC69/COUNT($AB$25:$AB$74),0) -> 2 | AE69: =IF(4_Screening!E69>0,4_Screening!C69/4_Screening!E69,"") -> 11.320713 | AF69: =MIN(MAX(4_Screening!H69,PERCENTILE(4_Screening!$H$25:$H$74,0.05)),PERCENTILE(4_Screening!$H$25:$H$74,0.95)) -> 0.1499
M70: =3_Returns!B70/3_Returns!B69-1 -> -0.014150943 | N70: =3_Returns!C70/3_Returns!C69-1 -> 0.0042791023 | O70: =3_Returns!D70/3_Returns!D69-1 -> 0.0018107561 | P70: =MAX(3_Returns!$B$31:B70) -> 52.89 | Q70: =3_Returns!B70/P70-1 -> -0.13064852 | R70: =LN(3_Returns!B70/3_Returns!B69) -> -0.014252023 | S70: =M70-O70 -> -0.015961699 | T70: =IF(M70>O70,1,0) -> 0 | V70: =4_Screening!C70/4_Screening!D70 -> 2.9019984 | W70: =4_Screening!E70/4_Screening!C70 -> 0.041128195 | X70: =4_Screening!F70/4_Screening!G70 -> 7.8341969 | Y70: =RANK(V70,$V$25:$V$74,1) -> 45 | Z70: =RANK(W70,$W$25:$W$74,0) -> 29 | AA70: =RANK(X70,$X$25:$X$74,1) -> 15 | AB70: =AVERAGE(Y70:AA70) -> 29.666667 | AC70: =RANK(AB70,$AB$25:$AB$74,1) -> 31 | AD70: =ROUNDUP(5*AC70/COUNT($AB$25:$AB$74),0) -> 4 | AE70: =IF(4_Screening!E70>0,4_Screening!C70/4_Screening!E70,"") -> 24.31422 | AF70: =MIN(MAX(4_Screening!H70,PERCENTILE(4_Screening!$H$25:$H$74,0.05)),PERCENTILE(4_Screening!$H$25:$H$74,0.95)) -> 0.2152
M71: =3_Returns!B71/3_Returns!B70-1 -> -0.017616355 | N71: =3_Returns!C71/3_Returns!C70-1 -> 0.0096521739 | O71: =3_Returns!D71/3_Returns!D70-1 -> -0.0015538677 | P71: =MAX(3_Returns!$B$31:B71) -> 52.89 | Q71: =3_Returns!B71/P71-1 -> -0.14596332 | R71: =LN(3_Returns!B71/3_Returns!B70) -> -0.01777337 | S71: =M71-O71 -> -0.016062487 | T71: =IF(M71>O71,1,0) -> 0 | V71: =4_Screening!C71/4_Screening!D71 -> 5.9388169 | W71: =4_Screening!E71/4_Screening!C71 -> -0.043528689 | X71: =4_Screening!F71/4_Screening!G71 -> 5.2067511 | Y71: =RANK(V71,$V$25:$V$74,1) -> 49 | Z71: =RANK(W71,$W$25:$W$74,0) -> 45 | AA71: =RANK(X71,$X$25:$X$74,1) -> 2 | AB71: =AVERAGE(Y71:AA71) -> 32 | AC71: =RANK(AB71,$AB$25:$AB$74,1) -> 39 | AD71: =ROUNDUP(5*AC71/COUNT($AB$25:$AB$74),0) -> 4 | AE71: =IF(4_Screening!E71>0,4_Screening!C71/4_Screening!E71,"") | AF71: =MIN(MAX(4_Screening!H71,PERCENTILE(4_Screening!$H$25:$H$74,0.05)),PERCENTILE(4_Screening!$H$25:$H$74,0.95)) -> 0.0581
M72: =3_Returns!B72/3_Returns!B71-1 -> -0.027009077 | N72: =3_Returns!C72/3_Returns!C71-1 -> -0.012057532 | O72: =3_Returns!D72/3_Returns!D71-1 -> -0.017562716 | P72: =MAX(3_Returns!$B$31:B72) -> 52.89 | Q72: =3_Returns!B72/P72-1 -> -0.16903006 | R72: =LN(3_Returns!B72/3_Returns!B71) -> -0.027380526 | S72: =M72-O72 -> -0.009446361 | T72: =IF(M72>O72,1,0) -> 0 | V72: =4_Screening!C72/4_Screening!D72 -> 2.7839228 | W72: =4_Screening!E72/4_Screening!C72 -> 0.078309078 | X72: =4_Screening!F72/4_Screening!G72 -> 6.1197605 | Y72: =RANK(V72,$V$25:$V$74,1) -> 43 | Z72: =RANK(W72,$W$25:$W$74,0) -> 13 | AA72: =RANK(X72,$X$25:$X$74,1) -> 6 | AB72: =AVERAGE(Y72:AA72) -> 20.666667 | AC72: =RANK(AB72,$AB$25:$AB$74,1) -> 15 | AD72: =ROUNDUP(5*AC72/COUNT($AB$25:$AB$74),0) -> 2 | AE72: =IF(4_Screening!E72>0,4_Screening!C72/4_Screening!E72,"") -> 12.769912 | AF72: =MIN(MAX(4_Screening!H72,PERCENTILE(4_Screening!$H$25:$H$74,0.05)),PERCENTILE(4_Screening!$H$25:$H$74,0.95)) -> 0.0325
M73: =3_Returns!B73/3_Returns!B72-1 -> -0.028441411 | N73: =3_Returns!C73/3_Returns!C72-1 -> 0.008281754 | O73: =3_Returns!D73/3_Returns!D72-1 -> -0.0043567772 | P73: =MAX(3_Returns!$B$31:B73) -> 52.89 | Q73: =3_Returns!B73/P73-1 -> -0.19266402 | R73: =LN(3_Returns!B73/3_Returns!B72) -> -0.028853704 | S73: =M73-O73 -> -0.024084633 | T73: =IF(M73>O73,1,0) -> 0 | V73: =4_Screening!C73/4_Screening!D73 -> 2.1449024 | W73: =4_Screening!E73/4_Screening!C73 -> 0.066140777 | X73: =4_Screening!F73/4_Screening!G73 -> 16.767857 | Y73: =RANK(V73,$V$25:$V$74,1) -> 32 | Z73: =RANK(W73,$W$25:$W$74,0) -> 19 | AA73: =RANK(X73,$X$25:$X$74,1) -> 49 | AB73: =AVERAGE(Y73:AA73) -> 33.333333 | AC73: =RANK(AB73,$AB$25:$AB$74,1) -> 41 | AD73: =ROUNDUP(5*AC73/COUNT($AB$25:$AB$74),0) -> 5 | AE73: =IF(4_Screening!E73>0,4_Screening!C73/4_Screening!E73,"") -> 15.119266 | AF73: =MIN(MAX(4_Screening!H73,PERCENTILE(4_Screening!$H$25:$H$74,0.05)),PERCENTILE(4_Screening!$H$25:$H$74,0.95)) -> 0.2299
M74: =3_Returns!B74/3_Returns!B73-1 -> -0.0067915691 | N74: =3_Returns!C74/3_Returns!C73-1 -> 0.014006571 | O74: =3_Returns!D74/3_Returns!D73-1 -> 0.0083640979 | P74: =MAX(3_Returns!$B$31:B74) -> 52.89 | Q74: =3_Returns!B74/P74-1 -> -0.1981471 | R74: =LN(3_Returns!B74/3_Returns!B73) -> -0.0068147367 | S74: =M74-O74 -> -0.015155667 | T74: =IF(M74>O74,1,0) -> 0 | V74: =4_Screening!C74/4_Screening!D74 -> 3.707019 | W74: =4_Screening!E74/4_Screening!C74 -> 0.06163281 | X74: =4_Screening!F74/4_Screening!G74 -> 5.3093923 | Y74: =RANK(V74,$V$25:$V$74,1) -> 47 | Z74: =RANK(W74,$W$25:$W$74,0) -> 22 | AA74: =RANK(X74,$X$25:$X$74,1) -> 3 | AB74: =AVERAGE(Y74:AA74) -> 24 | AC74: =RANK(AB74,$AB$25:$AB$74,1) -> 23 | AD74: =ROUNDUP(5*AC74/COUNT($AB$25:$AB$74),0) -> 3 | AE74: =IF(4_Screening!E74>0,4_Screening!C74/4_Screening!E74,"") -> 16.225124 | AF74: =MIN(MAX(4_Screening!H74,PERCENTILE(4_Screening!$H$25:$H$74,0.05)),PERCENTILE(4_Screening!$H$25:$H$74,0.95)) -> 0.2332
M75: =3_Returns!B75/3_Returns!B74-1 -> -0.013204433 | N75: =3_Returns!C75/3_Returns!C74-1 -> 0.010999318 | O75: =3_Returns!D75/3_Returns!D74-1 -> 0.0059212309 | P75: =MAX(3_Returns!$B$31:B75) -> 52.89 | Q75: =3_Returns!B75/P75-1 -> -0.20873511 | R75: =LN(3_Returns!B75/3_Returns!B74) -> -0.013292387 | S75: =M75-O75 -> -0.019125664 | T75: =IF(M75>O75,1,0) -> 0
M76: =3_Returns!B76/3_Returns!B75-1 -> 0.001911589 | N76: =3_Returns!C76/3_Returns!C75-1 -> 0.0045542717 | O76: =3_Returns!D76/3_Returns!D75-1 -> -0.00047763521 | P76: =MAX(3_Returns!$B$31:B76) -> 52.89 | Q76: =3_Returns!B76/P76-1 -> -0.20722254 | R76: =LN(3_Returns!B76/3_Returns!B75) -> 0.0019097642 | S76: =M76-O76 -> 0.0023892242 | T76: =IF(M76>O76,1,0) -> 1
...

Sheet 3_Returns
A1: 3 · Returns, Risk & Performance Math
A2: ~2 years of daily closes for two stocks and a benchmark. Build return columns to the right (E onward), then answer.
A4: # | B4: Task | H4: Your Answer | I4: Check | J4: Hint (functions to use)
A5: R1 | B5: Total (cumulative) return of Stock A over the full period. | I5: =IF(H5="","",IFERROR(IF(ISNUMBER('Answer Key'!$D$32),IF(ABS(H5-'Answer Key'!$D$32)<=MAX(0.0001,ABS('Answer Key'!$D$32)*0.001),"✓ Correct","✗ Try again"),IF(TRIM(H5)=TRIM('Answer Key'!$D$32),"✓ Correct","✗ Try again")),"✗ Try again")) | J5: last / first − 1
A6: R2 | B6: Total return of Stock B — compute it by compounding daily returns: PRODUCT(1+r)−1. Confirm it equals last/first−1. | I6: =IF(H6="","",IFERROR(IF(ISNUMBER('Answer Key'!$D$33),IF(ABS(H6-'Answer Key'!$D$33)<=MAX(0.0001,ABS('Answer Key'!$D$33)*0.001),"✓ Correct","✗ Try again"),IF(TRIM(H6)=TRIM('Answer Key'!$D$33),"✓ Correct","✗ Try again")),"✗ Try again")) | J6: Daily return column, then PRODUCT(1+range)-1 (Ctrl+Shift+Enter in old Excel)
A7: R3 | B7: Annualized return (CAGR) of Stock A. Use 252 trading days/yr and N = number of daily return observations. | I7: =IF(H7="","",IFERROR(IF(ISNUMBER('Answer Key'!$D$34),IF(ABS(H7-'Answer Key'!$D$34)<=MAX(0.0001,ABS('Answer Key'!$D$34)*0.001),"✓ Correct","✗ Try again"),IF(TRIM(H7)=TRIM('Answer Key'!$D$34),"✓ Correct","✗ Try again")),"✗ Try again")) | J7: (1+cum)^(252/N) − 1; N = COUNT(returns)
A8: R4 | B8: Annualized volatility of Stock A (sample std dev of daily returns). | I8: =IF(H8="","",IFERROR(IF(ISNUMBER('Answer Key'!$D$35),IF(ABS(H8-'Answer Key'!$D$35)<=MAX(0.0001,ABS('Answer Key'!$D$35)*0.001),"✓ Correct","✗ Try again"),IF(TRIM(H8)=TRIM('Answer Key'!$D$35),"✓ Correct","✗ Try again")),"✗ Try again")) | J8: STDEV.S × SQRT(252)
A9: R5 | B9: Sharpe ratio of Stock A = (AVERAGE(daily r)×252 − rf) ÷ annualized vol. | I9: =IF(H9="","",IFERROR(IF(ISNUMBER('Answer Key'!$D$36),IF(ABS(H9-'Answer Key'!$D$36)<=MAX(0.0001,ABS('Answer Key'!$D$36)*0.001),"✓ Correct","✗ Try again"),IF(TRIM(H9)=TRIM('Answer Key'!$D$36),"✓ Correct","✗ Try again")),"✗ Try again")) | J9: Arithmetic annualized mean; rf in G
