Workbook
Name IQ_CH: 110000
Name IQ_CQ: 5000
Name IQ_CY: 10000
Name IQ_DAILY: 500000
Name IQ_FH: 100000
Name IQ_FQ: 500
Name IQ_FY: 1000
Name IQ_LTM: 2000
Name IQ_MONTH: 15000
Name IQ_NTM: 6000
Name IQ_WEEK: 50000
Name IQ_YTD: 3000

Sheet Summary 2025
A1: 2025 Theatrical Releases
A2: Title | B2: Parent Company | C2: Release Date | D2: Release Quarter | E2: Release Type
A3: ='2025'!A2 -> From Ground Zero | B3: ='2025'!C2 -> Independent / Other | C3: ='2025'!D2 -> 45660 | D3: ='2025'!H2 -> Q1 2025 | E3: ='2025'!I2 -> Limited
A4: ='2025'!A3 -> Georgia O’Keeffe: The Brightness of Light | B4: ='2025'!C3 -> Independent / Other | C4: ='2025'!D3 -> 45660 | D4: ='2025'!H3 -> Q1 2025 | E4: ='2025'!I3 -> Limited
A5: ='2025'!A5 -> The Damned | B5: ='2025'!C5 -> Independent / Other | C5: ='2025'!D4 -> 45660 | D5: ='2025'!H5 -> Q1 2025 | E5: ='2025'!I5 -> Wide
A6: ='2025'!A6 -> The Last Republican | B6: ='2025'!C6 -> Independent / Other | C6: ='2025'!D5 -> 45660 | D6: ='2025'!H6 -> Q1 2025 | E6: ='2025'!I6 -> Limited
A7: ='2025'!A7 -> The Monster Beneath Us | B7: ='2025'!C7 -> Independent / Other | C7: ='2025'!D6 -> 45660 | D7: ='2025'!H7 -> Q1 2025 | E7: ='2025'!I7 -> Limited
A8: ='2025'!A9 -> Better Man | B8: ='2025'!C9 -> Paramount | C8: ='2025'!D7 -> 45660 | D8: ='2025'!H9 -> Q1 2025 | E8: ='2025'!I9 -> Wide
A9: ='2025'!A10 -> Birdeater | B9: ='2025'!C10 -> Independent / Other | C9: ='2025'!D8 -> 45665 | D9: ='2025'!H10 -> Q1 2025 | E9: ='2025'!I10 -> Limited
A10: ='2025'!A11 -> Black Diamond | B10: ='2025'!C11 -> Independent / Other | C10: ='2025'!D9 -> 45667 | D10: ='2025'!H11 -> Q1 2025 | E10: ='2025'!I11 -> Limited
A11: ='2025'!A12 -> Black Zone | B11: ='2025'!C12 -> Independent / Other | C11: ='2025'!D10 -> 45667 | D11: ='2025'!H12 -> Q1 2025 | E11: ='2025'!I12 -> Limited
A12: ='2025'!A13 -> Den of Thieves 2: Pantera | B12: ='2025'!C13 -> Lionsgate | C12: ='2025'!D11 -> 45667 | D12: ='2025'!H13 -> Q1 2025 | E12: ='2025'!I13 -> Wide
A13: ='2025'!A14 -> Diane Warren: Relentless | B13: ='2025'!C14 -> Independent / Other | C13: ='2025'!D12 -> 45667 | D13: ='2025'!H14 -> Q1 2025 | E13: ='2025'!I14 -> Limited
A14: ='2025'!A15 -> Eat the Night | B14: ='2025'!C15 -> Independent / Other | C14: ='2025'!D13 -> 45667 | D14: ='2025'!H15 -> Q1 2025 | E14: ='2025'!I15 -> Limited
A15: ='2025'!A16 -> Every Little Thing | B15: ='2025'!C16 -> Independent / Other | C15: ='2025'!D14 -> 45667 | D15: ='2025'!H16 -> Q1 2025 | E15: ='2025'!I16 -> Limited
A16: ='2025'!A17 -> Extremely Unique Dynamic | B16: ='2025'!C17 -> Independent / Other | C16: ='2025'!D15 -> 45667 | D16: ='2025'!H17 -> Q1 2025 | E16: ='2025'!I17 -> Limited
A17: ='2025'!A18 -> Finist: The First Warrior | B17: ='2025'!C18 -> Independent / Other | C17: ='2025'!D16 -> 45667 | D17: ='2025'!H18 -> Q1 2025 | E17: ='2025'!I18 -> Limited
A18: ='2025'!A19 -> Game Changer | B18: ='2025'!C19 -> Independent / Other | C18: ='2025'!D17 -> 45667 | D18: ='2025'!H19 -> Q1 2025 | E18: ='2025'!I19 -> Wide
A19: ='2025'!A20 -> Hard Truths | B19: ='2025'!C20 -> Bleecker Street | C19: ='2025'!D18 -> 45667 | D19: ='2025'!H20 -> Q1 2025 | E19: ='2025'!I20 -> Limited
... A34: ='2025'!A35 -> Savor | B34: ='2025'!C35 -> Independent / Other | C34: ='2025'!D33 -> 45667 | D34: ='2025'!H35 -> Q1 2025 | E34: ='2025'!I35 -> Limited
A35: ='2025'!A37 -> Daaku Maharaaj | B35: ='2025'!C37 -> Independent / Other | C35: ='2025'!D34 -> 45667 | D35: ='2025'!H37 -> Q1 2025 | E35: ='2025'!I37 -> Limited
A36: ='2025'!A38 -> Peter Pan’s Neverland Nightmare | B36: ='2025'!C38 -> Independent / Other | C36: ='2025'!D35 -> 45668 | D36: ='2025'!H38 -> Q1 2025 | E36: ='2025'!I38 -> Wide
A37: ='2025'!A39 -> Kadhalikka Neramillai | B37: ='2025'!C39 -> Independent / Other | C37: ='2025'!D36 -> 45668 | D37: ='2025'!H39 -> Q1 2025 | E37: ='2025'!I39 -> Limited
A38: ='2025'!A40 -> Pay Dirt: The Story of Supercross | B38: ='2025'!C40 -> Independent / Other | C38: ='2025'!D37 -> 45669 | D38: ='2025'!H40 -> Q1 2025 | E38: ='2025'!I40 -> Limited
A39: ='2025'!A41 -> Sankrathiki Vasthunam | B39: ='2025'!C41 -> Independent / Other | C39: ='2025'!D38 -> 45670 | D39: ='2025'!H41 -> Q1 2025 | E39: ='2025'!I41 -> Limited
A40: ='2025'!A42 -> Praavinkoodu Shappu | B40: ='2025'!C42 -> Independent / Other | C40: ='2025'!D39 -> 45671 | D40: ='2025'!H42 -> Q1 2025 | E40: ='2025'!I42 -> Limited
A41: ='2025'!A43 -> Alarum | B41: ='2025'!C43 -> Lionsgate | C41: ='2025'!D40 -> 45671 | D41: ='2025'!H43 -> Q1 2025 | E41: ='2025'!I43 -> Limited
A42: ='2025'!A44 -> Autumn and the Black Jaguar | B42: ='2025'!C44 -> Independent / Other | C42: ='2025'!D41 -> 45671 | D42: ='2025'!H44 -> Q1 2025 | E42: ='2025'!I44 -> Limited
A43: ='2025'!A45 -> Azaad | B43: ='2025'!C45 -> Independent / Other | C43: ='2025'!D42 -> 45673 | D43: ='2025'!H45 -> Q1 2025 | E43: ='2025'!I45 -> Limited
A44: ='2025'!A46 -> Both Eyes Open | B44: ='2025'!C46 -> IFC | C44: ='2025'!D43 -> 45674 | D44: ='2025'!H46 -> Q1 2025 | E44: ='2025'!I46 -> Limited
A45: ='2025'!A47 -> DIG! XX | B45: ='2025'!C47 -> Independent / Other | C45: ='2025'!D44 -> 45674 | D45: ='2025'!H47 -> Q1 2025 | E45: ='2025'!I47 -> Limited
A46: ='2025'!A48 -> El Heredero | B46: ='2025'!C48 -> Independent / Other | C46: ='2025'!D45 -> 45674 | D46: ='2025'!H48 -> Q1 2025 | E46: ='2025'!I48 -> Limited
A47: ='2025'!A49 -> Emergency | B47: ='2025'!C49 -> Independent / Other | C47: ='2025'!D46 -> 45674 | D47: ='2025'!H49 -> Q1 2025 | E47: ='2025'!I49 -> Limited
A48: ='2025'!A51 -> Grand Theft Hamlet | B48: ='2025'!C51 -> Independent / Other | C48: ='2025'!D47 -> 45674 | D48: ='2025'!H51 -> Q1 2025 | E48: ='2025'!I51 -> Limited
A49: ='2025'!A52 -> Hold Me Close | B49: ='2025'!C52 -> Independent / Other | C49: ='2025'!D48 -> 45674 | D49: ='2025'!H52 -> Q1 2025 | E49: ='2025'!I52 -> Limited
A50: ='2025'!A53 -> I’m Still Here | B50: ='2025'!C53 -> Sony | C50: ='2025'!D49 -> 45674 | D50: ='2025'!H53 -> Q1 2025 | E50: ='2025'!I53 -> Wide
A51: ='2025'!A54 -> Left Behind | B51: ='2025'!C54 -> Independent / Other | C51: ='2025'!D50 -> 45674 | D51: ='2025'!H54 -> Q1 2025 | E51: ='2025'!I54 -> Limited
A52: ='2025'!A55 -> Night Call | B52: ='2025'!C55 -> Independent / Other | C52: ='2025'!D51 -> 45674 | D52: ='2025'!H55 -> Q1 2025 | E52: ='2025'!I55 -> Limited
A53: ='2025'!A56 -> One of Them Days | B53: ='2025'!C56 -> Sony | C53: ='2025'!D52 -> 45674 | D53: ='2025'!H56 -> Q1 2025 | E53: ='2025'!I56 -> Wide
A54: ='2025'!A57 -> Sing Sing | B54: ='2025'!C57 -> A24 | C54: ='2025'!D53 -> 45674 | D54: ='2025'!H57 -> Q1 2025 | E54: ='2025'!I57 -> Limited
...

Sheet Summary 2026
A1: 2026 Releases
A2: Title | B2: Parent Company | C2: Release Date | D2: Release Quarter | E2: Release Type
A3: ='2026'!A2 -> Ikkis | B3: ='2026'!C2 -> Independent / Other | C3: ='2026'!D2 -> 46023 | D3: ='2026'!H2 -> Q1 2026 | E3: ='2026'!I2 -> Limited
A4: ='2026'!A3 -> Patang | B4: ='2026'!C3 -> Unknown | C4: ='2026'!D3 -> 46023 | D4: ='2026'!H3 -> Q1 2026 | E4: ='2026'!I3 -> Limited
A5: ='2026'!A4 -> KIDZ BOP LIVE: The Concert Movie | B5: ='2026'!C4 -> Independent / Other | C5: ='2026'!D4 -> 46024 | D5: ='2026'!H4 -> Q1 2026 | E5: ='2026'!I4 -> Limited
A6: ='2026'!A5 -> The Dutchman | B6: ='2026'!C5 -> Independent / Other | C6: ='2026'!D5 -> 46024 | D6: ='2026'!H5 -> Q1 2026 | E6: ='2026'!I5 -> Limited
A7: ='2026'!A6 -> We Bury the Dead | B7: ='2026'!C6 -> Independent / Other | C7: ='2026'!D6 -> 46024 | D7: ='2026'!H6 -> Q1 2026 | E7: ='2026'!I6 -> Limited
A8: ='2026'!A7 -> Lupin the IIIRD: The Movie — The Immortal Bloodline | B8: ='2026'!C7 -> Independent / Other | C8: ='2026'!D7 -> 46026 | D8: ='2026'!H7 -> Q1 2026 | E8: ='2026'!I7 -> Limited
A9: ='2026'!A8 -> Weathered: Inside the LA Firestorm | B9: ='2026'!C8 -> Independent / Other | C9: ='2026'!D8 -> 46029 | D9: ='2026'!H8 -> Q1 2026 | E9: ='2026'!I8 -> Limited
A10: ='2026'!A10 -> The Raja Saab | B10: ='2026'!C10 -> Independent / Other | C10: ='2026'!D9 -> 46030 | D10: ='2026'!H10 -> Q1 2026 | E10: ='2026'!I10 -> Wide
A11: ='2026'!A11 -> 31 Candles | B11: ='2026'!C11 -> Independent / Other | C11: ='2026'!D10 -> 46030 | D11: ='2026'!H11 -> Q1 2026 | E11: ='2026'!I11 -> Limited
A12: ='2026'!A12 -> All That’s Left Of You | B12: ='2026'!C12 -> Independent / Other | C12: ='2026'!D11 -> 46031 | D12: ='2026'!H12 -> Q1 2026 | E12: ='2026'!I12 -> Limited
A13: ='2026'!A13 -> Bulls | B13: ='2026'!C13 -> Independent / Other | C13: ='2026'!D12 -> 46031 | D13: ='2026'!H13 -> Q1 2026 | E13: ='2026'!I13 -> Limited
A14: ='2026'!A14 -> Buratino | B14: ='2026'!C14 -> Unknown | C14: ='2026'!D13 -> 46031 | D14: ='2026'!H14 -> Q1 2026 | E14: ='2026'!I14 -> Limited
A15: ='2026'!A15 -> Dead Man’s Wire | B15: ='2026'!C15 -> Independent / Other | C15: ='2026'!D14 -> 46031 | D15: ='2026'!H15 -> Q1 2026 | E15: ='2026'!I15 -> Wide
A16: ='2026'!A16 -> Greenland 2: Migration | B16: ='2026'!C16 -> Lionsgate | C16: ='2026'!D15 -> 46031 | D16: ='2026'!H16 -> Q1 2026 | E16: ='2026'!I16 -> Wide
A17: ='2026'!A17 -> Holding Liat | B17: ='2026'!C17 -> Independent / Other | C17: ='2026'!D16 -> 46031 | D17: ='2026'!H17 -> Q1 2026 | E17: ='2026'!I17 -> Limited
A18: ='2026'!A18 -> I Was a Stranger | B18: ='2026'!C18 -> Angel Studios | C18: ='2026'!D17 -> 46031 | D18: ='2026'!H18 -> Q1 2026 | E18: ='2026'!I18 -> Wide
A19: ='2026'!A19 -> Is This Thing On? | B19: ='2026'!C19 -> Disney | C19: ='2026'!D18 -> 46031 | D19: ='2026'!H19 -> Q1 2026 | E19: ='2026'!I19 -> Wide
A20: ='2026'!A20 -> Magellan | B20: ='2026'!C20 -> Independent / Other | C20: ='2026'!D19 -> 46031 | D20: ='2026'!H20 -> Q1 2026 | E20: ='2026'!I20 -> Limited
A21: ='2026'!A21 -> My Neighbor Adolf | B21: ='2026'!C21 -> Independent / Other | C21: ='2026'!D20 -> 46031 | D21: ='2026'!H21 -> Q1 2026 | E21: ='2026'!I21 -> Limited
... A23: ='2026'!A23 -> Oscar Shaw | B23: ='2026'!C23 -> Independent / Other | C23: ='2026'!D22 -> 46031 | D23: ='2026'!H23 -> Q1 2026 | E23: ='2026'!I23 -> Limited
A24: ='2026'!A25 -> Primate | B24: ='2026'!C25 -> Paramount | C24: ='2026'!D23 -> 46031 | D24: ='2026'!H25 -> Q1 2026 | E24: ='2026'!I25 -> Wide
A25: ='2026'!A26 -> Sleepwalker | B25: ='2026'!C26 -> Independent / Other | C25: ='2026'!D24 -> 46031 | D25: ='2026'!H26 -> Q1 2026 | E25: ='2026'!I26 -> Limited
A26: ='2026'!A27 -> The Voice of Hind Rajab | B26: ='2026'!C27 -> Independent / Other | C26: ='2026'!D25 -> 46031 | D26: ='2026'!H27 -> Q1 2026 | E26: ='2026'!I27 -> Limited
A27: ='2026'!A28 -> Young Mothers | B27: ='2026'!C28 -> Independent / Other | C27: ='2026'!D26 -> 46031 | D27: ='2026'!H28 -> Q1 2026 | E27: ='2026'!I28 -> Limited
A28: ='2026'!A29 -> Mana ShankaraVaraprasad Garu | B28: ='2026'!C29 -> Independent / Other | C28: ='2026'!D27 -> 46031 | D28: ='2026'!H29 -> Q1 2026 | E28: ='2026'!I29 -> Limited
A29: ='2026'!A30 -> Godfrey: Rebel with a Cause | B29: ='2026'!C30 -> Independent / Other | C29: ='2026'!D28 -> 46031 | D29: ='2026'!H30 -> Q1 2026 | E29: ='2026'!I30 -> Limited
A30: ='2026'!A31 -> Nari Nari Naduma Murari | B30: ='2026'!C31 -> Independent / Other | C30: ='2026'!D29 -> 46034 | D30: ='2026'!H31 -> Q1 2026 | E30: ='2026'!I31 -> Limited
A31: ='2026'!A32 -> Once Upon My Mother | B31: ='2026'!C32 -> Unknown | C31: ='2026'!D30 -> 46036 | D31: ='2026'!H32 -> Q1 2026 | E31: ='2026'!I32 -> Limited
A32: ='2026'!A33 -> TTT: Thalaivar Thambi Thalamaiyil | B32: ='2026'!C33 -> Independent / Other | C32: ='2026'!D31 -> 46036 | D32: ='2026'!H33 -> Q1 2026 | E32: ='2026'!I33 -> Limited
A33: ='2026'!A34 -> 28 Years Later: The Bone Temple | B33: ='2026'!C34 -> Sony | C33: ='2026'!D32 -> 46036 | D33: ='2026'!H34 -> Q1 2026 | E33: ='2026'!I34 -> Wide
A34: ='2026'!A35 -> A Private Life | B34: ='2026'!C35 -> Sony | C34: ='2026'!D33 -> 46037 | D34: ='2026'!H35 -> Q1 2026 | E34: ='2026'!I35 -> Limited
A35: ='2026'!A36 -> A Useful Ghost | B35: ='2026'!C36 -> Independent / Other | C35: ='2026'!D34 -> 46038 | D35: ='2026'!H36 -> Q1 2026 | E35: ='2026'!I36 -> Limited
... A42: ='2026'!A43 -> Leave | B42: ='2026'!C43 -> Independent / Other | C42: ='2026'!D41 -> 46038 | D42: ='2026'!H43 -> Q1 2026 | E42: ='2026'!I43 -> Limited
A43: ='2026'!A45 -> Night Patrol | B43: ='2026'!C45 -> IFC | C43: ='2026'!D42 -> 46038 | D43: ='2026'!H45 -> Q1 2026 | E43: ='2026'!I45 -> Wide
A44: ='2026'!A46 -> No Other Choice | B44: ='2026'!C46 -> Neon | C44: ='2026'!D43 -> 46038 | D44: ='2026'!H46 -> Q1 2026 | E44: ='2026'!I46 -> Wide
A45: ='2026'!A48 -> Shuffle | B45: ='2026'!C48 -> Independent / Other | C45: ='2026'!D44 -> 46038 | D45: ='2026'!H48 -> Q1 2026 | E45: ='2026'!I48 -> Limited
A46: ='2026'!A49 -> Signing Tony Raymond | B46: ='2026'!C49 -> Independent / Other | C46: ='2026'!D45 -> 46038 | D46: ='2026'!H49 -> Q1 2026 | E46: ='2026'!I49 -> Limited
A47: ='2026'!A50 -> Sound of Falling | B47: ='2026'!C50 -> Unknown | C47: ='2026'!D46 -> 46038 | D47: ='2026'!H50 -> Q1 2026 | E47: ='2026'!I50 -> Limited
...

Sheet Summary 2027
A1: 2027 Releases
A2: Title | B2: Parent Company | C2: Release Date | D2: Release Quarter | E2: Release Type
A3: ='2027'!A2 -> Bagworm | B3: ='2027'!C2 -> Independent / Other | C3: ='2027'!D2 -> 46388 | D3: ='2027'!H2 -> Q1 2027 | E3: ='2027'!I2 -> Limited
A4: ='2027'!A3 -> Pendulum | B4: ='2027'!C3 -> Independent / Other | C4: ='2027'!D3 -> 46388 | D4: ='2027'!H3 -> Q1 2027 | E4: ='2027'!I3 -> Wide
A5: ='2027'!A4 -> The Meltdown | B5: ='2027'!C4 -> Independent / Other | C5: ='2027'!D4 -> 46388 | D5: ='2027'!H4 -> Q1 2027 | E5: ='2027'!I4 -> Limited
A6: ='2027'!A5 -> Untitled Shudder Horror Film | B6: ='2027'!C5 -> Independent / Other | C6: ='2027'!D5 -> 46395 | D6: ='2027'!H5 -> Q1 2027 | E6: ='2027'!I5 -> Limited
A7: ='2027'!A6 -> Children of Blood and Bone | B7: ='2027'!C6 -> Paramount | C7: ='2027'!D6 -> 46402 | D7: ='2027'!H6 -> Q1 2027 | E7: ='2027'!I6 -> Wide
A8: ='2027'!A7 -> The Beekeeper 2 | B8: ='2027'!C7 -> Amazon | C8: ='2027'!D7 -> 46402 | D8: ='2027'!H7 -> Q1 2027 | E8: ='2027'!I7 -> Wide
A9: ='2027'!A8 -> Untitled Blumhouse Event Film | B9: ='2027'!C8 -> Universal / NBCU | C9: ='2027'!D8 -> 46402 | D9: ='2027'!H8 -> Q1 2027 | E9: ='2027'!I8 -> Wide
A10: ='2027'!A9 -> Air Bud Returns | B10: ='2027'!C9 -> Independent / Other | C10: ='2027'!D9 -> 46409 | D10: ='2027'!H9 -> Q1 2027 | E10: ='2027'!I9 -> Wide
A11: ='2027'!A10 -> Animal Friends | B11: ='2027'!C10 -> Warner Bros. Discovery | C11: ='2027'!D10 -> 46409 | D11: ='2027'!H10 -> Q1 2027 | E11: ='2027'!I10 -> Wide
A12: ='2027'!A11 -> The Third Parent | B12: ='2027'!C11 -> Bleecker Street | C12: ='2027'!D11 -> 46409 | D12: ='2027'!H11 -> Q1 2027 | E12: ='2027'!I11 -> Wide
A13: ='2027'!A12 -> Drag | B13: ='2027'!C12 -> Independent / Other | C13: ='2027'!D12 -> 46416 | D13: ='2027'!H12 -> Q1 2027 | E13: ='2027'!I12 -> Wide
A14: ='2027'!A13 -> Karoshi | B14: ='2027'!C13 -> Lionsgate | C14: ='2027'!D13 -> 46416 | D14: ='2027'!H13 -> Q1 2027 | E14: ='2027'!I13 -> Wide
... A23: ='2027'!A22 -> CoComelon: The Movie | B23: ='2027'!C22 -> Universal / NBCU | C23: ='2027'!D22 -> 46437 | D23: ='2027'!H22 -> Q1 2027 | E23: ='2027'!I22 -> Wide
A24: ='2027'!A24 -> Untitled Neon Horror Film | B24: ='2027'!C24 -> Neon | C24: ='2027'!D23 -> 46437 | D24: ='2027'!H24 -> Q1 2027 | E24: ='2027'!I24 -> Wide
A25: ='2027'!A25 -> Wife & Dog | B25: ='2027'!C25 -> Independent / Other | C25: ='2027'!D24 -> 46437 | D25: ='2027'!H25 -> Q1 2027 | E25: ='2027'!I25 -> Wide
A26: ='2027'!A26 -> K-Pop: The Debut | B26: ='2027'!C26 -> Paramount | C26: ='2027'!D25 -> 46437 | D26: ='2027'!H26 -> Q1 2027 | E26: ='2027'!I26 -> Wide
A27: ='2027'!A27 -> Live Like That | B27: ='2027'!C27 -> Sony | C27: ='2027'!D26 -> 46444 | D27: ='2027'!H27 -> Q1 2027 | E27: ='2027'!I27 -> Wide
A28: ='2027'!A28 -> The Revenge of La Llorona | B28: ='2027'!C28 -> Warner Bros. Discovery | C28: ='2027'!D27 -> 46444 | D28: ='2027'!H28 -> Q1 2027 | E28: ='2027'!I28 -> Wide
A29: ='2027'!A29 -> Gatto | B29: ='2027'!C29 -> Disney | C29: ='2027'!D28 -> 46444 | D29: ='2027'!H29 -> Q1 2027 | E29: ='2027'!I29 -> Wide
A30: ='2027'!A30 -> The Thomas Crown Affair | B30: ='2027'!C30 -> Amazon | C30: ='2027'!D29 -> 46451 | D30: ='2027'!H30 -> Q1 2027 | E30: ='2027'!I30 -> Wide
A31: ='2027'!A31 -> Untitled DC Event Film | B31: ='2027'!C31 -> Warner Bros. Discovery | C31: ='2027'!D30 -> 46451 | D31: ='2027'!H31 -> Q1 2027 | E31: ='2027'!I31 -> Wide
A32: ='2027'!A32 -> Untitled Mike Flanagan Exorcist Film | B32: ='2027'!C32 -> Universal / NBCU | C32: ='2027'!D31 -> 46451 | D32: ='2027'!H32 -> Q1 2027 | E32: ='2027'!I32 -> Wide
A33: ='2027'!A33 -> Untitled The Chosen Season 6 Finale Film | B33: ='2027'!C33 -> Amazon | C33: ='2027'!D32 -> 46458 | D33: ='2027'!H33 -> Q1 2027 | E33: ='2027'!I33 -> Wide
A34: ='2027'!A34 -> Untitled Warner Bros. Event Film | B34: ='2027'!C34 -> Warner Bros. Discovery | C34: ='2027'!D33 -> 46458 | D34: ='2027'!H34 -> Q1 2027 | E34: ='2027'!I34 -> Wide
A35: ='2027'!A35 -> Sonic the Hedgehog 4 | B35: ='2027'!C35 -> Paramount | C35: ='2027'!D34 -> 46458 | D35: ='2027'!H35 -> Q1 2027 | E35: ='2027'!I35 -> Wide
... A107: ='2027'!A107 -> Zac Power | B107: ='2027'!C107 -> Independent / Other | C107: ='2027'!D106 -> 46752 | D107: ='2027'!H107 -> TBD 2027 | E107: ='2027'!I107 -> Wide

Sheet Data ->

Sheet 2025
A1: Title | B1: Distributor | C1: Parent Company | D1: Release Date | E1: Date Precision | F1: Date (as sourced) | G1: Wide Expansion Date | H1: Release Quarter | I1: Release Type | J1: Is Re-release | K1: Is IMAX | L1: Domestic BO (Lifetime) | M1: BO Caveat | N1: Is Canceled | O1: Is Catalog Aggregate | P1: Dup BO Flag | Q1: Merge Span (days) | R1: In Scope
A2: From Ground Zero | B2: Watermelon Pictures | C2: Independent / Other | D2: 45660 | E2: exact | F2: 2025-01-03 | H2: Q1 2025 | I2: Limited | J2: FALSE | K2: FALSE | L2: 330188 | N2: FALSE | O2: FALSE | P2: FALSE | Q2: 0 | R2: FALSE
A3: Georgia O’Keeffe: The Brightness of Light | B3: Cargo Film & Releasing | C3: Independent / Other | D3: 45660 | E3: exact | F3: 2025-01-03 | H3: Q1 2025 | I3: Limited | J3: FALSE | K3: FALSE | L3: 166349 | N3: FALSE | O3: FALSE | P3: FALSE | Q3: 0 | R3: FALSE
A4: Se7en | B4: Warner Bros. | C4: Warner Bros. Discovery | D4: 45660 | E4: exact | F4: 2025-01-03 | H4: Q1 2025 | I4: Special Engagement | J4: TRUE | K4: TRUE | L4: 101871174 | M4: Lifetime gross incl. original run - not 2025 revenue | N4: FALSE | O4: FALSE | P4: FALSE | Q4: 0 | R4: TRUE
A5: The Damned | B5: Vertical Entertainment | C5: Independent / Other | D5: 45660 | E5: exact | F5: 2025-01-03 | H5: Q1 2025 | I5: Wide | J5: FALSE | K5: FALSE | L5: 1342796 | N5: FALSE | O5: FALSE | P5: FALSE | Q5: 0 | R5: FALSE
A6: The Last Republican | B6: Media Courthouse Documentary Collective | C6: Independent / Other | D6: 45660 | E6: exact | F6: 2025-01-03 | H6: Q1 2025 | I6: Limited | J6: FALSE | K6: FALSE | N6: FALSE | O6: FALSE | P6: FALSE | Q6: 0 | R6: FALSE
A7: The Monster Beneath Us | B7: Vertical Entertainment | C7: Independent / Other | D7: 45660 | E7: exact | F7: 2025-01-03 | H7: Q1 2025 | I7: Limited | J7: FALSE | K7: FALSE | N7: FALSE | O7: FALSE | P7: FALSE | Q7: 0 | R7: FALSE
A8: AXCN: Paprika | B8: Iconic Releasing | C8: Independent / Other | D8: 45665 | E8: exact | F8: 2025-01-08 | H8: Q1 2025 | I8: Special Engagement | J8: TRUE | K8: FALSE | L8: 881302 | M8: Lifetime gross incl. original run - not 2025 revenue | N8: FALSE | O8: FALSE | P8: FALSE | Q8: 0 | R8: FALSE
A9: Better Man | B9: Paramount Pictures | C9: Paramount | D9: 45667 | E9: exact | F9: 2025-01-10 | H9: Q1 2025 | I9: Wide | J9: FALSE | K9: FALSE | L9: 1983648 | N9: FALSE | O9: FALSE | P9: FALSE | Q9: 0 | R9: TRUE
A10: Birdeater | B10: Dark Sky Films | C10: Independent / Other | D10: 45667 | E10: exact | F10: 2025-01-10 | H10: Q1 2025 | I10: Limited | J10: FALSE | K10: FALSE | N10: FALSE | O10: FALSE | P10: FALSE | Q10: 0 | R10: FALSE
A11: Black Diamond | B11: Brainstorm Media | C11: Independent / Other | D11: 45667 | E11: exact | F11: 2025-01-10 | H11: Q1 2025 | I11: Limited | J11: FALSE | K11: FALSE | N11: FALSE | O11: FALSE | P11: FALSE | Q11: 0 | R11: FALSE
A12: Black Zone | B12: Black Zone Productions | C12: Independent / Other | D12: 45667 | E12: exact | F12: 2025-01-10 | H12: Q1 2025 | I12: Limited | J12: FALSE | K12: FALSE | N12: FALSE | O12: FALSE | P12: FALSE | Q12: 0 | R12: FALSE
A13: Den of Thieves 2: Pantera | B13: Lionsgate | C13: Lionsgate | D13: 45667 | E13: exact | F13: 2025-01-10 | H13: Q1 2025 | I13: Wide | J13: FALSE | K13: FALSE | L13: 36015016 | N13: FALSE | O13: FALSE | P13: FALSE | Q13: 0 | R13: TRUE
A14: Diane Warren: Relentless | B14: Greenwich | C14: Independent / Other | D14: 45667 | E14: exact | F14: 2025-01-10 | H14: Q1 2025 | I14: Limited | J14: FALSE | K14: FALSE | N14: FALSE | O14: FALSE | P14: FALSE | Q14: 0 | R14: FALSE
A15: Eat the Night | B15: Altered Innocence | C15: Independent / Other | D15: 45667 | E15: exact | F15: 2025-01-10 | H15: Q1 2025 | I15: Limited | J15: FALSE | K15: FALSE | N15: FALSE | O15: FALSE | P15: FALSE | Q15: 0 | R15: FALSE
A16: Every Little Thing | B16: Kino Lorber | C16: Independent / Other | D16: 45667 | E16: exact | F16: 2025-01-10 | H16: Q1 2025 | I16: Limited | J16: FALSE | K16: FALSE | L16: 200679 | N16: FALSE | O16: FALSE | P16: FALSE | Q16: 0 | R16: FALSE
A17: Extremely Unique Dynamic | B17: Strand Releasing | C17: Independent / Other | D17: 45667 | E17: exact | F17: 2025-01-10 | H17: Q1 2025 | I17: Limited | J17: FALSE | K17: FALSE | L17: 38207 | N17: FALSE | O17: FALSE | P17: FALSE | Q17: 0 | R17: FALSE
A18: Finist: The First Warrior | B18: START | C18: Independent / Other | D18: 45667 | E18: exact | F18: 2025-01-10 | H18: Q1 2025 | I18: Limited | J18: FALSE | K18: FALSE | N18: FALSE | O18: FALSE | P18: FALSE | Q18: 0 | R18: FALSE
A19: Game Changer | B19: Shloka Entertainments | C19: Independent / Other | D19: 45667 | E19: exact | F19: 2025-01-10 | H19: Q1 2025 | I19: Wide | J19: FALSE | K19: FALSE | L19: 2060000 | N19: FALSE | O19: FALSE | P19: FALSE | Q19: 0 | R19: FALSE
A20: Hard Truths | B20: Bleecker Street | C20: Bleecker Street | D20: 45667 | E20: exact | F20: 2025-01-10 | H20: Q1 2025 | I20: Limited | J20: FALSE | K20: FALSE | L20: 811683 | N20: FALSE | O20: FALSE | P20: FALSE | Q20: 0 | R20: TRUE
A21: Hazard | B21: Emphatic Films | C21: Independent / Other | D21: 45667 | E21: exact | F21: 2025-01-10 | H21: Q1 2025 | I21: Limited | J21: FALSE | K21: FALSE | N21: FALSE | O21: FALSE | P21: FALSE | Q21: 0 | R21: FALSE
A22: Laws of Man | B22: Saban Films | C22: Independent / Other | D22: 45667 | E22: exact | F22: 2025-01-10 | H22: Q1 2025 | I22: Limited | J22: FALSE | K22: FALSE | N22: FALSE | O22: FALSE | P22: FALSE | Q22: 0 | R22: FALSE
A23: Oceans Are The Real Continents | B23: Film Movement | C23: Independent / Other | D23: 45667 | E23: exact | F23: 2025-01-10 | H23: Q1 2025 | I23: Limited | J23: FALSE | K23: FALSE | N23: FALSE | O23: FALSE | P23: FALSE | Q23: 0 | R23: FALSE
A24: Octopus with Broken Arms | B24: CMC Pictures | C24: Independent / Other | D24: 45667 | E24: exact | F24: 2025-01-10 | H24: Q1 2025 | I24: Limited | J24: FALSE | K24: FALSE | N24: FALSE | O24: FALSE | P24: FALSE | Q24: 0 | R24: FALSE
A25: Putin | B25: Horizon Events | C25: Independent / Other | D25: 45667 | E25: exact | F25: 2025-01-10 | H25: Q1 2025 | I25: Limited | J25: FALSE | K25: FALSE | N25: FALSE | O25: FALSE | P25: FALSE | Q25: 0 | R25: FALSE
A26: Sangeet Manapman | B26: Jio Studios | C26: Independent / Other | D26: 45667 | E26: exact | F26: 2025-01-10 | H26: Q1 2025 | I26: Limited | J26: FALSE | K26: FALSE | N26: FALSE | O26: FALSE | P26: FALSE | Q26: 0 | R26: FALSE
A27: Sanju Weds Geetha 2 | C27: Unknown | D27: 45667 | E27: exact | F27: 2025-01-10 | H27: Q1 2025 | I27: Limited | J27: FALSE | K27: FALSE | N27: FALSE | O27: FALSE | P27: FALSE | Q27: 0 | R27: FALSE
A28: Somewhere in Montana | B28: Nova Vento Entertainment | C28: Independent / Other | D28: 45667 | E28: exact | F28: 2025-01-10 | H28: Q1 2025 | I28: Limited | J28: FALSE | K28: FALSE | N28: FALSE | O28: FALSE | P28: FALSE | Q28: 0 | R28: FALSE
A29: Survive | B29: Samuel Goldwyn Films | C29: Independent / Other | D29: 45667 | E29: exact | F29: 2025-01-10 | H29: Q1 2025 | I29: Limited | J29: FALSE | K29: FALSE | N29: FALSE | O29: FALSE | P29: FALSE | Q29: 0 | R29: FALSE
A30: The Last Showgirl | B30: Roadside Attractions | C30: Independent / Other | D30: 45667 | E30: exact | F30: 2025-01-10 | H30: Q1 2025 | I30: Wide | J30: FALSE | K30: FALSE | L30: 4799804 | N30: FALSE | O30: FALSE | P30: FALSE | Q30: 0 | R30: FALSE
A31: The Prosecutor | B31: Well Go USA | C31: Independent / Other | D31: 45667 | E31: exact | F31: 2025-01-10 | H31: Q1 2025 | I31: Limited | J31: FALSE | K31: FALSE | L31: 407965 | N31: FALSE | O31: FALSE | P31: FALSE | Q31: 0 | R31: FALSE
A32: Turn Me On | B32: Vertical Entertainment | C32: Independent / Other | D32: 45667 | E32: exact | F32: 2025-01-10 | H32: Q1 2025 | I32: Limited | J32: FALSE | K32: FALSE | N32: FALSE | O32: FALSE | P32: FALSE | Q32: 0 | R32: FALSE
A33: Uninvited | B33: Mentorque Productions | C33: Independent / Other | D33: 45667 | E33: exact | F33: 2025-01-10 | H33: Q1 2025 | I33: Limited | J33: FALSE | K33: FALSE | N33: FALSE | O33: FALSE | P33: FALSE | Q33: 0 | R33: FALSE
A34: Vanangaan | B34: V House Productions | C34: Independent / Other | D34: 45667 | E34: exact | F34: 2025-01-10 | H34: Q1 2025 | I34: Limited | J34: FALSE | K34: FALSE | N34: FALSE | O34: FALSE | P34: FALSE | Q34: 0 | R34: FALSE
A35: Savor | B35: Barnshow Productions | C35: Independent / Other | D35: 45668 | E35: exact | F35: 2025-01-11 | H35: Q1 2025 | I35: Limited | J35: FALSE | K35: FALSE | N35: FALSE | O35: FALSE | P35: FALSE | Q35: 0 | R35: FALSE
A36: Talk To Me | B36: A24 | C36: A24 | D36: 45668 | E36: exact | F36: 2025-01-11 | H36: Q1 2025 | I36: Special Engagement | J36: TRUE | K36: TRUE | L36: 48299436 | M36: Lifetime gross incl. original run - not 2025 revenue | N36: FALSE | O36: FALSE | P36: FALSE | Q36: 0 | R36: TRUE
A37: Daaku Maharaaj | B37: Shloka Entertainments | C37: Independent / Other | D37: 45669 | E37: exact | F37: 2025-01-12 | H37: Q1 2025 | I37: Limited | J37: FALSE | K37: FALSE | N37: FALSE | O37: FALSE | P37: FALSE | Q37: 0 | R37: FALSE
A38: Peter Pan’s Neverland Nightmare | B38: Iconic Releasing | C38: Independent / Other | D38: 45670 | E38: exact | F38: 2025-01-13 | H38: Q1 2025 | I38: Wide | J38: FALSE | K38: FALSE | L38: 230515 | N38: FALSE | O38: FALSE | P38: FALSE | Q38: 0 | R38: FALSE
A39: Kadhalikka Neramillai | B39: Red Giant Movies | C39: Independent / Other | D39: 45671 | E39: exact | F39: 2025-01-14 | H39: Q1 2025 | I39: Limited | J39: FALSE | K39: FALSE | N39: FALSE | O39: FALSE | P39: FALSE | Q39: 0 | R39: FALSE
A40: Pay Dirt: The Story of Supercross | B40: Monkey Wrench Films | C40: Independent / Other | D40: 45671 | E40: exact | F40: 2025-01-14 | H40: Q1 2025 | I40: Limited | J40: FALSE | K40: FALSE | N40: FALSE | O40: FALSE | P40: FALSE | Q40: 0 | R40: FALSE
...

Sheet 2026
A1: Title | B1: Distributor | C1: Parent Company | D1: Release Date | E1: Date Precision | F1: Date (as sourced) | G1: Wide Expansion Date | H1: Release Quarter | I1: Release Type | J1: Is Re-release | K1: Is IMAX | L1: Domestic BO (Lifetime) | M1: BO Caveat | N1: Is Canceled | O1: Is Catalog Aggregate | P1: Dup BO Flag | Q1: Merge Span (days) | R1: In Scope
A2: Ikkis | B2: Yash Raj Films | C2: Independent / Other | D2: 46023 | E2: exact | F2: 2026-01-01 | H2: Q1 2026 | I2: Limited | J2: FALSE | K2: FALSE | N2: FALSE | O2: FALSE | P2: FALSE | Q2: 0 | R2: FALSE
A3: Patang | C3: Unknown | D3: 46023 | E3: exact | F3: 2026-01-01 | H3: Q1 2026 | I3: Limited | J3: FALSE | K3: FALSE | N3: FALSE | O3: FALSE | P3: FALSE | Q3: 0 | R3: FALSE
A4: KIDZ BOP LIVE: The Concert Movie | B4: Fathom Entertainment | C4: Independent / Other | D4: 46024 | E4: exact | F4: 2026-01-02 | H4: Q1 2026 | I4: Limited | J4: FALSE | K4: FALSE | N4: FALSE | O4: FALSE | P4: FALSE | Q4: 0 | R4: FALSE
A5: The Dutchman | B5: Inaugural Entertainment | C5: Independent / Other | D5: 46024 | E5: exact | F5: 2026-01-02 | H5: Q1 2026 | I5: Limited | J5: FALSE | K5: FALSE | N5: FALSE | O5: FALSE | P5: FALSE | Q5: 0 | R5: FALSE
A6: We Bury the Dead | B6: Vertical Entertainment | C6: Independent / Other | D6: 46024 | E6: exact | F6: 2026-01-02 | H6: Q1 2026 | I6: Limited | J6: FALSE | K6: FALSE | L6: 3711918 | N6: FALSE | O6: FALSE | P6: FALSE | Q6: 0 | R6: FALSE
A7: Lupin the IIIRD: The Movie — The Immortal Bloodline | B7: GKIDS | C7: Independent / Other | D7: 46026 | E7: exact | F7: 2026-01-04 | H7: Q1 2026 | I7: Limited | J7: FALSE | K7: FALSE | L7: 121507 | N7: FALSE | O7: FALSE | P7: FALSE | Q7: 0 | R7: FALSE
A8: Weathered: Inside the LA Firestorm | B8: PBS Distribution | C8: Independent / Other | D8: 46029 | E8: exact | F8: 2026-01-07 | H8: Q1 2026 | I8: Limited | J8: FALSE | K8: FALSE | N8: FALSE | O8: FALSE | P8: FALSE | Q8: 0 | R8: FALSE
A9: Labyrinth | B9: Fathom Events | C9: Independent / Other | D9: 46030 | E9: exact | F9: 2026-01-08 | H9: Q1 2026 | I9: Limited | J9: TRUE | K9: FALSE | L9: 12729917 | M9: Lifetime gross incl. original run - not 2026 revenue | N9: FALSE | O9: FALSE | P9: FALSE | Q9: 0 | R9: FALSE
A10: The Raja Saab | B10: Prathyangira Cinemas | C10: Independent / Other | D10: 46030 | E10: exact | F10: 2026-01-08 | H10: Q1 2026 | I10: Wide | J10: FALSE | K10: FALSE | L10: 2300000 | N10: FALSE | O10: FALSE | P10: FALSE | Q10: 0 | R10: FALSE
A11: 31 Candles | B11: Level 33 | C11: Independent / Other | D11: 46031 | E11: exact | F11: 2026-01-09 | H11: Q1 2026 | I11: Limited | J11: FALSE | K11: FALSE | N11: FALSE | O11: FALSE | P11: FALSE | Q11: 0 | R11: FALSE
A12: All That’s Left Of You | B12: Watermelon Pictures | C12: Independent / Other | D12: 46031 | E12: exact | F12: 2026-01-09 | H12: Q1 2026 | I12: Limited | J12: FALSE | K12: FALSE | L12: 514374 | N12: FALSE | O12: FALSE | P12: FALSE | Q12: 0 | R12: FALSE
A13: Bulls | B13: VRC | C13: Independent / Other | D13: 46031 | E13: exact | F13: 2026-01-09 | H13: Q1 2026 | I13: Limited | J13: FALSE | K13: FALSE | N13: FALSE | O13: FALSE | P13: FALSE | Q13: 0 | R13: FALSE
A14: Buratino | C14: Unknown | D14: 46031 | E14: exact | F14: 2026-01-09 | H14: Q1 2026 | I14: Limited | J14: FALSE | K14: FALSE | N14: FALSE | O14: FALSE | P14: FALSE | Q14: 0 | R14: FALSE
A15: Dead Man’s Wire | B15: Row K Entertainment | C15: Independent / Other | D15: 46031 | E15: exact | F15: 2026-01-09 | G15: 46038 | H15: Q1 2026 | I15: Wide | J15: FALSE | K15: FALSE | L15: 2236813 | N15: FALSE | O15: FALSE | P15: FALSE | Q15: 7 | R15: FALSE
A16: Greenland 2: Migration | B16: Lionsgate | C16: Lionsgate | D16: 46031 | E16: exact | F16: 2026-01-09 | H16: Q1 2026 | I16: Wide | J16: FALSE | K16: FALSE | L16: 17770308 | N16: FALSE | O16: FALSE | P16: FALSE | Q16: 0 | R16: TRUE
A17: Holding Liat | B17: The Film Collaborative | C17: Independent / Other | D17: 46031 | E17: exact | F17: 2026-01-09 | H17: Q1 2026 | I17: Limited | J17: FALSE | K17: FALSE | L17: 78535 | N17: FALSE | O17: FALSE | P17: FALSE | Q17: 0 | R17: FALSE
A18: I Was a Stranger | B18: Angel Studios | C18: Angel Studios | D18: 46031 | E18: exact | F18: 2026-01-09 | H18: Q1 2026 | I18: Wide | J18: FALSE | K18: FALSE | L18: 2008685 | N18: FALSE | O18: FALSE | P18: FALSE | Q18: 0 | R18: TRUE
A19: Is This Thing On? | B19: Searchlight Pictures | C19: Disney | D19: 46031 | E19: exact | F19: 2026-01-09 | H19: Q1 2026 | I19: Wide | J19: FALSE | K19: FALSE | L19: 6185385 | N19: FALSE | O19: FALSE | P19: FALSE | Q19: 0 | R19: TRUE
A20: Magellan | B20: Janus Films | C20: Independent / Other | D20: 46031 | E20: exact | F20: 2026-01-09 | H20: Q1 2026 | I20: Limited | J20: FALSE | K20: FALSE | L20: 231318 | N20: FALSE | O20: FALSE | P20: FALSE | Q20: 0 | R20: FALSE
A21: My Neighbor Adolf | B21: Cohen Media Group | C21: Independent / Other | D21: 46031 | E21: exact | F21: 2026-01-09 | H21: Q1 2026 | I21: Limited | J21: FALSE | K21: FALSE | N21: FALSE | O21: FALSE | P21: FALSE | Q21: 0 | R21: FALSE
A22: OBEX | B22: Oscilloscope Pictures | C22: Independent / Other | D22: 46031 | E22: exact | F22: 2026-01-09 | H22: Q1 2026 | I22: Limited | J22: FALSE | K22: FALSE | L22: 48257 | N22: FALSE | O22: FALSE | P22: FALSE | Q22: 0 | R22: FALSE
A23: Oscar Shaw | B23: Samuel Goldwyn Films | C23: Independent / Other | D23: 46031 | E23: exact | F23: 2026-01-09 | H23: Q1 2026 | I23: Limited | J23: FALSE | K23: FALSE | N23: FALSE | O23: FALSE | P23: FALSE | Q23: 0 | R23: FALSE
A24: Port of Shadows | B24: Rialto Pictures | C24: Independent / Other | D24: 46031 | E24: exact | F24: 2026-01-09 | H24: Q1 2026 | I24: Limited | J24: TRUE | K24: FALSE | L24: 35962 | M24: Lifetime gross incl. original run - not 2026 revenue | N24: FALSE | O24: FALSE | P24: FALSE | Q24: 0 | R24: FALSE
A25: Primate | B25: Paramount Pictures | C25: Paramount | D25: 46031 | E25: exact | F25: 2026-01-09 | H25: Q1 2026 | I25: Wide | J25: FALSE | K25: FALSE | L25: 25635665 | N25: FALSE | O25: FALSE | P25: FALSE | Q25: 0 | R25: TRUE
A26: Sleepwalker | B26: Brainstorm Media | C26: Independent / Other | D26: 46031 | E26: exact | F26: 2026-01-09 | H26: Q1 2026 | I26: Limited | J26: FALSE | K26: FALSE | N26: FALSE | O26: FALSE | P26: FALSE | Q26: 0 | R26: FALSE
A27: The Voice of Hind Rajab | B27: WILLA | C27: Independent / Other | D27: 46031 | E27: exact | F27: 2026-01-09 | H27: Q1 2026 | I27: Limited | J27: FALSE | K27: FALSE | L27: 955679 | N27: FALSE | O27: FALSE | P27: FALSE | Q27: 0 | R27: FALSE
A28: Young Mothers | B28: Music Box Films | C28: Independent / Other | D28: 46031 | E28: exact | F28: 2026-01-09 | H28: Q1 2026 | I28: Limited | J28: FALSE | K28: FALSE | L28: 13032 | N28: FALSE | O28: FALSE | P28: FALSE | Q28: 0 | R28: FALSE
A29: Mana ShankaraVaraprasad Garu | B29: Sarigama Cinemas | C29: Independent / Other | D29: 46034 | E29: exact | F29: 2026-01-12 | H29: Q1 2026 | I29: Limited | J29: FALSE | K29: FALSE | N29: FALSE | O29: FALSE | P29: FALSE | Q29: 0 | R29: FALSE
A30: Godfrey: Rebel with a Cause | B30: Gathr Films | C30: Independent / Other | D30: 46036 | E30: exact | F30: 2026-01-14 | H30: Q1 2026 | I30: Limited | J30: FALSE | K30: FALSE | N30: FALSE | O30: FALSE | P30: FALSE | Q30: 0 | R30: FALSE
A31: Nari Nari Naduma Murari | B31: Sarigama Cinemas | C31: Independent / Other | D31: 46036 | E31: exact | F31: 2026-01-14 | H31: Q1 2026 | I31: Limited | J31: FALSE | K31: FALSE | N31: FALSE | O31: FALSE | P31: FALSE | Q31: 0 | R31: FALSE
A32: Once Upon My Mother | C32: Unknown | D32: 46036 | E32: exact | F32: 2026-01-14 | H32: Q1 2026 | I32: Limited | J32: FALSE | K32: FALSE | N32: FALSE | O32: FALSE | P32: FALSE | Q32: 0 | R32: FALSE
A33: TTT: Thalaivar Thambi Thalamaiyil | B33: Prathyangira Cinemas | C33: Independent / Other | D33: 46037 | E33: exact | F33: 2026-01-15 | H33: Q1 2026 | I33: Limited | J33: FALSE | K33: FALSE | N33: FALSE | O33: FALSE | P33: FALSE | Q33: 0 | R33: FALSE
A34: 28 Years Later: The Bone Temple | B34: Sony Pictures | C34: Sony | D34: 46038 | E34: exact | F34: 2026-01-16 | H34: Q1 2026 | I34: Wide | J34: FALSE | K34: FALSE | L34: 25147583 | N34: FALSE | O34: FALSE | P34: FALSE | Q34: 0 | R34: TRUE
A35: A Private Life | B35: Sony Pictures Classics | C35: Sony | D35: 46038 | E35: exact | F35: 2026-01-16 | H35: Q1 2026 | I35: Limited | J35: FALSE | K35: FALSE | L35: 1421315 | N35: FALSE | O35: FALSE | P35: FALSE | Q35: 0 | R35: TRUE
A36: A Useful Ghost | B36: Cineverse | C36: Independent / Other | D36: 46038 | E36: exact | F36: 2026-01-16 | H36: Q1 2026 | I36: Limited | J36: FALSE | K36: FALSE | N36: FALSE | O36: FALSE | P36: FALSE | Q36: 0 | R36: FALSE
A37: All You Need Is Kill | B37: GKIDS | C37: Independent / Other | D37: 46038 | E37: exact | F37: 2026-01-16 | H37: Q1 2026 | I37: Wide | J37: FALSE | K37: FALSE | L37: 695290 | N37: FALSE | O37: FALSE | P37: FALSE | Q37: 0 | R37: FALSE
A38: Charlie the Wonderdog | B38: Viva Pictures | C38: Independent / Other | D38: 46038 | E38: exact | F38: 2026-01-16 | H38: Q1 2026 | I38: Wide | J38: FALSE | K38: FALSE | L38: 2003436 | N38: FALSE | O38: FALSE | P38: FALSE | Q38: 0 | R38: FALSE
A39: Deepfaking Sam Altman | B39: Abramorama Films | C39: Independent / Other | D39: 46038 | E39: exact | F39: 2026-01-16 | H39: Q1 2026 | I39: Limited | J39: FALSE | K39: FALSE | N39: FALSE | O39: FALSE | P39: FALSE | Q39: 0 | R39: FALSE
A40: Happy Patel: Khatarnak Jasoos | B40: Shree Krishna Film | C40: Independent / Other | D40: 46038 | E40: exact | F40: 2026-01-16 | H40: Q1 2026 | I40: Limited | J40: FALSE | K40: FALSE | N40: FALSE | O40: FALSE | P40: FALSE | Q40: 0 | R40: FALSE
...

Sheet 2027
A1: Title | B1: Distributor | C1: Parent Company | D1: Release Date | E1: Date Precision | F1: Date (as sourced) | G1: Wide Expansion Date | H1: Release Quarter | I1: Release Type | J1: Is Re-release | K1: Is IMAX | L1: Domestic BO (Lifetime) | M1: BO Caveat | N1: Is Canceled | O1: Is Catalog Aggregate | P1: Dup BO Flag | Q1: Merge Span (days) | R1: In Scope
A2: Bagworm | B2: Oscilloscope Pictures | C2: Independent / Other | D2: 46388 | E2: season | F2: Winter 2027 | H2: Q1 2027 | I2: Limited | J2: FALSE | K2: FALSE | N2: FALSE | O2: FALSE | P2: FALSE | Q2: 0 | R2: FALSE
A3: Pendulum | B3: Vertical Entertainment | C3: Independent / Other | D3: 46388 | E3: exact | F3: 2027-01-01 | H3: Q1 2027 | I3: Wide | J3: FALSE | K3: FALSE | N3: FALSE | O3: FALSE | P3: FALSE | Q3: 0 | R3: FALSE
A4: The Meltdown | B4: Kino Lorber | C4: Independent / Other | D4: 46388 | E4: quarter | F4: 1st quarter | H4: Q1 2027 | I4: Limited | J4: FALSE | K4: FALSE | N4: FALSE | O4: FALSE | P4: FALSE | Q4: 0 | R4: FALSE
A5: Untitled Shudder Horror Film | B5: Independent Film Company | C5: Independent / Other | D5: 46395 | E5: exact | F5: 2027-01-08 | H5: Q1 2027 | I5: Limited | J5: FALSE | K5: FALSE | N5: FALSE | O5: FALSE | P5: FALSE | Q5: 0 | R5: FALSE
A6: Children of Blood and Bone | B6: Paramount Pictures | C6: Paramount | D6: 46402 | E6: exact | F6: 2027-01-15 | H6: Q1 2027 | I6: Wide | J6: FALSE | K6: TRUE | N6: FALSE | O6: FALSE | P6: FALSE | Q6: 0 | R6: TRUE
A7: The Beekeeper 2 | B7: Amazon MGM Studios | C7: Amazon | D7: 46402 | E7: exact | F7: 2027-01-15 | H7: Q1 2027 | I7: Wide | J7: FALSE | K7: FALSE | N7: FALSE | O7: FALSE | P7: FALSE | Q7: 0 | R7: TRUE
A8: Untitled Blumhouse Event Film | B8: Universal | C8: Universal / NBCU | D8: 46402 | E8: exact | F8: 2027-01-15 | H8: Q1 2027 | I8: Wide | J8: FALSE | K8: FALSE | N8: FALSE | O8: FALSE | P8: FALSE | Q8: 0 | R8: TRUE
A9: Air Bud Returns | B9: Cineverse | C9: Independent / Other | D9: 46409 | E9: exact | F9: 2027-01-22 | H9: Q1 2027 | I9: Wide | J9: FALSE | K9: FALSE | N9: FALSE | O9: FALSE | P9: FALSE | Q9: 0 | R9: FALSE
A10: Animal Friends | B10: Warner Bros. | C10: Warner Bros. Discovery | D10: 46409 | E10: exact | F10: 2027-01-22 | H10: Q1 2027 | I10: Wide | J10: FALSE | K10: FALSE | N10: FALSE | O10: FALSE | P10: FALSE | Q10: 0 | R10: TRUE
A11: The Third Parent | B11: Bleecker Street | C11: Bleecker Street | D11: 46409 | E11: exact | F11: 2027-01-22 | H11: Q1 2027 | I11: Wide | J11: FALSE | K11: FALSE | N11: FALSE | O11: FALSE | P11: FALSE | Q11: 0 | R11: TRUE
A12: Drag | B12: Briarcliff Entertainment | C12: Independent / Other | D12: 46416 | E12: exact | F12: 2027-01-29 | H12: Q1 2027 | I12: Wide | J12: FALSE | K12: FALSE | N12: FALSE | O12: FALSE | P12: FALSE | Q12: 0 | R12: FALSE
A13: Karoshi | B13: Lionsgate | C13: Lionsgate | D13: 46416 | E13: exact | F13: 2027-01-29 | H13: Q1 2027 | I13: Wide | J13: FALSE | K13: FALSE | N13: FALSE | O13: FALSE | P13: FALSE | Q13: 0 | R13: TRUE
... A22: CoComelon: The Movie | B22: Universal | C22: Universal / NBCU | D22: 46437 | E22: exact | F22: 2027-02-19 | H22: Q1 2027 | I22: Wide | J22: FALSE | K22: FALSE | N22: FALSE | O22: FALSE | P22: FALSE | Q22: 0 | R22: TRUE
A23: Star Wars Ep. IV: A New Hope | B23: Walt Disney | C23: Disney | D23: 46437 | E23: exact | F23: 2027-02-19 | H23: Q1 2027 | I23: Wide | J23: TRUE | K23: FALSE | L23: 460998007 | M23: Lifetime gross incl. original run - not 2027 revenue | N23: FALSE | O23: FALSE | P23: FALSE | Q23: 0 | R23: TRUE
A24: Untitled Neon Horror Film | B24: Neon | C24: Neon | D24: 46437 | E24: exact | F24: 2027-02-19 | H24: Q1 2027 | I24: Wide | J24: FALSE | K24: FALSE | N24: FALSE | O24: FALSE | P24: FALSE | Q24: 0 | R24: TRUE
A25: Wife & Dog | B25: Black Bear Pictures | C25: Independent / Other | D25: 46437 | E25: exact | F25: 2027-02-19 | H25: Q1 2027 | I25: Wide | J25: FALSE | K25: FALSE | N25: FALSE | O25: FALSE | P25: FALSE | Q25: 0 | R25: FALSE
A26: K-Pop: The Debut | B26: Paramount Pictures | C26: Paramount | D26: 46444 | E26: exact | F26: 2027-02-26 | H26: Q1 2027 | I26: Wide | J26: FALSE | K26: FALSE | N26: FALSE | O26: FALSE | P26: FALSE | Q26: 0 | R26: TRUE
A27: Live Like That | B27: Sony Pictures | C27: Sony | D27: 46444 | E27: exact | F27: 2027-02-26 | H27: Q1 2027 | I27: Wide | J27: FALSE | K27: FALSE | N27: FALSE | O27: FALSE | P27: FALSE | Q27: 0 | R27: TRUE
A28: The Revenge of La Llorona | B28: Warner Bros. | C28: Warner Bros. Discovery | D28: 46444 | E28: exact | F28: 2027-02-26 | H28: Q1 2027 | I28: Wide | J28: FALSE | K28: FALSE | N28: FALSE | O28: FALSE | P28: FALSE | Q28: 0 | R28: TRUE
A29: Gatto | B29: Walt Disney | C29: Disney | D29: 46451 | E29: exact | F29: 2027-03-05 | H29: Q1 2027 | I29: Wide | J29: FALSE | K29: FALSE | N29: FALSE | O29: FALSE | P29: FALSE | Q29: 0 | R29: TRUE
A30: The Thomas Crown Affair | B30: Amazon MGM Studios | C30: Amazon | D30: 46451 | E30: exact | F30: 2027-03-05 | H30: Q1 2027 | I30: Wide | J30: FALSE | K30: TRUE | N30: FALSE | O30: FALSE | P30: FALSE | Q30: 0 | R30: TRUE
A31: Untitled DC Event Film | B31: Warner Bros. | C31: Warner Bros. Discovery | D31: 46451 | E31: exact | F31: 2027-03-05 | H31: Q1 2027 | I31: Wide | J31: FALSE | K31: FALSE | N31: FALSE | O31: FALSE | P31: FALSE | Q31: 0 | R31: TRUE
A32: Untitled Mike Flanagan Exorcist Film | B32: Universal | C32: Universal / NBCU | D32: 46458 | E32: exact | F32: 2027-03-12 | H32: Q1 2027 | I32: Wide | J32: FALSE | K32: FALSE | N32: FALSE | O32: FALSE | P32: FALSE | Q32: 0 | R32: TRUE
A33: Untitled The Chosen Season 6 Finale Film | B33: Amazon MGM Studios | C33: Amazon | D33: 46458 | E33: exact | F33: 2027-03-12 | H33: Q1 2027 | I33: Wide | J33: FALSE | K33: FALSE | N33: FALSE | O33: FALSE | P33: FALSE | Q33: 0 | R33: TRUE
A34: Untitled Warner Bros. Event Film | B34: Warner Bros. | C34: Warner Bros. Discovery | D34: 46458 | E34: exact | F34: 2027-03-12 | H34: Q1 2027 | I34: Wide | J34: FALSE | K34: FALSE | N34: FALSE | O34: FALSE | P34: FALSE | Q34: 0 | R34: TRUE
A35: Sonic the Hedgehog 4 | B35: Paramount Pictures | C35: Paramount | D35: 46465 | E35: exact | F35: 2027-03-19 | H35: Q1 2027 | I35: Wide | J35: FALSE | K35: FALSE | N35: FALSE | O35: FALSE | P35: FALSE | Q35: 0 | R35: TRUE
... A41: Untitled Universal Event Film | B41: Universal | C41: Universal / NBCU | D41: 46479 | E41: exact | F41: 2027-04-02 | H41: Q2 2027 | I41: Wide | J41: FALSE | K41: FALSE | N41: FALSE | O41: FALSE | P41: FALSE | Q41: 0 | R41: TRUE
A42: Varanasi | C42: Unknown | D42: 46484 | E42: exact | F42: 2027-04-07 | H42: Q2 2027 | I42: Wide | J42: FALSE | K42: FALSE | N42: FALSE | O42: FALSE | P42: FALSE | Q42: 0 | R42: FALSE
A43: Boys for Life | B43: Paramount Pictures | C43: Paramount | D43: 46486 | E43: exact | F43: 2027-04-09 | H43: Q2 2027 | I43: Wide | J43: FALSE | K43: FALSE | N43: FALSE | O43: FALSE | P43: FALSE | Q43: 0 | R43: TRUE
A44: Panic Carefully | B44: Warner Bros. | C44: Warner Bros. Discovery | D44: 46486 | E44: exact | F44: 2027-04-09 | H44: Q2 2027 | I44: Wide | J44: FALSE | K44: FALSE | N44: FALSE | O44: FALSE | P44: FALSE | Q44: 0 | R44: TRUE
A45: Not Alone | B45: Universal | C45: Universal / NBCU | D45: 46493 | E45: exact | F45: 2027-04-16 | H45: Q2 2027 | I45: Wide | J45: FALSE | K45: FALSE | N45: FALSE | O45: FALSE | P45: FALSE | Q45: 0 | R45: TRUE
A46: F.A.S.T. | B46: Warner Bros. | C46: Warner Bros. Discovery | D46: 46500 | E46: exact | F46: 2027-04-23 | H46: Q2 2027 | I46: Wide | J46: FALSE | K46: FALSE | N46: FALSE | O46: FALSE | P46: FALSE | Q46: 0 | R46: TRUE
A47: Spaceballs: The New One | B47: Amazon MGM Studios | C47: Amazon | D47: 46500 | E47: exact | F47: 2027-04-23 | H47: Q2 2027 | I47: Wide | J47: FALSE | K47: FALSE | N47: FALSE | O47: FALSE | P47: FALSE | Q47: 0 | R47: TRUE
A48: Monitor | B48: Searchlight Pictures | C48: Disney | D48: 46507 | E48: exact | F48: 2027-04-30 | H48: Q2 2027 | I48: Wide | J48: FALSE | K48: FALSE | N48: FALSE | O48: FALSE | P48: FALSE | Q48: 0 | R48: TRUE
A49: The Legend of Zelda | B49: Sony Pictures | C49: Sony | D49: 46507 | E49: exact | F49: 2027-04-30 | H49: Q2 2027 | I49: Wide | J49: FALSE | K49: TRUE | N49: FALSE | O49: FALSE | P49: FALSE | Q49: 0 | R49: TRUE
A50: The Resurrection of the Christ: Part One | B50: Lionsgate | C50: Lionsgate | D50: 46513 | E50: exact | F50: 2027-05-06 | H50: Q2 2027 | I50: Wide | J50: FALSE | K50: FALSE | N50: FALSE | O50: FALSE | P50: FALSE | Q50: 0 | R50: TRUE
A51: Bad Fairies | B51: Warner Bros. | C51: Warner Bros. Discovery | D51: 46528 | E51: exact | F51: 2027-05-21 | H51: Q2 2027 | I51: Wide | J51: FALSE | K51: FALSE | N51: FALSE | O51: FALSE | P51: FALSE | Q51: 0 | R51: TRUE
A52: The Catch | B52: Universal | C52: Universal / NBCU | D52: 46528 | E52: exact | F52: 2027-05-21 | H52: Q2 2027 | I52: Wide | J52: FALSE | K52: FALSE | N52: FALSE | O52: FALSE | P52: FALSE | Q52: 0 | R52: TRUE
A53: Untitled Paranormal Activity Film | B53: Paramount Pictures | C53: Paramount | D53: 46528 | E53: exact | F53: 2027-05-21 | H53: Q2 2027 | I53: Wide | J53: FALSE | K53: FALSE | N53: FALSE | O53: FALSE | P53: FALSE | Q53: 0 | R53: TRUE
...
