Workbook
Name IQ_CH: 110000
Name IQ_CQ: 5000
Name IQ_CY: 10000
Name IQ_DAILY: 500000
Name IQ_FH: 100000
Name IQ_FQ: 500
Name IQ_FY: 1000
Name IQ_LTM: 2000
Name IQ_MONTH: 15000
Name IQ_NTM: 6000
Name IQ_WEEK: 50000
Name IQ_YTD: 3000

Sheet __snloffice
A1: 允䅁䅁䅧䅁捁䅁䅁杔桂䡁䅍䅚桂䡁䅅睒呂䑁䅯杔䝂䕁䅷䅗䅁䅁䅁䅁歂睁䅁䅐兂䝁䅅杣桂䝁䄰䅉灂䝁䅑児楁䑁䅕杉⭁䑁䅍䅐癁䙁䅁兙祂䝁䅅兢⭁䑁䅷䅕桂䡁䅉兙瑂䍁䅁兡歂䑁䄰杉硁䍁䅉材祁䑁䅙睍穁䑁䅉䅎硁䑁䅷睌兂䝁䅅杣桂䝁䄰材㡁䙁䅁兙祂䝁䅅兢杁䝁䅫䅚㥁䍁䅉杍楁䑁䄴免睁䑁䅁免㉁䑁䅕䅏穁䑁䅙䅎㡁䍁䄸䅕桂䡁䅉兙瑂䑁䄴䅐兂䝁䅅杣桂䝁䄰䅉灂䝁䅑児楁䑁䅍杉⭁䑁䅅䅍睁䑁䅅睎穁䑁䅷睌兂䝁䅅杣桂䝁䄰材㡁䙁䅁兙祂䝁䅅兢杁䝁䅫䅚㥁䍁䅉䅎楁䑁䄴杍㡁䍁䄸䅕桂䡁䅉兙瑂䑁䄴䅐兂䝁䅅杣桂䝁䄰䅉灂䝁䅑児楁䑁䅙杉⭁䑁䅁䅐癁䙁䅁兙祂䝁䅅兢⭁䑁䅷䅕桂䡁䅉兙瑂䍁䅁兡歂䑁䄰杉㍁䍁䅉材硁䑁䅙䅍㡁䍁䄸䅕桂䡁䅉兙瑂䑁䄴䅐兂䝁䅅杣桂䝁䄰䅉灂䝁䅑児楁䑁䅧杉⭁䑁䅁䅐癁䙁䅁兙祂䝁䅅兢⭁䑁䅷䅕桂䡁䅉兙瑂䍁䅁兡歂䑁䄰杉㕁䍁䅉材硁䑁䅷睌兂䝁䅅杣桂䝁䄰材㡁䙁䅁兙祂䝁䅅兢杁䝁䅫䅚㥁䍁䅉免睁䍁䅉材睁䑁䅷睌兂䝁䅅杣桂䝁䄰材㡁䙁䅁兙祂䝁䅅兢杁䝁䅫䅚㥁䍁䅉免硁䍁䅉材硁䑁䅑䅏㉁䑁䅣睎硁䑁䅑李㕁䑁䅁䅐癁䙁䅁兙祂䝁䅅兢⭁䑁䅷䅕桂䡁䅉兙瑂䍁䅁兡歂䑁䄰杉硁䑁䅉杉⭁䑁䅉䅐癁䙁䅁兙祂䝁䅅兢⭁䑁䅷䅕桂䡁䅉兙瑂䍁䅁兡歂䑁䄰杉硁䑁䅍杉⭁䑁䅣睌硁䑁䅣睌祁䑁䅁杍㉁䑁䅷睌兂䝁䅅杣桂䝁䄰材㡁䙁䅁兙祂䝁䅅兢杁䝁䅫䅚㥁䍁䅉免㉁䍁䅉材㉁䍁䄸睍睁䍁䄸杍睁䑁䅉李㡁䍁䄸䅕桂䡁䅉兙瑂䑁䄴䅐兂䝁䅅杣桂䝁䄰䅉灂䝁䅑児楁䑁䅅睎楁䑁䄴睍祁䑁䅁免祁䑁䅷睌兂䝁䅅杣桂䝁䄰材㡁䙁䅁兙祂䝁䅅兢杁䝁䅫䅚㥁䍁䅉免㑁䍁䅉材睁䍁䄴睎㑁䑁䅫兏ㅁ䑁䅷睌兂䝁䅅杣桂䝁䄰材䅁䅁䅣䅁敁䅁䅁兓剂䙁䄸杕䙂䙁䅙兒佂䙁䅕兒時䕁䅕睕啂䅁䅁允䅁䉁䅧䅁䩂䙁䅅睘䙂䕁䅉兓啂䙁䄸兒呂䙁䅑䅁䕁䅁䅁杅䅁䕁䅍兕祁䍁䅁杍睁䑁䅉李䅁䅁䅉䅁敂睁䅁䅐兂䝁䅅杣桂䝁䄰䅉灂䝁䅑児楁䑁䅕杉⭁䑁䅍䅐癁䙁䅁兙祂䝁䅅兢⭁䑁䅷䅕桂䡁䅉兙瑂䍁䅁兡歂䑁䄰杉硁䍁䅉材睁䑁䅷睌兂䝁䅅杣桂䝁䄰材㡁䙁䅁兙祂䝁䅅兢杁䝁䅫䅚㥁䍁䅉杍楁䑁䄴免睁䑁䅁免㉁䑁䅕䅏穁䑁䅙䅎㡁䍁䄸䅕桂䡁䅉兙瑂䑁䄴䅐兂䝁䅅杣桂䝁䄰䅉灂䝁䅑児楁䑁䅍杉⭁䑁䅅䅍睁䑁䅉免ㅁ䑁䅷睌兂䝁䅅杣桂䝁䄰材㡁䙁䅁兙祂䝁䅅兢杁䝁䅫䅚㥁䍁䅉䅎楁䑁䄴杍㡁䍁䄸䅕桂䡁䅉兙瑂䑁䄴䅐兂䝁䅅杣桂䝁䄰䅉灂䝁䅑児楁䑁䅙杉⭁䑁䅁䅐癁䙁䅁兙祂䝁䅅兢⭁䑁䅷䅕桂䡁䅉兙瑂䍁䅁兡歂䑁䄰杉㍁䍁䅉材硁䑁䅙䅍㡁䍁䄸䅕桂䡁䅉兙瑂䑁䄴䅐兂䝁䅅杣桂䝁䄰䅉灂䝁䅑児楁䑁䅧杉⭁䑁䅁䅐癁䙁䅁兙祂䝁䅅兢⭁䑁䅷䅕桂䡁䅉兙瑂䍁䅁兡歂䑁䄰杉㕁䍁䅉材硁䑁䅷睌兂䝁䅅杣桂䝁䄰材㡁䙁䅁兙祂䝁䅅兢杁䝁䅫䅚㥁䍁䅉免睁䍁䅉材睁䑁䅷睌兂䝁䅅杣桂䝁䄰材㡁䙁䅁兙祂䝁䅅兢杁䝁䅫䅚㥁䍁䅉免硁䍁䅉材硁䑁䅑䅏㉁䑁䅙䅎㕁䑁䅁兏㑁䑁䅙䅐癁䙁䅁兙祂䝁䅅兢⭁䑁䅷䅕桂䡁䅉兙瑂䍁䅁兡歂䑁䄰杉硁䑁䅉杉⭁䑁䅉䅐癁䙁䅁兙祂䝁䅅兢⭁䑁䅷䅕桂䡁䅉兙瑂䍁䅁兡歂䑁䄰杉硁䑁䅍杉⭁䑁䅣睌硁䑁䅣睌祁䑁䅁杍㉁䑁䅷睌兂䝁䅅杣桂䝁䄰材㡁䙁䅁兙祂䝁䅅兢杁䝁䅫䅚㥁䍁䅉免㉁䍁䅉材㉁䍁䄸睍睁䍁䄸杍睁䑁䅉李㡁䍁䄸䅕桂䡁䅉兙瑂䑁䄴䅐兂䝁䅅杣桂䝁䄰䅉灂䝁䅑児楁䑁䅅睎楁䑁䄴睍祁䑁䅁免祁䑁䅷睌兂䝁䅅杣桂䝁䄰材㡁䙁䅁兙祂䝁䅅兢杁䝁䅫䅚㥁䍁䅉免㑁䍁䅉材ぁ䑁䅅杍㉁䍁䄴䅎ㅁ䑁䅁兏㕁䑁䅷睌兂䝁䅅杣桂䝁䄰材䅁䅁䅕䅁杂睁䅁䅐兂䝁䅅杣桂䝁䄰䅉灂䝁䅑児楁䑁䅕杉⭁䑁䅍䅐癁䙁䅁兙祂䝁䅅兢⭁䑁䅷䅕桂䡁䅉兙瑂䍁䅁兡歂䑁䄰杉硁䍁䅉材睁䑁䅷睌兂䝁䅅杣桂䝁䄰材㡁䙁䅁兙祂䝁䅅兢杁䝁䅫䅚㥁䍁䅉杍楁䑁䄴免睁䑁䅁免㉁䑁䅕䅏穁䑁䅙䅎㡁䍁䄸䅕桂䡁䅉兙瑂䑁䄴䅐兂䝁䅅杣桂䝁䄰䅉灂䝁䅑児楁䑁䅍杉⭁䑁䅅䅍睁䑁䅅䅏睁䑁䅷睌兂䝁䅅杣桂䝁䄰材㡁䙁䅁兙祂䝁䅅兢杁䝁䅫䅚㥁䍁䅉䅎楁䑁䄴杍㡁䍁䄸䅕桂䡁䅉兙瑂䑁䄴䅐兂䝁䅅杣桂䝁䄰䅉灂䝁䅑児楁䑁䅙杉⭁䑁䅁䅐癁䙁䅁兙祂䝁䅅兢⭁䑁䅷䅕桂䡁䅉兙瑂䍁䅁兡歂䑁䄰杉㍁䍁䅉材硁䑁䅙䅍㡁䍁䄸䅕桂䡁䅉兙瑂䑁䄴䅐兂䝁䅅杣桂䝁䄰䅉灂䝁䅑児楁䑁䅧杉⭁䑁䅁䅐癁䙁䅁兙祂䝁䅅兢⭁䑁䅷䅕桂䡁䅉兙瑂䍁䅁兡歂䑁䄰杉㕁䍁䅉材硁䑁䅷睌兂䝁䅅杣桂䝁䄰材㡁䙁䅁兙祂䝁䅅兢杁䝁䅫䅚㥁䍁䅉免睁䍁䅉材睁䑁䅷睌兂䝁䅅杣桂䝁䄰材㡁䙁䅁兙祂䝁䅅兢杁䝁䅫䅚㥁䍁䅉免硁䍁䅉材硁䑁䅑䅏㉁䑁䅣睎硁䑁䅑睎㑁䑁䅁䅐癁䙁䅁兙祂䝁䅅兢⭁䑁䅷䅕桂䡁䅉兙瑂䍁䅁兡歂䑁䄰杉硁䑁䅉杉⭁䑁䅉䅐癁䙁䅁兙祂䝁䅅兢⭁䑁䅷䅕桂䡁䅉兙瑂䍁䅁兡歂䑁䄰杉硁䑁䅍杉⭁䑁䅣睌硁䑁䅣睌祁䑁䅁杍㉁䑁䅷睌兂䝁䅅杣桂䝁䄰材㡁䙁䅁兙祂䝁䅅兢杁䝁䅫䅚㥁䍁䅉免㉁䍁䅉材㉁䍁䄸睍睁䍁䄸杍睁䑁䅉李㡁䍁䄸䅕桂䡁䅉兙瑂䑁䄴䅐兂䝁䅅杣桂䝁䄰䅉灂䝁䅑児楁䑁䅅睎楁䑁䄴睍祁䑁䅁免祁䑁䅷睌兂䝁䅅杣桂䝁䄰材㡁䙁䅁兙祂䝁䅅兢杁䝁䅫䅚㥁䍁䅉免㑁䍁䅉材硁䑁䅉兎㑁䑁䅉杌ㅁ䑁䅍䅍硁䑁䅧䅐癁䙁䅁兙祂䝁䅅兢⭁䅁䅁睁䅁䉁䅙䅁䩂䙁䅅睘䙂䙁䅁睕時䕁䅕睕啂䅁䅁杂䅁䅁䅁䅁㵁

Sheet 2Q26 Quick Look
A1: Netflix 2Q26 Earnings First Look
A2: KPI | B2: 2Q25A | C2: 2Q26 Consensus | D2: 2Q26A | E2: YoY Growth (2Q26 vs 2Q25) | F2: Beat/(Miss) %
A3: Total Revenue ($M) | B3: ='Income statement'!C14 -> 11079.17 | C3: ='Income statement'!H14 -> 12574.71 | D3: 12559.938 | E3: =IF(D3="","",(D3-B3)/B3) -> 0.13365333 | F3: =IF(D3="","",(D3-C3)/C3) -> -0.0011747388
A4: UCAN Revenue ($M) | B4: =Revenue!C19 -> 4929 | C4: =Revenue!H19 -> 5522.9 | D4: 5431.667 | E4: =IF(D4="","",(D4-B4)/B4) -> 0.10198154 | F4: =IF(D4="","",(D4-C4)/C4) -> -0.016519039
A5: EMEA Revenue ($M) | B5: =Revenue!C26 -> 3538.18 | C5: =Revenue!H26 -> 4014.96 | D5: 4033.515 | E5: =IF(D5="","",(D5-B5)/B5) -> 0.13999712 | F5: =IF(D5="","",(D5-C5)/C5) -> 0.0046214657
A6: LATAM Revenue ($M) | B6: =Revenue!C33 -> 1306.73 | C6: =Revenue!H33 -> 1504.65 | D6: 1584.29 | E6: =IF(D6="","",(D6-B6)/B6) -> 0.21240807 | F6: =IF(D6="","",(D6-C6)/C6) -> 0.052929253
A7: APAC Revenue ($M) | B7: =Revenue!C40 -> 1305.25 | C7: =Revenue!H40 -> 1522.16 | D7: 1510.466 | E7: =IF(D7="","",(D7-B7)/B7) -> 0.15722352 | F7: =IF(D7="","",(D7-C7)/C7) -> -0.0076825038
A9: Operating Income ($M) | B9: ='Income statement'!C21 -> 3774.69 | C9: ='Income statement'!H21 -> 4124.2 | D9: 4192.61 | E9: =IF(D9="","",(D9-B9)/B9) -> 0.11071638 | F9: =IF(D9="","",(D9-C9)/C9) -> 0.016587459
A10: Operating Margin (%) | B10: =B9/B3 -> 0.34070151 | C10: =C9/C3 -> 0.32797575 | D10: =IF(OR(D9="",D3=""),"",D9/D3) -> 0.33380818 | E10: =IF(D10="","",D10-B10) -> -0.0068933382 | F10: =IF(D10="","",(D10-C10)/C10) -> 0.017783089
A12: Diluted EPS ($) | B12: ='Income statement'!C33 -> 0.72 | C12: ='Income statement'!H33 -> 0.79 | D12: 0.8 | E12: =IF(D12="","",(D12-B12)/B12) -> 0.11111111 | F12: =IF(D12="","",(D12-C12)/C12) -> 0.012658228
A14: Content Amortization ($M) | B14: ='Cash flow'!C19 -> 3832.07 | C14: ='Cash flow'!H19 -> 4440.98 | D14: 4311.309 | E14: =IF(D14="","",(D14-B14)/B14) -> 0.12506009 | F14: =IF(D14="","",(D14-C14)/C14) -> -0.029198735
A16: Guidance Tracker
A17: KPI | B17: Current Guidance | C17: FY26 Consensus | D17: New Guidance | E17: Direction (select after earnings)
A18: Revenue ($M) | B18: ="$"&TEXT(B25,"#,##0")&" - $"&TEXT(D25,"#,##0") -> $50,700 - $51,700 | C18: ='Income statement'!K14 -> 51327.91 | D18: ="$"&TEXT(B30,"#,##0")&" - $"&TEXT(D30,"#,##0") -> $51,000 - $51,400
A19: Revenue Growth YoY (%) | B19: =TEXT(B26,"0%")&" - "&TEXT(D26,"0%") -> 12% - 14% | C19: =(C18/'Income statement'!F14)-1 -> 0.13599948 | D19: =TEXT(B31,"0%")&" - "&TEXT(D31,"0%") -> 13% - 14% | E19: Raised Low end
A20: Operating Income ($M, implied) | B20: ="$"&TEXT(B25*B27,"#,##0")&" - $"&TEXT(D25*B27,"#,##0") -> $15,971 - $16,286 | C20: ='Income statement'!K21 -> 16261.81 | D20: ="$"&TEXT(B30*B32,"#,##0")&" - $"&TEXT(D30*B32,"#,##0") -> $16,065 - $16,191
A21: Operating Margin (%) | B21: =TEXT(B27,"0.0%") -> 31.5% | C21: =C20/C18 -> 0.31682198 | D21: =TEXT(B32,"0.0%") -> 31.5% | E21: Reiterated
A24: Guidance calc inputs (used in formulas above)
A25: Revenue Guidance - Low ($M) | B25: 50700 | C25: Revenue Guidance - High ($M) | D25: 51700
A26: Revenue Growth Guidance - Low (%) | B26: 0.12 | C26: Revenue Growth Guidance - High (%) | D26: 0.14
A27: Operating Margin Guidance (%) | B27: 0.315
A29: New guidance calc inputs (used in formulas above)
A30: Revenue Guidance - Low ($M) | B30: 51000 | C30: Revenue Guidance - High ($M) | D30: 51400
A31: Revenue Growth Guidance - Low (%) | B31: 0.13 | C31: Revenue Growth Guidance - High (%) | D31: 0.14
A32: Operating Margin Guidance (%) | B32: 0.315

Sheet 2Q26 Consensus (CapIQ)
A1: Netflix 2Q26 Consensus — Capital IQ Pro
A2: Ticker: | B2: NasdaqGS:NFLX
A3: Estimate period: | B3: CQ2 2026
A5: KPI | B5: 2Q26 Consensus | C5: CapIQ field / note
A6: Total Revenue ($M) | B6: {=_xll.ciqfunctions.udf.CIQ($B$2,"IQ_REVENUE_EST",$B$3)} -> 12582.53 | C6: IQ_REVENUE_EST (consensus mean)
A7: UCAN Revenue ($M) | C7: No segment-level consensus in CapIQ — fill manually
A8: EMEA Revenue ($M) | C8: No segment-level consensus in CapIQ — fill manually
A9: LATAM Revenue ($M) | C9: No segment-level consensus in CapIQ — fill manually
A10: APAC Revenue ($M) | C10: No segment-level consensus in CapIQ — fill manually
A11: Operating Income ($M) | B11: {=_xll.ciqfunctions.udf.CIQ($B$2,"IQ_EBIT_EST",$B$3)} -> 4126.451 | C11: IQ_EBIT_EST (consensus mean)
A12: Operating Margin (%) | B12: =IF(OR(B11="",B6=""),"",B11/B6) -> 0.32795081 | C12: = Operating Income / Revenue
A13: Diluted EPS ($) | B13: {=_xll.ciqfunctions.udf.CIQ($B$2,"IQ_EPS_EST",$B$3)} -> 0.78995 | C13: IQ_EPS_EST (consensus mean, normalized)
A14: Content Amortization ($M) | C14: No consensus estimate for content amortization — fill manually

Sheet 1Q26 Quick Look
A1: Netflix 1Q26 Earnings First Look
A2: KPI | B2: 1Q25A | C2: 1Q26 Consensus | D2: 1Q26A | E2: YoY Growth (1Q26 vs 1Q25) | F2: Beat/(Miss) %
A3: Total Revenue ($M) | B3: ='Income statement'!B14 -> 10542.8 | C3: 12174 | D3: 12249.76 | E3: =IF(D3="","",(D3-B3)/B3) -> 0.16190765 | F3: =IF(D3="","",(D3-C3)/C3) -> 0.0062230984
A4: UCAN Revenue ($M) | B4: =Revenue!B19 -> 4617.1 | C4: 5279 | D4: 5245.3 | E4: =IF(D4="","",(D4-B4)/B4) -> 0.13605943 | F4: =IF(D4="","",(D4-C4)/C4) -> -0.0063837848
A5: EMEA Revenue ($M) | B5: =Revenue!B26 -> 3404.68 | C5: 3949 | D5: 3998.42 | E5: =IF(D5="","",(D5-B5)/B5) -> 0.17438937 | F5: =IF(D5="","",(D5-C5)/C5) -> 0.012514561
A6: LATAM Revenue ($M) | B6: =Revenue!B33 -> 1261.93 | C6: 1453 | D6: 1497.06 | E6: =IF(D6="","",(D6-B6)/B6) -> 0.18632571 | F6: =IF(D6="","",(D6-C6)/C6) -> 0.030323469
A7: APAC Revenue ($M) | B7: =Revenue!B40 -> 1259.09 | C7: 1479 | D7: 1508.98 | E7: =IF(D7="","",(D7-B7)/B7) -> 0.19846874 | F7: =IF(D7="","",(D7-C7)/C7) -> 0.020270453
A9: Operating Income ($M) | B9: ='Income statement'!B21 -> 3347 | C9: 3936 | D9: 3957 | E9: =IF(D9="","",(D9-B9)/B9) -> 0.18225276 | F9: =IF(D9="","",(D9-C9)/C9) -> 0.0053353659
A10: Operating Margin (%) | B10: =B9/B3 -> 0.31746785 | C10: =C9/C3 -> 0.32331198 | D10: =IF(OR(D9="",D3=""),"",D9/D3) -> 0.32302674 | E10: =IF(D10="","",D10-B10) -> 0.0055588915 | F10: =IF(D10="","",(D10-C10)/C10) -> -0.00088224227
A12: Diluted EPS ($) | B12: ='Income statement'!B33 -> 0.66 | C12: 0.76 | D12: 1.23 | E12: =IF(D12="","",(D12-B12)/B12) -> 0.86363636 | F12: =IF(D12="","",(D12-C12)/C12) -> 0.61842105
A14: Content Amortization ($M) | B14: ='Cash flow'!B19 -> 3823.11 | D14: 4217.9 | E14: =IF(D14="","",(D14-B14)/B14) -> 0.1032641 | F14: =IF(OR(D14="",C14=""),"",(D14-C14)/C14)
A16: Guidance Tracker
A17: KPI | B17: Current Guidance | C17: FY26 Consensus | D17: New Guidance | E17: Direction
A18: Revenue ($M) | B18: ="$"&TEXT(B25,"#,##0")&" - $"&TEXT(D25,"#,##0") -> $50,700 - $51,700 | C18: 51373 | D18: =B18 -> $50,700 - $51,700 | E18: Reiterated
A19: Revenue Growth YoY (%) | B19: =TEXT(B26,"0%")&" - "&TEXT(D26,"0%") -> 12% - 14% | C19: =(C18/'Income statement'!F14)-1 -> 0.13699742 | D19: =B19 -> 12% - 14% | E19: Reiterated
A20: Operating Income ($M, implied) | B20: ="$"&TEXT(B25*B27,"#,##0")&" - $"&TEXT(D25*B27,"#,##0") -> $15,971 - $16,286 | C20: 16384 | D20: =B20 -> $15,971 - $16,286 | E20: Reiterated
A21: Operating Margin (%) | B21: =TEXT(B27,"0.0%") -> 31.5% | C21: =C20/C18 -> 0.31892239 | D21: =B21 -> 31.5% | E21: Reiterated
A24: Guidance calc inputs (used in formulas above)
A25: Revenue Guidance - Low ($M) | B25: 50700 | C25: Revenue Guidance - High ($M) | D25: 51700
A26: Revenue Growth Guidance - Low (%) | B26: 0.12 | C26: Revenue Growth Guidance - High (%) | D26: 0.14
A27: Operating Margin Guidance (%) | B27: 0.315

Sheet Cash flow
A2: Netflix, Inc. | Cash flow
A3: NASDAQGS:NFLX (MI KEY: 4104060; SPCIQ KEY: 32012)
A5: Visible Alpha
A7: Period Type : Fiscal Quarter, Fiscal Halves, Fiscal Year
A8: Period Start : 2025
A9: Period End : 2030
A10: Currency : Reported
A11: Consensus View : Mean
A13: All numbers in $M unless otherwise indicated | B13: FQ1 2025A | C13: FQ2 2025A | D13: FQ3 2025A | E13: FQ4 2025A | F13: FY2025A | G13: FQ1 2026A | H13: FQ2 2026E | I13: FQ3 2026E | J13: FQ4 2026E | K13: FY2026E | L13: FQ1 2027E | M13: FQ2 2027E | N13: FQ3 2027E | O13: FQ4 2027E | P13: FY2027E | Q13: FQ1 2028E | R13: FQ2 2028E | S13: FQ3 2028E | T13: FQ4 2028E | U13: FY2028E | V13: FQ1 2029E | W13: FQ2 2029E | X13: FQ3 2029E | Y13: FQ4 2029E | Z13: FY2029E | AA13: FQ1 2030E | AB13: FQ2 2030E | AC13: FQ3 2030E | AD13: FQ4 2030E | AE13: FY2030E
A14: Number of Contributors Available | B14: 38 | C14: 38 | D14: 37 | E14: 37 | F14: 39 | G14: 36 | H14: 36 of 38 | I14: 35 of 38 | J14: 35 of 38 | K14: 38 of 38 | L14: 22 of 38 | M14: 22 of 38 | N14: 22 of 38 | O14: 22 of 38 | P14: 37 of 38 | Q14: 13 of 38 | R14: 13 of 38 | S14: 13 of 38 | T14: 13 of 38 | U14: 32 of 38 | V14: 9 of 38 | W14: 9 of 38 | X14: 9 of 38 | Y14: 9 of 38 | Z14: 24 of 38 | AA14: 8 of 38 | AB14: 8 of 38 | AC14: 8 of 38 | AD14: 8 of 38 | AE14: 23 of 38
A15: Net income | B15: 2890.35 | C15: 3125.41 | D15: 2546.92 | E15: 2418.52 | F15: 10981.2 | G15: 5282.79 | H15: 3370.44 | I15: 3588.96 | J15: 3132.38 | K15: 15404.9 | L15: 3968.31 | M15: 4121.53 | N15: 4332.9 | O15: 3882.04 | P15: 16156.97 | Q15: 4714.09 | R15: 4947.06 | S15: 5159.42 | T15: 4718.52 | U15: 19106.82 | V15: 5519.22 | W15: 5806.7 | X15: 6107.83 | Y15: 5642.91 | Z15: 22153.62 | AA15: 6436.67 | AB15: 6808.08 | AC15: 7095.12 | AD15: 6660.41 | AE15: 25349.72
A16: Additions to streaming content library | B16: -3549.66 | C16: -3835.81 | D16: -4653.94 | E16: -5057.21 | F16: -17096.62 | G16: -4846.92 | H16: -4755.87 | I16: -4829.52 | J16: -5361.93 | K16: -19789.1 | L16: -5161.71 | M16: -5047.37 | N16: -5251.34 | O16: -5842.47 | P16: -21231.71 | Q16: -5370.58 | R16: -5314.37 | S16: -5596.81 | T16: -6208.8 | U16: -22509.93 | V16: -5734.41 | W16: -5575.18 | X16: -6004.72 | Y16: -6602.48 | Z16: -23934.31 | AA16: -5953.27 | AB16: -5722.94 | AC16: -6236.02 | AD16: -6806.41 | AE16: -25007.37
A17: Change in streaming content liabilities | B17: -411.25 | C17: -214.05 | D17: 24.26 | E17: -9.79 | F17: -610.84 | G17: 45.22 | H17: -84.44 | I17: -44.9 | J17: -1.74 | K17: -66.15 | L17: 112.16 | M17: 51.42 | N17: -20.98 | O17: 95.12 | P17: 86.08 | Q17: -66.83 | R17: 80.75 | S17: -31.36 | T17: 83.3 | U17: -67.27 | V17: 3.57 | W17: 135.1 | X17: -50.41 | Y17: 202.36 | Z17: -15.88 | AA17: -67.05 | AB17: 146.76 | AC17: -77.92 | AD17: 230.03 | AE17: -58.73
A18: Cash outlay on new streaming content | B18: -3960.91 | C18: -4049.86 | D18: -4629.67 | E18: -5067.01 | F18: -17707.46 | G18: -4801.7 | H18: -4831.01 | I18: -4867.8 | J18: -5415.72 | K18: -19877.56 | L18: -5074.48 | M18: -5007.37 | N18: -5267.66 | O18: -5768.49 | P18: -21148.69 | Q18: -5425.26 | R18: -5248.3 | S18: -5622.47 | T18: -6140.64 | U18: -22530.03 | V18: -5731.63 | W18: -5470.1 | X18: -6043.93 | Y18: -6445.09 | Z18: -23937.38 | AA18: -6003.56 | AB18: -5612.88 | AC18: -6294.47 | AD18: -6633.89 | AE18: -25049.74
A19: Amortization of streaming and DVD content | B19: 3823.11 | C19: 3832.07 | D19: 4002.74 | E19: 4764.24 | F19: 16422.17 | G19: 4217.9 | H19: 4440.98 | I19: 4353.43 | J19: 4966.89 | K19: 17923.92 | L19: 4557.17 | M19: 4720.27 | N19: 4693.17 | O19: 5352.06 | P19: 19285.01 | Q19: 4867.58 | R19: 5070.97 | S19: 4974.53 | T19: 5719.28 | U19: 20696.71 | V19: 5200.27 | W19: 5391.86 | X19: 5304.52 | Y19: 6100.5 | Z19: 22201.74 | AA19: 5484.39 | AB19: 5682.19 | AC19: 5588.99 | AD19: 6418.25 | AE19: 23492.81
A20: Depreciation and amortization of property, equipment and intangibles | B20: 80.07 | C20: 80.01 | D20: 87.33 | E20: 85.98 | F20: 333.39 | G20: 98.58 | H20: 98.93 | I20: 101.6 | J20: 102.77 | K20: 404.96 | L20: 107.66 | M20: 107.14 | N20: 110.3 | O20: 111.16 | P20: 438.86 | Q20: 121.38 | R20: 119.85 | S20: 124.77 | T20: 125.4 | U20: 472.7 | V20: 138.34 | W20: 136.13 | X20: 142.59 | Y20: 143.34 | Z20: 517.93 | AA20: 149.19 | AB20: 145.52 | AC20: 152.65 | AD20: 152.75 | AE20: 548.41
A21: Stock-based compensation expense | B21: 71.98 | C21: 80.86 | D21: 80.99 | E21: 134.62 | F21: 368.45 | G21: 140.41 | H21: 112.06 | I21: 113.85 | J21: 125.61 | K21: 486.53 | L21: 131.49 | M21: 113.59 | N21: 114.36 | O21: 130.22 | P21: 494.6 | Q21: 145.33 | R21: 119.99 | S21: 120.47 | T21: 141.49 | U21: 528.42 | V21: 159.75 | W21: 134.29 | X21: 134.93 | Y21: 154.75 | Z21: 559.04 | AA21: 166.1 | AB21: 135.82 | AC21: 137.36 | AD21: 160.13 | AE21: 581.44
A22: Total other non-cash expenses | B22: -20.65 | C22: 39.62 | D22: 161.12 | E22: 27.65 | F22: 207.74 | G22: 246.94 | H22: -11.26 | I22: -9.66 | J22: 9.93 | K22: 232.64 | L22: 55.81 | M22: 42.23 | N22: 44.14 | O22: 61.39 | P22: 118.33 | Q22: 87.1 | R22: 71.46 | S22: 76.07 | T22: 92.78 | U22: 125.57 | V22: 145.93 | W22: 118.86 | X22: 126.25 | Y22: 155.41 | Z22: 74.04 | AA22: 145.54 | AB22: 117.44 | AC22: 125 | AD22: 154.97 | AE22: 16.79
A23: Change in total other current assets | B23: 175.05 | C23: -443.92 | D23: 537.55 | E23: -178.12 | F23: 90.56 | G23: 591.26 | H23: -582.83 | I23: -38.99 | J23: -330.83 | K23: -403.33 | L23: 579.91 | M23: -372.28 | N23: 1.81 | O23: -219.31 | P23: 260.48 | Q23: 669.18 | R23: -498.45 | S23: 131.48 | T23: -192.82 | U23: 13.69 | V23: 643.48 | W23: -504.45 | X23: 140.56 | Y23: 21.52 | Z23: 127.04 | AA23: 558.93 | AB23: -740.59 | AC23: 37.67 | AD23: -42.78 | AE23: -35.72
A24: Change in accounts payable | B24: -276.43 | C24: 11.05 | D24: 139.45 | E24: 117.89 | F24: -8.04 | G24: 0.15 | H24: -117.02 | I24: 54.87 | J24: 49.38 | K24: 3.16 | L24: 48.64 | M24: -78.28 | N24: 95.9 | O24: 84.77 | P24: 123.19 | Q24: 47.87 | R24: -143.18 | S24: 96.81 | T24: 65.5 | U24: 76.41 | V24: 71.9 | W24: -150.17 | X24: 99.87 | Y24: 57.09 | Z24: 9.85 | AA24: 46.55 | AB24: -180.6 | AC24: 107.51 | AD24: 90.05 | AE24: 0.72
A25: Change in deferred revenue | B25: 88.91 | C25: 118.64 | D25: -3.69 | E25: 51.05 | F25: 254.92 | G25: -32.28 | H25: 88.53 | I25: 32.78 | J25: 41.98 | K25: 89.99 | L25: -4.85 | M25: 109.3 | N25: 32.18 | O25: 63.94 | P25: 179.19 | Q25: -21.69 | R25: 142.47 | S25: 45.94 | T25: 76.85 | U25: 255.54 | V25: 4.66 | W25: 187.42 | X25: 49.14 | Y25: 119.07 | Z25: 307.06 | AA25: -121.03 | AB25: 238.35 | AC25: 40.28 | AD25: 125.94 | AE25: 262.83
A26: Change in other non-current assets and liabilities | B26: -82.28 | C26: -370.62 | D26: -97.57 | E26: -243.18 | F26: -793.65 | G26: -453.84 | H26: -27.81 | I26: -142.45 | J26: -148.33 | K26: -591.72 | L26: -152.26 | M26: 29.58 | N26: -171.01 | O26: -137.03 | P26: -326.23 | Q26: -119.56 | R26: 181.92 | S26: -183.91 | T26: -295.69 | U26: -371.51 | V26: -170.77 | W26: 265.55 | X26: -228.24 | Y26: -378.48 | Z26: -465.03 | AA26: -42.19 | AB26: 253.07 | AC26: -187.14 | AD26: -362.67 | AE26: -371.28
... A29: Purchases of property and equipment | B29: 128.28 | C29: 155.89 | D29: 164.72 | E29: 239.34 | F29: 688.22 | G29: 196.13 | H29: 172.7 | I29: 182.72 | J29: 199.01 | K29: 730.42 | L29: 186.76 | M29: 175.03 | N29: 196.4 | O29: 210.92 | P29: 747.26 | Q29: 201.18 | R29: 200.03 | S29: 207.32 | T29: 237.16 | U29: 788.77 | V29: 231.38 | W29: 229.93 | X29: 238.83 | Y29: 276.68 | Z29: 889.36 | AA29: 239.57 | AB29: 238.17 | AC29: 247.24 | AD29: 290.66 | AE29: 933.47
A30: Proceeds/(payments) of investments | B30: 613.94 | C30: 960.76 | D30: 172.4 | E30: -17.19 | F30: 1729.91 | G30: -585.74 | H30: 28.68 | I30: - | J30: - | K30: -415.77 | L30: - | M30: - | N30: - | O30: - | P30: 723.51 | Q30: - | R30: - | S30: - | T30: - | U30: 842.05 | V30: - | W30: - | X30: - | Y30: - | Z30: - | AA30: - | AB30: - | AC30: - | AD30: - | AE30: -
A31: Total other investing activities | B31: 769.95 | C31: -36.19 | D31: 36.19 | E31: -17.19 | F31: -17.19 | G31: -585.74 | H31: - | I31: - | J31: - | K31: -585.74 | L31: - | M31: - | N31: - | O31: - | P31: -300 | Q31: - | R31: - | S31: - | T31: - | U31: - | V31: - | W31: - | X31: - | Y31: - | Z31: - | AA31: - | AB31: - | AC31: - | AD31: - | AE31: -
A32: Net cash provided by/(used in) investing activities | B32: 485.66 | C32: 768.68 | D32: 43.87 | E32: -256.53 | F32: 1041.69 | G32: -781.87 | H32: -171.6 | I32: -177.27 | J32: -199.01 | K32: -1191.04 | L32: -186.76 | M32: -175.03 | N32: -187.93 | O32: -210.92 | P32: -688.8 | Q32: -201.18 | R32: -200.03 | S32: -207.32 | T32: -237.16 | U32: -728.62 | V32: -231.38 | W32: -229.93 | X32: -238.83 | Y32: -276.68 | Z32: -889.36 | AA32: -239.57 | AB32: -238.17 | AC32: -247.24 | AD32: -290.66 | AE32: -933.47
A33: Repurchases of common stock | B33: 3536.4 | C33: 1654.33 | D33: 1856.88 | E33: 2079.56 | F33: 9127.17 | G33: 1270.59 | H33: 2241.3 | I33: 2178.83 | J33: 2199.99 | K33: 7282.86 | L33: 2431.05 | M33: 2278.42 | N33: 2503.94 | O33: 2478.05 | P33: 9679.35 | Q33: 2788.13 | R33: 2540.04 | S33: 2866.97 | T33: 2657.34 | U33: 11454.33 | V33: 3050.96 | W33: 3054.14 | X33: 3177.36 | Y33: 3180.6 | Z33: 15042.74 | AA33: 3403.53 | AB33: 3407.67 | AC33: 3591.85 | AD33: 3596.07 | AE33: 17514.05
A34: Proceeds from Issuance of Equity | B34: 351.6 | C34: 169.07 | D34: 70.22 | E34: 76.08 | F34: 666.97 | G34: 49.31 | H34: 39.18 | I34: 35.24 | J34: 36.85 | K34: 132.06 | L34: 47.13 | M34: 46.41 | N34: 46.94 | O34: 48.66 | P34: 131.17 | Q34: 59.73 | R34: 57.95 | S34: 58.56 | T34: 61.4 | U34: 172.91 | V34: 88.14 | W34: 85.61 | X34: 86.55 | Y34: 90.71 | Z34: 187.41 | AA34: 117.08 | AB34: 113.91 | AC34: 115.22 | AD34: 120.64 | AE34: 211.07
A35: Issue/(repurchase) of shares | B35: -3184.79 | C35: -1485.26 | D35: -1786.67 | E35: -2003.48 | F35: -8460.2 | G35: -1221.28 | H35: -2035.47 | I35: -1877.2 | J35: -1922.48 | K35: -7044.5 | L35: -2405.38 | M35: -2272.65 | N35: -2281.98 | O35: -2259.66 | P35: -8387.04 | Q35: -2986.18 | R35: -2789.13 | S35: -3050.19 | T35: -2614.48 | U35: -9340.25 | V35: -2962.62 | W35: -2966.5 | X35: -3042.81 | Y35: -3041.72 | Z35: -11184.94 | AA35: -3324.51 | AB35: -3329.14 | AC35: -3433.45 | AD35: -3431.99 | AE35: -12555.38
A36: Net change in debt | B36: -800 | C36: -1033.45 | D36: 70.22 | E36: 70.1 | F36: -1833.45 | G36: - | H36: 99.46 | I36: - | J36: -1000 | K36: -737.78 | L36: -900 | M36: -762 | N36: -917.25 | O36: -1000 | P36: -1179.33 | Q36: -550 | R36: -1597.33 | S36: -600 | T36: 0 | U36: -1448.67 | V36: -1300 | W36: 912 | X36: -3198 | Y36: -63.33 | Z36: -1373 | AA36: -700 | AB36: -1542.67 | AC36: 2164 | AD36: - | AE36: -571.83
A37: Total other financing activities | B37: -43.52 | C37: 15.84 | D37: 49.64 | E37: -73.93 | F37: -51.97 | G37: -9.54 | H37: -13.13 | I37: -6.51 | J37: -257.58 | K37: -111.76 | L37: -10.8 | M37: -6.74 | N37: -6.75 | O37: -10.77 | P37: -282.64 | Q37: -11.21 | R37: -6.98 | S37: -6.99 | T37: -11.18 | U37: -257.45 | V37: -18.94 | W37: -12.35 | X37: -12.36 | Y37: -18.89 | Z37: 821.22 | AA37: -19.6 | AB37: -12.74 | AC37: -12.76 | AD37: -19.55 | AE37: 1505.66
A38: Net cash provided by/(used in) financing activities | B38: -4028.32 | C38: -2502.87 | D38: -1737.03 | E38: -2077.41 | F38: -10345.62 | G38: -1230.81 | H38: -2173.76 | I38: -2095.92 | J38: -2268.22 | K38: -7689.39 | L38: -2780.66 | M38: -2612.47 | N38: -2691.66 | O38: -2503.07 | P38: -9201.89 | Q38: -3099.54 | R38: -2973.11 | S38: -3172.29 | T38: -2617.83 | U38: -10718.75 | V38: -3292.35 | W38: -2741.59 | X38: -3845.4 | Y38: -2729.06 | Z38: -12409.16 | AA38: -4001.8 | AB38: -3993.92 | AC38: -3127.95 | AD38: -4010.51 | AE38: -13736.08
A39: Effect of exchange rate changes on cash and cash equivalents | B39: 150.15 | C39: 287.47 | D39: -21.72 | E39: -29.38 | F39: 386.52 | G39: -49.84 | H39: - | I39: - | J39: - | K39: -70.68 | L39: - | M39: - | N39: - | O39: - | P39: - | Q39: - | R39: - | S39: - | T39: - | U39: - | V39: - | W39: - | X39: - | Y39: - | Z39: - | AA39: - | AB39: - | AC39: - | AD39: - | AE39: -
A40: Net increase/(decrease) in cash and cash equivalents | B40: -603.31 | C40: 976.54 | D40: 1110.3 | E40: -251.67 | F40: 1231.86 | G40: 3227.68 | H40: 354.6 | I40: 1117.65 | J40: 202.62 | K40: 4613.8 | L40: 1515.03 | M40: 1276.93 | N40: 1428.9 | O40: 1144.94 | P40: 5433.52 | Q40: 2012.66 | R40: 1501.39 | S40: 1844.86 | T40: 1775.06 | U40: 7048.89 | V40: 2721.31 | W40: 3083.03 | X40: 2156.2 | Y40: 2594.69 | Z40: 8870.28 | AA40: 3464.39 | AB40: 2969.18 | AC40: 3806.01 | AD40: 3471.69 | AE40: 11440.72
A41: Cash and cash equivalents, beginning of period | B41: 7807.34 | C41: 7204.03 | D41: 8180.57 | E41: 9290.87 | F41: 7807.34 | G41: 9039.19 | H41: 12643.85 | I41: 13012.95 | J41: 14130.6 | K41: 9561.18 | L41: 14110.73 | M41: 15625.75 | N41: 16902.69 | O41: 18331.59 | P41: 14418.7 | Q41: 16820.03 | R41: 18832.7 | S41: 20334.09 | T41: 22178.95 | U41: 19038.06 | V41: 23821.01 | W41: 26542.33 | X41: 29625.36 | Y41: 31781.56 | Z41: 25403.03 | AA41: 34868.14 | AB41: 38332.53 | AC41: 41301.71 | AD41: 45107.72 | AE41: 34464.92
A42: Cash and cash equivalents, end of period | B42: 7204.03 | C42: 8180.57 | D42: 9290.87 | E42: 9039.19 | F42: 9039.19 | G42: 12266.87 | H42: 13012.95 | I42: 14130.6 | J42: 14333.22 | K42: 14165.66 | L42: 15625.75 | M42: 16902.69 | N42: 18331.59 | O42: 19476.53 | P42: 19598.91 | Q42: 18832.7 | R42: 20334.09 | S42: 22178.95 | T42: 23954.01 | U42: 26086.96 | V42: 26542.33 | W42: 29625.36 | X42: 31781.56 | Y42: 34376.25 | Z42: 34273.31 | AA42: 38332.53 | AB42: 41301.71 | AC42: 45107.72 | AD42: 48579.42 | AE42: 45333.6
A43: Free cash flow | B43: 2660.92 | C43: 2267.37 | D43: 2660.45 | E43: 1872.31 | F43: 9461.05 | G43: 5094.07 | H43: 2450.99 | I43: 3081.67 | J43: 2407.5 | K43: 12989.67 | L43: 3962.16 | M43: 3561.08 | N43: 3862.97 | O43: 3387.09 | P43: 14795.81 | Q43: 4780.8 | R43: 4452.77 | S43: 4702.68 | T43: 4161.72 | U43: 17420.22 | V43: 5647.85 | W43: 5520 | X43: 5574.33 | Y43: 5323.75 | Z43: 20596.32 | AA43: 6465.74 | AB43: 6463.86 | AC43: 6542.97 | AD43: 6479.58 | AE43: 23826.74

Sheet Segment
A1: Netflix, Inc. | Segment
A2: NASDAQGS:NFLX (MI KEY: 4104060; SPCIQ KEY: 32012)
A4: Visible Alpha
A6: Period Type : Fiscal Quarter, Fiscal Halves, Fiscal Year
A7: Period Start : 2025
A8: Period End : 2030
A9: Currency : Reported
A10: Consensus View : Mean
A12: All numbers in $M unless otherwise indicated | B12: FQ1 2025A | C12: FQ2 2025A | D12: FQ3 2025A | E12: FQ4 2025A | F12: FY2025A | G12: FQ1 2026A | H12: FQ2 2026E | I12: FQ3 2026E | J12: FQ4 2026E | K12: FY2026E | L12: FQ1 2027E | M12: FQ2 2027E | N12: FQ3 2027E | O12: FQ4 2027E | P12: FY2027E | Q12: FQ1 2028E | R12: FQ2 2028E | S12: FQ3 2028E | T12: FQ4 2028E | U12: FY2028E | V12: FQ1 2029E | W12: FQ2 2029E | X12: FQ3 2029E | Y12: FQ4 2029E | Z12: FY2029E | AA12: FQ1 2030E | AB12: FQ2 2030E | AC12: FQ3 2030E | AD12: FQ4 2030E | AE12: FY2030E
A13: Number of Contributors Available | B13: 38 | C13: 38 | D13: 37 | E13: 37 | F13: 39 | G13: 36 | H13: 36 of 38 | I13: 35 of 38 | J13: 35 of 38 | K13: 38 of 38 | L13: 22 of 38 | M13: 22 of 38 | N13: 22 of 38 | O13: 22 of 38 | P13: 37 of 38 | Q13: 13 of 38 | R13: 13 of 38 | S13: 13 of 38 | T13: 13 of 38 | U13: 32 of 38 | V13: 9 of 38 | W13: 9 of 38 | X13: 9 of 38 | Y13: 9 of 38 | Z13: 24 of 38 | AA13: 8 of 38 | AB13: 8 of 38 | AC13: 8 of 38 | AD13: 8 of 38 | AE13: 23 of 38
A14: Total revenue
A15: Revenues - UCAN Streaming | B15: 4617.1 | C15: 4929 | D15: 5071.78 | E15: 5339.27 | F15: 19957.15 | G15: 5245.3 | H15: 5522.9 | I15: 5694.52 | J15: 5964.08 | K15: 22388.21 | L15: 5862.28 | M15: 6115.19 | N15: 6316.58 | O15: 6599.95 | P15: 24627 | Q15: 6475.19 | R15: 6759.07 | S15: 6981.91 | T15: 7301.69 | U15: 26925.5 | V15: 7095.19 | W15: 7419.64 | X15: 7681.98 | Y15: 8061.26 | Z15: 29282.83 | AA15: 7787.47 | AB15: 8144.42 | AC15: 8462.14 | AD15: 8815.92 | AE15: 31654.53
A16: Revenues - EMEA Streaming | B16: 3404.68 | C16: 3538.18 | D16: 3699.05 | E16: 3872.74 | F16: 14514.65 | G16: 3998.42 | H16: 4014.96 | I16: 4152.32 | J16: 4321.92 | K16: 16451.97 | L16: 4477.92 | M16: 4486.21 | N16: 4630.99 | O16: 4830.21 | P16: 18341.25 | Q16: 4969.41 | R16: 4974.41 | S16: 5102.9 | T16: 5326.33 | U16: 20192.07 | V16: 5561.05 | W16: 5539.03 | X16: 5687.46 | Y16: 5937.46 | Z16: 22141.57 | AA16: 5988.03 | AB16: 5984.12 | AC16: 6123.34 | AD16: 6395.2 | AE16: 23864.23
A17: Revenues - LATAM Streaming | B17: 1261.93 | C17: 1306.73 | D17: 1370.91 | E17: 1417.94 | F17: 5357.52 | G17: 1497.06 | H17: 1504.65 | I17: 1568.41 | J17: 1612.19 | K17: 6175.17 | L17: 1673.99 | M17: 1677.62 | N17: 1746.9 | O17: 1800.15 | P17: 6892.44 | Q17: 1866.17 | R17: 1876.09 | S17: 1957.03 | T17: 2010.98 | U17: 7662.52 | V17: 2064.77 | W17: 2068.5 | X17: 2169.93 | Y17: 2230.1 | Z17: 8442.5 | AA17: 2290.03 | AB17: 2307.11 | AC17: 2400.43 | AD17: 2462.99 | AE17: 9277.16
A18: Revenues - APAC Streaming | B18: 1259.09 | C18: 1305.25 | D18: 1368.56 | E18: 1420.81 | F18: 5353.72 | G18: 1508.98 | H18: 1522.16 | I18: 1579.58 | J18: 1646.62 | K18: 6261.1 | L18: 1741.14 | M18: 1756.89 | N18: 1827.11 | O18: 1903.25 | P18: 7196.04 | Q18: 1974.9 | R18: 1982.4 | S18: 2059.27 | T18: 2142.67 | U18: 8145.13 | V18: 2226.72 | W18: 2226.79 | X18: 2318.83 | Y18: 2406.57 | Z18: 9055.37 | AA18: 2476.65 | AB18: 2468.66 | AC18: 2567.47 | AD18: 2657.65 | AE18: 9971.83
A19: Revenue - Global Streaming | B19: 10542.8 | C19: 11079.17 | D19: 11510.31 | E19: 12050.76 | F19: 45183.04 | G19: 12249.76 | H19: 12563.07 | I19: 12984.49 | J19: 13537.05 | K19: 51251.1 | L19: 13745.89 | M19: 14023.53 | N19: 14498.18 | O19: 15109.21 | P19: 57018.92 | Q19: 15243.47 | R19: 15543.73 | S19: 16032.24 | T19: 16706.84 | U19: 62774.15 | V19: 17097.24 | W19: 17358.66 | X19: 17926.62 | Y19: 18659.89 | Z19: 68898.8 | AA19: 18734.82 | AB19: 19034.41 | AC19: 19612.74 | AD19: 20276.93 | AE19: 74593.21
A20: Revenues - Domestic DVD | B20: - | C20: - | D20: - | E20: - | F20: - | G20: - | H20: - | I20: - | J20: - | K20: - | L20: - | M20: - | N20: - | O20: - | P20: - | Q20: - | R20: - | S20: - | T20: - | U20: - | V20: - | W20: - | X20: - | Y20: - | Z20: - | AA20: - | AB20: - | AC20: - | AD20: - | AE20: -
A21: Total revenues | B21: 10542.8 | C21: 11079.17 | D21: 11510.31 | E21: 12050.76 | F21: 45183.04 | G21: 12249.76 | H21: 12574.71 | I21: 13012.99 | J21: 13566.97 | K21: 51327.91 | L21: 13802.84 | M21: 14094.47 | N21: 14588.28 | O21: 15180.57 | P21: 57249.29 | Q21: 15339.32 | R21: 15632.33 | S21: 16151.29 | T21: 16839.62 | U21: 63122.51 | V21: 16947.74 | W21: 17253.96 | X21: 17858.2 | Y21: 18635.39 | Z21: 69141.19 | AA21: 18542.17 | AB21: 18904.31 | AC21: 19553.38 | AD21: 20331.76 | AE21: 75079.31
A23: Cost of revenue
A24: Cost of revenues - Total streaming | B24: 5263.15 | C24: 5325.31 | D24: 6164.25 | E24: 6522.62 | F24: 23275.33 | G24: 5888.24 | H24: 6135.42 | I24: 6176.98 | J24: 6882.21 | K24: 25082.85 | L24: 6401.62 | M24: 6585.71 | N24: 6643.94 | O24: 7554.67 | P24: 26936.68 | Q24: - | R24: - | S24: - | T24: - | U24: 28661.99 | V24: - | W24: - | X24: - | Y24: - | Z24: 29986.41 | AA24: - | AB24: - | AC24: - | AD24: - | AE24: 31502.9
A25: Cost of revenues - Domestic DVD | B25: - | C25: - | D25: - | E25: - | F25: - | G25: - | H25: - | I25: - | J25: - | K25: - | L25: - | M25: - | N25: - | O25: - | P25: - | Q25: - | R25: - | S25: - | T25: - | U25: - | V25: - | W25: - | X25: - | Y25: - | Z25: - | AA25: - | AB25: - | AC25: - | AD25: - | AE25: -
A26: Cost of revenues | B26: 5263.15 | C26: 5325.31 | D26: 6164.25 | E26: 6522.62 | F26: 23275.33 | G26: 5888.24 | H26: 6129.48 | I26: 6270.17 | J26: 6994.44 | K26: 25230.07 | L26: 6449.16 | M26: 6637.36 | N26: 6839.76 | O26: 7605.23 | P26: 27305.55 | Q26: 6870.74 | R26: 7072.47 | S26: 7313.86 | T26: 8137.96 | U26: 29172.41 | V26: 7332.67 | W26: 7560.07 | X26: 7765.83 | Y26: 8685.24 | Z26: 30937.44 | AA26: 7695.41 | AB26: 7939.29 | AC26: 8185.8 | AD26: 9112.98 | AE26: 32577.83
A28: Gross profit/(loss)
A29: Gross profit/(loss) - Total streaming | B29: 5279.65 | C29: 5753.85 | D29: 5346.06 | E29: 5528.14 | F29: 21907.71 | G29: 6361.52 | H29: 6443.4 | I29: 6863.92 | J29: 6617.17 | K29: 26286.01 | L29: 7151.67 | M29: 7384.67 | N29: 7884.34 | O29: 7512.39 | P29: 29841.8 | Q29: - | R29: - | S29: - | T29: - | U29: 33730.15 | V29: - | W29: - | X29: - | Y29: - | Z29: 37536.65 | AA29: - | AB29: - | AC29: - | AD29: - | AE29: 41583.78
A30: Gross profit/(loss) - Domestic DVD | B30: - | C30: - | D30: - | E30: - | F30: - | G30: - | H30: - | I30: - | J30: - | K30: - | L30: - | M30: - | N30: - | O30: - | P30: - | Q30: - | R30: - | S30: - | T30: - | U30: - | V30: - | W30: - | X30: - | Y30: - | Z30: - | AA30: - | AB30: - | AC30: - | AD30: - | AE30: -
A31: Gross profit/(loss) | B31: 5279.65 | C31: 5753.85 | D31: 5346.06 | E31: 5528.14 | F31: 21907.71 | G31: 6361.52 | H31: 6445.95 | I31: 6753.36 | J31: 6568.87 | K31: 26102.02 | L31: 7353.68 | M31: 7457.11 | N31: 7748.52 | O31: 7575.34 | P31: 29973.47 | Q31: 8468.58 | R31: 8559.87 | S31: 8837.43 | T31: 8701.66 | U31: 34043.96 | V31: 9615.06 | W31: 9693.89 | X31: 10092.36 | Y31: 9950.14 | Z31: 38398.82 | AA31: 10846.76 | AB31: 10965.02 | AC31: 11367.58 | AD31: 11218.78 | AE31: 42797.42
A33: Contribution profit/(loss)
A34: Contribution profit/(loss) - Total streaming | B34: 4591.35 | C34: 5040.53 | D34: 4559.99 | E34: 4414.84 | F34: 18737.39 | G34: 5519.05 | H34: 5598.85 | I34: 5859.89 | J34: 5503.35 | K34: 22639.52 | L34: - | M34: - | N34: - | O34: - | P34: 25946.91 | Q34: - | R34: - | S34: - | T34: - | U34: 29358.39 | V34: - | W34: - | X34: - | Y34: - | Z34: 32845.98 | AA34: - | AB34: - | AC34: - | AD34: - | AE34: 36313
A35: Contribution profit/(loss) - Domestic DVD | B35: - | C35: - | D35: - | E35: - | F35: - | G35: - | H35: - | I35: - | J35: - | K35: - | L35: - | M35: - | N35: - | O35: - | P35: - | Q35: - | R35: - | S35: - | T35: - | U35: - | V35: - | W35: - | X35: - | Y35: - | Z35: - | AA35: - | AB35: - | AC35: - | AD35: - | AE35: -
A36: Contribution profit/(loss) | B36: 4591.28 | C36: 5040.59 | D36: 4559.76 | E36: 4414.77 | F36: 18606.4 | G36: 5519.3 | H36: 5607.71 | I36: 5868.54 | J36: 5379.78 | K36: 22368.17 | L36: 6453.54 | M36: 6566.53 | N36: 6823.54 | O36: 6337.18 | P36: 26023.64 | Q36: 7511.14 | R36: 7623.14 | S36: 7868.18 | T36: 7394.32 | U36: 29841.52 | V36: 8619.02 | W36: 8732.12 | X36: 9091.48 | Y36: 8541.53 | Z36: 33923.67 | AA36: 9793.31 | AB36: 9952.05 | AC36: 10315.23 | AD36: 9748.32 | AE36: 38049.71
A38: Margin
A39: Gross margin - Total streaming(%) | B39: 0.5008 | C39: 0.5193 | D39: 0.4645 | E39: 0.4587 | F39: 0.4849 | G39: 0.5193 | H39: 0.5122 | I39: 0.5263 | J39: 0.4902 | K39: 0.5117 | L39: 0.5277 | M39: 0.5286 | N39: 0.5427 | O39: 0.4986 | P39: 0.5256 | Q39: - | R39: - | S39: - | T39: - | U39: 0.5406 | V39: - | W39: - | X39: - | Y39: - | Z39: 0.5559 | AA39: - | AB39: - | AC39: - | AD39: - | AE39: 0.569
A40: Gross margin - Domestic DVD(%) | B40: - | C40: - | D40: - | E40: - | F40: - | G40: - | H40: - | I40: - | J40: - | K40: - | L40: - | M40: - | N40: - | O40: - | P40: - | Q40: - | R40: - | S40: - | T40: - | U40: - | V40: - | W40: - | X40: - | Y40: - | Z40: - | AA40: - | AB40: - | AC40: - | AD40: - | AE40: -
A41: Gross margin(%) | B41: 0.5008 | C41: 0.5193 | D41: 0.4645 | E41: 0.4587 | F41: 0.4849 | G41: 0.5193 | H41: 0.5126 | I41: 0.5188 | J41: 0.4842 | K41: 0.5086 | L41: 0.5328 | M41: 0.5291 | N41: 0.5311 | O41: 0.499 | P41: 0.5233 | Q41: 0.5521 | R41: 0.5475 | S41: 0.5469 | T41: 0.5167 | U41: 0.5384 | V41: 0.5672 | W41: 0.5615 | X41: 0.5644 | Y41: 0.5338 | Z41: 0.5534 | AA41: 0.5844 | AB41: 0.5793 | AC41: 0.5799 | AD41: 0.5511 | AE41: 0.5671
A42: Operating margin(%) | B42: 0.3175 | C42: 0.3407 | D42: 0.2822 | E42: 0.2454 | F42: 0.2949 | G42: 0.323 | H42: 0.3281 | I42: 0.3377 | J42: 0.2794 | K42: 0.3171 | L42: 0.3483 | M42: 0.3534 | N42: 0.3595 | O42: 0.3052 | P42: 0.3406 | Q42: 0.3763 | R42: 0.3822 | S42: 0.3887 | T42: 0.3306 | U42: 0.3634 | V42: 0.3969 | W42: 0.4036 | X42: 0.4161 | Y42: 0.3527 | Z42: 0.3819 | AA42: 0.4233 | AB42: 0.4314 | AC42: 0.4419 | AD42: 0.3806 | AE42: 0.4008

Sheet Income statement
A1: Netflix, Inc. | Income statement
A2: NASDAQGS:NFLX (MI KEY: 4104060; SPCIQ KEY: 32012)
A4: Visible Alpha
A6: Period Type : Fiscal Quarter, Fiscal Halves, Fiscal Year
A7: Period Start : 2025
A8: Period End : 2030
A9: Currency : Reported
A10: Consensus View : Mean
A12: All numbers in $M unless otherwise indicated | B12: FQ1 2025A | C12: FQ2 2025A | D12: FQ3 2025A | E12: FQ4 2025A | F12: FY2025A | G12: FQ1 2026A | H12: FQ2 2026E | I12: FQ3 2026E | J12: FQ4 2026E | K12: FY2026E | L12: FQ1 2027E | M12: FQ2 2027E | N12: FQ3 2027E | O12: FQ4 2027E | P12: FY2027E | Q12: FQ1 2028E | R12: FQ2 2028E | S12: FQ3 2028E | T12: FQ4 2028E | U12: FY2028E | V12: FQ1 2029E | W12: FQ2 2029E | X12: FQ3 2029E | Y12: FQ4 2029E | Z12: FY2029E | AA12: FQ1 2030E | AB12: FQ2 2030E | AC12: FQ3 2030E | AD12: FQ4 2030E | AE12: FY2030E
A13: Number of Contributors Available | B13: 38 | C13: 38 | D13: 37 | E13: 37 | F13: 39 | G13: 36 | H13: 36 of 38 | I13: 35 of 38 | J13: 35 of 38 | K13: 38 of 38 | L13: 22 of 38 | M13: 22 of 38 | N13: 22 of 38 | O13: 22 of 38 | P13: 37 of 38 | Q13: 13 of 38 | R13: 13 of 38 | S13: 13 of 38 | T13: 13 of 38 | U13: 32 of 38 | V13: 9 of 38 | W13: 9 of 38 | X13: 9 of 38 | Y13: 9 of 38 | Z13: 24 of 38 | AA13: 8 of 38 | AB13: 8 of 38 | AC13: 8 of 38 | AD13: 8 of 38 | AE13: 23 of 38
A14: Total revenues | B14: 10542.8 | C14: 11079.17 | D14: 11510.31 | E14: 12050.76 | F14: 45183.04 | G14: 12249.76 | H14: 12574.71 | I14: 13012.99 | J14: 13566.97 | K14: 51327.91 | L14: 13802.84 | M14: 14094.47 | N14: 14588.28 | O14: 15180.57 | P14: 57249.29 | Q14: 15339.32 | R14: 15632.33 | S14: 16151.29 | T14: 16839.62 | U14: 63122.51 | V14: 16947.74 | W14: 17253.96 | X14: 17858.2 | Y14: 18635.39 | Z14: 69141.19 | AA14: 18542.17 | AB14: 18904.31 | AC14: 19553.38 | AD14: 20331.76 | AE14: 75079.31
A15: Cost of revenues | B15: 5263.15 | C15: 5325.31 | D15: 6164.25 | E15: 6522.62 | F15: 23275.33 | G15: 5888.24 | H15: 6129.48 | I15: 6270.17 | J15: 6994.44 | K15: 25230.07 | L15: 6449.16 | M15: 6637.36 | N15: 6839.76 | O15: 7605.23 | P15: 27305.55 | Q15: 6870.74 | R15: 7072.47 | S15: 7313.86 | T15: 8137.96 | U15: 29172.41 | V15: 7332.67 | W15: 7560.07 | X15: 7765.83 | Y15: 8685.24 | Z15: 30937.44 | AA15: 7695.41 | AB15: 7939.29 | AC15: 8185.8 | AD15: 9112.98 | AE15: 32577.83
A16: Gross profit/(loss) | B16: 5279.65 | C16: 5753.85 | D16: 5346.06 | E16: 5528.14 | F16: 21907.71 | G16: 6361.52 | H16: 6445.95 | I16: 6753.36 | J16: 6568.87 | K16: 26102.02 | L16: 7353.68 | M16: 7457.11 | N16: 7748.52 | O16: 7575.34 | P16: 29973.47 | Q16: 8468.58 | R16: 8559.87 | S16: 8837.43 | T16: 8701.66 | U16: 34043.96 | V16: 9615.06 | W16: 9693.89 | X16: 10092.36 | Y16: 9950.14 | Z16: 38398.82 | AA16: 10846.76 | AB16: 10965.02 | AC16: 11367.58 | AD16: 11218.78 | AE16: 42797.42
A17: Marketing | B17: 688.37 | C17: 713.26 | D17: 786.29 | E17: 1113.38 | F17: 3301.31 | G17: 842.22 | H17: 836.99 | I17: 877.26 | J17: 1194.94 | K17: 3721.74 | L17: 900.14 | M17: 890.58 | N17: 924.97 | O17: 1238.15 | P17: 3930.46 | Q17: 957.44 | R17: 936.72 | S17: 969.24 | T17: 1307.33 | U17: 4146.19 | V17: 996.04 | W17: 961.77 | X17: 1000.88 | Y17: 1408.62 | Z17: 4373.9 | AA17: 1053.45 | AB17: 1012.98 | AC17: 1052.35 | AD17: 1470.46 | AE17: 4600.75
A18: Technology and development | B18: 822.82 | C18: 824.68 | D18: 853.58 | E18: 890.3 | F18: 3391.39 | G18: 959.7 | H18: 945.74 | I18: 956.7 | J18: 987.85 | K18: 3846.34 | L18: 1034.18 | M18: 1031.1 | N18: 1035.09 | O18: 1063.12 | P18: 4182.04 | Q18: 1100.89 | R18: 1092.9 | S18: 1093.6 | T18: 1127.39 | U18: 4472.12 | V18: 1194.47 | W18: 1179.31 | X18: 1176.89 | Y18: 1206.53 | Z18: 4786.2 | AA18: 1254.61 | AB18: 1243.45 | AC18: 1233.25 | AD18: 1261.55 | AE18: 5054.51
A19: General and administrative | B19: 421.46 | C19: 441.21 | D19: 457.93 | E19: 567.8 | F19: 1888.41 | G19: 602.61 | H19: 537.58 | I19: 535.24 | J19: 588.5 | K19: 2250.32 | L19: 610.95 | M19: 565.54 | N19: 567.97 | O19: 623.58 | P19: 2330.25 | Q19: 651.81 | R19: 591.23 | S19: 570.73 | T19: 661.74 | U19: 2405.91 | V19: 724.62 | W19: 626.15 | X19: 597.04 | Y19: 721.27 | Z19: 2549.64 | AA19: 756.99 | AB19: 635.76 | AC19: 608.7 | AD19: 733.81 | AE19: 2631.49
A20: Total operating expenses | B20: 1932.65 | C20: 1979.16 | D20: 2097.81 | E20: 2571.48 | F20: 8581.1 | G20: 2404.52 | H20: 2321.84 | I20: 2369.74 | J20: 2773.4 | K20: 9812.72 | L20: 2543.48 | M20: 2488.21 | N20: 2526.57 | O20: 2921.11 | P20: 10440.64 | Q20: 2704.31 | R20: 2619.44 | S20: 2627.63 | T20: 3086.04 | U20: 11016.13 | V20: 2906.11 | W20: 2762.93 | X20: 2763.48 | Y20: 3321.16 | Z20: 11697.23 | AA20: 3050.54 | AB20: 2883.82 | AC20: 2875.31 | AD20: 3442.76 | AE20: 12266.17
A21: Operating income/(loss) | B21: 3347 | C21: 3774.69 | D21: 3248.25 | E21: 2956.66 | F21: 13326.6 | G21: 3957 | H21: 4124.2 | I21: 4379.75 | J21: 3796.52 | K21: 16261.81 | L21: 4805.23 | M21: 4968.13 | N21: 5217.57 | O21: 4644.54 | P21: 19479.91 | Q21: 5752.54 | R21: 5934.79 | S21: 6195.79 | T21: 5594.07 | U21: 22892.21 | V21: 6694.34 | W21: 6919.8 | X21: 7304.01 | Y21: 6598.63 | Z21: 26442.48 | AA21: 7773.28 | AB21: 8060.74 | AC21: 8453.65 | AD21: 7730.6 | AE21: 30153.18
A22: Depreciation and amortization of property, equipment and intangibles | B22: 80.07 | C22: 80.01 | D22: 87.33 | E22: 85.98 | F22: 333.39 | G22: 98.58 | H22: 98.93 | I22: 101.6 | J22: 102.77 | K22: 404.96 | L22: 107.66 | M22: 107.14 | N22: 110.3 | O22: 111.16 | P22: 438.86 | Q22: 121.38 | R22: 119.85 | S22: 124.77 | T22: 125.4 | U22: 472.7 | V22: 138.34 | W22: 136.13 | X22: 142.59 | Y22: 143.34 | Z22: 517.93 | AA22: 149.19 | AB22: 145.52 | AC22: 152.65 | AD22: 152.75 | AE22: 548.41
A23: EBITDA | B23: 3427.07 | C23: 3854.71 | D23: 3335.57 | E23: 3042.65 | F23: 13659.99 | G23: 4055.57 | H23: 4208.04 | I23: 4466.68 | J23: 3889.55 | K23: 16640.31 | L23: 4915.85 | M23: 5064.98 | N23: 5326.61 | O23: 4748.97 | P23: 19894.49 | Q23: 5846.36 | R23: 6021.52 | S23: 6302.36 | T23: 5700.14 | U23: 23366.24 | V23: 6832.68 | W23: 7055.93 | X23: 7446.6 | Y23: 6741.97 | Z23: 27023.2 | AA23: 7922.47 | AB23: 8206.26 | AC23: 8606.29 | AD23: 7883.35 | AE23: 30774.81
A24: SBC | B24: 71.98 | C24: 80.86 | D24: 80.99 | E24: 134.62 | F24: 368.45 | G24: 140.41 | H24: 111.07 | I24: 112.66 | J24: 126.83 | K24: 482.28 | L24: 133.22 | M24: 114.27 | N24: 114.97 | O24: 132.61 | P24: 495.17 | Q24: 146.95 | R24: 118.63 | S24: 119.08 | T24: 144.35 | U24: 530.8 | V24: 159.75 | W24: 134.29 | X24: 134.93 | Y24: 154.75 | Z24: 566.14 | AA24: 166.1 | AB24: 135.82 | AC24: 137.36 | AD24: 160.13 | AE24: 592.36
A25: EBITDA (ex-SBC) | B25: 3499.04 | C25: 3935.57 | D25: 3416.56 | E25: 3177.27 | F25: 14028.44 | G25: 4195.98 | H25: 4322.65 | I25: 4574.39 | J25: 4009.57 | K25: 17129 | L25: 5055.29 | M25: 5187.44 | N25: 5443.55 | O25: 4882.01 | P25: 20421.28 | Q25: 5993.31 | R25: 6140.14 | S25: 6421.44 | T25: 5844.49 | U25: 23906.03 | V25: 6992.43 | W25: 7190.22 | X25: 7581.54 | Y25: 6896.71 | Z25: 27589.93 | AA25: 8088.57 | AB25: 8342.08 | AC25: 8743.66 | AD25: 8043.48 | AE25: 31367.26
... A37: Net income/(loss) | B37: 2890.35 | C37: 3125.41 | D37: 2546.92 | E37: 2418.52 | F37: 10981.2 | G37: 5282.79 | H37: 3380.99 | I37: 3603.56 | J37: 3126.68 | K37: 15374.91 | L37: 3968.25 | M37: 4116.14 | N37: 4323.71 | O37: 3870.82 | P37: 16175.62 | Q37: 4739.17 | R37: 4955.1 | S37: 5152.82 | T37: 4719.5 | U37: 19066.65 | V37: 5519.22 | W37: 5806.7 | X37: 6107.83 | Y37: 5642.91 | Z37: 22094.24 | AA37: 6436.67 | AB37: 6808.08 | AC37: 7095.12 | AD37: 6660.41 | AE37: 25280.94
A38: SBC adj. in Net income | B38: 71.98 | C38: 80.86 | D38: 80.99 | E38: 134.62 | F38: 368.45 | G38: 140.41 | H38: 105.26 | I38: 108.81 | J38: 130.14 | K38: 470.57 | L38: 157.64 | M38: 101.8 | N38: 101.37 | O38: 169.17 | P38: 470.51 | Q38: 121.77 | R38: 108.64 | S38: 120.47 | T38: 118.65 | U38: 484.77 | V38: - | W38: - | X38: - | Y38: - | Z38: 520.61 | AA38: - | AB38: - | AC38: - | AD38: - | AE38: 551.77
A39: Tax Effect of Non-GAAP Entries in Net income | B39: -174.31 | C39: -268.87 | D39: -298.7 | E39: -199.93 | F39: -941.81 | G39: -663.25 | H39: -293.67 | I39: -327.79 | J39: -255.98 | K39: -1540.7 | L39: - | M39: - | N39: - | O39: - | P39: -1472.81 | Q39: - | R39: - | S39: - | T39: - | U39: -1703.6 | V39: - | W39: - | X39: - | Y39: - | Z39: -1897.83 | AA39: - | AB39: - | AC39: - | AD39: - | AE39: -2097.64
A40: SBC and other adjustment, net of tax | B40: 71.98 | C40: 80.86 | D40: -0.7 | E40: 64.93 | F40: 368.45 | G40: -56.23 | H40: 22.57 | I40: 15.35 | J40: 51.11 | K40: 103.31 | L40: 125.55 | M40: 106.94 | N40: 106.79 | O40: 129.39 | P40: 132.53 | Q40: 121.77 | R40: 108.64 | S40: 120.47 | T40: 118.65 | U40: 30.08 | V40: - | W40: - | X40: - | Y40: - | Z40: -212.4 | AA40: - | AB40: - | AC40: - | AD40: - | AE40: -255.41
A41: Net income/(loss) - Operating | B41: 2962.33 | C41: 3206.28 | D41: 2546.28 | E41: 2476.98 | F41: 11349.65 | G41: 5232.81 | H41: 3413.24 | I41: 3625.2 | J41: 3124.02 | K41: 15447.63 | L41: 4067.99 | M41: 4146.7 | N41: 4312.61 | O41: 3911.16 | P41: 16194.5 | Q41: 4893.25 | R41: 4971.28 | S41: 5259.83 | T41: 4701.63 | U41: 18873.12 | V41: 5675.4 | W41: 5686.14 | X41: 6382.11 | Y41: 5435.19 | Z41: 20978.15 | AA41: - | AB41: - | AC41: - | AD41: - | AE41: 23123.19
A42: EPS - Diluted - Operating($) | B42: 0.68 | C42: 0.74 | D42: 0.59 | E42: 0.59 | F42: 2.56 | G42: 1.14 | H42: 0.8 | I42: 0.85 | J42: 0.73 | K42: 3.55 | L42: 0.96 | M42: 0.97 | N42: 1.01 | O42: 0.92 | P42: 3.77 | Q42: 1.16 | R42: 1.18 | S42: 1.25 | T42: 1.12 | U42: 4.44 | V42: 1.39 | W42: 1.4 | X42: 1.58 | Y42: 1.35 | Z42: 4.95 | AA42: - | AB42: - | AC42: - | AD42: - | AE42: 5.38

Sheet Revenue
A1: Netflix, Inc. | Revenue
A2: NASDAQGS:NFLX (MI KEY: 4104060; SPCIQ KEY: 32012)
A4: Visible Alpha
A6: Period Type : Fiscal Quarter, Fiscal Halves, Fiscal Year
A7: Period Start : 2025
A8: Period End : 2030
A9: Currency : Reported
A10: Consensus View : Mean
A12: All numbers in $M unless otherwise indicated | B12: FQ1 2025A | C12: FQ2 2025A | D12: FQ3 2025A | E12: FQ4 2025A | F12: FY2025A | G12: FQ1 2026A | H12: FQ2 2026E | I12: FQ3 2026E | J12: FQ4 2026E | K12: FY2026E | L12: FQ1 2027E | M12: FQ2 2027E | N12: FQ3 2027E | O12: FQ4 2027E | P12: FY2027E | Q12: FQ1 2028E | R12: FQ2 2028E | S12: FQ3 2028E | T12: FQ4 2028E | U12: FY2028E | V12: FQ1 2029E | W12: FQ2 2029E | X12: FQ3 2029E | Y12: FQ4 2029E | Z12: FY2029E | AA12: FQ1 2030E | AB12: FQ2 2030E | AC12: FQ3 2030E | AD12: FQ4 2030E | AE12: FY2030E
A13: Number of Contributors Available | B13: 38 | C13: 38 | D13: 37 | E13: 37 | F13: 39 | G13: 36 | H13: 36 of 38 | I13: 35 of 38 | J13: 35 of 38 | K13: 38 of 38 | L13: 22 of 38 | M13: 22 of 38 | N13: 22 of 38 | O13: 22 of 38 | P13: 37 of 38 | Q13: 13 of 38 | R13: 13 of 38 | S13: 13 of 38 | T13: 13 of 38 | U13: 32 of 38 | V13: 9 of 38 | W13: 9 of 38 | X13: 9 of 38 | Y13: 9 of 38 | Z13: 24 of 38 | AA13: 8 of 38 | AB13: 8 of 38 | AC13: 8 of 38 | AD13: 8 of 38 | AE13: 23 of 38
A14: United States and Canada(UCAN)
A15: Net adds - UCAN Streaming subs(M#) | B15: 1 | C15: 1 | D15: 1 | E15: 2.35 | F15: 4.71 | G15: 0.61 | H15: 0.6 | I15: 0.64 | J15: 1.36 | K15: 3.08 | L15: 0.62 | M15: 0.55 | N15: 0.61 | O15: 1.22 | P15: 3.19 | Q15: 0.51 | R15: 0.38 | S15: 0.44 | T15: 0.75 | U15: 2.06 | V15: 0.51 | W15: 0.35 | X15: 0.4 | Y15: 0.69 | Z15: 1.99 | AA15: 0.51 | AB15: 0.33 | AC15: 0.38 | AD15: 0.7 | AE15: 1.85
A16: Ending subs - UCAN Streaming(M#) | B16: 90.62 | C16: 91.07 | D16: 92.21 | E16: 94.61 | F16: 94.49 | G16: 95.24 | H16: 95.84 | I16: 96.47 | J16: 97.86 | K16: 97.58 | L16: 98.7 | M16: 99.21 | N16: 99.78 | O16: 100.93 | P16: 100.63 | Q16: 100.92 | R16: 101.3 | S16: 101.74 | T16: 102.49 | U16: 102.21 | V16: 102.55 | W16: 102.9 | X16: 103.3 | Y16: 103.99 | Z16: 103.81 | AA16: 105.4 | AB16: 105.73 | AC16: 106.11 | AD16: 106.81 | AE16: 105.96
A17: Average subs - UCAN Streaming(M#) | B17: 90.12 | C17: 90.59 | D17: 91.71 | E17: 93.53 | F17: 91.56 | G17: 95 | H17: 95.58 | I17: 96.21 | J17: 97.31 | K17: 95.98 | L17: 98.65 | M17: 99.19 | N17: 99.77 | O17: 100.78 | P17: 99.23 | Q17: 101.49 | R17: 101.95 | S17: 102.45 | T17: 103.32 | U17: 101.57 | V17: 102.3 | W17: 102.73 | X17: 103.1 | Y17: 103.64 | Z17: 102.81 | AA17: 105.15 | AB17: 105.57 | AC17: 105.92 | AD17: 106.46 | AE17: 105.04
A18: ARPU - UCAN Streaming($) | B18: 17.08 | C18: 18.08 | D18: 18.36 | E18: 18.93 | F18: 18.13 | G18: 18.44 | H18: 19.25 | I18: 19.71 | J18: 20.37 | K18: 19.43 | L18: 19.73 | M18: 20.44 | N18: 20.99 | O18: 21.66 | P18: 20.64 | Q18: 21.29 | R18: 22.09 | S18: 22.7 | T18: 23.55 | U18: 21.93 | V18: 23.45 | W18: 24.44 | X18: 25.28 | Y18: 26.36 | Z18: 23.79 | AA18: 25.35 | AB18: 26.39 | AC18: 27.45 | AD18: 28.38 | AE18: 25.16
A19: Revenues - UCAN Streaming | B19: 4617.1 | C19: 4929 | D19: 5071.78 | E19: 5339.27 | F19: 19957.15 | G19: 5245.3 | H19: 5522.9 | I19: 5694.52 | J19: 5964.08 | K19: 22388.21 | L19: 5862.28 | M19: 6115.19 | N19: 6316.58 | O19: 6599.95 | P19: 24627 | Q19: 6475.19 | R19: 6759.07 | S19: 6981.91 | T19: 7301.69 | U19: 26925.5 | V19: 7095.19 | W19: 7419.64 | X19: 7681.98 | Y19: 8061.26 | Z19: 29282.83 | AA19: 7787.47 | AB19: 8144.42 | AC19: 8462.14 | AD19: 8815.92 | AE19: 31654.53
A21: Europe, Middle East and Africa (EMEA)
A22: Net adds - EMEA Streaming subs(M#) | B22: 1.5 | C22: 2 | D22: 2 | E22: 2.5 | F22: 7.85 | G22: 1.22 | H22: 1.12 | I22: 1.25 | J22: 2.01 | K22: 5.93 | L22: 1.01 | M22: 1.01 | N22: 1.16 | O22: 1.93 | P22: 5.42 | Q22: 0.91 | R22: 0.82 | S22: 1.1 | T22: 1.5 | U22: 4.64 | V22: 0.88 | W22: 0.67 | X22: 0.96 | Y22: 1.32 | Z22: 4.15 | AA22: 0.73 | AB22: 0.54 | AC22: 0.85 | AD22: 1.05 | AE22: 3.72
A23: Ending subs - EMEA Streaming(M#) | B23: 102.63 | C23: 104.63 | D23: 106.63 | E23: 109.09 | F23: 109.06 | G23: 110.34 | H23: 111.43 | I23: 112.68 | J23: 114.71 | K23: 114.97 | L23: 115.85 | M23: 116.8 | N23: 117.89 | O23: 119.7 | P23: 120.14 | Q23: 120.67 | R23: 121.49 | S23: 122.59 | T23: 124.09 | U23: 124.51 | V23: 125.38 | W23: 126.05 | X23: 127.01 | Y23: 128.33 | Z23: 128.83 | AA23: 127.51 | AB23: 128.05 | AC23: 128.91 | AD23: 129.96 | AE23: 131.94
A24: Average subs - EMEA Streaming(M#) | B24: 101.88 | C24: 103.63 | D24: 105.63 | E24: 107.88 | F24: 104.84 | G24: 109.79 | H24: 111.03 | I24: 112.26 | J24: 114.01 | K24: 112.15 | L24: 115.76 | M24: 116.85 | N24: 117.98 | O24: 119.63 | P24: 118.07 | Q24: 121.52 | R24: 122.66 | S24: 123.82 | T24: 125.49 | U24: 123.32 | V24: 124.94 | W24: 125.71 | X24: 126.53 | Y24: 127.67 | Z24: 126.72 | AA24: 127.15 | AB24: 127.78 | AC24: 128.48 | AD24: 129.43 | AE24: 130.06
A25: ARPU - EMEA Streaming($) | B25: 11.14 | C25: 11.38 | D25: 11.67 | E25: 11.97 | F25: 11.51 | G25: 12.09 | H25: 11.99 | I25: 12.27 | J25: 12.57 | K25: 12.2 | L25: 12.77 | M25: 12.68 | N25: 12.97 | O25: 13.32 | P25: 12.93 | Q25: 13.57 | R25: 13.52 | S25: 13.75 | T25: 14.18 | U25: 13.53 | V25: 15.05 | W25: 14.97 | X25: 15.24 | Y25: 15.82 | Z25: 14.62 | AA25: 16.03 | AB25: 16.05 | AC25: 16.3 | AD25: 16.98 | AE25: 15.37
A26: Revenues - EMEA Streaming | B26: 3404.68 | C26: 3538.18 | D26: 3699.05 | E26: 3872.74 | F26: 14514.65 | G26: 3998.42 | H26: 4014.96 | I26: 4152.32 | J26: 4321.92 | K26: 16451.97 | L26: 4477.92 | M26: 4486.21 | N26: 4630.99 | O26: 4830.21 | P26: 18341.25 | Q26: 4969.41 | R26: 4974.41 | S26: 5102.9 | T26: 5326.33 | U26: 20192.07 | V26: 5561.05 | W26: 5539.03 | X26: 5687.46 | Y26: 5937.46 | Z26: 22141.57 | AA26: 5988.03 | AB26: 5984.12 | AC26: 6123.34 | AD26: 6395.2 | AE26: 23864.23
A28: Latin America (LATAM)
A29: Net adds - LATAM Streaming subs(M#) | B29: 0.8 | C29: 1 | D29: 1.5 | E29: 2 | F29: 5.08 | G29: 1 | H29: 0.95 | I29: 0.93 | J29: 1.48 | K29: 4.49 | L29: 0.82 | M29: 0.79 | N29: 0.81 | O29: 1.31 | P29: 3.79 | Q29: 0.69 | R29: 0.71 | S29: 0.77 | T29: 1.2 | U29: 3.67 | V29: 0.64 | W29: 0.63 | X29: 0.66 | Y29: 1.05 | Z29: 3.26 | AA29: 0.59 | AB29: 0.52 | AC29: 0.64 | AD29: 0.96 | AE29: 3.06
A30: Ending subs - LATAM Streaming(M#) | B30: 54.13 | C30: 55.29 | D30: 56.45 | E30: 58.29 | F30: 58.36 | G30: 59.35 | H30: 60.31 | I30: 61.23 | J30: 62.72 | K30: 62.86 | L30: 63.6 | M30: 64.35 | N30: 65.11 | O30: 66.34 | P30: 66.5 | Q30: 66.25 | R30: 66.96 | S30: 67.73 | T30: 68.93 | U30: 69.88 | V30: 68.94 | W30: 69.57 | X30: 70.23 | Y30: 71.28 | Z30: 72.83 | AA30: 71.75 | AB30: 72.27 | AC30: 72.9 | AD30: 73.86 | AE30: 75.9
A31: Average subs - LATAM Streaming(M#) | B31: 53.73 | C31: 54.62 | D31: 55.73 | E31: 57.3 | F31: 55.54 | G31: 58.64 | H31: 59.66 | I31: 60.6 | J31: 61.84 | K31: 60.47 | L31: 62.86 | M31: 63.69 | N31: 64.45 | O31: 65.53 | P31: 64.6 | Q31: 65.39 | R31: 66.22 | S31: 66.98 | T31: 68.11 | U31: 68.06 | V31: 68.62 | W31: 69.25 | X31: 69.9 | Y31: 70.76 | Z31: 71.16 | AA31: 71.45 | AB31: 72.01 | AC31: 72.58 | AD31: 73.38 | AE31: 74.34
A32: ARPU - LATAM Streaming($) | B32: 7.78 | C32: 7.97 | D32: 8.23 | E32: 8.28 | F32: 8.03 | G32: 8.46 | H32: 8.46 | I32: 8.71 | J32: 8.77 | K32: 8.51 | L32: 8.87 | M32: 8.83 | N32: 9.09 | O32: 9.19 | P32: 8.89 | Q32: 9.41 | R32: 9.43 | S32: 9.76 | T32: 9.87 | U32: 9.31 | V32: 10.11 | W32: 10.08 | X32: 10.53 | Y32: 10.77 | Z32: 9.87 | AA32: 10.85 | AB32: 10.92 | AC32: 11.34 | AD32: 11.63 | AE32: 10.37
A33: Revenues - LATAM Streaming | B33: 1261.93 | C33: 1306.73 | D33: 1370.91 | E33: 1417.94 | F33: 5357.52 | G33: 1497.06 | H33: 1504.65 | I33: 1568.41 | J33: 1612.19 | K33: 6175.17 | L33: 1673.99 | M33: 1677.62 | N33: 1746.9 | O33: 1800.15 | P33: 6892.44 | Q33: 1866.17 | R33: 1876.09 | S33: 1957.03 | T33: 2010.98 | U33: 7662.52 | V33: 2064.77 | W33: 2068.5 | X33: 2169.93 | Y33: 2230.1 | Z33: 8442.5 | AA33: 2290.03 | AB33: 2307.11 | AC33: 2400.43 | AD33: 2462.99 | AE33: 9277.16
A35: Asia-Pacific (APAC)
A36: Net adds - APAC Streaming subs(M#) | B36: 1.48 | C36: 2 | D36: 2 | E36: 3 | F36: 8.11 | G36: 1.99 | H36: 1.33 | I36: 1.62 | J36: 2.38 | K36: 7.63 | L36: 1.7 | M36: 1.19 | N36: 1.53 | O36: 2.27 | P36: 7.09 | Q36: 1.43 | R36: 1.02 | S36: 1.42 | T36: 2.13 | U36: 7 | V36: 1.39 | W36: 0.86 | X36: 1.31 | Y36: 2.04 | Z36: 6.3 | AA36: 1.35 | AB36: 0.66 | AC36: 1.24 | AD36: 1.83 | AE36: 6.01
A37: Ending subs - APAC Streaming(M#) | B37: 58.79 | C37: 60.56 | D37: 62.38 | E37: 65.22 | F37: 65.63 | G37: 67.07 | H37: 68.42 | I37: 70 | J37: 72.47 | K37: 73.28 | L37: 74.2 | M37: 75.32 | N37: 76.76 | O37: 78.9 | P37: 80.08 | Q37: 79.24 | R37: 80.26 | S37: 81.68 | T37: 83.81 | U37: 86.99 | V37: 85.73 | W37: 86.59 | X37: 87.9 | Y37: 89.94 | Z37: 93.59 | AA37: 90.39 | AB37: 91.05 | AC37: 92.29 | AD37: 94.12 | AE37: 99.4
A38: Average subs - APAC Streaming(M#) | B38: 57.96 | C38: 59.58 | D38: 61.41 | E38: 63.78 | F38: 61.14 | G38: 65.86 | H38: 67.48 | I38: 69.03 | J38: 71.15 | K38: 69.14 | L38: 72.91 | M38: 74.39 | N38: 75.8 | O38: 77.76 | P38: 76.52 | Q38: 77.9 | R38: 79.37 | S38: 80.84 | T38: 82.96 | U38: 83.5 | V38: 85.04 | W38: 86.16 | X38: 87.25 | Y38: 88.92 | Z38: 90.39 | AA38: 89.72 | AB38: 90.72 | AC38: 91.67 | AD38: 93.2 | AE38: 96.35
A39: ARPU - APAC Streaming($) | B39: 7.2 | C39: 7.25 | D39: 7.45 | E39: 7.47 | F39: 7.28 | G39: 7.59 | H39: 7.54 | I39: 7.65 | J39: 7.77 | K39: 7.53 | L39: 7.95 | M39: 7.9 | N39: 8.06 | O39: 8.2 | P39: 7.82 | Q39: 8.4 | R39: 8.33 | S39: 8.52 | T39: 8.71 | U39: 8.05 | V39: 8.97 | W39: 8.88 | X39: 9.14 | Y39: 9.39 | Z39: 8.36 | AA39: 9.51 | AB39: 9.42 | AC39: 9.7 | AD39: 9.99 | AE39: 8.64
A40: Revenues - APAC Streaming | B40: 1259.09 | C40: 1305.25 | D40: 1368.56 | E40: 1420.81 | F40: 5353.72 | G40: 1508.98 | H40: 1522.16 | I40: 1579.58 | J40: 1646.62 | K40: 6261.1 | L40: 1741.14 | M40: 1756.89 | N40: 1827.11 | O40: 1903.25 | P40: 7196.04 | Q40: 1974.9 | R40: 1982.4 | S40: 2059.27 | T40: 2142.67 | U40: 8145.13 | V40: 2226.72 | W40: 2226.79 | X40: 2318.83 | Y40: 2406.57 | Z40: 9055.37 | AA40: 2476.65 | AB40: 2468.66 | AC40: 2567.47 | AD40: 2657.65 | AE40: 9971.83
A42: Total streaming
A43: Net adds - Global Streaming subs(M#) | B43: 4.17 | C43: 5.98 | D43: 6.19 | E43: 9.65 | F43: 25.78 | G43: 4.68 | H43: 3.9 | I43: 4.41 | J43: 7.21 | K43: 21.13 | L43: 4.12 | M43: 3.54 | N43: 4.11 | O43: 6.73 | P43: 19.49 | Q43: 3.54 | R43: 2.93 | S43: 3.72 | T43: 5.58 | U43: 17.36 | V43: 3.42 | W43: 2.5 | X43: 3.34 | Y43: 5.1 | Z43: 15.7 | AA43: 3.18 | AB43: 2.04 | AC43: 3.11 | AD43: 4.54 | AE43: 14.64
A44: Ending subs - Global Streaming(M#) | B44: 305.67 | C44: 311.7 | D44: 317.39 | E44: 327.36 | F44: 328.29 | G44: 332.14 | H44: 336.1 | I44: 340.45 | J44: 347.79 | K44: 350.14 | L44: 352.34 | M44: 355.68 | N44: 359.55 | O44: 365.88 | P44: 369.71 | Q44: 367.08 | R44: 370.01 | S44: 373.73 | T44: 379.31 | U44: 387.16 | V44: 382.6 | W44: 385.11 | X44: 388.44 | Y44: 393.54 | Z44: 399.07 | AA44: 395.06 | AB44: 397.1 | AC44: 400.21 | AD44: 404.75 | AE44: 413.2
A45: Average subs - Global Streaming(M#) | B45: 304.13 | C45: 308.35 | D45: 314.02 | E45: 322.26 | F45: 313.1 | G45: 329.42 | H45: 333.75 | I45: 338.12 | J45: 344.28 | K45: 337.8 | L45: 350.18 | M45: 353.98 | N45: 357.93 | O45: 363.59 | P45: 358.46 | Q45: 366.31 | R45: 370.2 | S45: 374.09 | T45: 379.88 | U45: 376.46 | V45: 380.89 | W45: 383.85 | X45: 386.78 | Y45: 390.99 | Z45: 391.08 | AA45: 393.47 | AB45: 396.08 | AC45: 398.65 | AD45: 402.48 | AE45: 405.78
A46: ARPU - Global Streaming($) | B46: 11.56 | C46: 11.99 | D46: 12.24 | E46: 12.47 | F46: 12.02 | G46: 12.4 | H46: 12.55 | I46: 12.81 | J46: 13.09 | K46: 12.65 | L46: 13.05 | M46: 13.16 | N46: 13.46 | O46: 13.8 | P46: 13.23 | Q46: 13.71 | R46: 13.83 | S46: 14.1 | T46: 14.42 | U46: 13.89 | V46: 14.66 | W46: 14.76 | X46: 15.1 | Y46: 15.49 | Z46: 14.58 | AA46: 15.4 | AB46: 15.55 | AC46: 15.88 | AD46: 16.17 | AE46: 15.19
A47: Revenue - Global Streaming | B47: 10542.8 | C47: 11079.17 | D47: 11510.31 | E47: 12050.76 | F47: 45183.04 | G47: 12249.76 | H47: 12563.07 | I47: 12984.49 | J47: 13537.05 | K47: 51251.1 | L47: 13745.89 | M47: 14023.53 | N47: 14498.18 | O47: 15109.21 | P47: 57018.92 | Q47: 15243.47 | R47: 15543.73 | S47: 16032.24 | T47: 16706.84 | U47: 62774.15 | V47: 17097.24 | W47: 17358.66 | X47: 17926.62 | Y47: 18659.89 | Z47: 68898.8 | AA47: 18734.82 | AB47: 19034.41 | AC47: 19612.74 | AD47: 20276.93 | AE47: 74593.21
...
