Workbook
Name \p: #N/A
Name \s: #N/A
Name __FYE2: #REF!
Name _bdm.FastTrackBookmark.7_17_2019_4_42_29_PM.edm: #REF!
Name _ccVersion: 1.75
Name _FYE2: #REF!
Name _Order1: 255
Name _Order2: 255
Name _Regression_Int: 1
Name ActualRevenueUSDMTD: 2
Name ActualRevenueUSDQTD: 5
Name ActualRevenueUSDYTD: 8
Name anscount: 1
Name ASSET: #REF!
Name BACK_A: #REF!
Name BudgetRevenueUSDMTD: 3
Name BudgetRevenueUSDQTD: 6
Name BudgetRevenueUSDYTD: 9
Name BusSysEA: MATCH("Business Systems Enterprise Agreements", Categories,0)
Name BusSysEA2: MATCH("Business Systems Enterprise Agreements", Categories,0)
Name BusSysEALookup: OFFSET(#REF!,BusSysEA,1,BusSysEATotal-BusSysEA,1)
Name BusSysEATotal: MATCH("Business Systems Enterprise Agreements *", Categories,0)
Name Categories: #REF!
Name cc_ReportCurrency: "HKD"
Name cc_ReportCurrencyUnit: "HK$"
Name cc_ReportCurrencyUnitFactor: 1
Name CDate: TODAY()
Name clean_spreads: #REF!
Name Columns: #REF!,#REF!,#REF!,#REF!,#REF!,#REF!,#REF!,#REF!,#REF!,#REF!,#REF!,#REF!,#REF!,#REF!,#REF!,#REF!,#REF!,#REF!,#REF!,#REF!,#REF!,#REF!,#REF!,#REF!,#REF!,#REF!,#REF!,#REF!
Name CommercialExAIGMetrics: #REF!
Name CostPerCriticalWatt: #REF!
Name DB: "WIREHKPROD"
Name DiscountPercentage: #REF!
Name Divisions: OFFSET(#REF!,0,-1)
Name email: "iain.reed@clsa.com"
Name Ex8216DownPorts: #REF!
Name FTPFile: "CommandButton1"
Name FXVarianceMTD: 4
Name FXVarianceQTD: 7
Name FXVarianceYTD: 10
Name geogsp: "Chart 2"
Name Greetings: MATCH("Grtgs WS, PictureIt, Other DAD", Categories,0)
Name GreetingsLookup: OFFSET(#REF!,Greetings,1,GreetingsTotal-Greetings,1)
Name GreetingsTotal: MATCH("Grtgs WS, PictureIt, Other DAD *", Categories,0)
Name ictsymbol: "$"
Name icusymbol: "$"
Name Img_ML_2x8r4a2e: "IMG_10"
Name Img_ML_5k1g6v5e: "IMG_11"
Name Img_ML_6f9i2b5e: "IMG_18"
Name Img_ML_7m5m4k3b: "IMG_6"
Name Img_ML_7n6h3t1t: "IMG_10"
Name Img_ML_8b9j5t1p: "IMG_10"
Name Img_ML_8i9u7w8k: "IMG_10"
Name Img_ML_8r1k8t4y: "IMG_10"
Name ImpOM: #REF!
Name InfrastructureCostPerWattPerYear: #REF!
Name is: #REF!
Name iue: 0.01
Name iuesymbol: "c"
Name iun: 1000000

Sheet Population and Broadband subs
A2: TMT Geography Knowledge Base (Group by Metric)
A4: Available Markets: All Available Markets
A5: Selected Periods: 2030Y , 2029Y , 2028Y , 2027Y , 2026Y , 2025Y , 2024Y
A6: Available Metrics Household Universe, Subscriptions
A7: Rank by: Market
B9: 2024 | C9: 2025 | D9: 2026 | E9: 2027 | F9: 2028 | G9: 2029 | H9: 2030 | I9: CAGR (%) 2024-2030
A11: Population (actual)
A12: Argentina | B12: 45700000 | C12: 45850000 | D12: 46000000 | E12: 46150000 | F12: 46300000 | G12: 46440000 | H12: 46590000 | I12: 0.3219777
A13: Asia Pacific Summary | B13: 4331188359 | C13: 4351121073 | D13: 4374033563 | E13: 4396455467 | F13: 4418171484 | G13: 4439371409 | H13: 4459860038 | I13: 0.48911615
A14: Australia | B14: 26710000 | C14: 26970000 | D14: 27230000 | E14: 27470000 | F14: 27720000 | G14: 27960000 | H14: 28190000 | I14: 0.90287283
A15: Austria | B15: 8750000 | C15: 8770000 | D15: 8790000 | E15: 8800000 | F15: 8820000 | G15: 8830000 | H15: 8840000 | I15: 0.17069846
A16: Bahamas | B16: 422476 | C16: 426190 | D16: 429905 | E16: 433619 | F16: 437333 | G16: 441048 | H16: 444762 | I16: 0.86045863
A17: Bahrain | B17: 1640000 | C17: 1680000 | D17: 1720000 | E17: 1750000 | F17: 1780000 | G17: 1800000 | H17: 1830000 | I17: 1.8437871
A18: Barbados | B18: 290871 | C18: 291162 | D18: 291453 | E18: 291744 | F18: 292036 | G18: 292328 | H18: 292618 | I18: 0.099852056
A19: Belgium | B19: 11720000 | C19: 11740000 | D19: 11770000 | E19: 11800000 | F19: 11820000 | G19: 11850000 | H19: 11870000 | I19: 0.21218186
A20: Bolivia | B20: 12310000 | C20: 12470000 | D20: 12630000 | E20: 12780000 | F20: 12940000 | G20: 13090000 | H20: 13240000 | I20: 1.2212405
A21: Brazil | B21: 212000000 | C21: 212810000 | D21: 213560000 | E21: 214260000 | F21: 214910000 | G21: 215520000 | H21: 216070000 | I21: 0.31743868
A22: Bulgaria | B22: 6740000 | C22: 6690000 | D22: 6630000 | E22: 6580000 | F22: 6530000 | G22: 6470000 | H22: 6420000 | I22: -0.8074195
A23: Cambodia | B23: 17072678 | C23: 17250289 | D23: 17427953 | E23: 17605652 | F23: 17783368 | G23: 17961083 | H23: 18138778 | I23: 1.0146576
... A54: Jordan | B54: 11770000 | C54: 12010000 | D54: 12250000 | E54: 12340000 | F54: 12450000 | G54: 12560000 | H54: 12690000 | I54: 1.2622392
A55: Kenya | B55: NA | C55: NA | D55: NA | E55: NA | F55: NA | G55: NA | H55: NA | I55: NA
A56: Kuwait | B56: 4640000 | C56: 4710000 | D56: 4780000 | E56: 4830000 | F56: 4880000 | G56: 4920000 | H56: 4970000 | I56: 1.1516725
A57: Laos | B57: 7705419 | C57: 7810163 | D57: 7914207 | E57: 8017529 | F57: 8120106 | G57: 8221918 | H57: 8322945 | I57: 1.2931618
A58: Latin America and Caribbean Summary | B58: 645422731 | C58: 649767470 | D58: 653966791 | E58: 658078404 | F58: 662065477 | G58: 665912631 | H58: 669621535 | I58: 0.61533849
A59: Latvia | B59: 1870000 | C59: 1850000 | D59: 1840000 | E59: 1820000 | F59: 1810000 | G59: 1790000 | H59: 1780000 | I59: -0.81871457
A60: Lebanon | B60: 6750000 | C60: 6820000 | D60: 6890000 | E60: 6958900 | F60: 7028489 | G60: 7098774 | H60: 7169762 | I60: 1.0105714
A61: Lithuania | B61: 2690000 | C61: 2670000 | D61: 2650000 | E61: 2620000 | F61: 2600000 | G61: 2580000 | H61: 2560000 | I61: -0.82216715
A62: Malaysia | B62: 34670000 | C62: 35980000 | D62: 36120000 | E62: 36380000 | F62: 36630000 | G62: 36970000 | H62: 37200000 | I62: 1.1808173
A63: Mexico | B63: 130860000 | C63: 131950000 | D63: 133000000 | E63: 134020000 | F63: 135010000 | G63: 135970000 | H63: 136900000 | I63: 0.75487967
A64: Middle East and Africa Summary | B64: 1861372963 | C64: 1899479830 | D64: 1937876118 | E64: 1976155266 | F64: 1996083336 | G64: 2016370240 | H64: 2036956147 | I64: 1.513713
A65: Morocco | B65: NA | C65: NA | D65: NA | E65: NA | F65: NA | G65: NA | H65: NA | I65: NA
A66: Myanmar | B66: 54924186 | C66: 55289208 | D66: 55649307 | E66: 56004502 | F66: 56354815 | G66: 56700269 | H66: 57040890 | I66: 0.63223323
A67: Netherlands | B67: 17670000 | C67: 17720000 | D67: 17770000 | E67: 17820000 | F67: 17860000 | G67: 17910000 | H67: 17940000 | I67: 0.2530625
A68: New Zealand | B68: 5210000 | C68: 5250000 | D68: 5290000 | E68: 5320000 | F68: 5350000 | G68: 5380000 | H68: 5410000 | I68: 0.62979554
A69: Nicaragua | B69: 6930000 | C69: 6999300 | D69: 7069293 | E69: 7139986 | F69: 7211386 | G69: 7283500 | H69: 7356335 | I69: 1.0000008
A70: Nigeria | B70: NA | C70: NA | D70: NA | E70: NA | F70: NA | G70: NA | H70: NA | I70: NA
A71: North America Summary | B71: 380380000 | C71: 382680000 | D71: 383970000 | E71: 385180000 | F71: 386390000 | G71: 387780000 | H71: 389370000 | I71: 0.39008043
A72: Norway | B72: 5510000 | C72: 5550000 | D72: 5590000 | E72: 5630000 | F72: 5670000 | G72: 5710000 | H72: 5750000 | I72: 0.71311786
A73: Oman | B73: 4730000 | C73: 4810000 | D73: 4880000 | E73: 4950760 | F73: 5022546 | G73: 5095373 | H73: 5169256 | I73: 1.4910666
A74: Other Markets - Asia Pacific Summary | B74: 274376075 | C74: 276831413 | D74: 279333495 | E74: 281883440 | F74: 284430930 | G74: 286975737 | H74: 289517637 | I74: 0.89929484
...

Sheet Pop and BB subs by market
A2: TMT Geography Knowledge Base (Group by Market)
A3: Available Markets: All Available Markets
A4: Selected Periods: 2030Y , 2029Y , 2028Y , 2027Y , 2026Y , 2025Y , 2024Y
A5: Available Metrics Household Universe, Subscriptions
A6: Rank by: Market
B8: 2024 | C8: 2025 | D8: 2026 | E8: 2027 | F8: 2028 | G8: 2029 | H8: 2030 | I8: CAGR (%) 2024-2030
A10: Argentina
A11: Population (actual) | B11: 45700000 | C11: 45850000 | D11: 46000000 | E11: 46150000 | F11: 46300000 | G11: 46440000 | H11: 46590000 | I11: 0.3219777
A12: Occupied Households (actual) | B12: 16084433 | C12: 16136606 | D12: 16172812 | E12: 16192926 | F12: 16196872 | G12: 16184623 | H12: 16156198 | I12: 0.074224921
A13: TV Households (actual) | B13: 15722533 | C13: 15781601 | D13: 15825097 | E13: 15852875 | F13: 15864836 | G13: 15860931 | H13: 15841152 | I13: 0.12534857
A14: Residential Broadband Subscriptions (actual) | B14: 11913680 | C14: 12343343 | D14: 12739593 | E14: 12914784 | F14: 13119749 | G14: 13394220 | H14: 13746410 | I14: 2.4135044
A15: Residential Cable Broadband Subscriptions (actual) | B15: 5625728 | C15: 5545669 | D15: 5541236 | E15: 5524318 | F15: 5492683 | G15: 5438426 | H15: 5365770 | I15: -0.78540732
A16: Residential DSL Broadband Subscriptions (actual) | B16: 521297 | C16: 138098 | D16: 38702 | E16: 3414 | F16: 0 | G16: 0 | H16: 0 | I16: -100
A17: Residential Fiber Broadband Subscriptions (actual) | B17: 4875163 | C17: 5582880 | D17: 6087234 | E17: 6319871 | F17: 6566075 | G17: 6901806 | H17: 7334567 | I17: 7.0444668
A18: Residential Satellite Broadband Subscriptions (actual) | B18: 92757 | C18: 231893 | D18: 235023 | E18: 237961 | F18: 240697 | G18: 243345 | H18: 245779 | I18: 17.63404
A19: Residential Fixed Wireless Broadband Subscriptions (actual) | B19: 599299 | C19: 646763 | D19: 640943 | E19: 634533 | F19: 627553 | G19: 620023 | H19: 611962 | I19: 0.34910044
A20: Residential Other Broadband Subscriptions (actual) | B20: 199436 | C20: 198040 | D20: 196456 | E20: 194688 | F20: 192741 | G20: 190621 | H20: 188333 | I20: -0.95015242
A22: Asia Pacific Summary
A23: Population (actual) | B23: 4331188359 | C23: 4351121073 | D23: 4374033563 | E23: 4396455467 | F23: 4418171484 | G23: 4439371409 | H23: 4459860038 | I23: 0.48911615
A24: Occupied Households (actual) | B24: 1219853322 | C24: 1237040973 | D24: 1256896984 | E24: 1276766821 | F24: 1296495777 | G24: 1315646999 | H24: 1334882671 | I24: 1.5132145
A25: TV Households (actual) | B25: 1072806335 | C25: 1094209968 | D25: 1118839248 | E25: 1143163080 | F25: 1167900843 | G25: 1193142062 | H25: 1218054131 | I25: 2.1388295
A26: Residential Broadband Subscriptions (actual) | B26: 690877373 | C26: 720167261 | D26: 738812900 | E26: 757393412 | F26: 781907273 | G26: 803407390 | H26: 827351509 | I26: 3.0500442
A27: Residential Cable Broadband Subscriptions (actual) | B27: 56890760 | C27: 56542832 | D27: 56580414 | E27: 56407881 | F27: 56302333 | G27: 56403376 | H27: 56325227 | I27: -0.16636848
A28: Residential DSL Broadband Subscriptions (actual) | B28: 16862796 | C28: 15708680 | D28: 14816067 | E28: 14222418 | F28: 13711331 | G28: 13036008 | H28: 12506793 | I28: -4.8586311
A29: Residential Fiber Broadband Subscriptions (actual) | B29: 597962159 | C29: 619321039 | D29: 636915384 | E29: 654522497 | F29: 676941860 | G29: 696842972 | H29: 719325534 | I29: 3.1276914
A30: Residential Satellite Broadband Subscriptions (actual) | B30: 284146 | C30: 309419 | D30: 318347 | E30: 329254 | F30: 338124 | G30: 351748 | H30: 362894 | I30: 4.1612957
A31: Residential Fixed Wireless Broadband Subscriptions (actual) | B31: 14113196 | C31: 23688974 | D31: 25968635 | E31: 27617102 | F31: 30486603 | G31: 32885137 | H31: 35302235 | I31: 16.509893
A32: Residential Other Broadband Subscriptions (actual) | B32: 4764315 | C32: 4596316 | D32: 4214053 | E32: 4294260 | F32: 4127023 | G32: 3888150 | H32: 3528826 | I32: -4.8800465
A34: Australia
A35: Population (actual) | B35: 26710000 | C35: 26970000 | D35: 27230000 | E35: 27470000 | F35: 27720000 | G35: 27960000 | H35: 28190000 | I35: 0.90287283
A36: Occupied Households (actual) | B36: 8494954 | C36: 8527235 | D36: 8548553 | E36: 8576763 | F36: 8599063 | G36: 8620561 | H36: 8647284 | I36: 0.29665487
A37: TV Households (actual) | B37: 8476228 | C37: 8508863 | D37: 8530562 | E37: 8559140 | F37: 8581823 | G37: 8603708 | H37: 8630811 | I37: 0.3016697
A38: Residential Broadband Subscriptions (actual) | B38: 8103085 | C38: 8056182 | D38: 7982893 | E38: 8009401 | F38: 8050446 | G38: 8165452 | H38: 8231930 | I38: 0.26327332
A39: Residential Cable Broadband Subscriptions (actual) | B39: 986417 | C39: 769405 | D39: 607830 | E39: 480186 | F39: 374545 | G39: 337090 | H39: 269672 | I39: -19.438189
A40: Residential DSL Broadband Subscriptions (actual) | B40: 449868 | C40: 301412 | D40: 241129 | E40: 192903 | F40: 154323 | G40: 123458 | H40: 101236 | I40: -22.009511
A41: Residential Fiber Broadband Subscriptions (actual) | B41: 5981009 | C41: 6190344 | D41: 6314151 | E41: 6490947 | F41: 6653221 | G41: 6812898 | H41: 6949156 | I41: 2.5320406
A42: Residential Satellite Broadband Subscriptions (actual) | B42: 150961 | C42: 153225 | D42: 155524 | E42: 157857 | F42: 160225 | G42: 162628 | H42: 164254 | I42: 1.4164797
A43: Residential Fixed Wireless Broadband Subscriptions (actual) | B43: 534830 | C43: 641797 | D43: 664259 | E43: 687509 | F43: 708134 | G43: 729378 | H43: 747612 | I43: 5.741001
A44: Residential Other Broadband Subscriptions (actual) | B44: 0 | C44: 0 | D44: 0 | E44: 0 | F44: 0 | G44: 0 | H44: 0 | I44: NA
A46: Austria
...

Sheet penetration and ARPU
A2: TMT Geography Knowledge Base (Group by Metric)
A4: Available Markets: All Available Markets
A5: Selected Periods: 2030Y , 2029Y , 2028Y , 2027Y , 2026Y , 2025Y , 2024Y
A6: Available Metrics Penetration/Market Share, ARPU
A7: Rank by: Market
B9: 2024 | C9: 2025 | D9: 2026 | E9: 2027 | F9: 2028 | G9: 2029 | H9: 2030 | I9: CAGR (%) 2024-2030
A11: Residential Broadband Subs/ Occupied Households (%)
A12: Argentina | B12: 74.07 | C12: 76.49 | D12: 78.77 | E12: 79.76 | F12: 81 | G12: 82.76 | H12: 85.08 | I12: 2.33657
A13: Asia Pacific Summary | B13: 56.64 | C13: 58.22 | D13: 58.78 | E13: 59.32 | F13: 60.31 | G13: 61.07 | H13: 61.98 | I13: 1.512936
A14: Australia | B14: 95.39 | C14: 94.48 | D14: 93.38 | E14: 93.38 | F14: 93.62 | G14: 94.72 | H14: 95.2 | I14: -0.033225
A15: Austria | B15: 61.48 | C15: 62.53 | D15: 63.46 | E15: 64.44 | F15: 65.37 | G15: 66.25 | H15: 67.22 | I15: 1.498769
A16: Bahamas | B16: 60.84 | C16: 60.19 | D16: 59.54 | E16: 58.91 | F16: 58.3 | G16: 57.68 | H16: 57.08 | I16: -1.057596
A17: Bahrain | B17: 94.61 | C17: 95.77 | D17: 95.83 | E17: 96.08 | F17: 96.34 | G17: 96.63 | H17: 96.93 | I17: 0.404581
A18: Barbados | B18: 86.2 | C18: 86.37 | D18: 86.64 | E18: 87 | F18: 87.42 | G18: 88.11 | H18: 87.9 | I18: 0.326024
A19: Belgium | B19: 87.73 | C19: 88.62 | D19: 89.45 | E19: 90.33 | F19: 91.16 | G19: 91.89 | H19: 92.63 | I19: 0.909934
A20: Bolivia | B20: 33.96 | C20: 35.56 | D20: 37.15 | E20: 38.71 | F20: 40.11 | G20: 41.46 | H20: 42.77 | I20: 3.919072
A21: Brazil | B21: 61.31 | C21: 63.67 | D21: 65.84 | E21: 67.48 | F21: 68.58 | G21: 69.38 | H21: 69.74 | I21: 2.170403
A22: Bulgaria | B22: 92.59 | C22: 93.57 | D22: 93.65 | E22: 93.94 | F22: 94.32 | G22: 94.74 | H22: 95.15 | I22: 0.455592
A23: Cambodia | B23: 16.69 | C23: 17.54 | D23: 18.51 | E23: 19.61 | F23: 20.49 | G23: 21.44 | H23: 21.93 | I23: 4.6559
... A54: Jordan | B54: 56.73 | C54: 58.81 | D54: 62 | E54: 64.64 | F54: 66.13 | G54: 67.93 | H54: 70.24 | I54: 3.624382
A55: Kenya | B55: NA | C55: NA | D55: NA | E55: NA | F55: NA | G55: NA | H55: NA | I55: NA
A56: Kuwait | B56: 39.45 | C56: 41.71 | D56: 44.29 | E56: 47.24 | F56: 50.72 | G56: 52.22 | H56: 52.5 | I56: 4.878238
A57: Laos | B57: 16.27 | C57: 17.34 | D57: 18.44 | E57: 19.57 | F57: 21.04 | G57: 22.4 | H57: 23.92 | I57: 6.633976
A58: Latin America and Caribbean Summary | B58: 55.04 | C58: 57.2 | D58: 59.03 | E58: 60.42 | F58: 61.48 | G58: 62.34 | H58: 62.99 | I58: 2.274068
A59: Latvia | B59: 57.13 | C59: 57.14 | D59: 56.94 | E59: 56.85 | F59: 56.85 | G59: 56.81 | H59: 56.73 | I59: -0.117035
A60: Lebanon | B60: 67.78 | C60: 68 | D60: 68.09 | E60: 68.34 | F60: 68.89 | G60: 71.06 | H60: 73.17 | I60: 1.283472
A61: Lithuania | B61: 47.79 | C61: 46.09 | D61: 44.72 | E61: 43.58 | F61: 42.63 | G61: 41.81 | H61: 41.12 | I61: -2.474239
A62: Malaysia | B62: 52.36 | C62: 54.54 | D62: 55.9 | E62: 56.68 | F62: 57.54 | G62: 58.35 | H62: 59.14 | I62: 2.050142
A63: Mexico | B63: 67.37 | C63: 70.25 | D63: 72.19 | E63: 73.29 | F63: 73.71 | G63: 73.61 | H63: 73.09 | I63: 1.367461
A64: Middle East and Africa Summary | B64: 11.84 | C64: 12.3 | D64: 12.72 | E64: 13.13 | F64: 13.49 | G64: 13.76 | H64: 14.01 | I64: 2.8445
A65: Morocco | B65: NA | C65: NA | D65: NA | E65: NA | F65: NA | G65: NA | H65: NA | I65: NA
A66: Myanmar | B66: 10.23 | C66: 11.21 | D66: 12.17 | E66: 13.47 | F66: 14.64 | G66: 16.24 | H66: 17.88 | I66: 9.752725
A67: Netherlands | B67: 92.38 | C67: 92.21 | D67: 92.05 | E67: 91.88 | F67: 91.68 | G67: 91.85 | H67: 91.93 | I67: -0.081352
A68: New Zealand | B68: 91.68 | C68: 92.15 | D68: 91.95 | E68: 92.58 | F68: 92.48 | G68: 92.95 | H68: 93.06 | I68: 0.249313
A69: Nicaragua | B69: 24.05 | C69: 25.09 | D69: 25.93 | E69: 26.6 | F69: 27.08 | G69: 27.58 | H69: 28.1 | I69: 2.627844
A70: Nigeria | B70: NA | C70: NA | D70: NA | E70: NA | F70: NA | G70: NA | H70: NA | I70: NA
A71: North America Summary | B71: 90.08 | C71: 91.29 | D71: 92.72 | E71: 94.08 | F71: 95.5 | G71: 97.4 | H71: 98.47 | I71: 1.495299
A72: Norway | B72: 93.95 | C72: 95.05 | D72: 96.03 | E72: 97 | F72: 97.94 | G72: 98.74 | H72: 99.53 | I72: 0.966245
A73: Oman | B73: 77.55 | C73: 78.6 | D73: 79.47 | E73: 80.54 | F73: 82.07 | G73: 83.76 | H73: 85.6 | I73: 1.659662
A74: Other Markets - Asia Pacific Summary | B74: 28.83 | C74: 29.31 | D74: 29.73 | E74: 30.29 | F74: 32.26 | G74: 33.04 | H74: 33.93 | I74: 2.751902
...

Sheet Penetration and ARPU by market
A2: TMT Geography Knowledge Base (Group by Market)
A3: Available Markets: All Available Markets
A4: Selected Periods: 2030Y , 2029Y , 2028Y , 2027Y , 2026Y , 2025Y , 2024Y
A5: Available Metrics Penetration/Market Share, ARPU
A6: Rank by: Market
B8: 2024 | C8: 2025 | D8: 2026 | E8: 2027 | F8: 2028 | G8: 2029 | H8: 2030 | I8: CAGR (%) 2024-2030
A10: Argentina
A11: Residential Broadband Subs/ Occupied Households (%) | B11: 74.07 | C11: 76.49 | D11: 78.77 | E11: 79.76 | F11: 81 | G11: 82.76 | H11: 85.08 | I11: 2.33657
A12: Residential Cable BB Subs/ Occupied Households (%) | B12: 34.98 | C12: 34.37 | D12: 34.26 | E12: 34.12 | F12: 33.91 | G12: 33.6 | H12: 33.21 | I12: -0.86169
A13: Residential DSL BB Subs/ Occupied Households (%) | B13: 3.24 | C13: 0.86 | D13: 0.24 | E13: 0.02 | F13: 0 | G13: 0 | H13: 0 | I13: -100
A14: Residential Fiber BB Subs/ Occupied Households (%) | B14: 30.31 | C14: 34.6 | D14: 37.64 | E14: 39.03 | F14: 40.54 | G14: 42.64 | H14: 45.4 | I14: 6.96581
A15: Residential Satellite BB Subs/ Occupied Households (%) | B15: 0.58 | C15: 1.44 | D15: 1.45 | E15: 1.47 | F15: 1.49 | G15: 1.5 | H15: 1.52 | I15: 17.418339
A16: Residential Fixed Wireless BB Subs/ Occupied HHs (%) | B16: 3.73 | C16: 4.01 | D16: 3.96 | E16: 3.92 | F16: 3.87 | G16: 3.83 | H16: 3.79 | I16: 0.266317
A17: Residential Other Broadband Subs/ Occupied HHs (%) | B17: 1.24 | C17: 1.23 | D17: 1.21 | E17: 1.2 | F17: 1.19 | G17: 1.18 | H17: 1.17 | I17: -0.963786
A18: Cable Share of Residential Broadband Subs (%) | B18: 47.22 | C18: 44.93 | D18: 43.5 | E18: 42.78 | F18: 41.87 | G18: 40.6 | H18: 39.03 | I18: -3.124915
A19: DSL Share of Residential Broadband Subs (%) | B19: 4.38 | C19: 1.12 | D19: 0.3 | E19: 0.03 | F19: 0 | G19: 0 | H19: 0 | I19: -100
A20: Fiber Share of Residential Broadband Subs (%) | B20: 40.92 | C20: 45.23 | D20: 47.78 | E20: 48.94 | F20: 50.05 | G20: 51.53 | H20: 53.36 | I20: 4.523361
A21: Satellite Share of Residential Broadband Subs (%) | B21: 0.78 | C21: 1.88 | D21: 1.84 | E21: 1.84 | F21: 1.83 | G21: 1.82 | H21: 1.79 | I21: 14.848785
A22: Fixed Wireless Share of Residential Broadband Subs (%) | B22: 5.03 | C22: 5.24 | D22: 5.03 | E22: 4.91 | F22: 4.78 | G22: 4.63 | H22: 4.45 | I22: -2.021225
... A24: Residential Broadband ARPU ($) | B24: 17.36 | C24: 18.58 | D24: 17.34 | E24: 17.01 | F24: 16.55 | G24: 16.44 | H24: 17.22 | I24: -0.13486248
A25: Residential Cable Broadband ARPU ($) | B25: NA | C25: NA | D25: NA | E25: NA | F25: NA | G25: NA | H25: NA | I25: NA
A26: Residential DSL Broadband ARPU ($) | B26: NA | C26: NA | D26: NA | E26: NA | F26: NA | G26: NA | H26: NA | I26: NA
A27: Residential Fiber Broadband ARPU ($) | B27: NA | C27: NA | D27: NA | E27: NA | F27: NA | G27: NA | H27: NA | I27: NA
A28: Residential Satellite Broadband ARPU ($) | B28: NA | C28: NA | D28: NA | E28: NA | F28: NA | G28: NA | H28: NA | I28: NA
A29: Residential Fixed Wireless Broadband ARPU ($) | B29: NA | C29: NA | D29: NA | E29: NA | F29: NA | G29: NA | H29: NA | I29: NA
A31: Asia Pacific Summary
A32: Residential Broadband Subs/ Occupied Households (%) | B32: 56.64 | C32: 58.22 | D32: 58.78 | E32: 59.32 | F32: 60.31 | G32: 61.07 | H32: 61.98 | I32: 1.512936
A33: Residential Cable BB Subs/ Occupied Households (%) | B33: 4.66 | C33: 4.57 | D33: 4.5 | E33: 4.42 | F33: 4.34 | G33: 4.29 | H33: 4.22 | I33: -1.639418
A34: Residential DSL BB Subs/ Occupied Households (%) | B34: 1.38 | C34: 1.27 | D34: 1.18 | E34: 1.11 | F34: 1.06 | G34: 0.99 | H34: 0.94 | I34: -6.198858
A35: Residential Fiber BB Subs/ Occupied Households (%) | B35: 49.02 | C35: 50.06 | D35: 50.67 | E35: 51.26 | F35: 52.21 | G35: 52.97 | H35: 53.89 | I35: 1.591135
A36: Residential Satellite BB Subs/ Occupied Households (%) | B36: 0.02 | C36: 0.03 | D36: 0.03 | E36: 0.03 | F36: 0.03 | G36: 0.03 | H36: 0.03 | I36: 6.991319
A37: Residential Fixed Wireless BB Subs/ Occupied HHs (%) | B37: 1.16 | C37: 1.91 | D37: 2.07 | E37: 2.16 | F37: 2.35 | G37: 2.5 | H37: 2.64 | I37: 14.689675
A38: Residential Other Broadband Subs/ Occupied HHs (%) | B38: 0.39 | C38: 0.37 | D38: 0.34 | E38: 0.34 | F38: 0.32 | G38: 0.3 | H38: 0.26 | I38: -6.534474
A39: Cable Share of Residential Broadband Subs (%) | B39: 8.23 | C39: 7.85 | D39: 7.66 | E39: 7.45 | F39: 7.2 | G39: 7.02 | H39: 6.81 | I39: -3.107265
A40: DSL Share of Residential Broadband Subs (%) | B40: 2.44 | C40: 2.18 | D40: 2.01 | E40: 1.88 | F40: 1.75 | G40: 1.62 | H40: 1.51 | I40: -7.686648
A41: Fiber Share of Residential Broadband Subs (%) | B41: 86.55 | C41: 86 | D41: 86.21 | E41: 86.42 | F41: 86.58 | G41: 86.74 | H41: 86.94 | I41: 0.07496
A42: Satellite Share of Residential Broadband Subs (%) | B42: 0.04 | C42: 0.04 | D42: 0.04 | E42: 0.04 | F42: 0.04 | G42: 0.04 | H42: 0.04 | I42: 0
A43: Fixed Wireless Share of Residential Broadband Subs (%) | B43: 2.04 | C43: 3.29 | D43: 3.51 | E43: 3.65 | F43: 3.9 | G43: 4.09 | H43: 4.27 | I43: 13.100958
... A50: Residential Fixed Wireless Broadband ARPU ($) | B50: 12.92 | C50: 9.37 | D50: 8.01 | E50: 7.75 | F50: 7.43 | G50: 7.21 | H50: 7.03 | I50: -9.645705
A52: Australia
...

Sheet starlink countries list
A1: ISO Code | B1: Country / Territory | C1: Status | D1: Notes
A2: AF | B2: Afghanistan | C2: Not Available (Blocked)
A3: XA | B3: Akrotiri & Dhekelia (UK Sovereign Base) | C3: Coming Soon | D3: Service date is unknown at this time | E3: =COUNTIF(C:C, "Available") -> 164
A4: AL | B4: Albania | C4: Available
A5: DZ | B5: Algeria | C5: Coming Soon | D5: Service date is unknown at this time
A6: AS | B6: American Samoa | C6: Available
A7: AD | B7: Andorra | C7: Coming Soon | D7: Service date is unknown at this time
A8: AO | B8: Angola | C8: Coming Soon | D8: Starting in 2026
A9: AI | B9: Anguilla | C9: Coming Soon | D9: Starting in 2026
A10: AQ | B10: Antarctica | C10: Available
A11: AG | B11: Antigua and Barbuda | C11: Available
A12: AR | B12: Argentina | C12: Available
A13: AM | B13: Armenia | C13: Available
A14: AW | B14: Aruba | C14: Coming Soon | D14: Starting in 2026
A15: AU | B15: Australia | C15: Available
A16: AT | B16: Austria | C16: Available
A17: AZ | B17: Azerbaijan | C17: Available
A18: BS | B18: Bahamas | C18: Available
A19: BH | B19: Bahrain | C19: Available
A20: BD | B20: Bangladesh | C20: Available
A21: BB | B21: Barbados | C21: Available
A22: BY | B22: Belarus | C22: Not Available (Blocked)
A23: BE | B23: Belgium | C23: Available
A24: BZ | B24: Belize | C24: Coming Soon | D24: Starting in 2026
A25: BJ | B25: Benin | C25: Available
A26: BM | B26: Bermuda | C26: Coming Soon | D26: Starting in 2026
A27: BT | B27: Bhutan | C27: Available
A28: BO | B28: Bolivia, Plurinational State of | C28: Available
A29: BA | B29: Bosnia and Herzegovina | C29: Coming Soon | D29: Starting in 2026
A30: BW | B30: Botswana | C30: Available
A31: BV | B31: Bouvet Island | C31: Available
A32: BR | B32: Brazil | C32: Available
A33: IO | B33: British Indian Ocean Territory | C33: Coming Soon | D33: Service date is unknown at this time
A34: BN | B34: Brunei Darussalam | C34: Coming Soon | D34: Pending regulatory approval
A35: BG | B35: Bulgaria | C35: Available
A36: BF | B36: Burkina Faso | C36: Coming Soon | D36: Starting in 2026
A37: BI | B37: Burundi | C37: Available
A38: CV | B38: Cabo Verde | C38: Available
A39: KH | B39: Cambodia | C39: Coming Soon | D39: Starting in 2026
A40: CM | B40: Cameroon | C40: Coming Soon | D40: Starting in 2026
...

Sheet Starlink countries with data
A1: Starlink Available / Coming Soon Countries — 2026 Market Data
A2: Filtered from 'starlink countries list' (Status = Available or Coming Soon); data linked from 'Population and Broadband subs' and 'penetration and ARPU' tabs, year 2026
A4: Region | B4: Country | C4: Starlink Status | D4: Data Tab Name | E4: Population (2026) | F4: Broadband Subs - Residential (2026) | G4: Penetration (2026) | H4: ARPU ($) (2026) | I4: Satellite ARPU ($) (2026)
A5: Asia Pacific
B6: Australia | C6: =INDEX('starlink countries list'!$C$2:$C$256,MATCH($B6,'starlink countries list'!$B$2:$B$256,0)) -> Available | D6: Australia | E6: =INDEX('Population and Broadband subs'!$D$12:$D$113,MATCH($D6,'Population and Broadband subs'!$A$12:$A$113,0)) -> 27230000 | F6: =INDEX('Population and Broadband subs'!$D$324:$D$425,MATCH($D6,'Population and Broadband subs'!$A$324:$A$425,0)) -> 7982893 | G6: =INDEX('penetration and ARPU'!$D$12:$D$113,MATCH($D6,'penetration and ARPU'!$A$12:$A$113,0)) -> 93.38 | H6: =INDEX('penetration and ARPU'!$D$1364:$D$1465,MATCH($D6,'penetration and ARPU'!$A$1364:$A$1465,0)) -> 34.66 | I6: =IFERROR(INDEX('penetration and ARPU'!$D$1780:$D$1881,MATCH($D6,'penetration and ARPU'!$A$1780:$A$1881,0)),"n/a") -> 20.208225
B7: Cambodia | C7: =INDEX('starlink countries list'!$C$2:$C$256,MATCH($B7,'starlink countries list'!$B$2:$B$256,0)) -> Coming Soon | D7: Cambodia | E7: =INDEX('Population and Broadband subs'!$D$12:$D$113,MATCH($D7,'Population and Broadband subs'!$A$12:$A$113,0)) -> 17427953 | F7: =INDEX('Population and Broadband subs'!$D$324:$D$425,MATCH($D7,'Population and Broadband subs'!$A$324:$A$425,0)) -> 760035 | G7: =INDEX('penetration and ARPU'!$D$12:$D$113,MATCH($D7,'penetration and ARPU'!$A$12:$A$113,0)) -> 18.51 | H7: =INDEX('penetration and ARPU'!$D$1364:$D$1465,MATCH($D7,'penetration and ARPU'!$A$1364:$A$1465,0)) -> 17.19 | I7: =IFERROR(INDEX('penetration and ARPU'!$D$1780:$D$1881,MATCH($D7,'penetration and ARPU'!$A$1780:$A$1881,0)),"n/a") -> NA
B8: Indonesia | C8: =INDEX('starlink countries list'!$C$2:$C$256,MATCH($B8,'starlink countries list'!$B$2:$B$256,0)) -> Available | D8: Indonesia | E8: =INDEX('Population and Broadband subs'!$D$12:$D$113,MATCH($D8,'Population and Broadband subs'!$A$12:$A$113,0)) -> 287148600 | F8: =INDEX('Population and Broadband subs'!$D$324:$D$425,MATCH($D8,'Population and Broadband subs'!$A$324:$A$425,0)) -> 18616010 | G8: =INDEX('penetration and ARPU'!$D$12:$D$113,MATCH($D8,'penetration and ARPU'!$A$12:$A$113,0)) -> 25.17 | H8: =INDEX('penetration and ARPU'!$D$1364:$D$1465,MATCH($D8,'penetration and ARPU'!$A$1364:$A$1465,0)) -> 12.14 | I8: =IFERROR(INDEX('penetration and ARPU'!$D$1780:$D$1881,MATCH($D8,'penetration and ARPU'!$A$1780:$A$1881,0)),"n/a") -> 15.810295
B9: Japan | C9: =INDEX('starlink countries list'!$C$2:$C$256,MATCH($B9,'starlink countries list'!$B$2:$B$256,0)) -> Available | D9: Japan | E9: =INDEX('Population and Broadband subs'!$D$12:$D$113,MATCH($D9,'Population and Broadband subs'!$A$12:$A$113,0)) -> 123400000 | F9: =INDEX('Population and Broadband subs'!$D$324:$D$425,MATCH($D9,'Population and Broadband subs'!$A$324:$A$425,0)) -> 53909050 | G9: =INDEX('penetration and ARPU'!$D$12:$D$113,MATCH($D9,'penetration and ARPU'!$A$12:$A$113,0)) -> 87.64 | H9: =INDEX('penetration and ARPU'!$D$1364:$D$1465,MATCH($D9,'penetration and ARPU'!$A$1364:$A$1465,0)) -> 24.66 | I9: =IFERROR(INDEX('penetration and ARPU'!$D$1780:$D$1881,MATCH($D9,'penetration and ARPU'!$A$1780:$A$1881,0)),"n/a") -> 41.485826
B10: Korea, Republic of | C10: =INDEX('starlink countries list'!$C$2:$C$256,MATCH($B10,'starlink countries list'!$B$2:$B$256,0)) -> Available | D10: South Korea | E10: =INDEX('Population and Broadband subs'!$D$12:$D$113,MATCH($D10,'Population and Broadband subs'!$A$12:$A$113,0)) -> 51320000 | F10: =INDEX('Population and Broadband subs'!$D$324:$D$425,MATCH($D10,'Population and Broadband subs'!$A$324:$A$425,0)) -> 25060177 | G10: =INDEX('penetration and ARPU'!$D$12:$D$113,MATCH($D10,'penetration and ARPU'!$A$12:$A$113,0)) -> 112.57 | H10: =INDEX('penetration and ARPU'!$D$1364:$D$1465,MATCH($D10,'penetration and ARPU'!$A$1364:$A$1465,0)) -> 14.14 | I10: =IFERROR(INDEX('penetration and ARPU'!$D$1780:$D$1881,MATCH($D10,'penetration and ARPU'!$A$1780:$A$1881,0)),"n/a") -> NA
B11: Lao People's Democratic Republic | C11: =INDEX('starlink countries list'!$C$2:$C$256,MATCH($B11,'starlink countries list'!$B$2:$B$256,0)) -> Coming Soon | D11: Laos | E11: =INDEX('Population and Broadband subs'!$D$12:$D$113,MATCH($D11,'Population and Broadband subs'!$A$12:$A$113,0)) -> 7914207 | F11: =INDEX('Population and Broadband subs'!$D$324:$D$425,MATCH($D11,'Population and Broadband subs'!$A$324:$A$425,0)) -> 271294 | G11: =INDEX('penetration and ARPU'!$D$12:$D$113,MATCH($D11,'penetration and ARPU'!$A$12:$A$113,0)) -> 18.44 | H11: =INDEX('penetration and ARPU'!$D$1364:$D$1465,MATCH($D11,'penetration and ARPU'!$A$1364:$A$1465,0)) -> 15.25 | I11: =IFERROR(INDEX('penetration and ARPU'!$D$1780:$D$1881,MATCH($D11,'penetration and ARPU'!$A$1780:$A$1881,0)),"n/a") -> NA
B12: Malaysia | C12: =INDEX('starlink countries list'!$C$2:$C$256,MATCH($B12,'starlink countries list'!$B$2:$B$256,0)) -> Available | D12: Malaysia | E12: =INDEX('Population and Broadband subs'!$D$12:$D$113,MATCH($D12,'Population and Broadband subs'!$A$12:$A$113,0)) -> 36120000 | F12: =INDEX('Population and Broadband subs'!$D$324:$D$425,MATCH($D12,'Population and Broadband subs'!$A$324:$A$425,0)) -> 5273631 | G12: =INDEX('penetration and ARPU'!$D$12:$D$113,MATCH($D12,'penetration and ARPU'!$A$12:$A$113,0)) -> 55.9 | H12: =INDEX('penetration and ARPU'!$D$1364:$D$1465,MATCH($D12,'penetration and ARPU'!$A$1364:$A$1465,0)) -> 31.46 | I12: =IFERROR(INDEX('penetration and ARPU'!$D$1780:$D$1881,MATCH($D12,'penetration and ARPU'!$A$1780:$A$1881,0)),"n/a") -> 33.618076
B13: Myanmar | C13: =INDEX('starlink countries list'!$C$2:$C$256,MATCH($B13,'starlink countries list'!$B$2:$B$256,0)) -> Coming Soon | D13: Myanmar | E13: =INDEX('Population and Broadband subs'!$D$12:$D$113,MATCH($D13,'Population and Broadband subs'!$A$12:$A$113,0)) -> 55649307 | F13: =INDEX('Population and Broadband subs'!$D$324:$D$425,MATCH($D13,'Population and Broadband subs'!$A$324:$A$425,0)) -> 1440690 | G13: =INDEX('penetration and ARPU'!$D$12:$D$113,MATCH($D13,'penetration and ARPU'!$A$12:$A$113,0)) -> 12.17 | H13: =INDEX('penetration and ARPU'!$D$1364:$D$1465,MATCH($D13,'penetration and ARPU'!$A$1364:$A$1465,0)) -> 6.59 | I13: =IFERROR(INDEX('penetration and ARPU'!$D$1780:$D$1881,MATCH($D13,'penetration and ARPU'!$A$1780:$A$1881,0)),"n/a") -> 14.021602
B14: New Zealand | C14: =INDEX('starlink countries list'!$C$2:$C$256,MATCH($B14,'starlink countries list'!$B$2:$B$256,0)) -> Available | D14: New Zealand | E14: =INDEX('Population and Broadband subs'!$D$12:$D$113,MATCH($D14,'Population and Broadband subs'!$A$12:$A$113,0)) -> 5290000 | F14: =INDEX('Population and Broadband subs'!$D$324:$D$425,MATCH($D14,'Population and Broadband subs'!$A$324:$A$425,0)) -> 1648032 | G14: =INDEX('penetration and ARPU'!$D$12:$D$113,MATCH($D14,'penetration and ARPU'!$A$12:$A$113,0)) -> 91.95 | H14: =INDEX('penetration and ARPU'!$D$1364:$D$1465,MATCH($D14,'penetration and ARPU'!$A$1364:$A$1465,0)) -> 42.19 | I14: =IFERROR(INDEX('penetration and ARPU'!$D$1780:$D$1881,MATCH($D14,'penetration and ARPU'!$A$1780:$A$1881,0)),"n/a") -> 74.806329
B15: Philippines | C15: =INDEX('starlink countries list'!$C$2:$C$256,MATCH($B15,'starlink countries list'!$B$2:$B$256,0)) -> Available | D15: Philippines | E15: =INDEX('Population and Broadband subs'!$D$12:$D$113,MATCH($D15,'Population and Broadband subs'!$A$12:$A$113,0)) -> 119850000 | F15: =INDEX('Population and Broadband subs'!$D$324:$D$425,MATCH($D15,'Population and Broadband subs'!$A$324:$A$425,0)) -> 12651229 | G15: =INDEX('penetration and ARPU'!$D$12:$D$113,MATCH($D15,'penetration and ARPU'!$A$12:$A$113,0)) -> 44.16 | H15: =INDEX('penetration and ARPU'!$D$1364:$D$1465,MATCH($D15,'penetration and ARPU'!$A$1364:$A$1465,0)) -> 19.52 | I15: =IFERROR(INDEX('penetration and ARPU'!$D$1780:$D$1881,MATCH($D15,'penetration and ARPU'!$A$1780:$A$1881,0)),"n/a") -> 44.802737
B16: Singapore | C16: =INDEX('starlink countries list'!$C$2:$C$256,MATCH($B16,'starlink countries list'!$B$2:$B$256,0)) -> Available | D16: Singapore | E16: =INDEX('Population and Broadband subs'!$D$12:$D$113,MATCH($D16,'Population and Broadband subs'!$A$12:$A$113,0)) -> 5860000 | F16: =INDEX('Population and Broadband subs'!$D$324:$D$425,MATCH($D16,'Population and Broadband subs'!$A$324:$A$425,0)) -> 1527944 | G16: =INDEX('penetration and ARPU'!$D$12:$D$113,MATCH($D16,'penetration and ARPU'!$A$12:$A$113,0)) -> 102.13 | H16: =INDEX('penetration and ARPU'!$D$1364:$D$1465,MATCH($D16,'penetration and ARPU'!$A$1364:$A$1465,0)) -> 26.61 | I16: =IFERROR(INDEX('penetration and ARPU'!$D$1780:$D$1881,MATCH($D16,'penetration and ARPU'!$A$1780:$A$1881,0)),"n/a") -> NA
B17: Taiwan, Province of China | C17: =INDEX('starlink countries list'!$C$2:$C$256,MATCH($B17,'starlink countries list'!$B$2:$B$256,0)) -> Coming Soon | D17: Taiwan | E17: =INDEX('Population and Broadband subs'!$D$12:$D$113,MATCH($D17,'Population and Broadband subs'!$A$12:$A$113,0)) -> 23340000 | F17: =INDEX('Population and Broadband subs'!$D$324:$D$425,MATCH($D17,'Population and Broadband subs'!$A$324:$A$425,0)) -> 7347276 | G17: =INDEX('penetration and ARPU'!$D$12:$D$113,MATCH($D17,'penetration and ARPU'!$A$12:$A$113,0)) -> 76.61 | H17: =INDEX('penetration and ARPU'!$D$1364:$D$1465,MATCH($D17,'penetration and ARPU'!$A$1364:$A$1465,0)) -> 13.12 | I17: =IFERROR(INDEX('penetration and ARPU'!$D$1780:$D$1881,MATCH($D17,'penetration and ARPU'!$A$1780:$A$1881,0)),"n/a") -> NA
B18: Viet Nam | C18: =INDEX('starlink countries list'!$C$2:$C$256,MATCH($B18,'starlink countries list'!$B$2:$B$256,0)) -> Coming Soon | D18: Vietnam | E18: =INDEX('Population and Broadband subs'!$D$12:$D$113,MATCH($D18,'Population and Broadband subs'!$A$12:$A$113,0)) -> 101800000 | F18: =INDEX('Population and Broadband subs'!$D$324:$D$425,MATCH($D18,'Population and Broadband subs'!$A$324:$A$425,0)) -> 24897638 | G18: =INDEX('penetration and ARPU'!$D$12:$D$113,MATCH($D18,'penetration and ARPU'!$A$12:$A$113,0)) -> 84.02 | H18: =INDEX('penetration and ARPU'!$D$1364:$D$1465,MATCH($D18,'penetration and ARPU'!$A$1364:$A$1465,0)) -> 9.22 | I18: =IFERROR(INDEX('penetration and ARPU'!$D$1780:$D$1881,MATCH($D18,'penetration and ARPU'!$A$1780:$A$1881,0)),"n/a") -> 0
A20: Eastern Europe
B21: Bulgaria | C21: =INDEX('starlink countries list'!$C$2:$C$256,MATCH($B21,'starlink countries list'!$B$2:$B$256,0)) -> Available | D21: Bulgaria | E21: =INDEX('Population and Broadband subs'!$D$12:$D$113,MATCH($D21,'Population and Broadband subs'!$A$12:$A$113,0)) -> 6630000 | F21: =INDEX('Population and Broadband subs'!$D$324:$D$425,MATCH($D21,'Population and Broadband subs'!$A$324:$A$425,0)) -> 2686193 | G21: =INDEX('penetration and ARPU'!$D$12:$D$113,MATCH($D21,'penetration and ARPU'!$A$12:$A$113,0)) -> 93.65 | H21: =INDEX('penetration and ARPU'!$D$1364:$D$1465,MATCH($D21,'penetration and ARPU'!$A$1364:$A$1465,0)) -> NA | I21: =IFERROR(INDEX('penetration and ARPU'!$D$1780:$D$1881,MATCH($D21,'penetration and ARPU'!$A$1780:$A$1881,0)),"n/a") -> NA
B22: Croatia | C22: =INDEX('starlink countries list'!$C$2:$C$256,MATCH($B22,'starlink countries list'!$B$2:$B$256,0)) -> Available | D22: Croatia | E22: =INDEX('Population and Broadband subs'!$D$12:$D$113,MATCH($D22,'Population and Broadband subs'!$A$12:$A$113,0)) -> 3940000 | F22: =INDEX('Population and Broadband subs'!$D$324:$D$425,MATCH($D22,'Population and Broadband subs'!$A$324:$A$425,0)) -> 1204292 | G22: =INDEX('penetration and ARPU'!$D$12:$D$113,MATCH($D22,'penetration and ARPU'!$A$12:$A$113,0)) -> 81.66 | H22: =INDEX('penetration and ARPU'!$D$1364:$D$1465,MATCH($D22,'penetration and ARPU'!$A$1364:$A$1465,0)) -> 18.11 | I22: =IFERROR(INDEX('penetration and ARPU'!$D$1780:$D$1881,MATCH($D22,'penetration and ARPU'!$A$1780:$A$1881,0)),"n/a") -> NA
B23: Czechia | C23: =INDEX('starlink countries list'!$C$2:$C$256,MATCH($B23,'starlink countries list'!$B$2:$B$256,0)) -> Available | D23: Czechia | E23: =INDEX('Population and Broadband subs'!$D$12:$D$113,MATCH($D23,'Population and Broadband subs'!$A$12:$A$113,0)) -> 10530000 | F23: =INDEX('Population and Broadband subs'!$D$324:$D$425,MATCH($D23,'Population and Broadband subs'!$A$324:$A$425,0)) -> 3720133 | G23: =INDEX('penetration and ARPU'!$D$12:$D$113,MATCH($D23,'penetration and ARPU'!$A$12:$A$113,0)) -> 80.95 | H23: =INDEX('penetration and ARPU'!$D$1364:$D$1465,MATCH($D23,'penetration and ARPU'!$A$1364:$A$1465,0)) -> NA | I23: =IFERROR(INDEX('penetration and ARPU'!$D$1780:$D$1881,MATCH($D23,'penetration and ARPU'!$A$1780:$A$1881,0)),"n/a") -> NA
B24: Estonia | C24: =INDEX('starlink countries list'!$C$2:$C$256,MATCH($B24,'starlink countries list'!$B$2:$B$256,0)) -> Available | D24: Estonia | E24: =INDEX('Population and Broadband subs'!$D$12:$D$113,MATCH($D24,'Population and Broadband subs'!$A$12:$A$113,0)) -> 1330000 | F24: =INDEX('Population and Broadband subs'!$D$324:$D$425,MATCH($D24,'Population and Broadband subs'!$A$324:$A$425,0)) -> 498071 | G24: =INDEX('penetration and ARPU'!$D$12:$D$113,MATCH($D24,'penetration and ARPU'!$A$12:$A$113,0)) -> 75.45 | H24: =INDEX('penetration and ARPU'!$D$1364:$D$1465,MATCH($D24,'penetration and ARPU'!$A$1364:$A$1465,0)) -> NA | I24: =IFERROR(INDEX('penetration and ARPU'!$D$1780:$D$1881,MATCH($D24,'penetration and ARPU'!$A$1780:$A$1881,0)),"n/a") -> NA
B25: Hungary | C25: =INDEX('starlink countries list'!$C$2:$C$256,MATCH($B25,'starlink countries list'!$B$2:$B$256,0)) -> Available | D25: Hungary | E25: =INDEX('Population and Broadband subs'!$D$12:$D$113,MATCH($D25,'Population and Broadband subs'!$A$12:$A$113,0)) -> 9590000 | F25: =INDEX('Population and Broadband subs'!$D$324:$D$425,MATCH($D25,'Population and Broadband subs'!$A$324:$A$425,0)) -> 3508829 | G25: =INDEX('penetration and ARPU'!$D$12:$D$113,MATCH($D25,'penetration and ARPU'!$A$12:$A$113,0)) -> 86.79 | H25: =INDEX('penetration and ARPU'!$D$1364:$D$1465,MATCH($D25,'penetration and ARPU'!$A$1364:$A$1465,0)) -> NA | I25: =IFERROR(INDEX('penetration and ARPU'!$D$1780:$D$1881,MATCH($D25,'penetration and ARPU'!$A$1780:$A$1881,0)),"n/a") -> NA
B26: Latvia | C26: =INDEX('starlink countries list'!$C$2:$C$256,MATCH($B26,'starlink countries list'!$B$2:$B$256,0)) -> Available | D26: Latvia | E26: =INDEX('Population and Broadband subs'!$D$12:$D$113,MATCH($D26,'Population and Broadband subs'!$A$12:$A$113,0)) -> 1840000 | F26: =INDEX('Population and Broadband subs'!$D$324:$D$425,MATCH($D26,'Population and Broadband subs'!$A$324:$A$425,0)) -> 479552 | G26: =INDEX('penetration and ARPU'!$D$12:$D$113,MATCH($D26,'penetration and ARPU'!$A$12:$A$113,0)) -> 56.94 | H26: =INDEX('penetration and ARPU'!$D$1364:$D$1465,MATCH($D26,'penetration and ARPU'!$A$1364:$A$1465,0)) -> NA | I26: =IFERROR(INDEX('penetration and ARPU'!$D$1780:$D$1881,MATCH($D26,'penetration and ARPU'!$A$1780:$A$1881,0)),"n/a") -> NA
B27: Lithuania | C27: =INDEX('starlink countries list'!$C$2:$C$256,MATCH($B27,'starlink countries list'!$B$2:$B$256,0)) -> Available | D27: Lithuania | E27: =INDEX('Population and Broadband subs'!$D$12:$D$113,MATCH($D27,'Population and Broadband subs'!$A$12:$A$113,0)) -> 2650000 | F27: =INDEX('Population and Broadband subs'!$D$324:$D$425,MATCH($D27,'Population and Broadband subs'!$A$324:$A$425,0)) -> 779389 | G27: =INDEX('penetration and ARPU'!$D$12:$D$113,MATCH($D27,'penetration and ARPU'!$A$12:$A$113,0)) -> 44.72 | H27: =INDEX('penetration and ARPU'!$D$1364:$D$1465,MATCH($D27,'penetration and ARPU'!$A$1364:$A$1465,0)) -> NA | I27: =IFERROR(INDEX('penetration and ARPU'!$D$1780:$D$1881,MATCH($D27,'penetration and ARPU'!$A$1780:$A$1881,0)),"n/a") -> NA
B28: Poland | C28: =INDEX('starlink countries list'!$C$2:$C$256,MATCH($B28,'starlink countries list'!$B$2:$B$256,0)) -> Available | D28: Poland | E28: =INDEX('Population and Broadband subs'!$D$12:$D$113,MATCH($D28,'Population and Broadband subs'!$A$12:$A$113,0)) -> 37420000 | F28: =INDEX('Population and Broadband subs'!$D$324:$D$425,MATCH($D28,'Population and Broadband subs'!$A$324:$A$425,0)) -> 10421021 | G28: =INDEX('penetration and ARPU'!$D$12:$D$113,MATCH($D28,'penetration and ARPU'!$A$12:$A$113,0)) -> 67.6 | H28: =INDEX('penetration and ARPU'!$D$1364:$D$1465,MATCH($D28,'penetration and ARPU'!$A$1364:$A$1465,0)) -> 12.79 | I28: =IFERROR(INDEX('penetration and ARPU'!$D$1780:$D$1881,MATCH($D28,'penetration and ARPU'!$A$1780:$A$1881,0)),"n/a") -> NA
B29: Romania | C29: =INDEX('starlink countries list'!$C$2:$C$256,MATCH($B29,'starlink countries list'!$B$2:$B$256,0)) -> Available | D29: Romania | E29: =INDEX('Population and Broadband subs'!$D$12:$D$113,MATCH($D29,'Population and Broadband subs'!$A$12:$A$113,0)) -> 18800000 | F29: =INDEX('Population and Broadband subs'!$D$324:$D$425,MATCH($D29,'Population and Broadband subs'!$A$324:$A$425,0)) -> 7148437 | G29: =INDEX('penetration and ARPU'!$D$12:$D$113,MATCH($D29,'penetration and ARPU'!$A$12:$A$113,0)) -> 89.83 | H29: =INDEX('penetration and ARPU'!$D$1364:$D$1465,MATCH($D29,'penetration and ARPU'!$A$1364:$A$1465,0)) -> NA | I29: =IFERROR(INDEX('penetration and ARPU'!$D$1780:$D$1881,MATCH($D29,'penetration and ARPU'!$A$1780:$A$1881,0)),"n/a") -> NA
B30: Serbia | C30: =INDEX('starlink countries list'!$C$2:$C$256,MATCH($B30,'starlink countries list'!$B$2:$B$256,0)) -> Coming Soon | D30: Serbia | E30: =INDEX('Population and Broadband subs'!$D$12:$D$113,MATCH($D30,'Population and Broadband subs'!$A$12:$A$113,0)) -> 6490000 | F30: =INDEX('Population and Broadband subs'!$D$324:$D$425,MATCH($D30,'Population and Broadband subs'!$A$324:$A$425,0)) -> 2293279 | G30: =INDEX('penetration and ARPU'!$D$12:$D$113,MATCH($D30,'penetration and ARPU'!$A$12:$A$113,0)) -> 89.3 | H30: =INDEX('penetration and ARPU'!$D$1364:$D$1465,MATCH($D30,'penetration and ARPU'!$A$1364:$A$1465,0)) -> NA | I30: =IFERROR(INDEX('penetration and ARPU'!$D$1780:$D$1881,MATCH($D30,'penetration and ARPU'!$A$1780:$A$1881,0)),"n/a") -> NA
B31: Slovakia | C31: =INDEX('starlink countries list'!$C$2:$C$256,MATCH($B31,'starlink countries list'!$B$2:$B$256,0)) -> Available | D31: Slovakia | E31: =INDEX('Population and Broadband subs'!$D$12:$D$113,MATCH($D31,'Population and Broadband subs'!$A$12:$A$113,0)) -> 5440000 | F31: =INDEX('Population and Broadband subs'!$D$324:$D$425,MATCH($D31,'Population and Broadband subs'!$A$324:$A$425,0)) -> 1759589 | G31: =INDEX('penetration and ARPU'!$D$12:$D$113,MATCH($D31,'penetration and ARPU'!$A$12:$A$113,0)) -> 97.15 | H31: =INDEX('penetration and ARPU'!$D$1364:$D$1465,MATCH($D31,'penetration and ARPU'!$A$1364:$A$1465,0)) -> 0 | I31: =IFERROR(INDEX('penetration and ARPU'!$D$1780:$D$1881,MATCH($D31,'penetration and ARPU'!$A$1780:$A$1881,0)),"n/a") -> NA
B32: Slovenia | C32: =INDEX('starlink countries list'!$C$2:$C$256,MATCH($B32,'starlink countries list'!$B$2:$B$256,0)) -> Available | D32: Slovenia | E32: =INDEX('Population and Broadband subs'!$D$12:$D$113,MATCH($D32,'Population and Broadband subs'!$A$12:$A$113,0)) -> 2120000 | F32: =INDEX('Population and Broadband subs'!$D$324:$D$425,MATCH($D32,'Population and Broadband subs'!$A$324:$A$425,0)) -> 773555 | G32: =INDEX('penetration and ARPU'!$D$12:$D$113,MATCH($D32,'penetration and ARPU'!$A$12:$A$113,0)) -> 89.73 | H32: =INDEX('penetration and ARPU'!$D$1364:$D$1465,MATCH($D32,'penetration and ARPU'!$A$1364:$A$1465,0)) -> NA | I32: =IFERROR(INDEX('penetration and ARPU'!$D$1780:$D$1881,MATCH($D32,'penetration and ARPU'!$A$1780:$A$1881,0)),"n/a") -> NA
B33: Türkiye | C33: =INDEX('starlink countries list'!$C$2:$C$256,MATCH("T*rkiye",'starlink countries list'!$B$2:$B$256,0)) -> Coming Soon | D33: Türkiye | E33: =INDEX('Population and Broadband subs'!$D$12:$D$113,MATCH($D33,'Population and Broadband subs'!$A$12:$A$113,0)) -> 87930000 | F33: =INDEX('Population and Broadband subs'!$D$324:$D$425,MATCH($D33,'Population and Broadband subs'!$A$324:$A$425,0)) -> 24574121 | G33: =INDEX('penetration and ARPU'!$D$12:$D$113,MATCH($D33,'penetration and ARPU'!$A$12:$A$113,0)) -> 82.44 | H33: =INDEX('penetration and ARPU'!$D$1364:$D$1465,MATCH($D33,'penetration and ARPU'!$A$1364:$A$1465,0)) -> NA | I33: =IFERROR(INDEX('penetration and ARPU'!$D$1780:$D$1881,MATCH($D33,'penetration and ARPU'!$A$1780:$A$1881,0)),"n/a") -> NA
A35: Latin America and Caribbean
B36: Argentina | C36: =INDEX('starlink countries list'!$C$2:$C$256,MATCH($B36,'starlink countries list'!$B$2:$B$256,0)) -> Available | D36: Argentina | E36: =INDEX('Population and Broadband subs'!$D$12:$D$113,MATCH($D36,'Population and Broadband subs'!$A$12:$A$113,0)) -> 46000000 | F36: =INDEX('Population and Broadband subs'!$D$324:$D$425,MATCH($D36,'Population and Broadband subs'!$A$324:$A$425,0)) -> 12739593 | G36: =INDEX('penetration and ARPU'!$D$12:$D$113,MATCH($D36,'penetration and ARPU'!$A$12:$A$113,0)) -> 78.77 | H36: =INDEX('penetration and ARPU'!$D$1364:$D$1465,MATCH($D36,'penetration and ARPU'!$A$1364:$A$1465,0)) -> 17.34 | I36: =IFERROR(INDEX('penetration and ARPU'!$D$1780:$D$1881,MATCH($D36,'penetration and ARPU'!$A$1780:$A$1881,0)),"n/a") -> NA
B37: Bahamas | C37: =INDEX('starlink countries list'!$C$2:$C$256,MATCH($B37,'starlink countries list'!$B$2:$B$256,0)) -> Available | D37: Bahamas | E37: =INDEX('Population and Broadband subs'!$D$12:$D$113,MATCH($D37,'Population and Broadband subs'!$A$12:$A$113,0)) -> 429905 | F37: =INDEX('Population and Broadband subs'!$D$324:$D$425,MATCH($D37,'Population and Broadband subs'!$A$324:$A$425,0)) -> 77435 | G37: =INDEX('penetration and ARPU'!$D$12:$D$113,MATCH($D37,'penetration and ARPU'!$A$12:$A$113,0)) -> 59.54 | H37: =INDEX('penetration and ARPU'!$D$1364:$D$1465,MATCH($D37,'penetration and ARPU'!$A$1364:$A$1465,0)) -> NA | I37: =IFERROR(INDEX('penetration and ARPU'!$D$1780:$D$1881,MATCH($D37,'penetration and ARPU'!$A$1780:$A$1881,0)),"n/a") -> NA
B38: Barbados | C38: =INDEX('starlink countries list'!$C$2:$C$256,MATCH($B38,'starlink countries list'!$B$2:$B$256,0)) -> Available | D38: Barbados | E38: =INDEX('Population and Broadband subs'!$D$12:$D$113,MATCH($D38,'Population and Broadband subs'!$A$12:$A$113,0)) -> 291453 | F38: =INDEX('Population and Broadband subs'!$D$324:$D$425,MATCH($D38,'Population and Broadband subs'!$A$324:$A$425,0)) -> 97018 | G38: =INDEX('penetration and ARPU'!$D$12:$D$113,MATCH($D38,'penetration and ARPU'!$A$12:$A$113,0)) -> 86.64 | H38: =INDEX('penetration and ARPU'!$D$1364:$D$1465,MATCH($D38,'penetration and ARPU'!$A$1364:$A$1465,0)) -> NA | I38: =IFERROR(INDEX('penetration and ARPU'!$D$1780:$D$1881,MATCH($D38,'penetration and ARPU'!$A$1780:$A$1881,0)),"n/a") -> NA
B39: Bolivia, Plurinational State of | C39: =INDEX('starlink countries list'!$C$2:$C$256,MATCH($B39,'starlink countries list'!$B$2:$B$256,0)) -> Available | D39: Bolivia | E39: =INDEX('Population and Broadband subs'!$D$12:$D$113,MATCH($D39,'Population and Broadband subs'!$A$12:$A$113,0)) -> 12630000 | F39: =INDEX('Population and Broadband subs'!$D$324:$D$425,MATCH($D39,'Population and Broadband subs'!$A$324:$A$425,0)) -> 1589668 | G39: =INDEX('penetration and ARPU'!$D$12:$D$113,MATCH($D39,'penetration and ARPU'!$A$12:$A$113,0)) -> 37.15 | H39: =INDEX('penetration and ARPU'!$D$1364:$D$1465,MATCH($D39,'penetration and ARPU'!$A$1364:$A$1465,0)) -> NA | I39: =IFERROR(INDEX('penetration and ARPU'!$D$1780:$D$1881,MATCH($D39,'penetration and ARPU'!$A$1780:$A$1881,0)),"n/a") -> NA
B40: Brazil | C40: =INDEX('starlink countries list'!$C$2:$C$256,MATCH($B40,'starlink countries list'!$B$2:$B$256,0)) -> Available | D40: Brazil | E40: =INDEX('Population and Broadband subs'!$D$12:$D$113,MATCH($D40,'Population and Broadband subs'!$A$12:$A$113,0)) -> 213560000 | F40: =INDEX('Population and Broadband subs'!$D$324:$D$425,MATCH($D40,'Population and Broadband subs'!$A$324:$A$425,0)) -> 50287033 | G40: =INDEX('penetration and ARPU'!$D$12:$D$113,MATCH($D40,'penetration and ARPU'!$A$12:$A$113,0)) -> 65.84 | H40: =INDEX('penetration and ARPU'!$D$1364:$D$1465,MATCH($D40,'penetration and ARPU'!$A$1364:$A$1465,0)) -> 17.81 | I40: =IFERROR(INDEX('penetration and ARPU'!$D$1780:$D$1881,MATCH($D40,'penetration and ARPU'!$A$1780:$A$1881,0)),"n/a") -> 36.323708
B41: Chile | C41: =INDEX('starlink countries list'!$C$2:$C$256,MATCH($B41,'starlink countries list'!$B$2:$B$256,0)) -> Available | D41: Chile | E41: =INDEX('Population and Broadband subs'!$D$12:$D$113,MATCH($D41,'Population and Broadband subs'!$A$12:$A$113,0)) -> 19950000 | F41: =INDEX('Population and Broadband subs'!$D$324:$D$425,MATCH($D41,'Population and Broadband subs'!$A$324:$A$425,0)) -> 4553468 | G41: =INDEX('penetration and ARPU'!$D$12:$D$113,MATCH($D41,'penetration and ARPU'!$A$12:$A$113,0)) -> 74.08 | H41: =INDEX('penetration and ARPU'!$D$1364:$D$1465,MATCH($D41,'penetration and ARPU'!$A$1364:$A$1465,0)) -> 17.51 | I41: =IFERROR(INDEX('penetration and ARPU'!$D$1780:$D$1881,MATCH($D41,'penetration and ARPU'!$A$1780:$A$1881,0)),"n/a") -> NA
B42: Colombia | C42: =INDEX('starlink countries list'!$C$2:$C$256,MATCH($B42,'starlink countries list'!$B$2:$B$256,0)) -> Available | D42: Colombia | E42: =INDEX('Population and Broadband subs'!$D$12:$D$113,MATCH($D42,'Population and Broadband subs'!$A$12:$A$113,0)) -> 52900000 | F42: =INDEX('Population and Broadband subs'!$D$324:$D$425,MATCH($D42,'Population and Broadband subs'!$A$324:$A$425,0)) -> 9074736 | G42: =INDEX('penetration and ARPU'!$D$12:$D$113,MATCH($D42,'penetration and ARPU'!$A$12:$A$113,0)) -> 47.11 | H42: =INDEX('penetration and ARPU'!$D$1364:$D$1465,MATCH($D42,'penetration and ARPU'!$A$1364:$A$1465,0)) -> 13.09 | I42: =IFERROR(INDEX('penetration and ARPU'!$D$1780:$D$1881,MATCH($D42,'penetration and ARPU'!$A$1780:$A$1881,0)),"n/a") -> NA
B43: Costa Rica | C43: =INDEX('starlink countries list'!$C$2:$C$256,MATCH($B43,'starlink countries list'!$B$2:$B$256,0)) -> Available | D43: Costa Rica | E43: =INDEX('Population and Broadband subs'!$D$12:$D$113,MATCH($D43,'Population and Broadband subs'!$A$12:$A$113,0)) -> 5170000 | F43: =INDEX('Population and Broadband subs'!$D$324:$D$425,MATCH($D43,'Population and Broadband subs'!$A$324:$A$425,0)) -> 1423540 | G43: =INDEX('penetration and ARPU'!$D$12:$D$113,MATCH($D43,'penetration and ARPU'!$A$12:$A$113,0)) -> 82.56 | H43: =INDEX('penetration and ARPU'!$D$1364:$D$1465,MATCH($D43,'penetration and ARPU'!$A$1364:$A$1465,0)) -> 29.56 | I43: =IFERROR(INDEX('penetration and ARPU'!$D$1780:$D$1881,MATCH($D43,'penetration and ARPU'!$A$1780:$A$1881,0)),"n/a") -> NA
...

Sheet Population vs Penetration
A1: Country | B1: Population (2026) | C1: Broadband Penetration (2026) | D1: Population (millions) | E1: Country Code | F1: ARPU ($) (2026) | H1: Country Code | I1: Penetration (2026) | J1: ARPU ($) (2026)
A2: ='Starlink countries with data'!B6 -> Australia | B2: ='Starlink countries with data'!E6 -> 27230000 | C2: ='Starlink countries with data'!G6 -> 93.38 | D2: =B2/1000000 -> 27.23 | E2: =INDEX('starlink countries list'!$A$2:$A$256,MATCH(A2,'starlink countries list'!$B$2:$B$256,0)) -> AU | F2: =IFERROR(INDEX('Starlink countries with data'!$H$6:$H$97,MATCH($A2,'Starlink countries with data'!$B$6:$B$97,0)),"NA") -> 34.66 | H2: =E2 -> AU | I2: =C2 -> 93.38 | J2: =F2 -> 34.66
A3: ='Starlink countries with data'!B7 -> Cambodia | B3: ='Starlink countries with data'!E7 -> 17427953 | C3: ='Starlink countries with data'!G7 -> 18.51 | D3: =B3/1000000 -> 17.427953 | E3: =INDEX('starlink countries list'!$A$2:$A$256,MATCH(A3,'starlink countries list'!$B$2:$B$256,0)) -> KH | F3: =IFERROR(INDEX('Starlink countries with data'!$H$6:$H$97,MATCH($A3,'Starlink countries with data'!$B$6:$B$97,0)),"NA") -> 17.19 | H3: =E3 -> KH | I3: =C3 -> 18.51 | J3: =F3 -> 17.19
A4: ='Starlink countries with data'!B8 -> Indonesia | B4: ='Starlink countries with data'!E8 -> 287148600 | C4: ='Starlink countries with data'!G8 -> 25.17 | D4: =B4/1000000 -> 287.1486 | E4: =INDEX('starlink countries list'!$A$2:$A$256,MATCH(A4,'starlink countries list'!$B$2:$B$256,0)) -> ID | F4: =IFERROR(INDEX('Starlink countries with data'!$H$6:$H$97,MATCH($A4,'Starlink countries with data'!$B$6:$B$97,0)),"NA") -> 12.14 | H4: =E4 -> ID | I4: =C4 -> 25.17 | J4: =F4 -> 12.14
A5: ='Starlink countries with data'!B9 -> Japan | B5: ='Starlink countries with data'!E9 -> 123400000 | C5: ='Starlink countries with data'!G9 -> 87.64 | D5: =B5/1000000 -> 123.4 | E5: =INDEX('starlink countries list'!$A$2:$A$256,MATCH(A5,'starlink countries list'!$B$2:$B$256,0)) -> JP | F5: =IFERROR(INDEX('Starlink countries with data'!$H$6:$H$97,MATCH($A5,'Starlink countries with data'!$B$6:$B$97,0)),"NA") -> 24.66 | H5: =E5 -> JP | I5: =C5 -> 87.64 | J5: =F5 -> 24.66
A6: ='Starlink countries with data'!B10 -> Korea, Republic of | B6: ='Starlink countries with data'!E10 -> 51320000 | C6: ='Starlink countries with data'!G10 -> 112.57 | D6: =B6/1000000 -> 51.32 | E6: =INDEX('starlink countries list'!$A$2:$A$256,MATCH(A6,'starlink countries list'!$B$2:$B$256,0)) -> KR | F6: =IFERROR(INDEX('Starlink countries with data'!$H$6:$H$97,MATCH($A6,'Starlink countries with data'!$B$6:$B$97,0)),"NA") -> 14.14 | H6: =E6 -> KR | I6: =C6 -> 112.57 | J6: =F6 -> 14.14
A7: ='Starlink countries with data'!B11 -> Lao People's Democratic Republic | B7: ='Starlink countries with data'!E11 -> 7914207 | C7: ='Starlink countries with data'!G11 -> 18.44 | D7: =B7/1000000 -> 7.914207 | E7: =INDEX('starlink countries list'!$A$2:$A$256,MATCH(A7,'starlink countries list'!$B$2:$B$256,0)) -> LA | F7: =IFERROR(INDEX('Starlink countries with data'!$H$6:$H$97,MATCH($A7,'Starlink countries with data'!$B$6:$B$97,0)),"NA") -> 15.25 | H7: =E7 -> LA | I7: =C7 -> 18.44 | J7: =F7 -> 15.25
A8: ='Starlink countries with data'!B12 -> Malaysia | B8: ='Starlink countries with data'!E12 -> 36120000 | C8: ='Starlink countries with data'!G12 -> 55.9 | D8: =B8/1000000 -> 36.12 | E8: =INDEX('starlink countries list'!$A$2:$A$256,MATCH(A8,'starlink countries list'!$B$2:$B$256,0)) -> MY | F8: =IFERROR(INDEX('Starlink countries with data'!$H$6:$H$97,MATCH($A8,'Starlink countries with data'!$B$6:$B$97,0)),"NA") -> 31.46 | H8: =E8 -> MY | I8: =C8 -> 55.9 | J8: =F8 -> 31.46
A9: ='Starlink countries with data'!B13 -> Myanmar | B9: ='Starlink countries with data'!E13 -> 55649307 | C9: ='Starlink countries with data'!G13 -> 12.17 | D9: =B9/1000000 -> 55.649307 | E9: =INDEX('starlink countries list'!$A$2:$A$256,MATCH(A9,'starlink countries list'!$B$2:$B$256,0)) -> MM | F9: =IFERROR(INDEX('Starlink countries with data'!$H$6:$H$97,MATCH($A9,'Starlink countries with data'!$B$6:$B$97,0)),"NA") -> 6.59 | H9: =E9 -> MM | I9: =C9 -> 12.17 | J9: =F9 -> 6.59
A10: ='Starlink countries with data'!B14 -> New Zealand | B10: ='Starlink countries with data'!E14 -> 5290000 | C10: ='Starlink countries with data'!G14 -> 91.95 | D10: =B10/1000000 -> 5.29 | E10: =INDEX('starlink countries list'!$A$2:$A$256,MATCH(A10,'starlink countries list'!$B$2:$B$256,0)) -> NZ | F10: =IFERROR(INDEX('Starlink countries with data'!$H$6:$H$97,MATCH($A10,'Starlink countries with data'!$B$6:$B$97,0)),"NA") -> 42.19 | H10: =E10 -> NZ | I10: =C10 -> 91.95 | J10: =F10 -> 42.19
A11: ='Starlink countries with data'!B15 -> Philippines | B11: ='Starlink countries with data'!E15 -> 119850000 | C11: ='Starlink countries with data'!G15 -> 44.16 | D11: =B11/1000000 -> 119.85 | E11: =INDEX('starlink countries list'!$A$2:$A$256,MATCH(A11,'starlink countries list'!$B$2:$B$256,0)) -> PH | F11: =IFERROR(INDEX('Starlink countries with data'!$H$6:$H$97,MATCH($A11,'Starlink countries with data'!$B$6:$B$97,0)),"NA") -> 19.52 | H11: =E11 -> PH | I11: =C11 -> 44.16 | J11: =F11 -> 19.52
A12: ='Starlink countries with data'!B16 -> Singapore | B12: ='Starlink countries with data'!E16 -> 5860000 | C12: ='Starlink countries with data'!G16 -> 102.13 | D12: =B12/1000000 -> 5.86 | E12: =INDEX('starlink countries list'!$A$2:$A$256,MATCH(A12,'starlink countries list'!$B$2:$B$256,0)) -> SG | F12: =IFERROR(INDEX('Starlink countries with data'!$H$6:$H$97,MATCH($A12,'Starlink countries with data'!$B$6:$B$97,0)),"NA") -> 26.61 | H12: =E12 -> SG | I12: =C12 -> 102.13 | J12: =F12 -> 26.61
A13: ='Starlink countries with data'!B17 -> Taiwan, Province of China | B13: ='Starlink countries with data'!E17 -> 23340000 | C13: ='Starlink countries with data'!G17 -> 76.61 | D13: =B13/1000000 -> 23.34 | E13: =INDEX('starlink countries list'!$A$2:$A$256,MATCH(A13,'starlink countries list'!$B$2:$B$256,0)) -> TW | F13: =IFERROR(INDEX('Starlink countries with data'!$H$6:$H$97,MATCH($A13,'Starlink countries with data'!$B$6:$B$97,0)),"NA") -> 13.12 | H13: =E13 -> TW | I13: =C13 -> 76.61 | J13: =F13 -> 13.12
A14: ='Starlink countries with data'!B18 -> Viet Nam | B14: ='Starlink countries with data'!E18 -> 101800000 | C14: ='Starlink countries with data'!G18 -> 84.02 | D14: =B14/1000000 -> 101.8 | E14: =INDEX('starlink countries list'!$A$2:$A$256,MATCH(A14,'starlink countries list'!$B$2:$B$256,0)) -> VN | F14: =IFERROR(INDEX('Starlink countries with data'!$H$6:$H$97,MATCH($A14,'Starlink countries with data'!$B$6:$B$97,0)),"NA") -> 9.22 | H14: =E14 -> VN | I14: =C14 -> 84.02 | J14: =F14 -> 9.22
A15: ='Starlink countries with data'!B21 -> Bulgaria | B15: ='Starlink countries with data'!E21 -> 6630000 | C15: ='Starlink countries with data'!G21 -> 93.65 | D15: =B15/1000000 -> 6.63 | E15: =INDEX('starlink countries list'!$A$2:$A$256,MATCH(A15,'starlink countries list'!$B$2:$B$256,0)) -> BG | F15: =IFERROR(INDEX('Starlink countries with data'!$H$6:$H$97,MATCH($A15,'Starlink countries with data'!$B$6:$B$97,0)),"NA") -> NA | H15: =E16 -> HR | I15: =C16 -> 81.66 | J15: =F16 -> 18.11
A16: ='Starlink countries with data'!B22 -> Croatia | B16: ='Starlink countries with data'!E22 -> 3940000 | C16: ='Starlink countries with data'!G22 -> 81.66 | D16: =B16/1000000 -> 3.94 | E16: =INDEX('starlink countries list'!$A$2:$A$256,MATCH(A16,'starlink countries list'!$B$2:$B$256,0)) -> HR | F16: =IFERROR(INDEX('Starlink countries with data'!$H$6:$H$97,MATCH($A16,'Starlink countries with data'!$B$6:$B$97,0)),"NA") -> 18.11 | H16: =E22 -> PL | I16: =C22 -> 67.6 | J16: =F22 -> 12.79
A17: ='Starlink countries with data'!B23 -> Czechia | B17: ='Starlink countries with data'!E23 -> 10530000 | C17: ='Starlink countries with data'!G23 -> 80.95 | D17: =B17/1000000 -> 10.53 | E17: =INDEX('starlink countries list'!$A$2:$A$256,MATCH(A17,'starlink countries list'!$B$2:$B$256,0)) -> CZ | F17: =IFERROR(INDEX('Starlink countries with data'!$H$6:$H$97,MATCH($A17,'Starlink countries with data'!$B$6:$B$97,0)),"NA") -> NA | H17: =E28 -> AR | I17: =C28 -> 78.77 | J17: =F28 -> 17.34
A18: ='Starlink countries with data'!B24 -> Estonia | B18: ='Starlink countries with data'!E24 -> 1330000 | C18: ='Starlink countries with data'!G24 -> 75.45 | D18: =B18/1000000 -> 1.33 | E18: =INDEX('starlink countries list'!$A$2:$A$256,MATCH(A18,'starlink countries list'!$B$2:$B$256,0)) -> EE | F18: =IFERROR(INDEX('Starlink countries with data'!$H$6:$H$97,MATCH($A18,'Starlink countries with data'!$B$6:$B$97,0)),"NA") -> NA | H18: =E32 -> BR | I18: =C32 -> 65.84 | J18: =F32 -> 17.81
